Workbook

Sheet Sheet4
B2: ADEM DUMAN - 2021-2025
C3: HESAP ÖZETİ
B5: DÖNEM 1 Aylık Tutar | F5: =E9/12 -> 2000
C6: AÜ TL-Adet | E6: 2324 | F6: =E9/E6 -> 10.327022
C7: 28-02-2021 27-02-2022 DÖNEMİ
E8: tutar | F8: bakiye
C9: DÖNEM 1 Hesabı | E9: 24000 | F9: =E9 -> 24000
B10: 44250 | C10: Ödeme | E10: -2000 | F10: =F9+E10 -> 22000
A11: 1 | B11: 44285 | C11: Ödeme | E11: -2000 | F11: =F10+E11 -> 20000
A12: 2 | B12: 44316 | C12: Ödeme | E12: -2000 | F12: =F11+E12 -> 18000
A13: 3 | B13: 44346 | C13: Ödeme | E13: -1000 | F13: =F12+E13 -> 17000
A14: 4 | B14: 44377 | C14: Ödeme | E14: -3000 | F14: =F13+E14 -> 14000
A15: 5 | B15: 44407 | C15: Ödeme | E15: -4000 | F15: =F14+E15 -> 10000
A16: 6 | B16: 44788 | C16: Ödeme | E16: -10000 | F16: =F15+E16 -> 0
C17: 2021-22 Tutarı 24000 TL | F17: =F16+E17 -> 0
E18: Dönem Sonu Kalan BAKİYE | F18: =F17 -> 0
B20: DÖNEM 2 Aylık Tutar | F20: =E26/12 -> 3088
C21: AÜ | E21: 2825 | F21: =E26/E21 -> 13.117168
C22: 28-02-2022 27-02-2023 DÖNEMİ
E23: tutar | F23: bakiye
C24: DÖNEM 1 Hesabı 24000 | F24: =E24 -> 0
C25: DÖNEM 1 Ek Hesabı 13056 | F25: =F24+E25 -> 0
C26: DÖNEM 2 Hesabı | E26: 37056 | F26: =F25+E26 -> 37056
A27: 1 | B27: 44438 | C27: Nakit 2000 TL | E27: -2000 | F27: =F26+E27 -> 35056
A28: 2 | B28: 44469 | C28: Nakit 2000 TL | E28: -2000 | F28: =F27+E28 -> 33056
A29: 3 | B29: 44499 | C29: Nakit 2000 TL | E29: -2000 | F29: =F28+E29 -> 31056
A30: 4 | B30: 44530 | C30: Nakit 2000 TL | E30: -2000 | F30: =F29+E30 -> 29056
A31: 5 | B31: 44560 | C31: Nakit 2000 TL | E31: -2000 | F31: =F30+E31 -> 27056
A32: 6 | B32: 44591 | C32: Nakit 2000 TL | E32: -2000 | F32: =F31+E32 -> 25056
A33: 7 | B33: 44620 | C33: Nakit 3000 TL ödendi | E33: -3000 | F33: =F32+E33 -> 22056
A34: 8 | B34: 44650 | C34: Nakit 3000 TL | E34: -3000 | F34: =F33+E34 -> 19056
A35: 9 | B35: 44681 | C35: Nakit 3000 TL 10-05-2022 | E35: -5000 | F35: =F34+E35 -> 14056
A36: 10 | B36: 44711 | C36: Nakit 5000 TL | E36: -3000 | F36: =F35+E36 -> 11056
A37: 11 | B37: 44742 | C37: Nakit 5000 TL 05-07-2022 | E37: -4000 | F37: =F36+E37 -> 7056
A38: 12 | B38: 44772 | C38: Nakit 5000 TL 29-08-2022 | E38: -3000 | F38: =F37+E38 -> 4056
A39: 13 | C39: GECİKEN ÖDEME -------------- | E39: -2000 | F39: =F38+E39 -> 2056
A40: 14 | C40: GECİKEN ÖDEME -------------- | E40: -1000 | F40: =F39+E40 -> 1056
F41: =F40+E41 -> 1056
E42: Dönem Sonu Kalan BAKİYE | F42: =F41 -> 1056
B47: DÖNEM 3 Aylık Tutar | F47: =E53/12 -> 5190
...

Sheet Senet Borçlu Alacaklı Giriş
B1: Alacaklı Adı Soyadı / Unvanı | C1: HACI MURAT BALCI
B2: İl | C2: TOKAT
A4: BORÇLU | B4: Kişilik | C4: Gerçek Kişi
B5: Adı Soyadı / Unvanı | C5: Adem Duman
B6: Adresi | C6: Hızarhane Cad. No:5 TOKAT
B7: Vergi Dairesi | C7: Tokat
B8: Vergi No/TC Kimlik No | C8: 341 3267 6260
A9: KEFİL | B9: Adı Soyadı / Unvanı | C9: Adem Duman
B10: Adresi | C10: Esentepe Mah. Şehit Ulaşar Cad. Belde Sitesi B Blk. K1: D:3 TOKAT
B11: Vergi Dairesi | C11: Tokat
B12: Vergi No/TC Kimlik No | C12: 341 3267 6260

Sheet Senet Taksit Giriş
B2: Senet No | C2: Düzenleme Tarihi | D2: Vade Tarihi | E2: Tutarı Rakamla | F2: Tutarı Yazıyla | G2: Borcun Nedeni | H2: Senet Mühteviyatı
B3: 1 | C3: 45503 | D3: 45534 | E3: 17000 | F3: =PROPER(IF(IF(LEN(SUBSTITUTE(ROUND(E3,2), ",", ""))=LEN(ROUND(E3,2)),ROUND(E3,2),TRIM(LEFT(ROUND(E3,2),FIND(",",ROUND(E3,2))-1)))*1>=10^6,CHOOSE(LEFT(RIGHT(IF(LEN(SUBSTITUTE(ROUND(E3,2), ",", ""))=LEN(ROUND(E3,2)),ROUND(E3,2),TRIM(LEFT(ROUND(E3,2),FIND(",",ROUND(E3,2))-1)))*1,7),1)+1,"","birmilyon","ikimilyon","üçmilyon","dörtmilyon","beşmilyon","altımilyon","yedimilyon","sekizmilyon","dokuzmilyon"),"")&IF(IF(LEN(SUBSTITUTE(ROUND(E3,2), ",", ""))=LEN(ROUND(E3,2)),ROUND(E3,2),TRIM(LEFT(ROUND(E3,2),FIND(",",ROUND(E3,2))-1)))*1>=10^5,CHOOSE(LEFT(RIGHT(IF(LEN(SUBSTITUTE(ROUND(E3,2), ",", ""))=LEN(ROUND(E3,2)),ROUND(E3,2),TRIM(LEFT(ROUND(E3,2),FIND(",",ROUND(E3,2))-1)))*1,6),1)+1,"","yüz","ikiyüz","üçyüz","dörtyüz","beşyüz","altıyüz","yediyüz","sekizyüz","dokuzyüz"),"")&IF(IF(LEN(SUBSTITUTE(ROUND(E3,2), ",", ""))=LEN(ROUND(E3,2)),ROUND(E3,2),TRIM(LEFT(ROUND(E3,2),FIND(",",ROUND(E3,2))-1)))*1>=10^4,CHOOSE(LEFT(RIGHT(IF(LEN(SUBSTITUTE(ROUND(E3,2), ",", ""))=LEN(ROUND(E3,2)),ROUND(E3,2),TRIM(LEFT(ROUND(E3,2),FIND(",",ROUND(E3,2))-1)))*1,5),1)+1,"","on","yirmi","otuz","kırk","elli","altmış","yetmiş","seksen","doksan"),"")&IF(IF(LEN(SUBSTITUTE(ROUND(E3,2), ",", ""))=LEN(ROUND(E3,2)),ROUND(E3,2),TRIM(LEFT(ROUND(E3,2),FIND(",",ROUND(E3,2))-1)))*1>=10^3,CHOOSE(LEFT(RIGHT(IF(LEN(SUBSTITUTE(ROUND(E3,2), ",", ""))=LEN(ROUND(E3,2)),ROUND(E3,2),TRIM(LEFT(ROUND(E3,2),FIND(",",ROUND(E3,2))-1)))*1,4),1)+1,"","","iki","üç","dört","beş","altı","yedi","sekiz","dokuz"),"")&IF(AND(IF(LEN(SUBSTITUTE(ROUND(E3,2), ",", ""))=LEN(ROUND(E3,2)),ROUND(E3,2),TRIM(LEFT(ROUND(E3,2),FIND(",",ROUND(E3,2))-1)))*1>=10^3,VALUE(LEFT(RIGHT(IF(LEN(SUBSTITUTE(ROUND(E3,2), ",", ""))=LEN(ROUND(E3,2)),ROUND(E3,2),TRIM(LEFT(ROUND(E3,2),FIND(",",ROUND(E3,2))-1)))*1,6),3))>0),IF(AND(IF(LEN(SUBSTITUTE(ROUND(E3,2), ",", ""))=LEN(ROUND(E3,2)),ROUND(E3,2),TRIM(LEFT(ROUND(E3,2),FIND(",",ROUND(E3,2))-1)))*1>1999,LEFT(RIGHT(IF(LEN(SUBSTITUTE(ROUND(E3,2), ",", ""))=LEN(ROUND(E3,2)),ROUND(E3,2),TRIM(LEFT(ROUND(E3,2),FIND(",",ROUND(E3,2))-1)))*1,4),1)="1",LEFT(RIGHT(IF(LEN(SUBSTITUTE(ROUND(E3,2), ",", ""))=LEN(ROUND(E3,2)),ROUND(E3,2),TRIM(LEFT(ROUND(E3,2),FIND(",",ROUND(E3,2))-1)))*1,6),2)<>"00"),"birbin","bin"),"")&IF(IF(LEN(SUBSTITUTE(ROUND(E3,2), ",", ""))=LEN(ROUND(E3,2)),ROUND(E3,2),TRIM(LEFT(ROUND(E3,2),FIND(",",ROUND(E3,2))-1)))*1>=100,CHOOSE(LEFT(RIGHT(IF(LEN(SUBSTITUTE(ROUND(E3,2), ",", ""))=LEN(ROUND(E3,2)),ROUND(E3,2),TRIM(LEFT(ROUND(E3,2),FIND(",",ROUND(E3,2))-1)))*1,3),1)+1,"","yüz","ikiyüz","üçyüz","dörtyüz","beşyüz","altıyüz","yediyüz","sekizyüz","dokuzyüz"),"")&IF(IF(LEN(SUBSTITUTE(ROUND(E3,2), ",", ""))=LEN(ROUND(E3,2)),ROUND(E3,2),TRIM(LEFT(ROUND(E3,2),FIND(",",ROUND(E3,2))-1)))*1>=10,CHOOSE(LEFT(RIGHT(IF(LEN(SUBSTITUTE(ROUND(E3,2), ",", ""))=LEN(ROUND(E3,2)),ROUND(E3,2),TRIM(LEFT(ROUND(E3,2),FIND(",",ROUND(E3,2))-1)))*1,2),1)+1,"","on","yirmi","otuz","kırk","elli","altmış","yetmiş","seksen","doksan"),"")&CHOOSE(MOD(IF(LEN(SUBSTITUTE(ROUND(E3,2), ",", ""))=LEN(ROUND(E3,2)),ROUND(E3,2),TRIM(LEFT(ROUND(E3,2),FIND(",",ROUND(E3,2))-1)))*1,10)+1,"","bir","iki","üç","dört","beş","altı","yedi","sekiz","dokuz")) & " TL " & IF(OR(LEN(SUBSTITUTE(E3, ",", ""))=LEN(E3),LEN(SUBSTITUTE(ROUND(E3,2), ",", ""))=LEN(ROUND(E3,2))),"", PROPER(IF(IF(LEN(TRIM(RIGHT(ROUND(E3,2),LEN(ROUND(E3,2))-FIND(",",ROUND(E3,2)))))<2,TRIM(RIGHT(ROUND(E3,2),LEN(ROUND(E3,2))-FIND(",",ROUND(E3,2))))*10,TRIM(RIGHT(ROUND(E3,2),LEN(ROUND(E3,2))-FIND(",",ROUND(E3,2))))*1)>=10^5,CHOOSE(LEFT(RIGHT(IF(LEN(TRIM(RIGHT(ROUND(E3,2),LEN(ROUND(E3,2))-FIND(",",ROUND(E3,2)))))<2,TRIM(RIGHT(ROUND(E3,2),LEN(ROUND(E3,2))-FIND(",",ROUND(E3,2))))*10,TRIM(RIGHT(ROUND(E3,2),LEN(ROUND(E3,2))-FIND(",",ROUND(E3,2))))*1),6),1)+1,"","yüz","ikiyüz","üçyüz","dörtyüz","beşyüz","altıyüz","yediyüz","sekizyüz","dokuzyüz"),"")&IF(IF(LEN(TRIM(RIGHT(ROUND(E3,2),LEN(ROUND(E3,2))-FIND(",",ROUND(E3,2)))))<2,TRIM(RIGHT(ROUND(E3,2),LEN(ROUND(E3,2))-FIND(",",ROUND(E3,2))))*10,TRIM(RIGHT(ROUND(E3,2),LEN(ROUND(E3,2))-FIND(",",ROUND(E3,2))))*1)>=10^4,CHOOSE(LEFT(RIGHT(IF(LEN(TRIM(RIGHT(ROUND(E3,2),LEN(ROUND(E3,2))-FIND(",",ROUND(E3,2)))))<2,TRIM(RIGHT(ROUND(E3,2),LEN(ROUND(E3,2))-FIND(",",ROUND(E3,2))))*10,TRIM(RIGHT(ROUND(E3,2),LEN(ROUND(E3,2))-FIND(",",ROUND(E3,2))))*1),5),1)+1,"","on","yirmi","otuz","kırk","elli","altmış","yetmiş","seksen","doksan"),"")&IF(IF(LEN(TRIM(RIGHT(ROUND(E3,2),LEN(ROUND(E3,2))-FIND(",",ROUND(E3,2)))))<2,TRIM(RIGHT(ROUND(E3,2),LEN(ROUND(E3,2))-FIND(",",ROUND(E3,2))))*10,TRIM(RIGHT(ROUND(E3,2),LEN(ROUND(E3,2))-FIND(",",ROUND(E3,2))))*1)>=10^3,CHOOSE(LEFT(RIGHT(IF(LEN(TRIM(RIGHT(ROUND(E3,2),LEN(ROUND(E3,2))-FIND(",",ROUND(E3,2)))))<2,TRIM(RIGHT(ROUND(E3,2),LEN(ROUND(E3,2))-FIND(",",ROUND(E3,2))))*10,TRIM(RIGHT(ROUND(E3,2),LEN(ROUND(E3,2))-FIND(",",ROUND(E3,2))))*1),4),1)+1,"","","iki","üç","dört","beş","altı","yedi","sekiz","dokuz"),"")&IF(IF(LEN(TRIM(RIGHT(ROUND(E3,2),LEN(ROUND(E3,2))-FIND(",",ROUND(E3,2)))))<2,TRIM(RIGHT(ROUND(E3,2),LEN(ROUND(E3,2))-FIND(",",ROUND(E3,2))))*10,TRIM(RIGHT(ROUND(E3,2),LEN(ROUND(E3,2))-FIND(",",ROUND(E3,2))))*1)>=10,CHOOSE(LEFT(RIGHT(IF(LEN(TRIM(RIGHT(ROUND(E3,2),LEN(ROUND(E3,2))-FIND(",",ROUND(E3,2)))))<2,TRIM(RIGHT(ROUND(E3,2),LEN(ROUND(E3,2))-FIND(",",ROUND(E3,2))))*10,TRIM(RIGHT(ROUND(E3,2),LEN(ROUND(E3,2))-FIND(",",ROUND(E3,2))))*1),2),1)+1,"","on","yirmi","otuz","kırk","elli","altmış","yetmiş","seksen","doksan"),"")&CHOOSE(MOD(IF(LEN(TRIM(RIGHT(ROUND(E3,2),LEN(ROUND(E3,2))-FIND(",",ROUND(E3,2)))))<2,TRIM(RIGHT(ROUND(E3,2),LEN(ROUND(E3,2))-FIND(",",ROUND(E3,2))))*10,TRIM(RIGHT(ROUND(E3,2),LEN(ROUND(E3,2))-FIND(",",ROUND(E3,2))))*1),10)+1,"","bir","iki","üç","dört","beş","altı","yedi","sekiz","dokuz")) & " Kr") -> Onyedibin TL | G3: NAKDEN | H3: 1. Taksit
B4: 2 | C4: 45503 | D4: 45565 | E4: 17000 | F4: =PROPER(IF(IF(LEN(SUBSTITUTE(ROUND(E4,2), ",", ""))=LEN(ROUND(E4,2)),ROUND(E4,2),TRIM(LEFT(ROUND(E4,2),FIND(",",ROUND(E4,2))-1)))*1>=10^6,CHOOSE(LEFT(RIGHT(IF(LEN(SUBSTITUTE(ROUND(E4,2), ",", ""))=LEN(ROUND(E4,2)),ROUND(E4,2),TRIM(LEFT(ROUND(E4,2),FIND(",",ROUND(E4,2))-1)))*1,7),1)+1,"","birmilyon","ikimilyon","üçmilyon","dörtmilyon","beşmilyon","altımilyon","yedimilyon","sekizmilyon","dokuzmilyon"),"")&IF(IF(LEN(SUBSTITUTE(ROUND(E4,2), ",", ""))=LEN(ROUND(E4,2)),ROUND(E4,2),TRIM(LEFT(ROUND(E4,2),FIND(",",ROUND(E4,2))-1)))*1>=10^5,CHOOSE(LEFT(RIGHT(IF(LEN(SUBSTITUTE(ROUND(E4,2), ",", ""))=LEN(ROUND(E4,2)),ROUND(E4,2),TRIM(LEFT(ROUND(E4,2),FIND(",",ROUND(E4,2))-1)))*1,6),1)+1,"","yüz","ikiyüz","üçyüz","dörtyüz","beşyüz","altıyüz","yediyüz","sekizyüz","dokuzyüz"),"")&IF(IF(LEN(SUBSTITUTE(ROUND(E4,2), ",", ""))=LEN(ROUND(E4,2)),ROUND(E4,2),TRIM(LEFT(ROUND(E4,2),FIND(",",ROUND(E4,2))-1)))*1>=10^4,CHOOSE(LEFT(RIGHT(IF(LEN(SUBSTITUTE(ROUND(E4,2), ",", ""))=LEN(ROUND(E4,2)),ROUND(E4,2),TRIM(LEFT(ROUND(E4,2),FIND(",",ROUND(E4,2))-1)))*1,5),1)+1,"","on","yirmi","otuz","kırk","elli","altmış","yetmiş","seksen","doksan"),"")&IF(IF(LEN(SUBSTITUTE(ROUND(E4,2), ",", ""))=LEN(ROUND(E4,2)),ROUND(E4,2),TRIM(LEFT(ROUND(E4,2),FIND(",",ROUND(E4,2))-1)))*1>=10^3,CHOOSE(LEFT(RIGHT(IF(LEN(SUBSTITUTE(ROUND(E4,2), ",", ""))=LEN(ROUND(E4,2)),ROUND(E4,2),TRIM(LEFT(ROUND(E4,2),FIND(",",ROUND(E4,2))-1)))*1,4),1)+1,"","","iki","üç","dört","beş","altı","yedi","sekiz","dokuz"),"")&IF(AND(IF(LEN(SUBSTITUTE(ROUND(E4,2), ",", ""))=LEN(ROUND(E4,2)),ROUND(E4,2),TRIM(LEFT(ROUND(E4,2),FIND(",",ROUND(E4,2))-1)))*1>=10^3,VALUE(LEFT(RIGHT(IF(LEN(SUBSTITUTE(ROUND(E4,2), ",", ""))=LEN(ROUND(E4,2)),ROUND(E4,2),TRIM(LEFT(ROUND(E4,2),FIND(",",ROUND(E4,2))-1)))*1,6),3))>0),IF(AND(IF(LEN(SUBSTITUTE(ROUND(E4,2), ",", ""))=LEN(ROUND(E4,2)),ROUND(E4,2),TRIM(LEFT(ROUND(E4,2),FIND(",",ROUND(E4,2))-1)))*1>1999,LEFT(RIGHT(IF(LEN(SUBSTITUTE(ROUND(E4,2), ",", ""))=LEN(ROUND(E4,2)),ROUND(E4,2),TRIM(LEFT(ROUND(E4,2),FIND(",",ROUND(E4,2))-1)))*1,4),1)="1",LEFT(RIGHT(IF(LEN(SUBSTITUTE(ROUND(E4,2), ",", ""))=LEN(ROUND(E4,2)),ROUND(E4,2),TRIM(LEFT(ROUND(E4,2),FIND(",",ROUND(E4,2))-1)))*1,6),2)<>"00"),"birbin","bin"),"")&IF(IF(LEN(SUBSTITUTE(ROUND(E4,2), ",", ""))=LEN(ROUND(E4,2)),ROUND(E4,2),TRIM(LEFT(ROUND(E4,2),FIND(",",ROUND(E4,2))-1)))*1>=100,CHOOSE(LEFT(RIGHT(IF(LEN(SUBSTITUTE(ROUND(E4,2), ",", ""))=LEN(ROUND(E4,2)),ROUND(E4,2),TRIM(LEFT(ROUND(E4,2),FIND(",",ROUND(E4,2))-1)))*1,3),1)+1,"","yüz","ikiyüz","üçyüz","dörtyüz","beşyüz","altıyüz","yediyüz","sekizyüz","dokuzyüz"),"")&IF(IF(LEN(SUBSTITUTE(ROUND(E4,2), ",", ""))=LEN(ROUND(E4,2)),ROUND(E4,2),TRIM(LEFT(ROUND(E4,2),FIND(",",ROUND(E4,2))-1)))*1>=10,CHOOSE(LEFT(RIGHT(IF(LEN(SUBSTITUTE(ROUND(E4,2), ",", ""))=LEN(ROUND(E4,2)),ROUND(E4,2),TRIM(LEFT(ROUND(E4,2),FIND(",",ROUND(E4,2))-1)))*1,2),1)+1,"","on","yirmi","otuz","kırk","elli","altmış","yetmiş","seksen","doksan"),"")&CHOOSE(MOD(IF(LEN(SUBSTITUTE(ROUND(E4,2), ",", ""))=LEN(ROUND(E4,2)),ROUND(E4,2),TRIM(LEFT(ROUND(E4,2),FIND(",",ROUND(E4,2))-1)))*1,10)+1,"","bir","iki","üç","dört","beş","altı","yedi","sekiz","dokuz")) & " TL " & IF(OR(LEN(SUBSTITUTE(E4, ",", ""))=LEN(E4),LEN(SUBSTITUTE(ROUND(E4,2), ",", ""))=LEN(ROUND(E4,2))),"", PROPER(IF(IF(LEN(TRIM(RIGHT(ROUND(E4,2),LEN(ROUND(E4,2))-FIND(",",ROUND(E4,2)))))<2,TRIM(RIGHT(ROUND(E4,2),LEN(ROUND(E4,2))-FIND(",",ROUND(E4,2))))*10,TRIM(RIGHT(ROUND(E4,2),LEN(ROUND(E4,2))-FIND(",",ROUND(E4,2))))*1)>=10^5,CHOOSE(LEFT(RIGHT(IF(LEN(TRIM(RIGHT(ROUND(E4,2),LEN(ROUND(E4,2))-FIND(",",ROUND(E4,2)))))<2,TRIM(RIGHT(ROUND(E4,2),LEN(ROUND(E4,2))-FIND(",",ROUND(E4,2))))*10,TRIM(RIGHT(ROUND(E4,2),LEN(ROUND(E4,2))-FIND(",",ROUND(E4,2))))*1),6),1)+1,"","yüz","ikiyüz","üçyüz","dörtyüz","beşyüz","altıyüz","yediyüz","sekizyüz","dokuzyüz"),"")&IF(IF(LEN(TRIM(RIGHT(ROUND(E4,2),LEN(ROUND(E4,2))-FIND(",",ROUND(E4,2)))))<2,TRIM(RIGHT(ROUND(E4,2),LEN(ROUND(E4,2))-FIND(",",ROUND(E4,2))))*10,TRIM(RIGHT(ROUND(E4,2),LEN(ROUND(E4,2))-FIND(",",ROUND(E4,2))))*1)>=10^4,CHOOSE(LEFT(RIGHT(IF(LEN(TRIM(RIGHT(ROUND(E4,2),LEN(ROUND(E4,2))-FIND(",",ROUND(E4,2)))))<2,TRIM(RIGHT(ROUND(E4,2),LEN(ROUND(E4,2))-FIND(",",ROUND(E4,2))))*10,TRIM(RIGHT(ROUND(E4,2),LEN(ROUND(E4,2))-FIND(",",ROUND(E4,2))))*1),5),1)+1,"","on","yirmi","otuz","kırk","elli","altmış","yetmiş","seksen","doksan"),"")&IF(IF(LEN(TRIM(RIGHT(ROUND(E4,2),LEN(ROUND(E4,2))-FIND(",",ROUND(E4,2)))))<2,TRIM(RIGHT(ROUND(E4,2),LEN(ROUND(E4,2))-FIND(",",ROUND(E4,2))))*10,TRIM(RIGHT(ROUND(E4,2),LEN(ROUND(E4,2))-FIND(",",ROUND(E4,2))))*1)>=10^3,CHOOSE(LEFT(RIGHT(IF(LEN(TRIM(RIGHT(ROUND(E4,2),LEN(ROUND(E4,2))-FIND(",",ROUND(E4,2)))))<2,TRIM(RIGHT(ROUND(E4,2),LEN(ROUND(E4,2))-FIND(",",ROUND(E4,2))))*10,TRIM(RIGHT(ROUND(E4,2),LEN(ROUND(E4,2))-FIND(",",ROUND(E4,2))))*1),4),1)+1,"","","iki","üç","dört","beş","altı","yedi","sekiz","dokuz"),"")&IF(IF(LEN(TRIM(RIGHT(ROUND(E4,2),LEN(ROUND(E4,2))-FIND(",",ROUND(E4,2)))))<2,TRIM(RIGHT(ROUND(E4,2),LEN(ROUND(E4,2))-FIND(",",ROUND(E4,2))))*10,TRIM(RIGHT(ROUND(E4,2),LEN(ROUND(E4,2))-FIND(",",ROUND(E4,2))))*1)>=10,CHOOSE(LEFT(RIGHT(IF(LEN(TRIM(RIGHT(ROUND(E4,2),LEN(ROUND(E4,2))-FIND(",",ROUND(E4,2)))))<2,TRIM(RIGHT(ROUND(E4,2),LEN(ROUND(E4,2))-FIND(",",ROUND(E4,2))))*10,TRIM(RIGHT(ROUND(E4,2),LEN(ROUND(E4,2))-FIND(",",ROUND(E4,2))))*1),2),1)+1,"","on","yirmi","otuz","kırk","elli","altmış","yetmiş","seksen","doksan"),"")&CHOOSE(MOD(IF(LEN(TRIM(RIGHT(ROUND(E4,2),LEN(ROUND(E4,2))-FIND(",",ROUND(E4,2)))))<2,TRIM(RIGHT(ROUND(E4,2),LEN(ROUND(E4,2))-FIND(",",ROUND(E4,2))))*10,TRIM(RIGHT(ROUND(E4,2),LEN(ROUND(E4,2))-FIND(",",ROUND(E4,2))))*1),10)+1,"","bir","iki","üç","dört","beş","altı","yedi","sekiz","dokuz")) & " Kr") -> Onyedibin TL | G4: =G3 -> NAKDEN | H4: 2. Taksit
B5: 3 | C5: 45503 | D5: 45595 | E5: 17000 | F5: =PROPER(IF(IF(LEN(SUBSTITUTE(ROUND(E5,2), ",", ""))=LEN(ROUND(E5,2)),ROUND(E5,2),TRIM(LEFT(ROUND(E5,2),FIND(",",ROUND(E5,2))-1)))*1>=10^6,CHOOSE(LEFT(RIGHT(IF(LEN(SUBSTITUTE(ROUND(E5,2), ",", ""))=LEN(ROUND(E5,2)),ROUND(E5,2),TRIM(LEFT(ROUND(E5,2),FIND(",",ROUND(E5,2))-1)))*1,7),1)+1,"","birmilyon","ikimilyon","üçmilyon","dörtmilyon","beşmilyon","altımilyon","yedimilyon","sekizmilyon","dokuzmilyon"),"")&IF(IF(LEN(SUBSTITUTE(ROUND(E5,2), ",", ""))=LEN(ROUND(E5,2)),ROUND(E5,2),TRIM(LEFT(ROUND(E5,2),FIND(",",ROUND(E5,2))-1)))*1>=10^5,CHOOSE(LEFT(RIGHT(IF(LEN(SUBSTITUTE(ROUND(E5,2), ",", ""))=LEN(ROUND(E5,2)),ROUND(E5,2),TRIM(LEFT(ROUND(E5,2),FIND(",",ROUND(E5,2))-1)))*1,6),1)+1,"","yüz","ikiyüz","üçyüz","dörtyüz","beşyüz","altıyüz","yediyüz","sekizyüz","dokuzyüz"),"")&IF(IF(LEN(SUBSTITUTE(ROUND(E5,2), ",", ""))=LEN(ROUND(E5,2)),ROUND(E5,2),TRIM(LEFT(ROUND(E5,2),FIND(",",ROUND(E5,2))-1)))*1>=10^4,CHOOSE(LEFT(RIGHT(IF(LEN(SUBSTITUTE(ROUND(E5,2), ",", ""))=LEN(ROUND(E5,2)),ROUND(E5,2),TRIM(LEFT(ROUND(E5,2),FIND(",",ROUND(E5,2))-1)))*1,5),1)+1,"","on","yirmi","otuz","kırk","elli","altmış","yetmiş","seksen","doksan"),"")&IF(IF(LEN(SUBSTITUTE(ROUND(E5,2), ",", ""))=LEN(ROUND(E5,2)),ROUND(E5,2),TRIM(LEFT(ROUND(E5,2),FIND(",",ROUND(E5,2))-1)))*1>=10^3,CHOOSE(LEFT(RIGHT(IF(LEN(SUBSTITUTE(ROUND(E5,2), ",", ""))=LEN(ROUND(E5,2)),ROUND(E5,2),TRIM(LEFT(ROUND(E5,2),FIND(",",ROUND(E5,2))-1)))*1,4),1)+1,"","","iki","üç","dört","beş","altı","yedi","sekiz","dokuz"),"")&IF(AND(IF(LEN(SUBSTITUTE(ROUND(E5,2), ",", ""))=LEN(ROUND(E5,2)),ROUND(E5,2),TRIM(LEFT(ROUND(E5,2),FIND(",",ROUND(E5,2))-1)))*1>=10^3,VALUE(LEFT(RIGHT(IF(LEN(SUBSTITUTE(ROUND(E5,2), ",", ""))=LEN(ROUND(E5,2)),ROUND(E5,2),TRIM(LEFT(ROUND(E5,2),FIND(",",ROUND(E5,2))-1)))*1,6),3))>0),IF(AND(IF(LEN(SUBSTITUTE(ROUND(E5,2), ",", ""))=LEN(ROUND(E5,2)),ROUND(E5,2),TRIM(LEFT(ROUND(E5,2),FIND(",",ROUND(E5,2))-1)))*1>1999,LEFT(RIGHT(IF(LEN(SUBSTITUTE(ROUND(E5,2), ",", ""))=LEN(ROUND(E5,2)),ROUND(E5,2),TRIM(LEFT(ROUND(E5,2),FIND(",",ROUND(E5,2))-1)))*1,4),1)="1",LEFT(RIGHT(IF(LEN(SUBSTITUTE(ROUND(E5,2), ",", ""))=LEN(ROUND(E5,2)),ROUND(E5,2),TRIM(LEFT(ROUND(E5,2),FIND(",",ROUND(E5,2))-1)))*1,6),2)<>"00"),"birbin","bin"),"")&IF(IF(LEN(SUBSTITUTE(ROUND(E5,2), ",", ""))=LEN(ROUND(E5,2)),ROUND(E5,2),TRIM(LEFT(ROUND(E5,2),FIND(",",ROUND(E5,2))-1)))*1>=100,CHOOSE(LEFT(RIGHT(IF(LEN(SUBSTITUTE(ROUND(E5,2), ",", ""))=LEN(ROUND(E5,2)),ROUND(E5,2),TRIM(LEFT(ROUND(E5,2),FIND(",",ROUND(E5,2))-1)))*1,3),1)+1,"","yüz","ikiyüz","üçyüz","dörtyüz","beşyüz","altıyüz","yediyüz","sekizyüz","dokuzyüz"),"")&IF(IF(LEN(SUBSTITUTE(ROUND(E5,2), ",", ""))=LEN(ROUND(E5,2)),ROUND(E5,2),TRIM(LEFT(ROUND(E5,2),FIND(",",ROUND(E5,2))-1)))*1>=10,CHOOSE(LEFT(RIGHT(IF(LEN(SUBSTITUTE(ROUND(E5,2), ",", ""))=LEN(ROUND(E5,2)),ROUND(E5,2),TRIM(LEFT(ROUND(E5,2),FIND(",",ROUND(E5,2))-1)))*1,2),1)+1,"","on","yirmi","otuz","kırk","elli","altmış","yetmiş","seksen","doksan"),"")&CHOOSE(MOD(IF(LEN(SUBSTITUTE(ROUND(E5,2), ",", ""))=LEN(ROUND(E5,2)),ROUND(E5,2),TRIM(LEFT(ROUND(E5,2),FIND(",",ROUND(E5,2))-1)))*1,10)+1,"","bir","iki","üç","dört","beş","altı","yedi","sekiz","dokuz")) & " TL " & IF(OR(LEN(SUBSTITUTE(E5, ",", ""))=LEN(E5),LEN(SUBSTITUTE(ROUND(E5,2), ",", ""))=LEN(ROUND(E5,2))),"", PROPER(IF(IF(LEN(TRIM(RIGHT(ROUND(E5,2),LEN(ROUND(E5,2))-FIND(",",ROUND(E5,2)))))<2,TRIM(RIGHT(ROUND(E5,2),LEN(ROUND(E5,2))-FIND(",",ROUND(E5,2))))*10,TRIM(RIGHT(ROUND(E5,2),LEN(ROUND(E5,2))-FIND(",",ROUND(E5,2))))*1)>=10^5,CHOOSE(LEFT(RIGHT(IF(LEN(TRIM(RIGHT(ROUND(E5,2),LEN(ROUND(E5,2))-FIND(",",ROUND(E5,2)))))<2,TRIM(RIGHT(ROUND(E5,2),LEN(ROUND(E5,2))-FIND(",",ROUND(E5,2))))*10,TRIM(RIGHT(ROUND(E5,2),LEN(ROUND(E5,2))-FIND(",",ROUND(E5,2))))*1),6),1)+1,"","yüz","ikiyüz","üçyüz","dörtyüz","beşyüz","altıyüz","yediyüz","sekizyüz","dokuzyüz"),"")&IF(IF(LEN(TRIM(RIGHT(ROUND(E5,2),LEN(ROUND(E5,2))-FIND(",",ROUND(E5,2)))))<2,TRIM(RIGHT(ROUND(E5,2),LEN(ROUND(E5,2))-FIND(",",ROUND(E5,2))))*10,TRIM(RIGHT(ROUND(E5,2),LEN(ROUND(E5,2))-FIND(",",ROUND(E5,2))))*1)>=10^4,CHOOSE(LEFT(RIGHT(IF(LEN(TRIM(RIGHT(ROUND(E5,2),LEN(ROUND(E5,2))-FIND(",",ROUND(E5,2)))))<2,TRIM(RIGHT(ROUND(E5,2),LEN(ROUND(E5,2))-FIND(",",ROUND(E5,2))))*10,TRIM(RIGHT(ROUND(E5,2),LEN(ROUND(E5,2))-FIND(",",ROUND(E5,2))))*1),5),1)+1,"","on","yirmi","otuz","kırk","elli","altmış","yetmiş","seksen","doksan"),"")&IF(IF(LEN(TRIM(RIGHT(ROUND(E5,2),LEN(ROUND(E5,2))-FIND(",",ROUND(E5,2)))))<2,TRIM(RIGHT(ROUND(E5,2),LEN(ROUND(E5,2))-FIND(",",ROUND(E5,2))))*10,TRIM(RIGHT(ROUND(E5,2),LEN(ROUND(E5,2))-FIND(",",ROUND(E5,2))))*1)>=10^3,CHOOSE(LEFT(RIGHT(IF(LEN(TRIM(RIGHT(ROUND(E5,2),LEN(ROUND(E5,2))-FIND(",",ROUND(E5,2)))))<2,TRIM(RIGHT(ROUND(E5,2),LEN(ROUND(E5,2))-FIND(",",ROUND(E5,2))))*10,TRIM(RIGHT(ROUND(E5,2),LEN(ROUND(E5,2))-FIND(",",ROUND(E5,2))))*1),4),1)+1,"","","iki","üç","dört","beş","altı","yedi","sekiz","dokuz"),"")&IF(IF(LEN(TRIM(RIGHT(ROUND(E5,2),LEN(ROUND(E5,2))-FIND(",",ROUND(E5,2)))))<2,TRIM(RIGHT(ROUND(E5,2),LEN(ROUND(E5,2))-FIND(",",ROUND(E5,2))))*10,TRIM(RIGHT(ROUND(E5,2),LEN(ROUND(E5,2))-FIND(",",ROUND(E5,2))))*1)>=10,CHOOSE(LEFT(RIGHT(IF(LEN(TRIM(RIGHT(ROUND(E5,2),LEN(ROUND(E5,2))-FIND(",",ROUND(E5,2)))))<2,TRIM(RIGHT(ROUND(E5,2),LEN(ROUND(E5,2))-FIND(",",ROUND(E5,2))))*10,TRIM(RIGHT(ROUND(E5,2),LEN(ROUND(E5,2))-FIND(",",ROUND(E5,2))))*1),2),1)+1,"","on","yirmi","otuz","kırk","elli","altmış","yetmiş","seksen","doksan"),"")&CHOOSE(MOD(IF(LEN(TRIM(RIGHT(ROUND(E5,2),LEN(ROUND(E5,2))-FIND(",",ROUND(E5,2)))))<2,TRIM(RIGHT(ROUND(E5,2),LEN(ROUND(E5,2))-FIND(",",ROUND(E5,2))))*10,TRIM(RIGHT(ROUND(E5,2),LEN(ROUND(E5,2))-FIND(",",ROUND(E5,2))))*1),10)+1,"","bir","iki","üç","dört","beş","altı","yedi","sekiz","dokuz")) & " Kr") -> Onyedibin TL | G5: =G4 -> NAKDEN | H5: 3. Taksit
B6: 4 | C6: 45503 | D6: 45626 | E6: 17000 | F6: =PROPER(IF(IF(LEN(SUBSTITUTE(ROUND(E6,2), ",", ""))=LEN(ROUND(E6,2)),ROUND(E6,2),TRIM(LEFT(ROUND(E6,2),FIND(",",ROUND(E6,2))-1)))*1>=10^6,CHOOSE(LEFT(RIGHT(IF(LEN(SUBSTITUTE(ROUND(E6,2), ",", ""))=LEN(ROUND(E6,2)),ROUND(E6,2),TRIM(LEFT(ROUND(E6,2),FIND(",",ROUND(E6,2))-1)))*1,7),1)+1,"","birmilyon","ikimilyon","üçmilyon","dörtmilyon","beşmilyon","altımilyon","yedimilyon","sekizmilyon","dokuzmilyon"),"")&IF(IF(LEN(SUBSTITUTE(ROUND(E6,2), ",", ""))=LEN(ROUND(E6,2)),ROUND(E6,2),TRIM(LEFT(ROUND(E6,2),FIND(",",ROUND(E6,2))-1)))*1>=10^5,CHOOSE(LEFT(RIGHT(IF(LEN(SUBSTITUTE(ROUND(E6,2), ",", ""))=LEN(ROUND(E6,2)),ROUND(E6,2),TRIM(LEFT(ROUND(E6,2),FIND(",",ROUND(E6,2))-1)))*1,6),1)+1,"","yüz","ikiyüz","üçyüz","dörtyüz","beşyüz","altıyüz","yediyüz","sekizyüz","dokuzyüz"),"")&IF(IF(LEN(SUBSTITUTE(ROUND(E6,2), ",", ""))=LEN(ROUND(E6,2)),ROUND(E6,2),TRIM(LEFT(ROUND(E6,2),FIND(",",ROUND(E6,2))-1)))*1>=10^4,CHOOSE(LEFT(RIGHT(IF(LEN(SUBSTITUTE(ROUND(E6,2), ",", ""))=LEN(ROUND(E6,2)),ROUND(E6,2),TRIM(LEFT(ROUND(E6,2),FIND(",",ROUND(E6,2))-1)))*1,5),1)+1,"","on","yirmi","otuz","kırk","elli","altmış","yetmiş","seksen","doksan"),"")&IF(IF(LEN(SUBSTITUTE(ROUND(E6,2), ",", ""))=LEN(ROUND(E6,2)),ROUND(E6,2),TRIM(LEFT(ROUND(E6,2),FIND(",",ROUND(E6,2))-1)))*1>=10^3,CHOOSE(LEFT(RIGHT(IF(LEN(SUBSTITUTE(ROUND(E6,2), ",", ""))=LEN(ROUND(E6,2)),ROUND(E6,2),TRIM(LEFT(ROUND(E6,2),FIND(",",ROUND(E6,2))-1)))*1,4),1)+1,"","","iki","üç","dört","beş","altı","yedi","sekiz","dokuz"),"")&IF(AND(IF(LEN(SUBSTITUTE(ROUND(E6,2), ",", ""))=LEN(ROUND(E6,2)),ROUND(E6,2),TRIM(LEFT(ROUND(E6,2),FIND(",",ROUND(E6,2))-1)))*1>=10^3,VALUE(LEFT(RIGHT(IF(LEN(SUBSTITUTE(ROUND(E6,2), ",", ""))=LEN(ROUND(E6,2)),ROUND(E6,2),TRIM(LEFT(ROUND(E6,2),FIND(",",ROUND(E6,2))-1)))*1,6),3))>0),IF(AND(IF(LEN(SUBSTITUTE(ROUND(E6,2), ",", ""))=LEN(ROUND(E6,2)),ROUND(E6,2),TRIM(LEFT(ROUND(E6,2),FIND(",",ROUND(E6,2))-1)))*1>1999,LEFT(RIGHT(IF(LEN(SUBSTITUTE(ROUND(E6,2), ",", ""))=LEN(ROUND(E6,2)),ROUND(E6,2),TRIM(LEFT(ROUND(E6,2),FIND(",",ROUND(E6,2))-1)))*1,4),1)="1",LEFT(RIGHT(IF(LEN(SUBSTITUTE(ROUND(E6,2), ",", ""))=LEN(ROUND(E6,2)),ROUND(E6,2),TRIM(LEFT(ROUND(E6,2),FIND(",",ROUND(E6,2))-1)))*1,6),2)<>"00"),"birbin","bin"),"")&IF(IF(LEN(SUBSTITUTE(ROUND(E6,2), ",", ""))=LEN(ROUND(E6,2)),ROUND(E6,2),TRIM(LEFT(ROUND(E6,2),FIND(",",ROUND(E6,2))-1)))*1>=100,CHOOSE(LEFT(RIGHT(IF(LEN(SUBSTITUTE(ROUND(E6,2), ",", ""))=LEN(ROUND(E6,2)),ROUND(E6,2),TRIM(LEFT(ROUND(E6,2),FIND(",",ROUND(E6,2))-1)))*1,3),1)+1,"","yüz","ikiyüz","üçyüz","dörtyüz","beşyüz","altıyüz","yediyüz","sekizyüz","dokuzyüz"),"")&IF(IF(LEN(SUBSTITUTE(ROUND(E6,2), ",", ""))=LEN(ROUND(E6,2)),ROUND(E6,2),TRIM(LEFT(ROUND(E6,2),FIND(",",ROUND(E6,2))-1)))*1>=10,CHOOSE(LEFT(RIGHT(IF(LEN(SUBSTITUTE(ROUND(E6,2), ",", ""))=LEN(ROUND(E6,2)),ROUND(E6,2),TRIM(LEFT(ROUND(E6,2),FIND(",",ROUND(E6,2))-1)))*1,2),1)+1,"","on","yirmi","otuz","kırk","elli","altmış","yetmiş","seksen","doksan"),"")&CHOOSE(MOD(IF(LEN(SUBSTITUTE(ROUND(E6,2), ",", ""))=LEN(ROUND(E6,2)),ROUND(E6,2),TRIM(LEFT(ROUND(E6,2),FIND(",",ROUND(E6,2))-1)))*1,10)+1,"","bir","iki","üç","dört","beş","altı","yedi","sekiz","dokuz")) & " TL " & IF(OR(LEN(SUBSTITUTE(E6, ",", ""))=LEN(E6),LEN(SUBSTITUTE(ROUND(E6,2), ",", ""))=LEN(ROUND(E6,2))),"", PROPER(IF(IF(LEN(TRIM(RIGHT(ROUND(E6,2),LEN(ROUND(E6,2))-FIND(",",ROUND(E6,2)))))<2,TRIM(RIGHT(ROUND(E6,2),LEN(ROUND(E6,2))-FIND(",",ROUND(E6,2))))*10,TRIM(RIGHT(ROUND(E6,2),LEN(ROUND(E6,2))-FIND(",",ROUND(E6,2))))*1)>=10^5,CHOOSE(LEFT(RIGHT(IF(LEN(TRIM(RIGHT(ROUND(E6,2),LEN(ROUND(E6,2))-FIND(",",ROUND(E6,2)))))<2,TRIM(RIGHT(ROUND(E6,2),LEN(ROUND(E6,2))-FIND(",",ROUND(E6,2))))*10,TRIM(RIGHT(ROUND(E6,2),LEN(ROUND(E6,2))-FIND(",",ROUND(E6,2))))*1),6),1)+1,"","yüz","ikiyüz","üçyüz","dörtyüz","beşyüz","altıyüz","yediyüz","sekizyüz","dokuzyüz"),"")&IF(IF(LEN(TRIM(RIGHT(ROUND(E6,2),LEN(ROUND(E6,2))-FIND(",",ROUND(E6,2)))))<2,TRIM(RIGHT(ROUND(E6,2),LEN(ROUND(E6,2))-FIND(",",ROUND(E6,2))))*10,TRIM(RIGHT(ROUND(E6,2),LEN(ROUND(E6,2))-FIND(",",ROUND(E6,2))))*1)>=10^4,CHOOSE(LEFT(RIGHT(IF(LEN(TRIM(RIGHT(ROUND(E6,2),LEN(ROUND(E6,2))-FIND(",",ROUND(E6,2)))))<2,TRIM(RIGHT(ROUND(E6,2),LEN(ROUND(E6,2))-FIND(",",ROUND(E6,2))))*10,TRIM(RIGHT(ROUND(E6,2),LEN(ROUND(E6,2))-FIND(",",ROUND(E6,2))))*1),5),1)+1,"","on","yirmi","otuz","kırk","elli","altmış","yetmiş","seksen","doksan"),"")&IF(IF(LEN(TRIM(RIGHT(ROUND(E6,2),LEN(ROUND(E6,2))-FIND(",",ROUND(E6,2)))))<2,TRIM(RIGHT(ROUND(E6,2),LEN(ROUND(E6,2))-FIND(",",ROUND(E6,2))))*10,TRIM(RIGHT(ROUND(E6,2),LEN(ROUND(E6,2))-FIND(",",ROUND(E6,2))))*1)>=10^3,CHOOSE(LEFT(RIGHT(IF(LEN(TRIM(RIGHT(ROUND(E6,2),LEN(ROUND(E6,2))-FIND(",",ROUND(E6,2)))))<2,TRIM(RIGHT(ROUND(E6,2),LEN(ROUND(E6,2))-FIND(",",ROUND(E6,2))))*10,TRIM(RIGHT(ROUND(E6,2),LEN(ROUND(E6,2))-FIND(",",ROUND(E6,2))))*1),4),1)+1,"","","iki","üç","dört","beş","altı","yedi","sekiz","dokuz"),"")&IF(IF(LEN(TRIM(RIGHT(ROUND(E6,2),LEN(ROUND(E6,2))-FIND(",",ROUND(E6,2)))))<2,TRIM(RIGHT(ROUND(E6,2),LEN(ROUND(E6,2))-FIND(",",ROUND(E6,2))))*10,TRIM(RIGHT(ROUND(E6,2),LEN(ROUND(E6,2))-FIND(",",ROUND(E6,2))))*1)>=10,CHOOSE(LEFT(RIGHT(IF(LEN(TRIM(RIGHT(ROUND(E6,2),LEN(ROUND(E6,2))-FIND(",",ROUND(E6,2)))))<2,TRIM(RIGHT(ROUND(E6,2),LEN(ROUND(E6,2))-FIND(",",ROUND(E6,2))))*10,TRIM(RIGHT(ROUND(E6,2),LEN(ROUND(E6,2))-FIND(",",ROUND(E6,2))))*1),2),1)+1,"","on","yirmi","otuz","kırk","elli","altmış","yetmiş","seksen","doksan"),"")&CHOOSE(MOD(IF(LEN(TRIM(RIGHT(ROUND(E6,2),LEN(ROUND(E6,2))-FIND(",",ROUND(E6,2)))))<2,TRIM(RIGHT(ROUND(E6,2),LEN(ROUND(E6,2))-FIND(",",ROUND(E6,2))))*10,TRIM(RIGHT(ROUND(E6,2),LEN(ROUND(E6,2))-FIND(",",ROUND(E6,2))))*1),10)+1,"","bir","iki","üç","dört","beş","altı","yedi","sekiz","dokuz")) & " Kr") -> Onyedibin TL | G6: =G5 -> NAKDEN | H6: 4. Taksit
B7: 5 | C7: 45503 | D7: 45656 | E7: 17000 | F7: =PROPER(IF(IF(LEN(SUBSTITUTE(ROUND(E7,2), ",", ""))=LEN(ROUND(E7,2)),ROUND(E7,2),TRIM(LEFT(ROUND(E7,2),FIND(",",ROUND(E7,2))-1)))*1>=10^6,CHOOSE(LEFT(RIGHT(IF(LEN(SUBSTITUTE(ROUND(E7,2), ",", ""))=LEN(ROUND(E7,2)),ROUND(E7,2),TRIM(LEFT(ROUND(E7,2),FIND(",",ROUND(E7,2))-1)))*1,7),1)+1,"","birmilyon","ikimilyon","üçmilyon","dörtmilyon","beşmilyon","altımilyon","yedimilyon","sekizmilyon","dokuzmilyon"),"")&IF(IF(LEN(SUBSTITUTE(ROUND(E7,2), ",", ""))=LEN(ROUND(E7,2)),ROUND(E7,2),TRIM(LEFT(ROUND(E7,2),FIND(",",ROUND(E7,2))-1)))*1>=10^5,CHOOSE(LEFT(RIGHT(IF(LEN(SUBSTITUTE(ROUND(E7,2), ",", ""))=LEN(ROUND(E7,2)),ROUND(E7,2),TRIM(LEFT(ROUND(E7,2),FIND(",",ROUND(E7,2))-1)))*1,6),1)+1,"","yüz","ikiyüz","üçyüz","dörtyüz","beşyüz","altıyüz","yediyüz","sekizyüz","dokuzyüz"),"")&IF(IF(LEN(SUBSTITUTE(ROUND(E7,2), ",", ""))=LEN(ROUND(E7,2)),ROUND(E7,2),TRIM(LEFT(ROUND(E7,2),FIND(",",ROUND(E7,2))-1)))*1>=10^4,CHOOSE(LEFT(RIGHT(IF(LEN(SUBSTITUTE(ROUND(E7,2), ",", ""))=LEN(ROUND(E7,2)),ROUND(E7,2),TRIM(LEFT(ROUND(E7,2),FIND(",",ROUND(E7,2))-1)))*1,5),1)+1,"","on","yirmi","otuz","kırk","elli","altmış","yetmiş","seksen","doksan"),"")&IF(IF(LEN(SUBSTITUTE(ROUND(E7,2), ",", ""))=LEN(ROUND(E7,2)),ROUND(E7,2),TRIM(LEFT(ROUND(E7,2),FIND(",",ROUND(E7,2))-1)))*1>=10^3,CHOOSE(LEFT(RIGHT(IF(LEN(SUBSTITUTE(ROUND(E7,2), ",", ""))=LEN(ROUND(E7,2)),ROUND(E7,2),TRIM(LEFT(ROUND(E7,2),FIND(",",ROUND(E7,2))-1)))*1,4),1)+1,"","","iki","üç","dört","beş","altı","yedi","sekiz","dokuz"),"")&IF(AND(IF(LEN(SUBSTITUTE(ROUND(E7,2), ",", ""))=LEN(ROUND(E7,2)),ROUND(E7,2),TRIM(LEFT(ROUND(E7,2),FIND(",",ROUND(E7,2))-1)))*1>=10^3,VALUE(LEFT(RIGHT(IF(LEN(SUBSTITUTE(ROUND(E7,2), ",", ""))=LEN(ROUND(E7,2)),ROUND(E7,2),TRIM(LEFT(ROUND(E7,2),FIND(",",ROUND(E7,2))-1)))*1,6),3))>0),IF(AND(IF(LEN(SUBSTITUTE(ROUND(E7,2), ",", ""))=LEN(ROUND(E7,2)),ROUND(E7,2),TRIM(LEFT(ROUND(E7,2),FIND(",",ROUND(E7,2))-1)))*1>1999,LEFT(RIGHT(IF(LEN(SUBSTITUTE(ROUND(E7,2), ",", ""))=LEN(ROUND(E7,2)),ROUND(E7,2),TRIM(LEFT(ROUND(E7,2),FIND(",",ROUND(E7,2))-1)))*1,4),1)="1",LEFT(RIGHT(IF(LEN(SUBSTITUTE(ROUND(E7,2), ",", ""))=LEN(ROUND(E7,2)),ROUND(E7,2),TRIM(LEFT(ROUND(E7,2),FIND(",",ROUND(E7,2))-1)))*1,6),2)<>"00"),"birbin","bin"),"")&IF(IF(LEN(SUBSTITUTE(ROUND(E7,2), ",", ""))=LEN(ROUND(E7,2)),ROUND(E7,2),TRIM(LEFT(ROUND(E7,2),FIND(",",ROUND(E7,2))-1)))*1>=100,CHOOSE(LEFT(RIGHT(IF(LEN(SUBSTITUTE(ROUND(E7,2), ",", ""))=LEN(ROUND(E7,2)),ROUND(E7,2),TRIM(LEFT(ROUND(E7,2),FIND(",",ROUND(E7,2))-1)))*1,3),1)+1,"","yüz","ikiyüz","üçyüz","dörtyüz","beşyüz","altıyüz","yediyüz","sekizyüz","dokuzyüz"),"")&IF(IF(LEN(SUBSTITUTE(ROUND(E7,2), ",", ""))=LEN(ROUND(E7,2)),ROUND(E7,2),TRIM(LEFT(ROUND(E7,2),FIND(",",ROUND(E7,2))-1)))*1>=10,CHOOSE(LEFT(RIGHT(IF(LEN(SUBSTITUTE(ROUND(E7,2), ",", ""))=LEN(ROUND(E7,2)),ROUND(E7,2),TRIM(LEFT(ROUND(E7,2),FIND(",",ROUND(E7,2))-1)))*1,2),1)+1,"","on","yirmi","otuz","kırk","elli","altmış","yetmiş","seksen","doksan"),"")&CHOOSE(MOD(IF(LEN(SUBSTITUTE(ROUND(E7,2), ",", ""))=LEN(ROUND(E7,2)),ROUND(E7,2),TRIM(LEFT(ROUND(E7,2),FIND(",",ROUND(E7,2))-1)))*1,10)+1,"","bir","iki","üç","dört","beş","altı","yedi","sekiz","dokuz")) & " TL " & IF(OR(LEN(SUBSTITUTE(E7, ",", ""))=LEN(E7),LEN(SUBSTITUTE(ROUND(E7,2), ",", ""))=LEN(ROUND(E7,2))),"", PROPER(IF(IF(LEN(TRIM(RIGHT(ROUND(E7,2),LEN(ROUND(E7,2))-FIND(",",ROUND(E7,2)))))<2,TRIM(RIGHT(ROUND(E7,2),LEN(ROUND(E7,2))-FIND(",",ROUND(E7,2))))*10,TRIM(RIGHT(ROUND(E7,2),LEN(ROUND(E7,2))-FIND(",",ROUND(E7,2))))*1)>=10^5,CHOOSE(LEFT(RIGHT(IF(LEN(TRIM(RIGHT(ROUND(E7,2),LEN(ROUND(E7,2))-FIND(",",ROUND(E7,2)))))<2,TRIM(RIGHT(ROUND(E7,2),LEN(ROUND(E7,2))-FIND(",",ROUND(E7,2))))*10,TRIM(RIGHT(ROUND(E7,2),LEN(ROUND(E7,2))-FIND(",",ROUND(E7,2))))*1),6),1)+1,"","yüz","ikiyüz","üçyüz","dörtyüz","beşyüz","altıyüz","yediyüz","sekizyüz","dokuzyüz"),"")&IF(IF(LEN(TRIM(RIGHT(ROUND(E7,2),LEN(ROUND(E7,2))-FIND(",",ROUND(E7,2)))))<2,TRIM(RIGHT(ROUND(E7,2),LEN(ROUND(E7,2))-FIND(",",ROUND(E7,2))))*10,TRIM(RIGHT(ROUND(E7,2),LEN(ROUND(E7,2))-FIND(",",ROUND(E7,2))))*1)>=10^4,CHOOSE(LEFT(RIGHT(IF(LEN(TRIM(RIGHT(ROUND(E7,2),LEN(ROUND(E7,2))-FIND(",",ROUND(E7,2)))))<2,TRIM(RIGHT(ROUND(E7,2),LEN(ROUND(E7,2))-FIND(",",ROUND(E7,2))))*10,TRIM(RIGHT(ROUND(E7,2),LEN(ROUND(E7,2))-FIND(",",ROUND(E7,2))))*1),5),1)+1,"","on","yirmi","otuz","kırk","elli","altmış","yetmiş","seksen","doksan"),"")&IF(IF(LEN(TRIM(RIGHT(ROUND(E7,2),LEN(ROUND(E7,2))-FIND(",",ROUND(E7,2)))))<2,TRIM(RIGHT(ROUND(E7,2),LEN(ROUND(E7,2))-FIND(",",ROUND(E7,2))))*10,TRIM(RIGHT(ROUND(E7,2),LEN(ROUND(E7,2))-FIND(",",ROUND(E7,2))))*1)>=10^3,CHOOSE(LEFT(RIGHT(IF(LEN(TRIM(RIGHT(ROUND(E7,2),LEN(ROUND(E7,2))-FIND(",",ROUND(E7,2)))))<2,TRIM(RIGHT(ROUND(E7,2),LEN(ROUND(E7,2))-FIND(",",ROUND(E7,2))))*10,TRIM(RIGHT(ROUND(E7,2),LEN(ROUND(E7,2))-FIND(",",ROUND(E7,2))))*1),4),1)+1,"","","iki","üç","dört","beş","altı","yedi","sekiz","dokuz"),"")&IF(IF(LEN(TRIM(RIGHT(ROUND(E7,2),LEN(ROUND(E7,2))-FIND(",",ROUND(E7,2)))))<2,TRIM(RIGHT(ROUND(E7,2),LEN(ROUND(E7,2))-FIND(",",ROUND(E7,2))))*10,TRIM(RIGHT(ROUND(E7,2),LEN(ROUND(E7,2))-FIND(",",ROUND(E7,2))))*1)>=10,CHOOSE(LEFT(RIGHT(IF(LEN(TRIM(RIGHT(ROUND(E7,2),LEN(ROUND(E7,2))-FIND(",",ROUND(E7,2)))))<2,TRIM(RIGHT(ROUND(E7,2),LEN(ROUND(E7,2))-FIND(",",ROUND(E7,2))))*10,TRIM(RIGHT(ROUND(E7,2),LEN(ROUND(E7,2))-FIND(",",ROUND(E7,2))))*1),2),1)+1,"","on","yirmi","otuz","kırk","elli","altmış","yetmiş","seksen","doksan"),"")&CHOOSE(MOD(IF(LEN(TRIM(RIGHT(ROUND(E7,2),LEN(ROUND(E7,2))-FIND(",",ROUND(E7,2)))))<2,TRIM(RIGHT(ROUND(E7,2),LEN(ROUND(E7,2))-FIND(",",ROUND(E7,2))))*10,TRIM(RIGHT(ROUND(E7,2),LEN(ROUND(E7,2))-FIND(",",ROUND(E7,2))))*1),10)+1,"","bir","iki","üç","dört","beş","altı","yedi","sekiz","dokuz")) & " Kr") -> Onyedibin TL | G7: =G6 -> NAKDEN | H7: 5. Taksit
B8: 6 | C8: 45503 | D8: 45687 | E8: 17000 | F8: =PROPER(IF(IF(LEN(SUBSTITUTE(ROUND(E8,2), ",", ""))=LEN(ROUND(E8,2)),ROUND(E8,2),TRIM(LEFT(ROUND(E8,2),FIND(",",ROUND(E8,2))-1)))*1>=10^6,CHOOSE(LEFT(RIGHT(IF(LEN(SUBSTITUTE(ROUND(E8,2), ",", ""))=LEN(ROUND(E8,2)),ROUND(E8,2),TRIM(LEFT(ROUND(E8,2),FIND(",",ROUND(E8,2))-1)))*1,7),1)+1,"","birmilyon","ikimilyon","üçmilyon","dörtmilyon","beşmilyon","altımilyon","yedimilyon","sekizmilyon","dokuzmilyon"),"")&IF(IF(LEN(SUBSTITUTE(ROUND(E8,2), ",", ""))=LEN(ROUND(E8,2)),ROUND(E8,2),TRIM(LEFT(ROUND(E8,2),FIND(",",ROUND(E8,2))-1)))*1>=10^5,CHOOSE(LEFT(RIGHT(IF(LEN(SUBSTITUTE(ROUND(E8,2), ",", ""))=LEN(ROUND(E8,2)),ROUND(E8,2),TRIM(LEFT(ROUND(E8,2),FIND(",",ROUND(E8,2))-1)))*1,6),1)+1,"","yüz","ikiyüz","üçyüz","dörtyüz","beşyüz","altıyüz","yediyüz","sekizyüz","dokuzyüz"),"")&IF(IF(LEN(SUBSTITUTE(ROUND(E8,2), ",", ""))=LEN(ROUND(E8,2)),ROUND(E8,2),TRIM(LEFT(ROUND(E8,2),FIND(",",ROUND(E8,2))-1)))*1>=10^4,CHOOSE(LEFT(RIGHT(IF(LEN(SUBSTITUTE(ROUND(E8,2), ",", ""))=LEN(ROUND(E8,2)),ROUND(E8,2),TRIM(LEFT(ROUND(E8,2),FIND(",",ROUND(E8,2))-1)))*1,5),1)+1,"","on","yirmi","otuz","kırk","elli","altmış","yetmiş","seksen","doksan"),"")&IF(IF(LEN(SUBSTITUTE(ROUND(E8,2), ",", ""))=LEN(ROUND(E8,2)),ROUND(E8,2),TRIM(LEFT(ROUND(E8,2),FIND(",",ROUND(E8,2))-1)))*1>=10^3,CHOOSE(LEFT(RIGHT(IF(LEN(SUBSTITUTE(ROUND(E8,2), ",", ""))=LEN(ROUND(E8,2)),ROUND(E8,2),TRIM(LEFT(ROUND(E8,2),FIND(",",ROUND(E8,2))-1)))*1,4),1)+1,"","","iki","üç","dört","beş","altı","yedi","sekiz","dokuz"),"")&IF(AND(IF(LEN(SUBSTITUTE(ROUND(E8,2), ",", ""))=LEN(ROUND(E8,2)),ROUND(E8,2),TRIM(LEFT(ROUND(E8,2),FIND(",",ROUND(E8,2))-1)))*1>=10^3,VALUE(LEFT(RIGHT(IF(LEN(SUBSTITUTE(ROUND(E8,2), ",", ""))=LEN(ROUND(E8,2)),ROUND(E8,2),TRIM(LEFT(ROUND(E8,2),FIND(",",ROUND(E8,2))-1)))*1,6),3))>0),IF(AND(IF(LEN(SUBSTITUTE(ROUND(E8,2), ",", ""))=LEN(ROUND(E8,2)),ROUND(E8,2),TRIM(LEFT(ROUND(E8,2),FIND(",",ROUND(E8,2))-1)))*1>1999,LEFT(RIGHT(IF(LEN(SUBSTITUTE(ROUND(E8,2), ",", ""))=LEN(ROUND(E8,2)),ROUND(E8,2),TRIM(LEFT(ROUND(E8,2),FIND(",",ROUND(E8,2))-1)))*1,4),1)="1",LEFT(RIGHT(IF(LEN(SUBSTITUTE(ROUND(E8,2), ",", ""))=LEN(ROUND(E8,2)),ROUND(E8,2),TRIM(LEFT(ROUND(E8,2),FIND(",",ROUND(E8,2))-1)))*1,6),2)<>"00"),"birbin","bin"),"")&IF(IF(LEN(SUBSTITUTE(ROUND(E8,2), ",", ""))=LEN(ROUND(E8,2)),ROUND(E8,2),TRIM(LEFT(ROUND(E8,2),FIND(",",ROUND(E8,2))-1)))*1>=100,CHOOSE(LEFT(RIGHT(IF(LEN(SUBSTITUTE(ROUND(E8,2), ",", ""))=LEN(ROUND(E8,2)),ROUND(E8,2),TRIM(LEFT(ROUND(E8,2),FIND(",",ROUND(E8,2))-1)))*1,3),1)+1,"","yüz","ikiyüz","üçyüz","dörtyüz","beşyüz","altıyüz","yediyüz","sekizyüz","dokuzyüz"),"")&IF(IF(LEN(SUBSTITUTE(ROUND(E8,2), ",", ""))=LEN(ROUND(E8,2)),ROUND(E8,2),TRIM(LEFT(ROUND(E8,2),FIND(",",ROUND(E8,2))-1)))*1>=10,CHOOSE(LEFT(RIGHT(IF(LEN(SUBSTITUTE(ROUND(E8,2), ",", ""))=LEN(ROUND(E8,2)),ROUND(E8,2),TRIM(LEFT(ROUND(E8,2),FIND(",",ROUND(E8,2))-1)))*1,2),1)+1,"","on","yirmi","otuz","kırk","elli","altmış","yetmiş","seksen","doksan"),"")&CHOOSE(MOD(IF(LEN(SUBSTITUTE(ROUND(E8,2), ",", ""))=LEN(ROUND(E8,2)),ROUND(E8,2),TRIM(LEFT(ROUND(E8,2),FIND(",",ROUND(E8,2))-1)))*1,10)+1,"","bir","iki","üç","dört","beş","altı","yedi","sekiz","dokuz")) & " TL " & IF(OR(LEN(SUBSTITUTE(E8, ",", ""))=LEN(E8),LEN(SUBSTITUTE(ROUND(E8,2), ",", ""))=LEN(ROUND(E8,2))),"", PROPER(IF(IF(LEN(TRIM(RIGHT(ROUND(E8,2),LEN(ROUND(E8,2))-FIND(",",ROUND(E8,2)))))<2,TRIM(RIGHT(ROUND(E8,2),LEN(ROUND(E8,2))-FIND(",",ROUND(E8,2))))*10,TRIM(RIGHT(ROUND(E8,2),LEN(ROUND(E8,2))-FIND(",",ROUND(E8,2))))*1)>=10^5,CHOOSE(LEFT(RIGHT(IF(LEN(TRIM(RIGHT(ROUND(E8,2),LEN(ROUND(E8,2))-FIND(",",ROUND(E8,2)))))<2,TRIM(RIGHT(ROUND(E8,2),LEN(ROUND(E8,2))-FIND(",",ROUND(E8,2))))*10,TRIM(RIGHT(ROUND(E8,2),LEN(ROUND(E8,2))-FIND(",",ROUND(E8,2))))*1),6),1)+1,"","yüz","ikiyüz","üçyüz","dörtyüz","beşyüz","altıyüz","yediyüz","sekizyüz","dokuzyüz"),"")&IF(IF(LEN(TRIM(RIGHT(ROUND(E8,2),LEN(ROUND(E8,2))-FIND(",",ROUND(E8,2)))))<2,TRIM(RIGHT(ROUND(E8,2),LEN(ROUND(E8,2))-FIND(",",ROUND(E8,2))))*10,TRIM(RIGHT(ROUND(E8,2),LEN(ROUND(E8,2))-FIND(",",ROUND(E8,2))))*1)>=10^4,CHOOSE(LEFT(RIGHT(IF(LEN(TRIM(RIGHT(ROUND(E8,2),LEN(ROUND(E8,2))-FIND(",",ROUND(E8,2)))))<2,TRIM(RIGHT(ROUND(E8,2),LEN(ROUND(E8,2))-FIND(",",ROUND(E8,2))))*10,TRIM(RIGHT(ROUND(E8,2),LEN(ROUND(E8,2))-FIND(",",ROUND(E8,2))))*1),5),1)+1,"","on","yirmi","otuz","kırk","elli","altmış","yetmiş","seksen","doksan"),"")&IF(IF(LEN(TRIM(RIGHT(ROUND(E8,2),LEN(ROUND(E8,2))-FIND(",",ROUND(E8,2)))))<2,TRIM(RIGHT(ROUND(E8,2),LEN(ROUND(E8,2))-FIND(",",ROUND(E8,2))))*10,TRIM(RIGHT(ROUND(E8,2),LEN(ROUND(E8,2))-FIND(",",ROUND(E8,2))))*1)>=10^3,CHOOSE(LEFT(RIGHT(IF(LEN(TRIM(RIGHT(ROUND(E8,2),LEN(ROUND(E8,2))-FIND(",",ROUND(E8,2)))))<2,TRIM(RIGHT(ROUND(E8,2),LEN(ROUND(E8,2))-FIND(",",ROUND(E8,2))))*10,TRIM(RIGHT(ROUND(E8,2),LEN(ROUND(E8,2))-FIND(",",ROUND(E8,2))))*1),4),1)+1,"","","iki","üç","dört","beş","altı","yedi","sekiz","dokuz"),"")&IF(IF(LEN(TRIM(RIGHT(ROUND(E8,2),LEN(ROUND(E8,2))-FIND(",",ROUND(E8,2)))))<2,TRIM(RIGHT(ROUND(E8,2),LEN(ROUND(E8,2))-FIND(",",ROUND(E8,2))))*10,TRIM(RIGHT(ROUND(E8,2),LEN(ROUND(E8,2))-FIND(",",ROUND(E8,2))))*1)>=10,CHOOSE(LEFT(RIGHT(IF(LEN(TRIM(RIGHT(ROUND(E8,2),LEN(ROUND(E8,2))-FIND(",",ROUND(E8,2)))))<2,TRIM(RIGHT(ROUND(E8,2),LEN(ROUND(E8,2))-FIND(",",ROUND(E8,2))))*10,TRIM(RIGHT(ROUND(E8,2),LEN(ROUND(E8,2))-FIND(",",ROUND(E8,2))))*1),2),1)+1,"","on","yirmi","otuz","kırk","elli","altmış","yetmiş","seksen","doksan"),"")&CHOOSE(MOD(IF(LEN(TRIM(RIGHT(ROUND(E8,2),LEN(ROUND(E8,2))-FIND(",",ROUND(E8,2)))))<2,TRIM(RIGHT(ROUND(E8,2),LEN(ROUND(E8,2))-FIND(",",ROUND(E8,2))))*10,TRIM(RIGHT(ROUND(E8,2),LEN(ROUND(E8,2))-FIND(",",ROUND(E8,2))))*1),10)+1,"","bir","iki","üç","dört","beş","altı","yedi","sekiz","dokuz")) & " Kr") -> Onyedibin TL | G8: =G7 -> NAKDEN | H8: 6. Taksit
B9: 7 | C9: 45503 | D9: 45716 | E9: 17000 | F9: =PROPER(IF(IF(LEN(SUBSTITUTE(ROUND(E9,2), ",", ""))=LEN(ROUND(E9,2)),ROUND(E9,2),TRIM(LEFT(ROUND(E9,2),FIND(",",ROUND(E9,2))-1)))*1>=10^6,CHOOSE(LEFT(RIGHT(IF(LEN(SUBSTITUTE(ROUND(E9,2), ",", ""))=LEN(ROUND(E9,2)),ROUND(E9,2),TRIM(LEFT(ROUND(E9,2),FIND(",",ROUND(E9,2))-1)))*1,7),1)+1,"","birmilyon","ikimilyon","üçmilyon","dörtmilyon","beşmilyon","altımilyon","yedimilyon","sekizmilyon","dokuzmilyon"),"")&IF(IF(LEN(SUBSTITUTE(ROUND(E9,2), ",", ""))=LEN(ROUND(E9,2)),ROUND(E9,2),TRIM(LEFT(ROUND(E9,2),FIND(",",ROUND(E9,2))-1)))*1>=10^5,CHOOSE(LEFT(RIGHT(IF(LEN(SUBSTITUTE(ROUND(E9,2), ",", ""))=LEN(ROUND(E9,2)),ROUND(E9,2),TRIM(LEFT(ROUND(E9,2),FIND(",",ROUND(E9,2))-1)))*1,6),1)+1,"","yüz","ikiyüz","üçyüz","dörtyüz","beşyüz","altıyüz","yediyüz","sekizyüz","dokuzyüz"),"")&IF(IF(LEN(SUBSTITUTE(ROUND(E9,2), ",", ""))=LEN(ROUND(E9,2)),ROUND(E9,2),TRIM(LEFT(ROUND(E9,2),FIND(",",ROUND(E9,2))-1)))*1>=10^4,CHOOSE(LEFT(RIGHT(IF(LEN(SUBSTITUTE(ROUND(E9,2), ",", ""))=LEN(ROUND(E9,2)),ROUND(E9,2),TRIM(LEFT(ROUND(E9,2),FIND(",",ROUND(E9,2))-1)))*1,5),1)+1,"","on","yirmi","otuz","kırk","elli","altmış","yetmiş","seksen","doksan"),"")&IF(IF(LEN(SUBSTITUTE(ROUND(E9,2), ",", ""))=LEN(ROUND(E9,2)),ROUND(E9,2),TRIM(LEFT(ROUND(E9,2),FIND(",",ROUND(E9,2))-1)))*1>=10^3,CHOOSE(LEFT(RIGHT(IF(LEN(SUBSTITUTE(ROUND(E9,2), ",", ""))=LEN(ROUND(E9,2)),ROUND(E9,2),TRIM(LEFT(ROUND(E9,2),FIND(",",ROUND(E9,2))-1)))*1,4),1)+1,"","","iki","üç","dört","beş","altı","yedi","sekiz","dokuz"),"")&IF(AND(IF(LEN(SUBSTITUTE(ROUND(E9,2), ",", ""))=LEN(ROUND(E9,2)),ROUND(E9,2),TRIM(LEFT(ROUND(E9,2),FIND(",",ROUND(E9,2))-1)))*1>=10^3,VALUE(LEFT(RIGHT(IF(LEN(SUBSTITUTE(ROUND(E9,2), ",", ""))=LEN(ROUND(E9,2)),ROUND(E9,2),TRIM(LEFT(ROUND(E9,2),FIND(",",ROUND(E9,2))-1)))*1,6),3))>0),IF(AND(IF(LEN(SUBSTITUTE(ROUND(E9,2), ",", ""))=LEN(ROUND(E9,2)),ROUND(E9,2),TRIM(LEFT(ROUND(E9,2),FIND(",",ROUND(E9,2))-1)))*1>1999,LEFT(RIGHT(IF(LEN(SUBSTITUTE(ROUND(E9,2), ",", ""))=LEN(ROUND(E9,2)),ROUND(E9,2),TRIM(LEFT(ROUND(E9,2),FIND(",",ROUND(E9,2))-1)))*1,4),1)="1",LEFT(RIGHT(IF(LEN(SUBSTITUTE(ROUND(E9,2), ",", ""))=LEN(ROUND(E9,2)),ROUND(E9,2),TRIM(LEFT(ROUND(E9,2),FIND(",",ROUND(E9,2))-1)))*1,6),2)<>"00"),"birbin","bin"),"")&IF(IF(LEN(SUBSTITUTE(ROUND(E9,2), ",", ""))=LEN(ROUND(E9,2)),ROUND(E9,2),TRIM(LEFT(ROUND(E9,2),FIND(",",ROUND(E9,2))-1)))*1>=100,CHOOSE(LEFT(RIGHT(IF(LEN(SUBSTITUTE(ROUND(E9,2), ",", ""))=LEN(ROUND(E9,2)),ROUND(E9,2),TRIM(LEFT(ROUND(E9,2),FIND(",",ROUND(E9,2))-1)))*1,3),1)+1,"","yüz","ikiyüz","üçyüz","dörtyüz","beşyüz","altıyüz","yediyüz","sekizyüz","dokuzyüz"),"")&IF(IF(LEN(SUBSTITUTE(ROUND(E9,2), ",", ""))=LEN(ROUND(E9,2)),ROUND(E9,2),TRIM(LEFT(ROUND(E9,2),FIND(",",ROUND(E9,2))-1)))*1>=10,CHOOSE(LEFT(RIGHT(IF(LEN(SUBSTITUTE(ROUND(E9,2), ",", ""))=LEN(ROUND(E9,2)),ROUND(E9,2),TRIM(LEFT(ROUND(E9,2),FIND(",",ROUND(E9,2))-1)))*1,2),1)+1,"","on","yirmi","otuz","kırk","elli","altmış","yetmiş","seksen","doksan"),"")&CHOOSE(MOD(IF(LEN(SUBSTITUTE(ROUND(E9,2), ",", ""))=LEN(ROUND(E9,2)),ROUND(E9,2),TRIM(LEFT(ROUND(E9,2),FIND(",",ROUND(E9,2))-1)))*1,10)+1,"","bir","iki","üç","dört","beş","altı","yedi","sekiz","dokuz")) & " TL " & IF(OR(LEN(SUBSTITUTE(E9, ",", ""))=LEN(E9),LEN(SUBSTITUTE(ROUND(E9,2), ",", ""))=LEN(ROUND(E9,2))),"", PROPER(IF(IF(LEN(TRIM(RIGHT(ROUND(E9,2),LEN(ROUND(E9,2))-FIND(",",ROUND(E9,2)))))<2,TRIM(RIGHT(ROUND(E9,2),LEN(ROUND(E9,2))-FIND(",",ROUND(E9,2))))*10,TRIM(RIGHT(ROUND(E9,2),LEN(ROUND(E9,2))-FIND(",",ROUND(E9,2))))*1)>=10^5,CHOOSE(LEFT(RIGHT(IF(LEN(TRIM(RIGHT(ROUND(E9,2),LEN(ROUND(E9,2))-FIND(",",ROUND(E9,2)))))<2,TRIM(RIGHT(ROUND(E9,2),LEN(ROUND(E9,2))-FIND(",",ROUND(E9,2))))*10,TRIM(RIGHT(ROUND(E9,2),LEN(ROUND(E9,2))-FIND(",",ROUND(E9,2))))*1),6),1)+1,"","yüz","ikiyüz","üçyüz","dörtyüz","beşyüz","altıyüz","yediyüz","sekizyüz","dokuzyüz"),"")&IF(IF(LEN(TRIM(RIGHT(ROUND(E9,2),LEN(ROUND(E9,2))-FIND(",",ROUND(E9,2)))))<2,TRIM(RIGHT(ROUND(E9,2),LEN(ROUND(E9,2))-FIND(",",ROUND(E9,2))))*10,TRIM(RIGHT(ROUND(E9,2),LEN(ROUND(E9,2))-FIND(",",ROUND(E9,2))))*1)>=10^4,CHOOSE(LEFT(RIGHT(IF(LEN(TRIM(RIGHT(ROUND(E9,2),LEN(ROUND(E9,2))-FIND(",",ROUND(E9,2)))))<2,TRIM(RIGHT(ROUND(E9,2),LEN(ROUND(E9,2))-FIND(",",ROUND(E9,2))))*10,TRIM(RIGHT(ROUND(E9,2),LEN(ROUND(E9,2))-FIND(",",ROUND(E9,2))))*1),5),1)+1,"","on","yirmi","otuz","kırk","elli","altmış","yetmiş","seksen","doksan"),"")&IF(IF(LEN(TRIM(RIGHT(ROUND(E9,2),LEN(ROUND(E9,2))-FIND(",",ROUND(E9,2)))))<2,TRIM(RIGHT(ROUND(E9,2),LEN(ROUND(E9,2))-FIND(",",ROUND(E9,2))))*10,TRIM(RIGHT(ROUND(E9,2),LEN(ROUND(E9,2))-FIND(",",ROUND(E9,2))))*1)>=10^3,CHOOSE(LEFT(RIGHT(IF(LEN(TRIM(RIGHT(ROUND(E9,2),LEN(ROUND(E9,2))-FIND(",",ROUND(E9,2)))))<2,TRIM(RIGHT(ROUND(E9,2),LEN(ROUND(E9,2))-FIND(",",ROUND(E9,2))))*10,TRIM(RIGHT(ROUND(E9,2),LEN(ROUND(E9,2))-FIND(",",ROUND(E9,2))))*1),4),1)+1,"","","iki","üç","dört","beş","altı","yedi","sekiz","dokuz"),"")&IF(IF(LEN(TRIM(RIGHT(ROUND(E9,2),LEN(ROUND(E9,2))-FIND(",",ROUND(E9,2)))))<2,TRIM(RIGHT(ROUND(E9,2),LEN(ROUND(E9,2))-FIND(",",ROUND(E9,2))))*10,TRIM(RIGHT(ROUND(E9,2),LEN(ROUND(E9,2))-FIND(",",ROUND(E9,2))))*1)>=10,CHOOSE(LEFT(RIGHT(IF(LEN(TRIM(RIGHT(ROUND(E9,2),LEN(ROUND(E9,2))-FIND(",",ROUND(E9,2)))))<2,TRIM(RIGHT(ROUND(E9,2),LEN(ROUND(E9,2))-FIND(",",ROUND(E9,2))))*10,TRIM(RIGHT(ROUND(E9,2),LEN(ROUND(E9,2))-FIND(",",ROUND(E9,2))))*1),2),1)+1,"","on","yirmi","otuz","kırk","elli","altmış","yetmiş","seksen","doksan"),"")&CHOOSE(MOD(IF(LEN(TRIM(RIGHT(ROUND(E9,2),LEN(ROUND(E9,2))-FIND(",",ROUND(E9,2)))))<2,TRIM(RIGHT(ROUND(E9,2),LEN(ROUND(E9,2))-FIND(",",ROUND(E9,2))))*10,TRIM(RIGHT(ROUND(E9,2),LEN(ROUND(E9,2))-FIND(",",ROUND(E9,2))))*1),10)+1,"","bir","iki","üç","dört","beş","altı","yedi","sekiz","dokuz")) & " Kr") -> Onyedibin TL | G9: =G8 -> NAKDEN | H9: 7. Taksit
B10: 8 | C10: 45503 | D10: 45746 | E10: 17000 | F10: =PROPER(IF(IF(LEN(SUBSTITUTE(ROUND(E10,2), ",", ""))=LEN(ROUND(E10,2)),ROUND(E10,2),TRIM(LEFT(ROUND(E10,2),FIND(",",ROUND(E10,2))-1)))*1>=10^6,CHOOSE(LEFT(RIGHT(IF(LEN(SUBSTITUTE(ROUND(E10,2), ",", ""))=LEN(ROUND(E10,2)),ROUND(E10,2),TRIM(LEFT(ROUND(E10,2),FIND(",",ROUND(E10,2))-1)))*1,7),1)+1,"","birmilyon","ikimilyon","üçmilyon","dörtmilyon","beşmilyon","altımilyon","yedimilyon","sekizmilyon","dokuzmilyon"),"")&IF(IF(LEN(SUBSTITUTE(ROUND(E10,2), ",", ""))=LEN(ROUND(E10,2)),ROUND(E10,2),TRIM(LEFT(ROUND(E10,2),FIND(",",ROUND(E10,2))-1)))*1>=10^5,CHOOSE(LEFT(RIGHT(IF(LEN(SUBSTITUTE(ROUND(E10,2), ",", ""))=LEN(ROUND(E10,2)),ROUND(E10,2),TRIM(LEFT(ROUND(E10,2),FIND(",",ROUND(E10,2))-1)))*1,6),1)+1,"","yüz","ikiyüz","üçyüz","dörtyüz","beşyüz","altıyüz","yediyüz","sekizyüz","dokuzyüz"),"")&IF(IF(LEN(SUBSTITUTE(ROUND(E10,2), ",", ""))=LEN(ROUND(E10,2)),ROUND(E10,2),TRIM(LEFT(ROUND(E10,2),FIND(",",ROUND(E10,2))-1)))*1>=10^4,CHOOSE(LEFT(RIGHT(IF(LEN(SUBSTITUTE(ROUND(E10,2), ",", ""))=LEN(ROUND(E10,2)),ROUND(E10,2),TRIM(LEFT(ROUND(E10,2),FIND(",",ROUND(E10,2))-1)))*1,5),1)+1,"","on","yirmi","otuz","kırk","elli","altmış","yetmiş","seksen","doksan"),"")&IF(IF(LEN(SUBSTITUTE(ROUND(E10,2), ",", ""))=LEN(ROUND(E10,2)),ROUND(E10,2),TRIM(LEFT(ROUND(E10,2),FIND(",",ROUND(E10,2))-1)))*1>=10^3,CHOOSE(LEFT(RIGHT(IF(LEN(SUBSTITUTE(ROUND(E10,2), ",", ""))=LEN(ROUND(E10,2)),ROUND(E10,2),TRIM(LEFT(ROUND(E10,2),FIND(",",ROUND(E10,2))-1)))*1,4),1)+1,"","","iki","üç","dört","beş","altı","yedi","sekiz","dokuz"),"")&IF(AND(IF(LEN(SUBSTITUTE(ROUND(E10,2), ",", ""))=LEN(ROUND(E10,2)),ROUND(E10,2),TRIM(LEFT(ROUND(E10,2),FIND(",",ROUND(E10,2))-1)))*1>=10^3,VALUE(LEFT(RIGHT(IF(LEN(SUBSTITUTE(ROUND(E10,2), ",", ""))=LEN(ROUND(E10,2)),ROUND(E10,2),TRIM(LEFT(ROUND(E10,2),FIND(",",ROUND(E10,2))-1)))*1,6),3))>0),IF(AND(IF(LEN(SUBSTITUTE(ROUND(E10,2), ",", ""))=LEN(ROUND(E10,2)),ROUND(E10,2),TRIM(LEFT(ROUND(E10,2),FIND(",",ROUND(E10,2))-1)))*1>1999,LEFT(RIGHT(IF(LEN(SUBSTITUTE(ROUND(E10,2), ",", ""))=LEN(ROUND(E10,2)),ROUND(E10,2),TRIM(LEFT(ROUND(E10,2),FIND(",",ROUND(E10,2))-1)))*1,4),1)="1",LEFT(RIGHT(IF(LEN(SUBSTITUTE(ROUND(E10,2), ",", ""))=LEN(ROUND(E10,2)),ROUND(E10,2),TRIM(LEFT(ROUND(E10,2),FIND(",",ROUND(E10,2))-1)))*1,6),2)<>"00"),"birbin","bin"),"")&IF(IF(LEN(SUBSTITUTE(ROUND(E10,2), ",", ""))=LEN(ROUND(E10,2)),ROUND(E10,2),TRIM(LEFT(ROUND(E10,2),FIND(",",ROUND(E10,2))-1)))*1>=100,CHOOSE(LEFT(RIGHT(IF(LEN(SUBSTITUTE(ROUND(E10,2), ",", ""))=LEN(ROUND(E10,2)),ROUND(E10,2),TRIM(LEFT(ROUND(E10,2),FIND(",",ROUND(E10,2))-1)))*1,3),1)+1,"","yüz","ikiyüz","üçyüz","dörtyüz","beşyüz","altıyüz","yediyüz","sekizyüz","dokuzyüz"),"")&IF(IF(LEN(SUBSTITUTE(ROUND(E10,2), ",", ""))=LEN(ROUND(E10,2)),ROUND(E10,2),TRIM(LEFT(ROUND(E10,2),FIND(",",ROUND(E10,2))-1)))*1>=10,CHOOSE(LEFT(RIGHT(IF(LEN(SUBSTITUTE(ROUND(E10,2), ",", ""))=LEN(ROUND(E10,2)),ROUND(E10,2),TRIM(LEFT(ROUND(E10,2),FIND(",",ROUND(E10,2))-1)))*1,2),1)+1,"","on","yirmi","otuz","kırk","elli","altmış","yetmiş","seksen","doksan"),"")&CHOOSE(MOD(IF(LEN(SUBSTITUTE(ROUND(E10,2), ",", ""))=LEN(ROUND(E10,2)),ROUND(E10,2),TRIM(LEFT(ROUND(E10,2),FIND(",",ROUND(E10,2))-1)))*1,10)+1,"","bir","iki","üç","dört","beş","altı","yedi","sekiz","dokuz")) & " TL " & IF(OR(LEN(SUBSTITUTE(E10, ",", ""))=LEN(E10),LEN(SUBSTITUTE(ROUND(E10,2), ",", ""))=LEN(ROUND(E10,2))),"", PROPER(IF(IF(LEN(TRIM(RIGHT(ROUND(E10,2),LEN(ROUND(E10,2))-FIND(",",ROUND(E10,2)))))<2,TRIM(RIGHT(ROUND(E10,2),LEN(ROUND(E10,2))-FIND(",",ROUND(E10,2))))*10,TRIM(RIGHT(ROUND(E10,2),LEN(ROUND(E10,2))-FIND(",",ROUND(E10,2))))*1)>=10^5,CHOOSE(LEFT(RIGHT(IF(LEN(TRIM(RIGHT(ROUND(E10,2),LEN(ROUND(E10,2))-FIND(",",ROUND(E10,2)))))<2,TRIM(RIGHT(ROUND(E10,2),LEN(ROUND(E10,2))-FIND(",",ROUND(E10,2))))*10,TRIM(RIGHT(ROUND(E10,2),LEN(ROUND(E10,2))-FIND(",",ROUND(E10,2))))*1),6),1)+1,"","yüz","ikiyüz","üçyüz","dörtyüz","beşyüz","altıyüz","yediyüz","sekizyüz","dokuzyüz"),"")&IF(IF(LEN(TRIM(RIGHT(ROUND(E10,2),LEN(ROUND(E10,2))-FIND(",",ROUND(E10,2)))))<2,TRIM(RIGHT(ROUND(E10,2),LEN(ROUND(E10,2))-FIND(",",ROUND(E10,2))))*10,TRIM(RIGHT(ROUND(E10,2),LEN(ROUND(E10,2))-FIND(",",ROUND(E10,2))))*1)>=10^4,CHOOSE(LEFT(RIGHT(IF(LEN(TRIM(RIGHT(ROUND(E10,2),LEN(ROUND(E10,2))-FIND(",",ROUND(E10,2)))))<2,TRIM(RIGHT(ROUND(E10,2),LEN(ROUND(E10,2))-FIND(",",ROUND(E10,2))))*10,TRIM(RIGHT(ROUND(E10,2),LEN(ROUND(E10,2))-FIND(",",ROUND(E10,2))))*1),5),1)+1,"","on","yirmi","otuz","kırk","elli","altmış","yetmiş","seksen","doksan"),"")&IF(IF(LEN(TRIM(RIGHT(ROUND(E10,2),LEN(ROUND(E10,2))-FIND(",",ROUND(E10,2)))))<2,TRIM(RIGHT(ROUND(E10,2),LEN(ROUND(E10,2))-FIND(",",ROUND(E10,2))))*10,TRIM(RIGHT(ROUND(E10,2),LEN(ROUND(E10,2))-FIND(",",ROUND(E10,2))))*1)>=10^3,CHOOSE(LEFT(RIGHT(IF(LEN(TRIM(RIGHT(ROUND(E10,2),LEN(ROUND(E10,2))-FIND(",",ROUND(E10,2)))))<2,TRIM(RIGHT(ROUND(E10,2),LEN(ROUND(E10,2))-FIND(",",ROUND(E10,2))))*10,TRIM(RIGHT(ROUND(E10,2),LEN(ROUND(E10,2))-FIND(",",ROUND(E10,2))))*1),4),1)+1,"","","iki","üç","dört","beş","altı","yedi","sekiz","dokuz"),"")&IF(IF(LEN(TRIM(RIGHT(ROUND(E10,2),LEN(ROUND(E10,2))-FIND(",",ROUND(E10,2)))))<2,TRIM(RIGHT(ROUND(E10,2),LEN(ROUND(E10,2))-FIND(",",ROUND(E10,2))))*10,TRIM(RIGHT(ROUND(E10,2),LEN(ROUND(E10,2))-FIND(",",ROUND(E10,2))))*1)>=10,CHOOSE(LEFT(RIGHT(IF(LEN(TRIM(RIGHT(ROUND(E10,2),LEN(ROUND(E10,2))-FIND(",",ROUND(E10,2)))))<2,TRIM(RIGHT(ROUND(E10,2),LEN(ROUND(E10,2))-FIND(",",ROUND(E10,2))))*10,TRIM(RIGHT(ROUND(E10,2),LEN(ROUND(E10,2))-FIND(",",ROUND(E10,2))))*1),2),1)+1,"","on","yirmi","otuz","kırk","elli","altmış","yetmiş","seksen","doksan"),"")&CHOOSE(MOD(IF(LEN(TRIM(RIGHT(ROUND(E10,2),LEN(ROUND(E10,2))-FIND(",",ROUND(E10,2)))))<2,TRIM(RIGHT(ROUND(E10,2),LEN(ROUND(E10,2))-FIND(",",ROUND(E10,2))))*10,TRIM(RIGHT(ROUND(E10,2),LEN(ROUND(E10,2))-FIND(",",ROUND(E10,2))))*1),10)+1,"","bir","iki","üç","dört","beş","altı","yedi","sekiz","dokuz")) & " Kr") -> Onyedibin TL | G10: =G9 -> NAKDEN | H10: 8. Taksit
B11: 9 | C11: 45503 | D11: 45777 | E11: 17000 | F11: =PROPER(IF(IF(LEN(SUBSTITUTE(ROUND(E11,2), ",", ""))=LEN(ROUND(E11,2)),ROUND(E11,2),TRIM(LEFT(ROUND(E11,2),FIND(",",ROUND(E11,2))-1)))*1>=10^6,CHOOSE(LEFT(RIGHT(IF(LEN(SUBSTITUTE(ROUND(E11,2), ",", ""))=LEN(ROUND(E11,2)),ROUND(E11,2),TRIM(LEFT(ROUND(E11,2),FIND(",",ROUND(E11,2))-1)))*1,7),1)+1,"","birmilyon","ikimilyon","üçmilyon","dörtmilyon","beşmilyon","altımilyon","yedimilyon","sekizmilyon","dokuzmilyon"),"")&IF(IF(LEN(SUBSTITUTE(ROUND(E11,2), ",", ""))=LEN(ROUND(E11,2)),ROUND(E11,2),TRIM(LEFT(ROUND(E11,2),FIND(",",ROUND(E11,2))-1)))*1>=10^5,CHOOSE(LEFT(RIGHT(IF(LEN(SUBSTITUTE(ROUND(E11,2), ",", ""))=LEN(ROUND(E11,2)),ROUND(E11,2),TRIM(LEFT(ROUND(E11,2),FIND(",",ROUND(E11,2))-1)))*1,6),1)+1,"","yüz","ikiyüz","üçyüz","dörtyüz","beşyüz","altıyüz","yediyüz","sekizyüz","dokuzyüz"),"")&IF(IF(LEN(SUBSTITUTE(ROUND(E11,2), ",", ""))=LEN(ROUND(E11,2)),ROUND(E11,2),TRIM(LEFT(ROUND(E11,2),FIND(",",ROUND(E11,2))-1)))*1>=10^4,CHOOSE(LEFT(RIGHT(IF(LEN(SUBSTITUTE(ROUND(E11,2), ",", ""))=LEN(ROUND(E11,2)),ROUND(E11,2),TRIM(LEFT(ROUND(E11,2),FIND(",",ROUND(E11,2))-1)))*1,5),1)+1,"","on","yirmi","otuz","kırk","elli","altmış","yetmiş","seksen","doksan"),"")&IF(IF(LEN(SUBSTITUTE(ROUND(E11,2), ",", ""))=LEN(ROUND(E11,2)),ROUND(E11,2),TRIM(LEFT(ROUND(E11,2),FIND(",",ROUND(E11,2))-1)))*1>=10^3,CHOOSE(LEFT(RIGHT(IF(LEN(SUBSTITUTE(ROUND(E11,2), ",", ""))=LEN(ROUND(E11,2)),ROUND(E11,2),TRIM(LEFT(ROUND(E11,2),FIND(",",ROUND(E11,2))-1)))*1,4),1)+1,"","","iki","üç","dört","beş","altı","yedi","sekiz","dokuz"),"")&IF(AND(IF(LEN(SUBSTITUTE(ROUND(E11,2), ",", ""))=LEN(ROUND(E11,2)),ROUND(E11,2),TRIM(LEFT(ROUND(E11,2),FIND(",",ROUND(E11,2))-1)))*1>=10^3,VALUE(LEFT(RIGHT(IF(LEN(SUBSTITUTE(ROUND(E11,2), ",", ""))=LEN(ROUND(E11,2)),ROUND(E11,2),TRIM(LEFT(ROUND(E11,2),FIND(",",ROUND(E11,2))-1)))*1,6),3))>0),IF(AND(IF(LEN(SUBSTITUTE(ROUND(E11,2), ",", ""))=LEN(ROUND(E11,2)),ROUND(E11,2),TRIM(LEFT(ROUND(E11,2),FIND(",",ROUND(E11,2))-1)))*1>1999,LEFT(RIGHT(IF(LEN(SUBSTITUTE(ROUND(E11,2), ",", ""))=LEN(ROUND(E11,2)),ROUND(E11,2),TRIM(LEFT(ROUND(E11,2),FIND(",",ROUND(E11,2))-1)))*1,4),1)="1",LEFT(RIGHT(IF(LEN(SUBSTITUTE(ROUND(E11,2), ",", ""))=LEN(ROUND(E11,2)),ROUND(E11,2),TRIM(LEFT(ROUND(E11,2),FIND(",",ROUND(E11,2))-1)))*1,6),2)<>"00"),"birbin","bin"),"")&IF(IF(LEN(SUBSTITUTE(ROUND(E11,2), ",", ""))=LEN(ROUND(E11,2)),ROUND(E11,2),TRIM(LEFT(ROUND(E11,2),FIND(",",ROUND(E11,2))-1)))*1>=100,CHOOSE(LEFT(RIGHT(IF(LEN(SUBSTITUTE(ROUND(E11,2), ",", ""))=LEN(ROUND(E11,2)),ROUND(E11,2),TRIM(LEFT(ROUND(E11,2),FIND(",",ROUND(E11,2))-1)))*1,3),1)+1,"","yüz","ikiyüz","üçyüz","dörtyüz","beşyüz","altıyüz","yediyüz","sekizyüz","dokuzyüz"),"")&IF(IF(LEN(SUBSTITUTE(ROUND(E11,2), ",", ""))=LEN(ROUND(E11,2)),ROUND(E11,2),TRIM(LEFT(ROUND(E11,2),FIND(",",ROUND(E11,2))-1)))*1>=10,CHOOSE(LEFT(RIGHT(IF(LEN(SUBSTITUTE(ROUND(E11,2), ",", ""))=LEN(ROUND(E11,2)),ROUND(E11,2),TRIM(LEFT(ROUND(E11,2),FIND(",",ROUND(E11,2))-1)))*1,2),1)+1,"","on","yirmi","otuz","kırk","elli","altmış","yetmiş","seksen","doksan"),"")&CHOOSE(MOD(IF(LEN(SUBSTITUTE(ROUND(E11,2), ",", ""))=LEN(ROUND(E11,2)),ROUND(E11,2),TRIM(LEFT(ROUND(E11,2),FIND(",",ROUND(E11,2))-1)))*1,10)+1,"","bir","iki","üç","dört","beş","altı","yedi","sekiz","dokuz")) & " TL " & IF(OR(LEN(SUBSTITUTE(E11, ",", ""))=LEN(E11),LEN(SUBSTITUTE(ROUND(E11,2), ",", ""))=LEN(ROUND(E11,2))),"", PROPER(IF(IF(LEN(TRIM(RIGHT(ROUND(E11,2),LEN(ROUND(E11,2))-FIND(",",ROUND(E11,2)))))<2,TRIM(RIGHT(ROUND(E11,2),LEN(ROUND(E11,2))-FIND(",",ROUND(E11,2))))*10,TRIM(RIGHT(ROUND(E11,2),LEN(ROUND(E11,2))-FIND(",",ROUND(E11,2))))*1)>=10^5,CHOOSE(LEFT(RIGHT(IF(LEN(TRIM(RIGHT(ROUND(E11,2),LEN(ROUND(E11,2))-FIND(",",ROUND(E11,2)))))<2,TRIM(RIGHT(ROUND(E11,2),LEN(ROUND(E11,2))-FIND(",",ROUND(E11,2))))*10,TRIM(RIGHT(ROUND(E11,2),LEN(ROUND(E11,2))-FIND(",",ROUND(E11,2))))*1),6),1)+1,"","yüz","ikiyüz","üçyüz","dörtyüz","beşyüz","altıyüz","yediyüz","sekizyüz","dokuzyüz"),"")&IF(IF(LEN(TRIM(RIGHT(ROUND(E11,2),LEN(ROUND(E11,2))-FIND(",",ROUND(E11,2)))))<2,TRIM(RIGHT(ROUND(E11,2),LEN(ROUND(E11,2))-FIND(",",ROUND(E11,2))))*10,TRIM(RIGHT(ROUND(E11,2),LEN(ROUND(E11,2))-FIND(",",ROUND(E11,2))))*1)>=10^4,CHOOSE(LEFT(RIGHT(IF(LEN(TRIM(RIGHT(ROUND(E11,2),LEN(ROUND(E11,2))-FIND(",",ROUND(E11,2)))))<2,TRIM(RIGHT(ROUND(E11,2),LEN(ROUND(E11,2))-FIND(",",ROUND(E11,2))))*10,TRIM(RIGHT(ROUND(E11,2),LEN(ROUND(E11,2))-FIND(",",ROUND(E11,2))))*1),5),1)+1,"","on","yirmi","otuz","kırk","elli","altmış","yetmiş","seksen","doksan"),"")&IF(IF(LEN(TRIM(RIGHT(ROUND(E11,2),LEN(ROUND(E11,2))-FIND(",",ROUND(E11,2)))))<2,TRIM(RIGHT(ROUND(E11,2),LEN(ROUND(E11,2))-FIND(",",ROUND(E11,2))))*10,TRIM(RIGHT(ROUND(E11,2),LEN(ROUND(E11,2))-FIND(",",ROUND(E11,2))))*1)>=10^3,CHOOSE(LEFT(RIGHT(IF(LEN(TRIM(RIGHT(ROUND(E11,2),LEN(ROUND(E11,2))-FIND(",",ROUND(E11,2)))))<2,TRIM(RIGHT(ROUND(E11,2),LEN(ROUND(E11,2))-FIND(",",ROUND(E11,2))))*10,TRIM(RIGHT(ROUND(E11,2),LEN(ROUND(E11,2))-FIND(",",ROUND(E11,2))))*1),4),1)+1,"","","iki","üç","dört","beş","altı","yedi","sekiz","dokuz"),"")&IF(IF(LEN(TRIM(RIGHT(ROUND(E11,2),LEN(ROUND(E11,2))-FIND(",",ROUND(E11,2)))))<2,TRIM(RIGHT(ROUND(E11,2),LEN(ROUND(E11,2))-FIND(",",ROUND(E11,2))))*10,TRIM(RIGHT(ROUND(E11,2),LEN(ROUND(E11,2))-FIND(",",ROUND(E11,2))))*1)>=10,CHOOSE(LEFT(RIGHT(IF(LEN(TRIM(RIGHT(ROUND(E11,2),LEN(ROUND(E11,2))-FIND(",",ROUND(E11,2)))))<2,TRIM(RIGHT(ROUND(E11,2),LEN(ROUND(E11,2))-FIND(",",ROUND(E11,2))))*10,TRIM(RIGHT(ROUND(E11,2),LEN(ROUND(E11,2))-FIND(",",ROUND(E11,2))))*1),2),1)+1,"","on","yirmi","otuz","kırk","elli","altmış","yetmiş","seksen","doksan"),"")&CHOOSE(MOD(IF(LEN(TRIM(RIGHT(ROUND(E11,2),LEN(ROUND(E11,2))-FIND(",",ROUND(E11,2)))))<2,TRIM(RIGHT(ROUND(E11,2),LEN(ROUND(E11,2))-FIND(",",ROUND(E11,2))))*10,TRIM(RIGHT(ROUND(E11,2),LEN(ROUND(E11,2))-FIND(",",ROUND(E11,2))))*1),10)+1,"","bir","iki","üç","dört","beş","altı","yedi","sekiz","dokuz")) & " Kr") -> Onyedibin TL | G11: =G10 -> NAKDEN | H11: 9. Taksit
