Workbook

Sheet Sheet4
B2: SALİH KAYMAK
C4: KİRA HESAP ÖZETİ
E5: Kira Bedeli | F5: Ödeme | G5: Bakiye
B9: 2023 | C9: Nisan | E9: 2800 | F9: 2800 | G9: =G8+E9-F9 -> 0
C10: Mayıs | E10: 2800 | F10: 2800 | G10: =G9+E10-F10 -> 0
C11: Haziran | E11: 2800 | F11: 2800 | G11: =G10+E11-F11 -> 0
C12: Temmuz | E12: 2800 | F12: 2800 | G12: =G11+E12-F12 -> 0
C13: Ağustos | E13: 2800 | F13: 2800 | G13: =G12+E13-F13 -> 0
C14: Eylül | E14: 2800 | F14: 2800 | G14: =G13+E14-F14 -> 0
C15: Ekim | E15: 2800 | F15: 2800 | G15: =G14+E15-F15 -> 0
C16: Kasım | E16: 2800 | F16: 2800 | G16: =G15+E16-F16 -> 0
C17: Aralık | E17: 2800 | F17: 2800 | G17: =G16+E17-F17 -> 0
C18: Ocak | E18: 2800 | F18: 2800 | G18: =G17+E18-F18 -> 0
C19: Şubat | E19: 2800 | F19: 2800 | G19: =G18+E19-F19 -> 0
C20: Mart | E20: 2800 | F20: 2800 | G20: =G19+E20-F20 -> 0
B21: 2023 | C21: Kira Bedeli + Mart Tüfe Ort 12 | D21: 55 | E21: =F37*D21/100 -> 782.44795 | F21: =F37+E21 -> 2205.0806
B22: 2023 | C22: Kira Bedeli + Mart Tüfe | D22: 70 | E22: =F39*D22/100 -> 700 | F22: =F39+E22 -> 1700
B24: 2022 | C24: Nisan | E24: 1650 | F24: 1650 | G24: =G21+E24-F24 -> 0
C25: Mayıs | E25: 1650 | F25: 1650 | G25: =G24+E25-F25 -> 0
C26: Haziran | E26: 1650 | F26: 1650 | G26: =G25+E26-F26 -> 0
C27: Temmuz | E27: 1650 | F27: 1650 | G27: =G26+E27-F27 -> 0
C28: Ağustos | E28: 1650 | F28: 1650 | G28: =G27+E28-F28 -> 0
C29: Eylül | E29: 1650 | F29: 1650 | G29: =G28+E29-F29 -> 0
C30: Ekim | E30: 1650 | F30: 1650 | G30: =G29+E30-F30 -> 0
C31: Kasım | E31: 1650 | F31: 1650 | G31: =G30+E31-F31 -> 0
C32: Aralık | E32: 1650 | F32: 1650 | G32: =G31+E32-F32 -> 0
C33: Ocak | E33: 1650 | F33: 1650 | G33: =G32+E33-F33 -> 0
C34: Şubat | E34: 1650 | F34: 1650 | G34: =G33+E34-F34 -> 0
C35: Mart | E35: 1650 | F35: 1650 | G35: =G34+E35-F35 -> 0
B36: 2022 | C36: Kira Bedeli + Mart Tüfe Ort 12 | D36: 29.88 | E36: =F51*D36/100 -> 256.82429 | F36: =F51+E36 -> 1116.3433
B37: 2022 | C37: Kira Bedeli + Mart Tüfe | D37: 61.14 | E37: =F52*D37/100 -> 539.77758 | F37: =F52+E37 -> 1422.6326
B39: 2021 | C39: Nisan | E39: 1000 | F39: 1000 | G39: =G35+E39-F39 -> 0
C40: Mayıs | E40: 1000 | F40: 1000 | G40: =G39+E40-F40 -> 0
C41: Haziran | E41: 1000 | F41: 1000 | G41: =G40+E41-F41 -> 0
C42: Temmuz | E42: 1000 | F42: 1000 | G42: =G41+E42-F42 -> 0
C43: Ağustos | E43: 1000 | F43: 1000 | G43: =G42+E43-F43 -> 0
C44: Eylül | E44: 1000 | F44: 1000 | G44: =G43+E44-F44 -> 0
C45: Ekim | E45: 1000 | F45: 1000 | G45: =G44+E45-F45 -> 0
C46: Kasım | E46: 1000 | F46: 1000 | G46: =G45+E46-F46 -> 0
C47: Aralık | E47: 1000 | F47: 1000 | G47: =G46+E47-F47 -> 0
...

Sheet Senet Borçlu Alacaklı Giriş
B1: Alacaklı Adı Soyadı / Unvanı | C1: HACI MURAT BALCI
B2: İl | C2: TOKAT
A4: BORÇLU | B4: Kişilik | C4: Tüzel Kişi
B5: Adı Soyadı / Unvanı | C5: Bursa Fabrika Satış Mağazası – Adem Duman
B6: Adresi | C6: Hızarhane Cad. No:5 TOKAT
B7: Vergi Dairesi | C7: Tokat
B8: Vergi No/TC Kimlik No | C8: 341 3267 6260
A9: KEFİL | B9: Adı Soyadı / Unvanı | C9: Adem Duman
B10: Adresi | C10: Esentepe Mah. Şehit Ulaşar Cad. Belde Sitesi B Blk. K1: D:3 TOKAT
B11: Vergi Dairesi | C11: Tokat
B12: Vergi No/TC Kimlik No | C12: 341 3267 6260

Sheet Senet Taksit Giriş
B2: Senet No | C2: Düzenleme Tarihi | D2: Vade Tarihi | E2: Tutarı Rakamla | F2: Tutarı Yazıyla | G2: Borcun Nedeni | H2: Senet Mühteviyatı
A3: 3 | B3: 1 | C3: 44252 | D3: 44285 | E3: 2000 | F3: =PROPER(IF(IF(LEN(SUBSTITUTE(ROUND(E3,2), ",", ""))=LEN(ROUND(E3,2)),ROUND(E3,2),TRIM(LEFT(ROUND(E3,2),FIND(",",ROUND(E3,2))-1)))*1>=10^6,CHOOSE(LEFT(RIGHT(IF(LEN(SUBSTITUTE(ROUND(E3,2), ",", ""))=LEN(ROUND(E3,2)),ROUND(E3,2),TRIM(LEFT(ROUND(E3,2),FIND(",",ROUND(E3,2))-1)))*1,7),1)+1,"","birmilyon","ikimilyon","üçmilyon","dörtmilyon","beşmilyon","altımilyon","yedimilyon","sekizmilyon","dokuzmilyon"),"")&IF(IF(LEN(SUBSTITUTE(ROUND(E3,2), ",", ""))=LEN(ROUND(E3,2)),ROUND(E3,2),TRIM(LEFT(ROUND(E3,2),FIND(",",ROUND(E3,2))-1)))*1>=10^5,CHOOSE(LEFT(RIGHT(IF(LEN(SUBSTITUTE(ROUND(E3,2), ",", ""))=LEN(ROUND(E3,2)),ROUND(E3,2),TRIM(LEFT(ROUND(E3,2),FIND(",",ROUND(E3,2))-1)))*1,6),1)+1,"","yüz","ikiyüz","üçyüz","dörtyüz","beşyüz","altıyüz","yediyüz","sekizyüz","dokuzyüz"),"")&IF(IF(LEN(SUBSTITUTE(ROUND(E3,2), ",", ""))=LEN(ROUND(E3,2)),ROUND(E3,2),TRIM(LEFT(ROUND(E3,2),FIND(",",ROUND(E3,2))-1)))*1>=10^4,CHOOSE(LEFT(RIGHT(IF(LEN(SUBSTITUTE(ROUND(E3,2), ",", ""))=LEN(ROUND(E3,2)),ROUND(E3,2),TRIM(LEFT(ROUND(E3,2),FIND(",",ROUND(E3,2))-1)))*1,5),1)+1,"","on","yirmi","otuz","kırk","elli","altmış","yetmiş","seksen","doksan"),"")&IF(IF(LEN(SUBSTITUTE(ROUND(E3,2), ",", ""))=LEN(ROUND(E3,2)),ROUND(E3,2),TRIM(LEFT(ROUND(E3,2),FIND(",",ROUND(E3,2))-1)))*1>=10^3,CHOOSE(LEFT(RIGHT(IF(LEN(SUBSTITUTE(ROUND(E3,2), ",", ""))=LEN(ROUND(E3,2)),ROUND(E3,2),TRIM(LEFT(ROUND(E3,2),FIND(",",ROUND(E3,2))-1)))*1,4),1)+1,"","","iki","üç","dört","beş","altı","yedi","sekiz","dokuz"),"")&IF(AND(IF(LEN(SUBSTITUTE(ROUND(E3,2), ",", ""))=LEN(ROUND(E3,2)),ROUND(E3,2),TRIM(LEFT(ROUND(E3,2),FIND(",",ROUND(E3,2))-1)))*1>=10^3,VALUE(LEFT(RIGHT(IF(LEN(SUBSTITUTE(ROUND(E3,2), ",", ""))=LEN(ROUND(E3,2)),ROUND(E3,2),TRIM(LEFT(ROUND(E3,2),FIND(",",ROUND(E3,2))-1)))*1,6),3))>0),IF(AND(IF(LEN(SUBSTITUTE(ROUND(E3,2), ",", ""))=LEN(ROUND(E3,2)),ROUND(E3,2),TRIM(LEFT(ROUND(E3,2),FIND(",",ROUND(E3,2))-1)))*1>1999,LEFT(RIGHT(IF(LEN(SUBSTITUTE(ROUND(E3,2), ",", ""))=LEN(ROUND(E3,2)),ROUND(E3,2),TRIM(LEFT(ROUND(E3,2),FIND(",",ROUND(E3,2))-1)))*1,4),1)="1",LEFT(RIGHT(IF(LEN(SUBSTITUTE(ROUND(E3,2), ",", ""))=LEN(ROUND(E3,2)),ROUND(E3,2),TRIM(LEFT(ROUND(E3,2),FIND(",",ROUND(E3,2))-1)))*1,6),2)<>"00"),"birbin","bin"),"")&IF(IF(LEN(SUBSTITUTE(ROUND(E3,2), ",", ""))=LEN(ROUND(E3,2)),ROUND(E3,2),TRIM(LEFT(ROUND(E3,2),FIND(",",ROUND(E3,2))-1)))*1>=100,CHOOSE(LEFT(RIGHT(IF(LEN(SUBSTITUTE(ROUND(E3,2), ",", ""))=LEN(ROUND(E3,2)),ROUND(E3,2),TRIM(LEFT(ROUND(E3,2),FIND(",",ROUND(E3,2))-1)))*1,3),1)+1,"","yüz","ikiyüz","üçyüz","dörtyüz","beşyüz","altıyüz","yediyüz","sekizyüz","dokuzyüz"),"")&IF(IF(LEN(SUBSTITUTE(ROUND(E3,2), ",", ""))=LEN(ROUND(E3,2)),ROUND(E3,2),TRIM(LEFT(ROUND(E3,2),FIND(",",ROUND(E3,2))-1)))*1>=10,CHOOSE(LEFT(RIGHT(IF(LEN(SUBSTITUTE(ROUND(E3,2), ",", ""))=LEN(ROUND(E3,2)),ROUND(E3,2),TRIM(LEFT(ROUND(E3,2),FIND(",",ROUND(E3,2))-1)))*1,2),1)+1,"","on","yirmi","otuz","kırk","elli","altmış","yetmiş","seksen","doksan"),"")&CHOOSE(MOD(IF(LEN(SUBSTITUTE(ROUND(E3,2), ",", ""))=LEN(ROUND(E3,2)),ROUND(E3,2),TRIM(LEFT(ROUND(E3,2),FIND(",",ROUND(E3,2))-1)))*1,10)+1,"","bir","iki","üç","dört","beş","altı","yedi","sekiz","dokuz")) & " TL " & IF(OR(LEN(SUBSTITUTE(E3, ",", ""))=LEN(E3),LEN(SUBSTITUTE(ROUND(E3,2), ",", ""))=LEN(ROUND(E3,2))),"", PROPER(IF(IF(LEN(TRIM(RIGHT(ROUND(E3,2),LEN(ROUND(E3,2))-FIND(",",ROUND(E3,2)))))<2,TRIM(RIGHT(ROUND(E3,2),LEN(ROUND(E3,2))-FIND(",",ROUND(E3,2))))*10,TRIM(RIGHT(ROUND(E3,2),LEN(ROUND(E3,2))-FIND(",",ROUND(E3,2))))*1)>=10^5,CHOOSE(LEFT(RIGHT(IF(LEN(TRIM(RIGHT(ROUND(E3,2),LEN(ROUND(E3,2))-FIND(",",ROUND(E3,2)))))<2,TRIM(RIGHT(ROUND(E3,2),LEN(ROUND(E3,2))-FIND(",",ROUND(E3,2))))*10,TRIM(RIGHT(ROUND(E3,2),LEN(ROUND(E3,2))-FIND(",",ROUND(E3,2))))*1),6),1)+1,"","yüz","ikiyüz","üçyüz","dörtyüz","beşyüz","altıyüz","yediyüz","sekizyüz","dokuzyüz"),"")&IF(IF(LEN(TRIM(RIGHT(ROUND(E3,2),LEN(ROUND(E3,2))-FIND(",",ROUND(E3,2)))))<2,TRIM(RIGHT(ROUND(E3,2),LEN(ROUND(E3,2))-FIND(",",ROUND(E3,2))))*10,TRIM(RIGHT(ROUND(E3,2),LEN(ROUND(E3,2))-FIND(",",ROUND(E3,2))))*1)>=10^4,CHOOSE(LEFT(RIGHT(IF(LEN(TRIM(RIGHT(ROUND(E3,2),LEN(ROUND(E3,2))-FIND(",",ROUND(E3,2)))))<2,TRIM(RIGHT(ROUND(E3,2),LEN(ROUND(E3,2))-FIND(",",ROUND(E3,2))))*10,TRIM(RIGHT(ROUND(E3,2),LEN(ROUND(E3,2))-FIND(",",ROUND(E3,2))))*1),5),1)+1,"","on","yirmi","otuz","kırk","elli","altmış","yetmiş","seksen","doksan"),"")&IF(IF(LEN(TRIM(RIGHT(ROUND(E3,2),LEN(ROUND(E3,2))-FIND(",",ROUND(E3,2)))))<2,TRIM(RIGHT(ROUND(E3,2),LEN(ROUND(E3,2))-FIND(",",ROUND(E3,2))))*10,TRIM(RIGHT(ROUND(E3,2),LEN(ROUND(E3,2))-FIND(",",ROUND(E3,2))))*1)>=10^3,CHOOSE(LEFT(RIGHT(IF(LEN(TRIM(RIGHT(ROUND(E3,2),LEN(ROUND(E3,2))-FIND(",",ROUND(E3,2)))))<2,TRIM(RIGHT(ROUND(E3,2),LEN(ROUND(E3,2))-FIND(",",ROUND(E3,2))))*10,TRIM(RIGHT(ROUND(E3,2),LEN(ROUND(E3,2))-FIND(",",ROUND(E3,2))))*1),4),1)+1,"","","iki","üç","dört","beş","altı","yedi","sekiz","dokuz"),"")&IF(IF(LEN(TRIM(RIGHT(ROUND(E3,2),LEN(ROUND(E3,2))-FIND(",",ROUND(E3,2)))))<2,TRIM(RIGHT(ROUND(E3,2),LEN(ROUND(E3,2))-FIND(",",ROUND(E3,2))))*10,TRIM(RIGHT(ROUND(E3,2),LEN(ROUND(E3,2))-FIND(",",ROUND(E3,2))))*1)>=10,CHOOSE(LEFT(RIGHT(IF(LEN(TRIM(RIGHT(ROUND(E3,2),LEN(ROUND(E3,2))-FIND(",",ROUND(E3,2)))))<2,TRIM(RIGHT(ROUND(E3,2),LEN(ROUND(E3,2))-FIND(",",ROUND(E3,2))))*10,TRIM(RIGHT(ROUND(E3,2),LEN(ROUND(E3,2))-FIND(",",ROUND(E3,2))))*1),2),1)+1,"","on","yirmi","otuz","kırk","elli","altmış","yetmiş","seksen","doksan"),"")&CHOOSE(MOD(IF(LEN(TRIM(RIGHT(ROUND(E3,2),LEN(ROUND(E3,2))-FIND(",",ROUND(E3,2)))))<2,TRIM(RIGHT(ROUND(E3,2),LEN(ROUND(E3,2))-FIND(",",ROUND(E3,2))))*10,TRIM(RIGHT(ROUND(E3,2),LEN(ROUND(E3,2))-FIND(",",ROUND(E3,2))))*1),10)+1,"","bir","iki","üç","dört","beş","altı","yedi","sekiz","dokuz")) & " Kr") -> İkibin TL | G3: NAKDEN | H3: 1. Taksit
B4: 2 | C4: 44252 | D4: 44316 | E4: 2000 | F4: =PROPER(IF(IF(LEN(SUBSTITUTE(ROUND(E4,2), ",", ""))=LEN(ROUND(E4,2)),ROUND(E4,2),TRIM(LEFT(ROUND(E4,2),FIND(",",ROUND(E4,2))-1)))*1>=10^6,CHOOSE(LEFT(RIGHT(IF(LEN(SUBSTITUTE(ROUND(E4,2), ",", ""))=LEN(ROUND(E4,2)),ROUND(E4,2),TRIM(LEFT(ROUND(E4,2),FIND(",",ROUND(E4,2))-1)))*1,7),1)+1,"","birmilyon","ikimilyon","üçmilyon","dörtmilyon","beşmilyon","altımilyon","yedimilyon","sekizmilyon","dokuzmilyon"),"")&IF(IF(LEN(SUBSTITUTE(ROUND(E4,2), ",", ""))=LEN(ROUND(E4,2)),ROUND(E4,2),TRIM(LEFT(ROUND(E4,2),FIND(",",ROUND(E4,2))-1)))*1>=10^5,CHOOSE(LEFT(RIGHT(IF(LEN(SUBSTITUTE(ROUND(E4,2), ",", ""))=LEN(ROUND(E4,2)),ROUND(E4,2),TRIM(LEFT(ROUND(E4,2),FIND(",",ROUND(E4,2))-1)))*1,6),1)+1,"","yüz","ikiyüz","üçyüz","dörtyüz","beşyüz","altıyüz","yediyüz","sekizyüz","dokuzyüz"),"")&IF(IF(LEN(SUBSTITUTE(ROUND(E4,2), ",", ""))=LEN(ROUND(E4,2)),ROUND(E4,2),TRIM(LEFT(ROUND(E4,2),FIND(",",ROUND(E4,2))-1)))*1>=10^4,CHOOSE(LEFT(RIGHT(IF(LEN(SUBSTITUTE(ROUND(E4,2), ",", ""))=LEN(ROUND(E4,2)),ROUND(E4,2),TRIM(LEFT(ROUND(E4,2),FIND(",",ROUND(E4,2))-1)))*1,5),1)+1,"","on","yirmi","otuz","kırk","elli","altmış","yetmiş","seksen","doksan"),"")&IF(IF(LEN(SUBSTITUTE(ROUND(E4,2), ",", ""))=LEN(ROUND(E4,2)),ROUND(E4,2),TRIM(LEFT(ROUND(E4,2),FIND(",",ROUND(E4,2))-1)))*1>=10^3,CHOOSE(LEFT(RIGHT(IF(LEN(SUBSTITUTE(ROUND(E4,2), ",", ""))=LEN(ROUND(E4,2)),ROUND(E4,2),TRIM(LEFT(ROUND(E4,2),FIND(",",ROUND(E4,2))-1)))*1,4),1)+1,"","","iki","üç","dört","beş","altı","yedi","sekiz","dokuz"),"")&IF(AND(IF(LEN(SUBSTITUTE(ROUND(E4,2), ",", ""))=LEN(ROUND(E4,2)),ROUND(E4,2),TRIM(LEFT(ROUND(E4,2),FIND(",",ROUND(E4,2))-1)))*1>=10^3,VALUE(LEFT(RIGHT(IF(LEN(SUBSTITUTE(ROUND(E4,2), ",", ""))=LEN(ROUND(E4,2)),ROUND(E4,2),TRIM(LEFT(ROUND(E4,2),FIND(",",ROUND(E4,2))-1)))*1,6),3))>0),IF(AND(IF(LEN(SUBSTITUTE(ROUND(E4,2), ",", ""))=LEN(ROUND(E4,2)),ROUND(E4,2),TRIM(LEFT(ROUND(E4,2),FIND(",",ROUND(E4,2))-1)))*1>1999,LEFT(RIGHT(IF(LEN(SUBSTITUTE(ROUND(E4,2), ",", ""))=LEN(ROUND(E4,2)),ROUND(E4,2),TRIM(LEFT(ROUND(E4,2),FIND(",",ROUND(E4,2))-1)))*1,4),1)="1",LEFT(RIGHT(IF(LEN(SUBSTITUTE(ROUND(E4,2), ",", ""))=LEN(ROUND(E4,2)),ROUND(E4,2),TRIM(LEFT(ROUND(E4,2),FIND(",",ROUND(E4,2))-1)))*1,6),2)<>"00"),"birbin","bin"),"")&IF(IF(LEN(SUBSTITUTE(ROUND(E4,2), ",", ""))=LEN(ROUND(E4,2)),ROUND(E4,2),TRIM(LEFT(ROUND(E4,2),FIND(",",ROUND(E4,2))-1)))*1>=100,CHOOSE(LEFT(RIGHT(IF(LEN(SUBSTITUTE(ROUND(E4,2), ",", ""))=LEN(ROUND(E4,2)),ROUND(E4,2),TRIM(LEFT(ROUND(E4,2),FIND(",",ROUND(E4,2))-1)))*1,3),1)+1,"","yüz","ikiyüz","üçyüz","dörtyüz","beşyüz","altıyüz","yediyüz","sekizyüz","dokuzyüz"),"")&IF(IF(LEN(SUBSTITUTE(ROUND(E4,2), ",", ""))=LEN(ROUND(E4,2)),ROUND(E4,2),TRIM(LEFT(ROUND(E4,2),FIND(",",ROUND(E4,2))-1)))*1>=10,CHOOSE(LEFT(RIGHT(IF(LEN(SUBSTITUTE(ROUND(E4,2), ",", ""))=LEN(ROUND(E4,2)),ROUND(E4,2),TRIM(LEFT(ROUND(E4,2),FIND(",",ROUND(E4,2))-1)))*1,2),1)+1,"","on","yirmi","otuz","kırk","elli","altmış","yetmiş","seksen","doksan"),"")&CHOOSE(MOD(IF(LEN(SUBSTITUTE(ROUND(E4,2), ",", ""))=LEN(ROUND(E4,2)),ROUND(E4,2),TRIM(LEFT(ROUND(E4,2),FIND(",",ROUND(E4,2))-1)))*1,10)+1,"","bir","iki","üç","dört","beş","altı","yedi","sekiz","dokuz")) & " TL " & IF(OR(LEN(SUBSTITUTE(E4, ",", ""))=LEN(E4),LEN(SUBSTITUTE(ROUND(E4,2), ",", ""))=LEN(ROUND(E4,2))),"", PROPER(IF(IF(LEN(TRIM(RIGHT(ROUND(E4,2),LEN(ROUND(E4,2))-FIND(",",ROUND(E4,2)))))<2,TRIM(RIGHT(ROUND(E4,2),LEN(ROUND(E4,2))-FIND(",",ROUND(E4,2))))*10,TRIM(RIGHT(ROUND(E4,2),LEN(ROUND(E4,2))-FIND(",",ROUND(E4,2))))*1)>=10^5,CHOOSE(LEFT(RIGHT(IF(LEN(TRIM(RIGHT(ROUND(E4,2),LEN(ROUND(E4,2))-FIND(",",ROUND(E4,2)))))<2,TRIM(RIGHT(ROUND(E4,2),LEN(ROUND(E4,2))-FIND(",",ROUND(E4,2))))*10,TRIM(RIGHT(ROUND(E4,2),LEN(ROUND(E4,2))-FIND(",",ROUND(E4,2))))*1),6),1)+1,"","yüz","ikiyüz","üçyüz","dörtyüz","beşyüz","altıyüz","yediyüz","sekizyüz","dokuzyüz"),"")&IF(IF(LEN(TRIM(RIGHT(ROUND(E4,2),LEN(ROUND(E4,2))-FIND(",",ROUND(E4,2)))))<2,TRIM(RIGHT(ROUND(E4,2),LEN(ROUND(E4,2))-FIND(",",ROUND(E4,2))))*10,TRIM(RIGHT(ROUND(E4,2),LEN(ROUND(E4,2))-FIND(",",ROUND(E4,2))))*1)>=10^4,CHOOSE(LEFT(RIGHT(IF(LEN(TRIM(RIGHT(ROUND(E4,2),LEN(ROUND(E4,2))-FIND(",",ROUND(E4,2)))))<2,TRIM(RIGHT(ROUND(E4,2),LEN(ROUND(E4,2))-FIND(",",ROUND(E4,2))))*10,TRIM(RIGHT(ROUND(E4,2),LEN(ROUND(E4,2))-FIND(",",ROUND(E4,2))))*1),5),1)+1,"","on","yirmi","otuz","kırk","elli","altmış","yetmiş","seksen","doksan"),"")&IF(IF(LEN(TRIM(RIGHT(ROUND(E4,2),LEN(ROUND(E4,2))-FIND(",",ROUND(E4,2)))))<2,TRIM(RIGHT(ROUND(E4,2),LEN(ROUND(E4,2))-FIND(",",ROUND(E4,2))))*10,TRIM(RIGHT(ROUND(E4,2),LEN(ROUND(E4,2))-FIND(",",ROUND(E4,2))))*1)>=10^3,CHOOSE(LEFT(RIGHT(IF(LEN(TRIM(RIGHT(ROUND(E4,2),LEN(ROUND(E4,2))-FIND(",",ROUND(E4,2)))))<2,TRIM(RIGHT(ROUND(E4,2),LEN(ROUND(E4,2))-FIND(",",ROUND(E4,2))))*10,TRIM(RIGHT(ROUND(E4,2),LEN(ROUND(E4,2))-FIND(",",ROUND(E4,2))))*1),4),1)+1,"","","iki","üç","dört","beş","altı","yedi","sekiz","dokuz"),"")&IF(IF(LEN(TRIM(RIGHT(ROUND(E4,2),LEN(ROUND(E4,2))-FIND(",",ROUND(E4,2)))))<2,TRIM(RIGHT(ROUND(E4,2),LEN(ROUND(E4,2))-FIND(",",ROUND(E4,2))))*10,TRIM(RIGHT(ROUND(E4,2),LEN(ROUND(E4,2))-FIND(",",ROUND(E4,2))))*1)>=10,CHOOSE(LEFT(RIGHT(IF(LEN(TRIM(RIGHT(ROUND(E4,2),LEN(ROUND(E4,2))-FIND(",",ROUND(E4,2)))))<2,TRIM(RIGHT(ROUND(E4,2),LEN(ROUND(E4,2))-FIND(",",ROUND(E4,2))))*10,TRIM(RIGHT(ROUND(E4,2),LEN(ROUND(E4,2))-FIND(",",ROUND(E4,2))))*1),2),1)+1,"","on","yirmi","otuz","kırk","elli","altmış","yetmiş","seksen","doksan"),"")&CHOOSE(MOD(IF(LEN(TRIM(RIGHT(ROUND(E4,2),LEN(ROUND(E4,2))-FIND(",",ROUND(E4,2)))))<2,TRIM(RIGHT(ROUND(E4,2),LEN(ROUND(E4,2))-FIND(",",ROUND(E4,2))))*10,TRIM(RIGHT(ROUND(E4,2),LEN(ROUND(E4,2))-FIND(",",ROUND(E4,2))))*1),10)+1,"","bir","iki","üç","dört","beş","altı","yedi","sekiz","dokuz")) & " Kr") -> İkibin TL | G4: =G3 -> NAKDEN | H4: 2. Taksit
B5: 3 | C5: 44252 | D5: 44346 | E5: 2000 | F5: =PROPER(IF(IF(LEN(SUBSTITUTE(ROUND(E5,2), ",", ""))=LEN(ROUND(E5,2)),ROUND(E5,2),TRIM(LEFT(ROUND(E5,2),FIND(",",ROUND(E5,2))-1)))*1>=10^6,CHOOSE(LEFT(RIGHT(IF(LEN(SUBSTITUTE(ROUND(E5,2), ",", ""))=LEN(ROUND(E5,2)),ROUND(E5,2),TRIM(LEFT(ROUND(E5,2),FIND(",",ROUND(E5,2))-1)))*1,7),1)+1,"","birmilyon","ikimilyon","üçmilyon","dörtmilyon","beşmilyon","altımilyon","yedimilyon","sekizmilyon","dokuzmilyon"),"")&IF(IF(LEN(SUBSTITUTE(ROUND(E5,2), ",", ""))=LEN(ROUND(E5,2)),ROUND(E5,2),TRIM(LEFT(ROUND(E5,2),FIND(",",ROUND(E5,2))-1)))*1>=10^5,CHOOSE(LEFT(RIGHT(IF(LEN(SUBSTITUTE(ROUND(E5,2), ",", ""))=LEN(ROUND(E5,2)),ROUND(E5,2),TRIM(LEFT(ROUND(E5,2),FIND(",",ROUND(E5,2))-1)))*1,6),1)+1,"","yüz","ikiyüz","üçyüz","dörtyüz","beşyüz","altıyüz","yediyüz","sekizyüz","dokuzyüz"),"")&IF(IF(LEN(SUBSTITUTE(ROUND(E5,2), ",", ""))=LEN(ROUND(E5,2)),ROUND(E5,2),TRIM(LEFT(ROUND(E5,2),FIND(",",ROUND(E5,2))-1)))*1>=10^4,CHOOSE(LEFT(RIGHT(IF(LEN(SUBSTITUTE(ROUND(E5,2), ",", ""))=LEN(ROUND(E5,2)),ROUND(E5,2),TRIM(LEFT(ROUND(E5,2),FIND(",",ROUND(E5,2))-1)))*1,5),1)+1,"","on","yirmi","otuz","kırk","elli","altmış","yetmiş","seksen","doksan"),"")&IF(IF(LEN(SUBSTITUTE(ROUND(E5,2), ",", ""))=LEN(ROUND(E5,2)),ROUND(E5,2),TRIM(LEFT(ROUND(E5,2),FIND(",",ROUND(E5,2))-1)))*1>=10^3,CHOOSE(LEFT(RIGHT(IF(LEN(SUBSTITUTE(ROUND(E5,2), ",", ""))=LEN(ROUND(E5,2)),ROUND(E5,2),TRIM(LEFT(ROUND(E5,2),FIND(",",ROUND(E5,2))-1)))*1,4),1)+1,"","","iki","üç","dört","beş","altı","yedi","sekiz","dokuz"),"")&IF(AND(IF(LEN(SUBSTITUTE(ROUND(E5,2), ",", ""))=LEN(ROUND(E5,2)),ROUND(E5,2),TRIM(LEFT(ROUND(E5,2),FIND(",",ROUND(E5,2))-1)))*1>=10^3,VALUE(LEFT(RIGHT(IF(LEN(SUBSTITUTE(ROUND(E5,2), ",", ""))=LEN(ROUND(E5,2)),ROUND(E5,2),TRIM(LEFT(ROUND(E5,2),FIND(",",ROUND(E5,2))-1)))*1,6),3))>0),IF(AND(IF(LEN(SUBSTITUTE(ROUND(E5,2), ",", ""))=LEN(ROUND(E5,2)),ROUND(E5,2),TRIM(LEFT(ROUND(E5,2),FIND(",",ROUND(E5,2))-1)))*1>1999,LEFT(RIGHT(IF(LEN(SUBSTITUTE(ROUND(E5,2), ",", ""))=LEN(ROUND(E5,2)),ROUND(E5,2),TRIM(LEFT(ROUND(E5,2),FIND(",",ROUND(E5,2))-1)))*1,4),1)="1",LEFT(RIGHT(IF(LEN(SUBSTITUTE(ROUND(E5,2), ",", ""))=LEN(ROUND(E5,2)),ROUND(E5,2),TRIM(LEFT(ROUND(E5,2),FIND(",",ROUND(E5,2))-1)))*1,6),2)<>"00"),"birbin","bin"),"")&IF(IF(LEN(SUBSTITUTE(ROUND(E5,2), ",", ""))=LEN(ROUND(E5,2)),ROUND(E5,2),TRIM(LEFT(ROUND(E5,2),FIND(",",ROUND(E5,2))-1)))*1>=100,CHOOSE(LEFT(RIGHT(IF(LEN(SUBSTITUTE(ROUND(E5,2), ",", ""))=LEN(ROUND(E5,2)),ROUND(E5,2),TRIM(LEFT(ROUND(E5,2),FIND(",",ROUND(E5,2))-1)))*1,3),1)+1,"","yüz","ikiyüz","üçyüz","dörtyüz","beşyüz","altıyüz","yediyüz","sekizyüz","dokuzyüz"),"")&IF(IF(LEN(SUBSTITUTE(ROUND(E5,2), ",", ""))=LEN(ROUND(E5,2)),ROUND(E5,2),TRIM(LEFT(ROUND(E5,2),FIND(",",ROUND(E5,2))-1)))*1>=10,CHOOSE(LEFT(RIGHT(IF(LEN(SUBSTITUTE(ROUND(E5,2), ",", ""))=LEN(ROUND(E5,2)),ROUND(E5,2),TRIM(LEFT(ROUND(E5,2),FIND(",",ROUND(E5,2))-1)))*1,2),1)+1,"","on","yirmi","otuz","kırk","elli","altmış","yetmiş","seksen","doksan"),"")&CHOOSE(MOD(IF(LEN(SUBSTITUTE(ROUND(E5,2), ",", ""))=LEN(ROUND(E5,2)),ROUND(E5,2),TRIM(LEFT(ROUND(E5,2),FIND(",",ROUND(E5,2))-1)))*1,10)+1,"","bir","iki","üç","dört","beş","altı","yedi","sekiz","dokuz")) & " TL " & IF(OR(LEN(SUBSTITUTE(E5, ",", ""))=LEN(E5),LEN(SUBSTITUTE(ROUND(E5,2), ",", ""))=LEN(ROUND(E5,2))),"", PROPER(IF(IF(LEN(TRIM(RIGHT(ROUND(E5,2),LEN(ROUND(E5,2))-FIND(",",ROUND(E5,2)))))<2,TRIM(RIGHT(ROUND(E5,2),LEN(ROUND(E5,2))-FIND(",",ROUND(E5,2))))*10,TRIM(RIGHT(ROUND(E5,2),LEN(ROUND(E5,2))-FIND(",",ROUND(E5,2))))*1)>=10^5,CHOOSE(LEFT(RIGHT(IF(LEN(TRIM(RIGHT(ROUND(E5,2),LEN(ROUND(E5,2))-FIND(",",ROUND(E5,2)))))<2,TRIM(RIGHT(ROUND(E5,2),LEN(ROUND(E5,2))-FIND(",",ROUND(E5,2))))*10,TRIM(RIGHT(ROUND(E5,2),LEN(ROUND(E5,2))-FIND(",",ROUND(E5,2))))*1),6),1)+1,"","yüz","ikiyüz","üçyüz","dörtyüz","beşyüz","altıyüz","yediyüz","sekizyüz","dokuzyüz"),"")&IF(IF(LEN(TRIM(RIGHT(ROUND(E5,2),LEN(ROUND(E5,2))-FIND(",",ROUND(E5,2)))))<2,TRIM(RIGHT(ROUND(E5,2),LEN(ROUND(E5,2))-FIND(",",ROUND(E5,2))))*10,TRIM(RIGHT(ROUND(E5,2),LEN(ROUND(E5,2))-FIND(",",ROUND(E5,2))))*1)>=10^4,CHOOSE(LEFT(RIGHT(IF(LEN(TRIM(RIGHT(ROUND(E5,2),LEN(ROUND(E5,2))-FIND(",",ROUND(E5,2)))))<2,TRIM(RIGHT(ROUND(E5,2),LEN(ROUND(E5,2))-FIND(",",ROUND(E5,2))))*10,TRIM(RIGHT(ROUND(E5,2),LEN(ROUND(E5,2))-FIND(",",ROUND(E5,2))))*1),5),1)+1,"","on","yirmi","otuz","kırk","elli","altmış","yetmiş","seksen","doksan"),"")&IF(IF(LEN(TRIM(RIGHT(ROUND(E5,2),LEN(ROUND(E5,2))-FIND(",",ROUND(E5,2)))))<2,TRIM(RIGHT(ROUND(E5,2),LEN(ROUND(E5,2))-FIND(",",ROUND(E5,2))))*10,TRIM(RIGHT(ROUND(E5,2),LEN(ROUND(E5,2))-FIND(",",ROUND(E5,2))))*1)>=10^3,CHOOSE(LEFT(RIGHT(IF(LEN(TRIM(RIGHT(ROUND(E5,2),LEN(ROUND(E5,2))-FIND(",",ROUND(E5,2)))))<2,TRIM(RIGHT(ROUND(E5,2),LEN(ROUND(E5,2))-FIND(",",ROUND(E5,2))))*10,TRIM(RIGHT(ROUND(E5,2),LEN(ROUND(E5,2))-FIND(",",ROUND(E5,2))))*1),4),1)+1,"","","iki","üç","dört","beş","altı","yedi","sekiz","dokuz"),"")&IF(IF(LEN(TRIM(RIGHT(ROUND(E5,2),LEN(ROUND(E5,2))-FIND(",",ROUND(E5,2)))))<2,TRIM(RIGHT(ROUND(E5,2),LEN(ROUND(E5,2))-FIND(",",ROUND(E5,2))))*10,TRIM(RIGHT(ROUND(E5,2),LEN(ROUND(E5,2))-FIND(",",ROUND(E5,2))))*1)>=10,CHOOSE(LEFT(RIGHT(IF(LEN(TRIM(RIGHT(ROUND(E5,2),LEN(ROUND(E5,2))-FIND(",",ROUND(E5,2)))))<2,TRIM(RIGHT(ROUND(E5,2),LEN(ROUND(E5,2))-FIND(",",ROUND(E5,2))))*10,TRIM(RIGHT(ROUND(E5,2),LEN(ROUND(E5,2))-FIND(",",ROUND(E5,2))))*1),2),1)+1,"","on","yirmi","otuz","kırk","elli","altmış","yetmiş","seksen","doksan"),"")&CHOOSE(MOD(IF(LEN(TRIM(RIGHT(ROUND(E5,2),LEN(ROUND(E5,2))-FIND(",",ROUND(E5,2)))))<2,TRIM(RIGHT(ROUND(E5,2),LEN(ROUND(E5,2))-FIND(",",ROUND(E5,2))))*10,TRIM(RIGHT(ROUND(E5,2),LEN(ROUND(E5,2))-FIND(",",ROUND(E5,2))))*1),10)+1,"","bir","iki","üç","dört","beş","altı","yedi","sekiz","dokuz")) & " Kr") -> İkibin TL | G5: =G4 -> NAKDEN | H5: 3. Taksit
B6: 4 | C6: 44252 | D6: 44377 | E6: 2000 | F6: =PROPER(IF(IF(LEN(SUBSTITUTE(ROUND(E6,2), ",", ""))=LEN(ROUND(E6,2)),ROUND(E6,2),TRIM(LEFT(ROUND(E6,2),FIND(",",ROUND(E6,2))-1)))*1>=10^6,CHOOSE(LEFT(RIGHT(IF(LEN(SUBSTITUTE(ROUND(E6,2), ",", ""))=LEN(ROUND(E6,2)),ROUND(E6,2),TRIM(LEFT(ROUND(E6,2),FIND(",",ROUND(E6,2))-1)))*1,7),1)+1,"","birmilyon","ikimilyon","üçmilyon","dörtmilyon","beşmilyon","altımilyon","yedimilyon","sekizmilyon","dokuzmilyon"),"")&IF(IF(LEN(SUBSTITUTE(ROUND(E6,2), ",", ""))=LEN(ROUND(E6,2)),ROUND(E6,2),TRIM(LEFT(ROUND(E6,2),FIND(",",ROUND(E6,2))-1)))*1>=10^5,CHOOSE(LEFT(RIGHT(IF(LEN(SUBSTITUTE(ROUND(E6,2), ",", ""))=LEN(ROUND(E6,2)),ROUND(E6,2),TRIM(LEFT(ROUND(E6,2),FIND(",",ROUND(E6,2))-1)))*1,6),1)+1,"","yüz","ikiyüz","üçyüz","dörtyüz","beşyüz","altıyüz","yediyüz","sekizyüz","dokuzyüz"),"")&IF(IF(LEN(SUBSTITUTE(ROUND(E6,2), ",", ""))=LEN(ROUND(E6,2)),ROUND(E6,2),TRIM(LEFT(ROUND(E6,2),FIND(",",ROUND(E6,2))-1)))*1>=10^4,CHOOSE(LEFT(RIGHT(IF(LEN(SUBSTITUTE(ROUND(E6,2), ",", ""))=LEN(ROUND(E6,2)),ROUND(E6,2),TRIM(LEFT(ROUND(E6,2),FIND(",",ROUND(E6,2))-1)))*1,5),1)+1,"","on","yirmi","otuz","kırk","elli","altmış","yetmiş","seksen","doksan"),"")&IF(IF(LEN(SUBSTITUTE(ROUND(E6,2), ",", ""))=LEN(ROUND(E6,2)),ROUND(E6,2),TRIM(LEFT(ROUND(E6,2),FIND(",",ROUND(E6,2))-1)))*1>=10^3,CHOOSE(LEFT(RIGHT(IF(LEN(SUBSTITUTE(ROUND(E6,2), ",", ""))=LEN(ROUND(E6,2)),ROUND(E6,2),TRIM(LEFT(ROUND(E6,2),FIND(",",ROUND(E6,2))-1)))*1,4),1)+1,"","","iki","üç","dört","beş","altı","yedi","sekiz","dokuz"),"")&IF(AND(IF(LEN(SUBSTITUTE(ROUND(E6,2), ",", ""))=LEN(ROUND(E6,2)),ROUND(E6,2),TRIM(LEFT(ROUND(E6,2),FIND(",",ROUND(E6,2))-1)))*1>=10^3,VALUE(LEFT(RIGHT(IF(LEN(SUBSTITUTE(ROUND(E6,2), ",", ""))=LEN(ROUND(E6,2)),ROUND(E6,2),TRIM(LEFT(ROUND(E6,2),FIND(",",ROUND(E6,2))-1)))*1,6),3))>0),IF(AND(IF(LEN(SUBSTITUTE(ROUND(E6,2), ",", ""))=LEN(ROUND(E6,2)),ROUND(E6,2),TRIM(LEFT(ROUND(E6,2),FIND(",",ROUND(E6,2))-1)))*1>1999,LEFT(RIGHT(IF(LEN(SUBSTITUTE(ROUND(E6,2), ",", ""))=LEN(ROUND(E6,2)),ROUND(E6,2),TRIM(LEFT(ROUND(E6,2),FIND(",",ROUND(E6,2))-1)))*1,4),1)="1",LEFT(RIGHT(IF(LEN(SUBSTITUTE(ROUND(E6,2), ",", ""))=LEN(ROUND(E6,2)),ROUND(E6,2),TRIM(LEFT(ROUND(E6,2),FIND(",",ROUND(E6,2))-1)))*1,6),2)<>"00"),"birbin","bin"),"")&IF(IF(LEN(SUBSTITUTE(ROUND(E6,2), ",", ""))=LEN(ROUND(E6,2)),ROUND(E6,2),TRIM(LEFT(ROUND(E6,2),FIND(",",ROUND(E6,2))-1)))*1>=100,CHOOSE(LEFT(RIGHT(IF(LEN(SUBSTITUTE(ROUND(E6,2), ",", ""))=LEN(ROUND(E6,2)),ROUND(E6,2),TRIM(LEFT(ROUND(E6,2),FIND(",",ROUND(E6,2))-1)))*1,3),1)+1,"","yüz","ikiyüz","üçyüz","dörtyüz","beşyüz","altıyüz","yediyüz","sekizyüz","dokuzyüz"),"")&IF(IF(LEN(SUBSTITUTE(ROUND(E6,2), ",", ""))=LEN(ROUND(E6,2)),ROUND(E6,2),TRIM(LEFT(ROUND(E6,2),FIND(",",ROUND(E6,2))-1)))*1>=10,CHOOSE(LEFT(RIGHT(IF(LEN(SUBSTITUTE(ROUND(E6,2), ",", ""))=LEN(ROUND(E6,2)),ROUND(E6,2),TRIM(LEFT(ROUND(E6,2),FIND(",",ROUND(E6,2))-1)))*1,2),1)+1,"","on","yirmi","otuz","kırk","elli","altmış","yetmiş","seksen","doksan"),"")&CHOOSE(MOD(IF(LEN(SUBSTITUTE(ROUND(E6,2), ",", ""))=LEN(ROUND(E6,2)),ROUND(E6,2),TRIM(LEFT(ROUND(E6,2),FIND(",",ROUND(E6,2))-1)))*1,10)+1,"","bir","iki","üç","dört","beş","altı","yedi","sekiz","dokuz")) & " TL " & IF(OR(LEN(SUBSTITUTE(E6, ",", ""))=LEN(E6),LEN(SUBSTITUTE(ROUND(E6,2), ",", ""))=LEN(ROUND(E6,2))),"", PROPER(IF(IF(LEN(TRIM(RIGHT(ROUND(E6,2),LEN(ROUND(E6,2))-FIND(",",ROUND(E6,2)))))<2,TRIM(RIGHT(ROUND(E6,2),LEN(ROUND(E6,2))-FIND(",",ROUND(E6,2))))*10,TRIM(RIGHT(ROUND(E6,2),LEN(ROUND(E6,2))-FIND(",",ROUND(E6,2))))*1)>=10^5,CHOOSE(LEFT(RIGHT(IF(LEN(TRIM(RIGHT(ROUND(E6,2),LEN(ROUND(E6,2))-FIND(",",ROUND(E6,2)))))<2,TRIM(RIGHT(ROUND(E6,2),LEN(ROUND(E6,2))-FIND(",",ROUND(E6,2))))*10,TRIM(RIGHT(ROUND(E6,2),LEN(ROUND(E6,2))-FIND(",",ROUND(E6,2))))*1),6),1)+1,"","yüz","ikiyüz","üçyüz","dörtyüz","beşyüz","altıyüz","yediyüz","sekizyüz","dokuzyüz"),"")&IF(IF(LEN(TRIM(RIGHT(ROUND(E6,2),LEN(ROUND(E6,2))-FIND(",",ROUND(E6,2)))))<2,TRIM(RIGHT(ROUND(E6,2),LEN(ROUND(E6,2))-FIND(",",ROUND(E6,2))))*10,TRIM(RIGHT(ROUND(E6,2),LEN(ROUND(E6,2))-FIND(",",ROUND(E6,2))))*1)>=10^4,CHOOSE(LEFT(RIGHT(IF(LEN(TRIM(RIGHT(ROUND(E6,2),LEN(ROUND(E6,2))-FIND(",",ROUND(E6,2)))))<2,TRIM(RIGHT(ROUND(E6,2),LEN(ROUND(E6,2))-FIND(",",ROUND(E6,2))))*10,TRIM(RIGHT(ROUND(E6,2),LEN(ROUND(E6,2))-FIND(",",ROUND(E6,2))))*1),5),1)+1,"","on","yirmi","otuz","kırk","elli","altmış","yetmiş","seksen","doksan"),"")&IF(IF(LEN(TRIM(RIGHT(ROUND(E6,2),LEN(ROUND(E6,2))-FIND(",",ROUND(E6,2)))))<2,TRIM(RIGHT(ROUND(E6,2),LEN(ROUND(E6,2))-FIND(",",ROUND(E6,2))))*10,TRIM(RIGHT(ROUND(E6,2),LEN(ROUND(E6,2))-FIND(",",ROUND(E6,2))))*1)>=10^3,CHOOSE(LEFT(RIGHT(IF(LEN(TRIM(RIGHT(ROUND(E6,2),LEN(ROUND(E6,2))-FIND(",",ROUND(E6,2)))))<2,TRIM(RIGHT(ROUND(E6,2),LEN(ROUND(E6,2))-FIND(",",ROUND(E6,2))))*10,TRIM(RIGHT(ROUND(E6,2),LEN(ROUND(E6,2))-FIND(",",ROUND(E6,2))))*1),4),1)+1,"","","iki","üç","dört","beş","altı","yedi","sekiz","dokuz"),"")&IF(IF(LEN(TRIM(RIGHT(ROUND(E6,2),LEN(ROUND(E6,2))-FIND(",",ROUND(E6,2)))))<2,TRIM(RIGHT(ROUND(E6,2),LEN(ROUND(E6,2))-FIND(",",ROUND(E6,2))))*10,TRIM(RIGHT(ROUND(E6,2),LEN(ROUND(E6,2))-FIND(",",ROUND(E6,2))))*1)>=10,CHOOSE(LEFT(RIGHT(IF(LEN(TRIM(RIGHT(ROUND(E6,2),LEN(ROUND(E6,2))-FIND(",",ROUND(E6,2)))))<2,TRIM(RIGHT(ROUND(E6,2),LEN(ROUND(E6,2))-FIND(",",ROUND(E6,2))))*10,TRIM(RIGHT(ROUND(E6,2),LEN(ROUND(E6,2))-FIND(",",ROUND(E6,2))))*1),2),1)+1,"","on","yirmi","otuz","kırk","elli","altmış","yetmiş","seksen","doksan"),"")&CHOOSE(MOD(IF(LEN(TRIM(RIGHT(ROUND(E6,2),LEN(ROUND(E6,2))-FIND(",",ROUND(E6,2)))))<2,TRIM(RIGHT(ROUND(E6,2),LEN(ROUND(E6,2))-FIND(",",ROUND(E6,2))))*10,TRIM(RIGHT(ROUND(E6,2),LEN(ROUND(E6,2))-FIND(",",ROUND(E6,2))))*1),10)+1,"","bir","iki","üç","dört","beş","altı","yedi","sekiz","dokuz")) & " Kr") -> İkibin TL | G6: =G5 -> NAKDEN | H6: 4. Taksit
B7: 5 | C7: 44252 | D7: 44407 | E7: 14000 | F7: =PROPER(IF(IF(LEN(SUBSTITUTE(ROUND(E7,2), ",", ""))=LEN(ROUND(E7,2)),ROUND(E7,2),TRIM(LEFT(ROUND(E7,2),FIND(",",ROUND(E7,2))-1)))*1>=10^6,CHOOSE(LEFT(RIGHT(IF(LEN(SUBSTITUTE(ROUND(E7,2), ",", ""))=LEN(ROUND(E7,2)),ROUND(E7,2),TRIM(LEFT(ROUND(E7,2),FIND(",",ROUND(E7,2))-1)))*1,7),1)+1,"","birmilyon","ikimilyon","üçmilyon","dörtmilyon","beşmilyon","altımilyon","yedimilyon","sekizmilyon","dokuzmilyon"),"")&IF(IF(LEN(SUBSTITUTE(ROUND(E7,2), ",", ""))=LEN(ROUND(E7,2)),ROUND(E7,2),TRIM(LEFT(ROUND(E7,2),FIND(",",ROUND(E7,2))-1)))*1>=10^5,CHOOSE(LEFT(RIGHT(IF(LEN(SUBSTITUTE(ROUND(E7,2), ",", ""))=LEN(ROUND(E7,2)),ROUND(E7,2),TRIM(LEFT(ROUND(E7,2),FIND(",",ROUND(E7,2))-1)))*1,6),1)+1,"","yüz","ikiyüz","üçyüz","dörtyüz","beşyüz","altıyüz","yediyüz","sekizyüz","dokuzyüz"),"")&IF(IF(LEN(SUBSTITUTE(ROUND(E7,2), ",", ""))=LEN(ROUND(E7,2)),ROUND(E7,2),TRIM(LEFT(ROUND(E7,2),FIND(",",ROUND(E7,2))-1)))*1>=10^4,CHOOSE(LEFT(RIGHT(IF(LEN(SUBSTITUTE(ROUND(E7,2), ",", ""))=LEN(ROUND(E7,2)),ROUND(E7,2),TRIM(LEFT(ROUND(E7,2),FIND(",",ROUND(E7,2))-1)))*1,5),1)+1,"","on","yirmi","otuz","kırk","elli","altmış","yetmiş","seksen","doksan"),"")&IF(IF(LEN(SUBSTITUTE(ROUND(E7,2), ",", ""))=LEN(ROUND(E7,2)),ROUND(E7,2),TRIM(LEFT(ROUND(E7,2),FIND(",",ROUND(E7,2))-1)))*1>=10^3,CHOOSE(LEFT(RIGHT(IF(LEN(SUBSTITUTE(ROUND(E7,2), ",", ""))=LEN(ROUND(E7,2)),ROUND(E7,2),TRIM(LEFT(ROUND(E7,2),FIND(",",ROUND(E7,2))-1)))*1,4),1)+1,"","","iki","üç","dört","beş","altı","yedi","sekiz","dokuz"),"")&IF(AND(IF(LEN(SUBSTITUTE(ROUND(E7,2), ",", ""))=LEN(ROUND(E7,2)),ROUND(E7,2),TRIM(LEFT(ROUND(E7,2),FIND(",",ROUND(E7,2))-1)))*1>=10^3,VALUE(LEFT(RIGHT(IF(LEN(SUBSTITUTE(ROUND(E7,2), ",", ""))=LEN(ROUND(E7,2)),ROUND(E7,2),TRIM(LEFT(ROUND(E7,2),FIND(",",ROUND(E7,2))-1)))*1,6),3))>0),IF(AND(IF(LEN(SUBSTITUTE(ROUND(E7,2), ",", ""))=LEN(ROUND(E7,2)),ROUND(E7,2),TRIM(LEFT(ROUND(E7,2),FIND(",",ROUND(E7,2))-1)))*1>1999,LEFT(RIGHT(IF(LEN(SUBSTITUTE(ROUND(E7,2), ",", ""))=LEN(ROUND(E7,2)),ROUND(E7,2),TRIM(LEFT(ROUND(E7,2),FIND(",",ROUND(E7,2))-1)))*1,4),1)="1",LEFT(RIGHT(IF(LEN(SUBSTITUTE(ROUND(E7,2), ",", ""))=LEN(ROUND(E7,2)),ROUND(E7,2),TRIM(LEFT(ROUND(E7,2),FIND(",",ROUND(E7,2))-1)))*1,6),2)<>"00"),"birbin","bin"),"")&IF(IF(LEN(SUBSTITUTE(ROUND(E7,2), ",", ""))=LEN(ROUND(E7,2)),ROUND(E7,2),TRIM(LEFT(ROUND(E7,2),FIND(",",ROUND(E7,2))-1)))*1>=100,CHOOSE(LEFT(RIGHT(IF(LEN(SUBSTITUTE(ROUND(E7,2), ",", ""))=LEN(ROUND(E7,2)),ROUND(E7,2),TRIM(LEFT(ROUND(E7,2),FIND(",",ROUND(E7,2))-1)))*1,3),1)+1,"","yüz","ikiyüz","üçyüz","dörtyüz","beşyüz","altıyüz","yediyüz","sekizyüz","dokuzyüz"),"")&IF(IF(LEN(SUBSTITUTE(ROUND(E7,2), ",", ""))=LEN(ROUND(E7,2)),ROUND(E7,2),TRIM(LEFT(ROUND(E7,2),FIND(",",ROUND(E7,2))-1)))*1>=10,CHOOSE(LEFT(RIGHT(IF(LEN(SUBSTITUTE(ROUND(E7,2), ",", ""))=LEN(ROUND(E7,2)),ROUND(E7,2),TRIM(LEFT(ROUND(E7,2),FIND(",",ROUND(E7,2))-1)))*1,2),1)+1,"","on","yirmi","otuz","kırk","elli","altmış","yetmiş","seksen","doksan"),"")&CHOOSE(MOD(IF(LEN(SUBSTITUTE(ROUND(E7,2), ",", ""))=LEN(ROUND(E7,2)),ROUND(E7,2),TRIM(LEFT(ROUND(E7,2),FIND(",",ROUND(E7,2))-1)))*1,10)+1,"","bir","iki","üç","dört","beş","altı","yedi","sekiz","dokuz")) & " TL " & IF(OR(LEN(SUBSTITUTE(E7, ",", ""))=LEN(E7),LEN(SUBSTITUTE(ROUND(E7,2), ",", ""))=LEN(ROUND(E7,2))),"", PROPER(IF(IF(LEN(TRIM(RIGHT(ROUND(E7,2),LEN(ROUND(E7,2))-FIND(",",ROUND(E7,2)))))<2,TRIM(RIGHT(ROUND(E7,2),LEN(ROUND(E7,2))-FIND(",",ROUND(E7,2))))*10,TRIM(RIGHT(ROUND(E7,2),LEN(ROUND(E7,2))-FIND(",",ROUND(E7,2))))*1)>=10^5,CHOOSE(LEFT(RIGHT(IF(LEN(TRIM(RIGHT(ROUND(E7,2),LEN(ROUND(E7,2))-FIND(",",ROUND(E7,2)))))<2,TRIM(RIGHT(ROUND(E7,2),LEN(ROUND(E7,2))-FIND(",",ROUND(E7,2))))*10,TRIM(RIGHT(ROUND(E7,2),LEN(ROUND(E7,2))-FIND(",",ROUND(E7,2))))*1),6),1)+1,"","yüz","ikiyüz","üçyüz","dörtyüz","beşyüz","altıyüz","yediyüz","sekizyüz","dokuzyüz"),"")&IF(IF(LEN(TRIM(RIGHT(ROUND(E7,2),LEN(ROUND(E7,2))-FIND(",",ROUND(E7,2)))))<2,TRIM(RIGHT(ROUND(E7,2),LEN(ROUND(E7,2))-FIND(",",ROUND(E7,2))))*10,TRIM(RIGHT(ROUND(E7,2),LEN(ROUND(E7,2))-FIND(",",ROUND(E7,2))))*1)>=10^4,CHOOSE(LEFT(RIGHT(IF(LEN(TRIM(RIGHT(ROUND(E7,2),LEN(ROUND(E7,2))-FIND(",",ROUND(E7,2)))))<2,TRIM(RIGHT(ROUND(E7,2),LEN(ROUND(E7,2))-FIND(",",ROUND(E7,2))))*10,TRIM(RIGHT(ROUND(E7,2),LEN(ROUND(E7,2))-FIND(",",ROUND(E7,2))))*1),5),1)+1,"","on","yirmi","otuz","kırk","elli","altmış","yetmiş","seksen","doksan"),"")&IF(IF(LEN(TRIM(RIGHT(ROUND(E7,2),LEN(ROUND(E7,2))-FIND(",",ROUND(E7,2)))))<2,TRIM(RIGHT(ROUND(E7,2),LEN(ROUND(E7,2))-FIND(",",ROUND(E7,2))))*10,TRIM(RIGHT(ROUND(E7,2),LEN(ROUND(E7,2))-FIND(",",ROUND(E7,2))))*1)>=10^3,CHOOSE(LEFT(RIGHT(IF(LEN(TRIM(RIGHT(ROUND(E7,2),LEN(ROUND(E7,2))-FIND(",",ROUND(E7,2)))))<2,TRIM(RIGHT(ROUND(E7,2),LEN(ROUND(E7,2))-FIND(",",ROUND(E7,2))))*10,TRIM(RIGHT(ROUND(E7,2),LEN(ROUND(E7,2))-FIND(",",ROUND(E7,2))))*1),4),1)+1,"","","iki","üç","dört","beş","altı","yedi","sekiz","dokuz"),"")&IF(IF(LEN(TRIM(RIGHT(ROUND(E7,2),LEN(ROUND(E7,2))-FIND(",",ROUND(E7,2)))))<2,TRIM(RIGHT(ROUND(E7,2),LEN(ROUND(E7,2))-FIND(",",ROUND(E7,2))))*10,TRIM(RIGHT(ROUND(E7,2),LEN(ROUND(E7,2))-FIND(",",ROUND(E7,2))))*1)>=10,CHOOSE(LEFT(RIGHT(IF(LEN(TRIM(RIGHT(ROUND(E7,2),LEN(ROUND(E7,2))-FIND(",",ROUND(E7,2)))))<2,TRIM(RIGHT(ROUND(E7,2),LEN(ROUND(E7,2))-FIND(",",ROUND(E7,2))))*10,TRIM(RIGHT(ROUND(E7,2),LEN(ROUND(E7,2))-FIND(",",ROUND(E7,2))))*1),2),1)+1,"","on","yirmi","otuz","kırk","elli","altmış","yetmiş","seksen","doksan"),"")&CHOOSE(MOD(IF(LEN(TRIM(RIGHT(ROUND(E7,2),LEN(ROUND(E7,2))-FIND(",",ROUND(E7,2)))))<2,TRIM(RIGHT(ROUND(E7,2),LEN(ROUND(E7,2))-FIND(",",ROUND(E7,2))))*10,TRIM(RIGHT(ROUND(E7,2),LEN(ROUND(E7,2))-FIND(",",ROUND(E7,2))))*1),10)+1,"","bir","iki","üç","dört","beş","altı","yedi","sekiz","dokuz")) & " Kr") -> Ondörtbin TL | G7: =G6 -> NAKDEN | H7: 5. Taksit
B8: 6 | C8: 44252 | D8: 44438 | E8: 2000 | F8: =PROPER(IF(IF(LEN(SUBSTITUTE(ROUND(E8,2), ",", ""))=LEN(ROUND(E8,2)),ROUND(E8,2),TRIM(LEFT(ROUND(E8,2),FIND(",",ROUND(E8,2))-1)))*1>=10^6,CHOOSE(LEFT(RIGHT(IF(LEN(SUBSTITUTE(ROUND(E8,2), ",", ""))=LEN(ROUND(E8,2)),ROUND(E8,2),TRIM(LEFT(ROUND(E8,2),FIND(",",ROUND(E8,2))-1)))*1,7),1)+1,"","birmilyon","ikimilyon","üçmilyon","dörtmilyon","beşmilyon","altımilyon","yedimilyon","sekizmilyon","dokuzmilyon"),"")&IF(IF(LEN(SUBSTITUTE(ROUND(E8,2), ",", ""))=LEN(ROUND(E8,2)),ROUND(E8,2),TRIM(LEFT(ROUND(E8,2),FIND(",",ROUND(E8,2))-1)))*1>=10^5,CHOOSE(LEFT(RIGHT(IF(LEN(SUBSTITUTE(ROUND(E8,2), ",", ""))=LEN(ROUND(E8,2)),ROUND(E8,2),TRIM(LEFT(ROUND(E8,2),FIND(",",ROUND(E8,2))-1)))*1,6),1)+1,"","yüz","ikiyüz","üçyüz","dörtyüz","beşyüz","altıyüz","yediyüz","sekizyüz","dokuzyüz"),"")&IF(IF(LEN(SUBSTITUTE(ROUND(E8,2), ",", ""))=LEN(ROUND(E8,2)),ROUND(E8,2),TRIM(LEFT(ROUND(E8,2),FIND(",",ROUND(E8,2))-1)))*1>=10^4,CHOOSE(LEFT(RIGHT(IF(LEN(SUBSTITUTE(ROUND(E8,2), ",", ""))=LEN(ROUND(E8,2)),ROUND(E8,2),TRIM(LEFT(ROUND(E8,2),FIND(",",ROUND(E8,2))-1)))*1,5),1)+1,"","on","yirmi","otuz","kırk","elli","altmış","yetmiş","seksen","doksan"),"")&IF(IF(LEN(SUBSTITUTE(ROUND(E8,2), ",", ""))=LEN(ROUND(E8,2)),ROUND(E8,2),TRIM(LEFT(ROUND(E8,2),FIND(",",ROUND(E8,2))-1)))*1>=10^3,CHOOSE(LEFT(RIGHT(IF(LEN(SUBSTITUTE(ROUND(E8,2), ",", ""))=LEN(ROUND(E8,2)),ROUND(E8,2),TRIM(LEFT(ROUND(E8,2),FIND(",",ROUND(E8,2))-1)))*1,4),1)+1,"","","iki","üç","dört","beş","altı","yedi","sekiz","dokuz"),"")&IF(AND(IF(LEN(SUBSTITUTE(ROUND(E8,2), ",", ""))=LEN(ROUND(E8,2)),ROUND(E8,2),TRIM(LEFT(ROUND(E8,2),FIND(",",ROUND(E8,2))-1)))*1>=10^3,VALUE(LEFT(RIGHT(IF(LEN(SUBSTITUTE(ROUND(E8,2), ",", ""))=LEN(ROUND(E8,2)),ROUND(E8,2),TRIM(LEFT(ROUND(E8,2),FIND(",",ROUND(E8,2))-1)))*1,6),3))>0),IF(AND(IF(LEN(SUBSTITUTE(ROUND(E8,2), ",", ""))=LEN(ROUND(E8,2)),ROUND(E8,2),TRIM(LEFT(ROUND(E8,2),FIND(",",ROUND(E8,2))-1)))*1>1999,LEFT(RIGHT(IF(LEN(SUBSTITUTE(ROUND(E8,2), ",", ""))=LEN(ROUND(E8,2)),ROUND(E8,2),TRIM(LEFT(ROUND(E8,2),FIND(",",ROUND(E8,2))-1)))*1,4),1)="1",LEFT(RIGHT(IF(LEN(SUBSTITUTE(ROUND(E8,2), ",", ""))=LEN(ROUND(E8,2)),ROUND(E8,2),TRIM(LEFT(ROUND(E8,2),FIND(",",ROUND(E8,2))-1)))*1,6),2)<>"00"),"birbin","bin"),"")&IF(IF(LEN(SUBSTITUTE(ROUND(E8,2), ",", ""))=LEN(ROUND(E8,2)),ROUND(E8,2),TRIM(LEFT(ROUND(E8,2),FIND(",",ROUND(E8,2))-1)))*1>=100,CHOOSE(LEFT(RIGHT(IF(LEN(SUBSTITUTE(ROUND(E8,2), ",", ""))=LEN(ROUND(E8,2)),ROUND(E8,2),TRIM(LEFT(ROUND(E8,2),FIND(",",ROUND(E8,2))-1)))*1,3),1)+1,"","yüz","ikiyüz","üçyüz","dörtyüz","beşyüz","altıyüz","yediyüz","sekizyüz","dokuzyüz"),"")&IF(IF(LEN(SUBSTITUTE(ROUND(E8,2), ",", ""))=LEN(ROUND(E8,2)),ROUND(E8,2),TRIM(LEFT(ROUND(E8,2),FIND(",",ROUND(E8,2))-1)))*1>=10,CHOOSE(LEFT(RIGHT(IF(LEN(SUBSTITUTE(ROUND(E8,2), ",", ""))=LEN(ROUND(E8,2)),ROUND(E8,2),TRIM(LEFT(ROUND(E8,2),FIND(",",ROUND(E8,2))-1)))*1,2),1)+1,"","on","yirmi","otuz","kırk","elli","altmış","yetmiş","seksen","doksan"),"")&CHOOSE(MOD(IF(LEN(SUBSTITUTE(ROUND(E8,2), ",", ""))=LEN(ROUND(E8,2)),ROUND(E8,2),TRIM(LEFT(ROUND(E8,2),FIND(",",ROUND(E8,2))-1)))*1,10)+1,"","bir","iki","üç","dört","beş","altı","yedi","sekiz","dokuz")) & " TL " & IF(OR(LEN(SUBSTITUTE(E8, ",", ""))=LEN(E8),LEN(SUBSTITUTE(ROUND(E8,2), ",", ""))=LEN(ROUND(E8,2))),"", PROPER(IF(IF(LEN(TRIM(RIGHT(ROUND(E8,2),LEN(ROUND(E8,2))-FIND(",",ROUND(E8,2)))))<2,TRIM(RIGHT(ROUND(E8,2),LEN(ROUND(E8,2))-FIND(",",ROUND(E8,2))))*10,TRIM(RIGHT(ROUND(E8,2),LEN(ROUND(E8,2))-FIND(",",ROUND(E8,2))))*1)>=10^5,CHOOSE(LEFT(RIGHT(IF(LEN(TRIM(RIGHT(ROUND(E8,2),LEN(ROUND(E8,2))-FIND(",",ROUND(E8,2)))))<2,TRIM(RIGHT(ROUND(E8,2),LEN(ROUND(E8,2))-FIND(",",ROUND(E8,2))))*10,TRIM(RIGHT(ROUND(E8,2),LEN(ROUND(E8,2))-FIND(",",ROUND(E8,2))))*1),6),1)+1,"","yüz","ikiyüz","üçyüz","dörtyüz","beşyüz","altıyüz","yediyüz","sekizyüz","dokuzyüz"),"")&IF(IF(LEN(TRIM(RIGHT(ROUND(E8,2),LEN(ROUND(E8,2))-FIND(",",ROUND(E8,2)))))<2,TRIM(RIGHT(ROUND(E8,2),LEN(ROUND(E8,2))-FIND(",",ROUND(E8,2))))*10,TRIM(RIGHT(ROUND(E8,2),LEN(ROUND(E8,2))-FIND(",",ROUND(E8,2))))*1)>=10^4,CHOOSE(LEFT(RIGHT(IF(LEN(TRIM(RIGHT(ROUND(E8,2),LEN(ROUND(E8,2))-FIND(",",ROUND(E8,2)))))<2,TRIM(RIGHT(ROUND(E8,2),LEN(ROUND(E8,2))-FIND(",",ROUND(E8,2))))*10,TRIM(RIGHT(ROUND(E8,2),LEN(ROUND(E8,2))-FIND(",",ROUND(E8,2))))*1),5),1)+1,"","on","yirmi","otuz","kırk","elli","altmış","yetmiş","seksen","doksan"),"")&IF(IF(LEN(TRIM(RIGHT(ROUND(E8,2),LEN(ROUND(E8,2))-FIND(",",ROUND(E8,2)))))<2,TRIM(RIGHT(ROUND(E8,2),LEN(ROUND(E8,2))-FIND(",",ROUND(E8,2))))*10,TRIM(RIGHT(ROUND(E8,2),LEN(ROUND(E8,2))-FIND(",",ROUND(E8,2))))*1)>=10^3,CHOOSE(LEFT(RIGHT(IF(LEN(TRIM(RIGHT(ROUND(E8,2),LEN(ROUND(E8,2))-FIND(",",ROUND(E8,2)))))<2,TRIM(RIGHT(ROUND(E8,2),LEN(ROUND(E8,2))-FIND(",",ROUND(E8,2))))*10,TRIM(RIGHT(ROUND(E8,2),LEN(ROUND(E8,2))-FIND(",",ROUND(E8,2))))*1),4),1)+1,"","","iki","üç","dört","beş","altı","yedi","sekiz","dokuz"),"")&IF(IF(LEN(TRIM(RIGHT(ROUND(E8,2),LEN(ROUND(E8,2))-FIND(",",ROUND(E8,2)))))<2,TRIM(RIGHT(ROUND(E8,2),LEN(ROUND(E8,2))-FIND(",",ROUND(E8,2))))*10,TRIM(RIGHT(ROUND(E8,2),LEN(ROUND(E8,2))-FIND(",",ROUND(E8,2))))*1)>=10,CHOOSE(LEFT(RIGHT(IF(LEN(TRIM(RIGHT(ROUND(E8,2),LEN(ROUND(E8,2))-FIND(",",ROUND(E8,2)))))<2,TRIM(RIGHT(ROUND(E8,2),LEN(ROUND(E8,2))-FIND(",",ROUND(E8,2))))*10,TRIM(RIGHT(ROUND(E8,2),LEN(ROUND(E8,2))-FIND(",",ROUND(E8,2))))*1),2),1)+1,"","on","yirmi","otuz","kırk","elli","altmış","yetmiş","seksen","doksan"),"")&CHOOSE(MOD(IF(LEN(TRIM(RIGHT(ROUND(E8,2),LEN(ROUND(E8,2))-FIND(",",ROUND(E8,2)))))<2,TRIM(RIGHT(ROUND(E8,2),LEN(ROUND(E8,2))-FIND(",",ROUND(E8,2))))*10,TRIM(RIGHT(ROUND(E8,2),LEN(ROUND(E8,2))-FIND(",",ROUND(E8,2))))*1),10)+1,"","bir","iki","üç","dört","beş","altı","yedi","sekiz","dokuz")) & " Kr") -> İkibin TL | G8: =G7 -> NAKDEN | H8: 6. Taksit
B9: 7 | C9: 44252 | D9: 44469 | E9: 2000 | F9: =PROPER(IF(IF(LEN(SUBSTITUTE(ROUND(E9,2), ",", ""))=LEN(ROUND(E9,2)),ROUND(E9,2),TRIM(LEFT(ROUND(E9,2),FIND(",",ROUND(E9,2))-1)))*1>=10^6,CHOOSE(LEFT(RIGHT(IF(LEN(SUBSTITUTE(ROUND(E9,2), ",", ""))=LEN(ROUND(E9,2)),ROUND(E9,2),TRIM(LEFT(ROUND(E9,2),FIND(",",ROUND(E9,2))-1)))*1,7),1)+1,"","birmilyon","ikimilyon","üçmilyon","dörtmilyon","beşmilyon","altımilyon","yedimilyon","sekizmilyon","dokuzmilyon"),"")&IF(IF(LEN(SUBSTITUTE(ROUND(E9,2), ",", ""))=LEN(ROUND(E9,2)),ROUND(E9,2),TRIM(LEFT(ROUND(E9,2),FIND(",",ROUND(E9,2))-1)))*1>=10^5,CHOOSE(LEFT(RIGHT(IF(LEN(SUBSTITUTE(ROUND(E9,2), ",", ""))=LEN(ROUND(E9,2)),ROUND(E9,2),TRIM(LEFT(ROUND(E9,2),FIND(",",ROUND(E9,2))-1)))*1,6),1)+1,"","yüz","ikiyüz","üçyüz","dörtyüz","beşyüz","altıyüz","yediyüz","sekizyüz","dokuzyüz"),"")&IF(IF(LEN(SUBSTITUTE(ROUND(E9,2), ",", ""))=LEN(ROUND(E9,2)),ROUND(E9,2),TRIM(LEFT(ROUND(E9,2),FIND(",",ROUND(E9,2))-1)))*1>=10^4,CHOOSE(LEFT(RIGHT(IF(LEN(SUBSTITUTE(ROUND(E9,2), ",", ""))=LEN(ROUND(E9,2)),ROUND(E9,2),TRIM(LEFT(ROUND(E9,2),FIND(",",ROUND(E9,2))-1)))*1,5),1)+1,"","on","yirmi","otuz","kırk","elli","altmış","yetmiş","seksen","doksan"),"")&IF(IF(LEN(SUBSTITUTE(ROUND(E9,2), ",", ""))=LEN(ROUND(E9,2)),ROUND(E9,2),TRIM(LEFT(ROUND(E9,2),FIND(",",ROUND(E9,2))-1)))*1>=10^3,CHOOSE(LEFT(RIGHT(IF(LEN(SUBSTITUTE(ROUND(E9,2), ",", ""))=LEN(ROUND(E9,2)),ROUND(E9,2),TRIM(LEFT(ROUND(E9,2),FIND(",",ROUND(E9,2))-1)))*1,4),1)+1,"","","iki","üç","dört","beş","altı","yedi","sekiz","dokuz"),"")&IF(AND(IF(LEN(SUBSTITUTE(ROUND(E9,2), ",", ""))=LEN(ROUND(E9,2)),ROUND(E9,2),TRIM(LEFT(ROUND(E9,2),FIND(",",ROUND(E9,2))-1)))*1>=10^3,VALUE(LEFT(RIGHT(IF(LEN(SUBSTITUTE(ROUND(E9,2), ",", ""))=LEN(ROUND(E9,2)),ROUND(E9,2),TRIM(LEFT(ROUND(E9,2),FIND(",",ROUND(E9,2))-1)))*1,6),3))>0),IF(AND(IF(LEN(SUBSTITUTE(ROUND(E9,2), ",", ""))=LEN(ROUND(E9,2)),ROUND(E9,2),TRIM(LEFT(ROUND(E9,2),FIND(",",ROUND(E9,2))-1)))*1>1999,LEFT(RIGHT(IF(LEN(SUBSTITUTE(ROUND(E9,2), ",", ""))=LEN(ROUND(E9,2)),ROUND(E9,2),TRIM(LEFT(ROUND(E9,2),FIND(",",ROUND(E9,2))-1)))*1,4),1)="1",LEFT(RIGHT(IF(LEN(SUBSTITUTE(ROUND(E9,2), ",", ""))=LEN(ROUND(E9,2)),ROUND(E9,2),TRIM(LEFT(ROUND(E9,2),FIND(",",ROUND(E9,2))-1)))*1,6),2)<>"00"),"birbin","bin"),"")&IF(IF(LEN(SUBSTITUTE(ROUND(E9,2), ",", ""))=LEN(ROUND(E9,2)),ROUND(E9,2),TRIM(LEFT(ROUND(E9,2),FIND(",",ROUND(E9,2))-1)))*1>=100,CHOOSE(LEFT(RIGHT(IF(LEN(SUBSTITUTE(ROUND(E9,2), ",", ""))=LEN(ROUND(E9,2)),ROUND(E9,2),TRIM(LEFT(ROUND(E9,2),FIND(",",ROUND(E9,2))-1)))*1,3),1)+1,"","yüz","ikiyüz","üçyüz","dörtyüz","beşyüz","altıyüz","yediyüz","sekizyüz","dokuzyüz"),"")&IF(IF(LEN(SUBSTITUTE(ROUND(E9,2), ",", ""))=LEN(ROUND(E9,2)),ROUND(E9,2),TRIM(LEFT(ROUND(E9,2),FIND(",",ROUND(E9,2))-1)))*1>=10,CHOOSE(LEFT(RIGHT(IF(LEN(SUBSTITUTE(ROUND(E9,2), ",", ""))=LEN(ROUND(E9,2)),ROUND(E9,2),TRIM(LEFT(ROUND(E9,2),FIND(",",ROUND(E9,2))-1)))*1,2),1)+1,"","on","yirmi","otuz","kırk","elli","altmış","yetmiş","seksen","doksan"),"")&CHOOSE(MOD(IF(LEN(SUBSTITUTE(ROUND(E9,2), ",", ""))=LEN(ROUND(E9,2)),ROUND(E9,2),TRIM(LEFT(ROUND(E9,2),FIND(",",ROUND(E9,2))-1)))*1,10)+1,"","bir","iki","üç","dört","beş","altı","yedi","sekiz","dokuz")) & " TL " & IF(OR(LEN(SUBSTITUTE(E9, ",", ""))=LEN(E9),LEN(SUBSTITUTE(ROUND(E9,2), ",", ""))=LEN(ROUND(E9,2))),"", PROPER(IF(IF(LEN(TRIM(RIGHT(ROUND(E9,2),LEN(ROUND(E9,2))-FIND(",",ROUND(E9,2)))))<2,TRIM(RIGHT(ROUND(E9,2),LEN(ROUND(E9,2))-FIND(",",ROUND(E9,2))))*10,TRIM(RIGHT(ROUND(E9,2),LEN(ROUND(E9,2))-FIND(",",ROUND(E9,2))))*1)>=10^5,CHOOSE(LEFT(RIGHT(IF(LEN(TRIM(RIGHT(ROUND(E9,2),LEN(ROUND(E9,2))-FIND(",",ROUND(E9,2)))))<2,TRIM(RIGHT(ROUND(E9,2),LEN(ROUND(E9,2))-FIND(",",ROUND(E9,2))))*10,TRIM(RIGHT(ROUND(E9,2),LEN(ROUND(E9,2))-FIND(",",ROUND(E9,2))))*1),6),1)+1,"","yüz","ikiyüz","üçyüz","dörtyüz","beşyüz","altıyüz","yediyüz","sekizyüz","dokuzyüz"),"")&IF(IF(LEN(TRIM(RIGHT(ROUND(E9,2),LEN(ROUND(E9,2))-FIND(",",ROUND(E9,2)))))<2,TRIM(RIGHT(ROUND(E9,2),LEN(ROUND(E9,2))-FIND(",",ROUND(E9,2))))*10,TRIM(RIGHT(ROUND(E9,2),LEN(ROUND(E9,2))-FIND(",",ROUND(E9,2))))*1)>=10^4,CHOOSE(LEFT(RIGHT(IF(LEN(TRIM(RIGHT(ROUND(E9,2),LEN(ROUND(E9,2))-FIND(",",ROUND(E9,2)))))<2,TRIM(RIGHT(ROUND(E9,2),LEN(ROUND(E9,2))-FIND(",",ROUND(E9,2))))*10,TRIM(RIGHT(ROUND(E9,2),LEN(ROUND(E9,2))-FIND(",",ROUND(E9,2))))*1),5),1)+1,"","on","yirmi","otuz","kırk","elli","altmış","yetmiş","seksen","doksan"),"")&IF(IF(LEN(TRIM(RIGHT(ROUND(E9,2),LEN(ROUND(E9,2))-FIND(",",ROUND(E9,2)))))<2,TRIM(RIGHT(ROUND(E9,2),LEN(ROUND(E9,2))-FIND(",",ROUND(E9,2))))*10,TRIM(RIGHT(ROUND(E9,2),LEN(ROUND(E9,2))-FIND(",",ROUND(E9,2))))*1)>=10^3,CHOOSE(LEFT(RIGHT(IF(LEN(TRIM(RIGHT(ROUND(E9,2),LEN(ROUND(E9,2))-FIND(",",ROUND(E9,2)))))<2,TRIM(RIGHT(ROUND(E9,2),LEN(ROUND(E9,2))-FIND(",",ROUND(E9,2))))*10,TRIM(RIGHT(ROUND(E9,2),LEN(ROUND(E9,2))-FIND(",",ROUND(E9,2))))*1),4),1)+1,"","","iki","üç","dört","beş","altı","yedi","sekiz","dokuz"),"")&IF(IF(LEN(TRIM(RIGHT(ROUND(E9,2),LEN(ROUND(E9,2))-FIND(",",ROUND(E9,2)))))<2,TRIM(RIGHT(ROUND(E9,2),LEN(ROUND(E9,2))-FIND(",",ROUND(E9,2))))*10,TRIM(RIGHT(ROUND(E9,2),LEN(ROUND(E9,2))-FIND(",",ROUND(E9,2))))*1)>=10,CHOOSE(LEFT(RIGHT(IF(LEN(TRIM(RIGHT(ROUND(E9,2),LEN(ROUND(E9,2))-FIND(",",ROUND(E9,2)))))<2,TRIM(RIGHT(ROUND(E9,2),LEN(ROUND(E9,2))-FIND(",",ROUND(E9,2))))*10,TRIM(RIGHT(ROUND(E9,2),LEN(ROUND(E9,2))-FIND(",",ROUND(E9,2))))*1),2),1)+1,"","on","yirmi","otuz","kırk","elli","altmış","yetmiş","seksen","doksan"),"")&CHOOSE(MOD(IF(LEN(TRIM(RIGHT(ROUND(E9,2),LEN(ROUND(E9,2))-FIND(",",ROUND(E9,2)))))<2,TRIM(RIGHT(ROUND(E9,2),LEN(ROUND(E9,2))-FIND(",",ROUND(E9,2))))*10,TRIM(RIGHT(ROUND(E9,2),LEN(ROUND(E9,2))-FIND(",",ROUND(E9,2))))*1),10)+1,"","bir","iki","üç","dört","beş","altı","yedi","sekiz","dokuz")) & " Kr") -> İkibin TL | G9: =G8 -> NAKDEN | H9: 7. Taksit
B10: 8 | C10: 44252 | D10: 44499 | E10: 2000 | F10: =PROPER(IF(IF(LEN(SUBSTITUTE(ROUND(E10,2), ",", ""))=LEN(ROUND(E10,2)),ROUND(E10,2),TRIM(LEFT(ROUND(E10,2),FIND(",",ROUND(E10,2))-1)))*1>=10^6,CHOOSE(LEFT(RIGHT(IF(LEN(SUBSTITUTE(ROUND(E10,2), ",", ""))=LEN(ROUND(E10,2)),ROUND(E10,2),TRIM(LEFT(ROUND(E10,2),FIND(",",ROUND(E10,2))-1)))*1,7),1)+1,"","birmilyon","ikimilyon","üçmilyon","dörtmilyon","beşmilyon","altımilyon","yedimilyon","sekizmilyon","dokuzmilyon"),"")&IF(IF(LEN(SUBSTITUTE(ROUND(E10,2), ",", ""))=LEN(ROUND(E10,2)),ROUND(E10,2),TRIM(LEFT(ROUND(E10,2),FIND(",",ROUND(E10,2))-1)))*1>=10^5,CHOOSE(LEFT(RIGHT(IF(LEN(SUBSTITUTE(ROUND(E10,2), ",", ""))=LEN(ROUND(E10,2)),ROUND(E10,2),TRIM(LEFT(ROUND(E10,2),FIND(",",ROUND(E10,2))-1)))*1,6),1)+1,"","yüz","ikiyüz","üçyüz","dörtyüz","beşyüz","altıyüz","yediyüz","sekizyüz","dokuzyüz"),"")&IF(IF(LEN(SUBSTITUTE(ROUND(E10,2), ",", ""))=LEN(ROUND(E10,2)),ROUND(E10,2),TRIM(LEFT(ROUND(E10,2),FIND(",",ROUND(E10,2))-1)))*1>=10^4,CHOOSE(LEFT(RIGHT(IF(LEN(SUBSTITUTE(ROUND(E10,2), ",", ""))=LEN(ROUND(E10,2)),ROUND(E10,2),TRIM(LEFT(ROUND(E10,2),FIND(",",ROUND(E10,2))-1)))*1,5),1)+1,"","on","yirmi","otuz","kırk","elli","altmış","yetmiş","seksen","doksan"),"")&IF(IF(LEN(SUBSTITUTE(ROUND(E10,2), ",", ""))=LEN(ROUND(E10,2)),ROUND(E10,2),TRIM(LEFT(ROUND(E10,2),FIND(",",ROUND(E10,2))-1)))*1>=10^3,CHOOSE(LEFT(RIGHT(IF(LEN(SUBSTITUTE(ROUND(E10,2), ",", ""))=LEN(ROUND(E10,2)),ROUND(E10,2),TRIM(LEFT(ROUND(E10,2),FIND(",",ROUND(E10,2))-1)))*1,4),1)+1,"","","iki","üç","dört","beş","altı","yedi","sekiz","dokuz"),"")&IF(AND(IF(LEN(SUBSTITUTE(ROUND(E10,2), ",", ""))=LEN(ROUND(E10,2)),ROUND(E10,2),TRIM(LEFT(ROUND(E10,2),FIND(",",ROUND(E10,2))-1)))*1>=10^3,VALUE(LEFT(RIGHT(IF(LEN(SUBSTITUTE(ROUND(E10,2), ",", ""))=LEN(ROUND(E10,2)),ROUND(E10,2),TRIM(LEFT(ROUND(E10,2),FIND(",",ROUND(E10,2))-1)))*1,6),3))>0),IF(AND(IF(LEN(SUBSTITUTE(ROUND(E10,2), ",", ""))=LEN(ROUND(E10,2)),ROUND(E10,2),TRIM(LEFT(ROUND(E10,2),FIND(",",ROUND(E10,2))-1)))*1>1999,LEFT(RIGHT(IF(LEN(SUBSTITUTE(ROUND(E10,2), ",", ""))=LEN(ROUND(E10,2)),ROUND(E10,2),TRIM(LEFT(ROUND(E10,2),FIND(",",ROUND(E10,2))-1)))*1,4),1)="1",LEFT(RIGHT(IF(LEN(SUBSTITUTE(ROUND(E10,2), ",", ""))=LEN(ROUND(E10,2)),ROUND(E10,2),TRIM(LEFT(ROUND(E10,2),FIND(",",ROUND(E10,2))-1)))*1,6),2)<>"00"),"birbin","bin"),"")&IF(IF(LEN(SUBSTITUTE(ROUND(E10,2), ",", ""))=LEN(ROUND(E10,2)),ROUND(E10,2),TRIM(LEFT(ROUND(E10,2),FIND(",",ROUND(E10,2))-1)))*1>=100,CHOOSE(LEFT(RIGHT(IF(LEN(SUBSTITUTE(ROUND(E10,2), ",", ""))=LEN(ROUND(E10,2)),ROUND(E10,2),TRIM(LEFT(ROUND(E10,2),FIND(",",ROUND(E10,2))-1)))*1,3),1)+1,"","yüz","ikiyüz","üçyüz","dörtyüz","beşyüz","altıyüz","yediyüz","sekizyüz","dokuzyüz"),"")&IF(IF(LEN(SUBSTITUTE(ROUND(E10,2), ",", ""))=LEN(ROUND(E10,2)),ROUND(E10,2),TRIM(LEFT(ROUND(E10,2),FIND(",",ROUND(E10,2))-1)))*1>=10,CHOOSE(LEFT(RIGHT(IF(LEN(SUBSTITUTE(ROUND(E10,2), ",", ""))=LEN(ROUND(E10,2)),ROUND(E10,2),TRIM(LEFT(ROUND(E10,2),FIND(",",ROUND(E10,2))-1)))*1,2),1)+1,"","on","yirmi","otuz","kırk","elli","altmış","yetmiş","seksen","doksan"),"")&CHOOSE(MOD(IF(LEN(SUBSTITUTE(ROUND(E10,2), ",", ""))=LEN(ROUND(E10,2)),ROUND(E10,2),TRIM(LEFT(ROUND(E10,2),FIND(",",ROUND(E10,2))-1)))*1,10)+1,"","bir","iki","üç","dört","beş","altı","yedi","sekiz","dokuz")) & " TL " & IF(OR(LEN(SUBSTITUTE(E10, ",", ""))=LEN(E10),LEN(SUBSTITUTE(ROUND(E10,2), ",", ""))=LEN(ROUND(E10,2))),"", PROPER(IF(IF(LEN(TRIM(RIGHT(ROUND(E10,2),LEN(ROUND(E10,2))-FIND(",",ROUND(E10,2)))))<2,TRIM(RIGHT(ROUND(E10,2),LEN(ROUND(E10,2))-FIND(",",ROUND(E10,2))))*10,TRIM(RIGHT(ROUND(E10,2),LEN(ROUND(E10,2))-FIND(",",ROUND(E10,2))))*1)>=10^5,CHOOSE(LEFT(RIGHT(IF(LEN(TRIM(RIGHT(ROUND(E10,2),LEN(ROUND(E10,2))-FIND(",",ROUND(E10,2)))))<2,TRIM(RIGHT(ROUND(E10,2),LEN(ROUND(E10,2))-FIND(",",ROUND(E10,2))))*10,TRIM(RIGHT(ROUND(E10,2),LEN(ROUND(E10,2))-FIND(",",ROUND(E10,2))))*1),6),1)+1,"","yüz","ikiyüz","üçyüz","dörtyüz","beşyüz","altıyüz","yediyüz","sekizyüz","dokuzyüz"),"")&IF(IF(LEN(TRIM(RIGHT(ROUND(E10,2),LEN(ROUND(E10,2))-FIND(",",ROUND(E10,2)))))<2,TRIM(RIGHT(ROUND(E10,2),LEN(ROUND(E10,2))-FIND(",",ROUND(E10,2))))*10,TRIM(RIGHT(ROUND(E10,2),LEN(ROUND(E10,2))-FIND(",",ROUND(E10,2))))*1)>=10^4,CHOOSE(LEFT(RIGHT(IF(LEN(TRIM(RIGHT(ROUND(E10,2),LEN(ROUND(E10,2))-FIND(",",ROUND(E10,2)))))<2,TRIM(RIGHT(ROUND(E10,2),LEN(ROUND(E10,2))-FIND(",",ROUND(E10,2))))*10,TRIM(RIGHT(ROUND(E10,2),LEN(ROUND(E10,2))-FIND(",",ROUND(E10,2))))*1),5),1)+1,"","on","yirmi","otuz","kırk","elli","altmış","yetmiş","seksen","doksan"),"")&IF(IF(LEN(TRIM(RIGHT(ROUND(E10,2),LEN(ROUND(E10,2))-FIND(",",ROUND(E10,2)))))<2,TRIM(RIGHT(ROUND(E10,2),LEN(ROUND(E10,2))-FIND(",",ROUND(E10,2))))*10,TRIM(RIGHT(ROUND(E10,2),LEN(ROUND(E10,2))-FIND(",",ROUND(E10,2))))*1)>=10^3,CHOOSE(LEFT(RIGHT(IF(LEN(TRIM(RIGHT(ROUND(E10,2),LEN(ROUND(E10,2))-FIND(",",ROUND(E10,2)))))<2,TRIM(RIGHT(ROUND(E10,2),LEN(ROUND(E10,2))-FIND(",",ROUND(E10,2))))*10,TRIM(RIGHT(ROUND(E10,2),LEN(ROUND(E10,2))-FIND(",",ROUND(E10,2))))*1),4),1)+1,"","","iki","üç","dört","beş","altı","yedi","sekiz","dokuz"),"")&IF(IF(LEN(TRIM(RIGHT(ROUND(E10,2),LEN(ROUND(E10,2))-FIND(",",ROUND(E10,2)))))<2,TRIM(RIGHT(ROUND(E10,2),LEN(ROUND(E10,2))-FIND(",",ROUND(E10,2))))*10,TRIM(RIGHT(ROUND(E10,2),LEN(ROUND(E10,2))-FIND(",",ROUND(E10,2))))*1)>=10,CHOOSE(LEFT(RIGHT(IF(LEN(TRIM(RIGHT(ROUND(E10,2),LEN(ROUND(E10,2))-FIND(",",ROUND(E10,2)))))<2,TRIM(RIGHT(ROUND(E10,2),LEN(ROUND(E10,2))-FIND(",",ROUND(E10,2))))*10,TRIM(RIGHT(ROUND(E10,2),LEN(ROUND(E10,2))-FIND(",",ROUND(E10,2))))*1),2),1)+1,"","on","yirmi","otuz","kırk","elli","altmış","yetmiş","seksen","doksan"),"")&CHOOSE(MOD(IF(LEN(TRIM(RIGHT(ROUND(E10,2),LEN(ROUND(E10,2))-FIND(",",ROUND(E10,2)))))<2,TRIM(RIGHT(ROUND(E10,2),LEN(ROUND(E10,2))-FIND(",",ROUND(E10,2))))*10,TRIM(RIGHT(ROUND(E10,2),LEN(ROUND(E10,2))-FIND(",",ROUND(E10,2))))*1),10)+1,"","bir","iki","üç","dört","beş","altı","yedi","sekiz","dokuz")) & " Kr") -> İkibin TL | G10: =G9 -> NAKDEN | H10: 8. Taksit
B11: 9 | C11: 44252 | D11: 44530 | E11: 2000 | F11: =PROPER(IF(IF(LEN(SUBSTITUTE(ROUND(E11,2), ",", ""))=LEN(ROUND(E11,2)),ROUND(E11,2),TRIM(LEFT(ROUND(E11,2),FIND(",",ROUND(E11,2))-1)))*1>=10^6,CHOOSE(LEFT(RIGHT(IF(LEN(SUBSTITUTE(ROUND(E11,2), ",", ""))=LEN(ROUND(E11,2)),ROUND(E11,2),TRIM(LEFT(ROUND(E11,2),FIND(",",ROUND(E11,2))-1)))*1,7),1)+1,"","birmilyon","ikimilyon","üçmilyon","dörtmilyon","beşmilyon","altımilyon","yedimilyon","sekizmilyon","dokuzmilyon"),"")&IF(IF(LEN(SUBSTITUTE(ROUND(E11,2), ",", ""))=LEN(ROUND(E11,2)),ROUND(E11,2),TRIM(LEFT(ROUND(E11,2),FIND(",",ROUND(E11,2))-1)))*1>=10^5,CHOOSE(LEFT(RIGHT(IF(LEN(SUBSTITUTE(ROUND(E11,2), ",", ""))=LEN(ROUND(E11,2)),ROUND(E11,2),TRIM(LEFT(ROUND(E11,2),FIND(",",ROUND(E11,2))-1)))*1,6),1)+1,"","yüz","ikiyüz","üçyüz","dörtyüz","beşyüz","altıyüz","yediyüz","sekizyüz","dokuzyüz"),"")&IF(IF(LEN(SUBSTITUTE(ROUND(E11,2), ",", ""))=LEN(ROUND(E11,2)),ROUND(E11,2),TRIM(LEFT(ROUND(E11,2),FIND(",",ROUND(E11,2))-1)))*1>=10^4,CHOOSE(LEFT(RIGHT(IF(LEN(SUBSTITUTE(ROUND(E11,2), ",", ""))=LEN(ROUND(E11,2)),ROUND(E11,2),TRIM(LEFT(ROUND(E11,2),FIND(",",ROUND(E11,2))-1)))*1,5),1)+1,"","on","yirmi","otuz","kırk","elli","altmış","yetmiş","seksen","doksan"),"")&IF(IF(LEN(SUBSTITUTE(ROUND(E11,2), ",", ""))=LEN(ROUND(E11,2)),ROUND(E11,2),TRIM(LEFT(ROUND(E11,2),FIND(",",ROUND(E11,2))-1)))*1>=10^3,CHOOSE(LEFT(RIGHT(IF(LEN(SUBSTITUTE(ROUND(E11,2), ",", ""))=LEN(ROUND(E11,2)),ROUND(E11,2),TRIM(LEFT(ROUND(E11,2),FIND(",",ROUND(E11,2))-1)))*1,4),1)+1,"","","iki","üç","dört","beş","altı","yedi","sekiz","dokuz"),"")&IF(AND(IF(LEN(SUBSTITUTE(ROUND(E11,2), ",", ""))=LEN(ROUND(E11,2)),ROUND(E11,2),TRIM(LEFT(ROUND(E11,2),FIND(",",ROUND(E11,2))-1)))*1>=10^3,VALUE(LEFT(RIGHT(IF(LEN(SUBSTITUTE(ROUND(E11,2), ",", ""))=LEN(ROUND(E11,2)),ROUND(E11,2),TRIM(LEFT(ROUND(E11,2),FIND(",",ROUND(E11,2))-1)))*1,6),3))>0),IF(AND(IF(LEN(SUBSTITUTE(ROUND(E11,2), ",", ""))=LEN(ROUND(E11,2)),ROUND(E11,2),TRIM(LEFT(ROUND(E11,2),FIND(",",ROUND(E11,2))-1)))*1>1999,LEFT(RIGHT(IF(LEN(SUBSTITUTE(ROUND(E11,2), ",", ""))=LEN(ROUND(E11,2)),ROUND(E11,2),TRIM(LEFT(ROUND(E11,2),FIND(",",ROUND(E11,2))-1)))*1,4),1)="1",LEFT(RIGHT(IF(LEN(SUBSTITUTE(ROUND(E11,2), ",", ""))=LEN(ROUND(E11,2)),ROUND(E11,2),TRIM(LEFT(ROUND(E11,2),FIND(",",ROUND(E11,2))-1)))*1,6),2)<>"00"),"birbin","bin"),"")&IF(IF(LEN(SUBSTITUTE(ROUND(E11,2), ",", ""))=LEN(ROUND(E11,2)),ROUND(E11,2),TRIM(LEFT(ROUND(E11,2),FIND(",",ROUND(E11,2))-1)))*1>=100,CHOOSE(LEFT(RIGHT(IF(LEN(SUBSTITUTE(ROUND(E11,2), ",", ""))=LEN(ROUND(E11,2)),ROUND(E11,2),TRIM(LEFT(ROUND(E11,2),FIND(",",ROUND(E11,2))-1)))*1,3),1)+1,"","yüz","ikiyüz","üçyüz","dörtyüz","beşyüz","altıyüz","yediyüz","sekizyüz","dokuzyüz"),"")&IF(IF(LEN(SUBSTITUTE(ROUND(E11,2), ",", ""))=LEN(ROUND(E11,2)),ROUND(E11,2),TRIM(LEFT(ROUND(E11,2),FIND(",",ROUND(E11,2))-1)))*1>=10,CHOOSE(LEFT(RIGHT(IF(LEN(SUBSTITUTE(ROUND(E11,2), ",", ""))=LEN(ROUND(E11,2)),ROUND(E11,2),TRIM(LEFT(ROUND(E11,2),FIND(",",ROUND(E11,2))-1)))*1,2),1)+1,"","on","yirmi","otuz","kırk","elli","altmış","yetmiş","seksen","doksan"),"")&CHOOSE(MOD(IF(LEN(SUBSTITUTE(ROUND(E11,2), ",", ""))=LEN(ROUND(E11,2)),ROUND(E11,2),TRIM(LEFT(ROUND(E11,2),FIND(",",ROUND(E11,2))-1)))*1,10)+1,"","bir","iki","üç","dört","beş","altı","yedi","sekiz","dokuz")) & " TL " & IF(OR(LEN(SUBSTITUTE(E11, ",", ""))=LEN(E11),LEN(SUBSTITUTE(ROUND(E11,2), ",", ""))=LEN(ROUND(E11,2))),"", PROPER(IF(IF(LEN(TRIM(RIGHT(ROUND(E11,2),LEN(ROUND(E11,2))-FIND(",",ROUND(E11,2)))))<2,TRIM(RIGHT(ROUND(E11,2),LEN(ROUND(E11,2))-FIND(",",ROUND(E11,2))))*10,TRIM(RIGHT(ROUND(E11,2),LEN(ROUND(E11,2))-FIND(",",ROUND(E11,2))))*1)>=10^5,CHOOSE(LEFT(RIGHT(IF(LEN(TRIM(RIGHT(ROUND(E11,2),LEN(ROUND(E11,2))-FIND(",",ROUND(E11,2)))))<2,TRIM(RIGHT(ROUND(E11,2),LEN(ROUND(E11,2))-FIND(",",ROUND(E11,2))))*10,TRIM(RIGHT(ROUND(E11,2),LEN(ROUND(E11,2))-FIND(",",ROUND(E11,2))))*1),6),1)+1,"","yüz","ikiyüz","üçyüz","dörtyüz","beşyüz","altıyüz","yediyüz","sekizyüz","dokuzyüz"),"")&IF(IF(LEN(TRIM(RIGHT(ROUND(E11,2),LEN(ROUND(E11,2))-FIND(",",ROUND(E11,2)))))<2,TRIM(RIGHT(ROUND(E11,2),LEN(ROUND(E11,2))-FIND(",",ROUND(E11,2))))*10,TRIM(RIGHT(ROUND(E11,2),LEN(ROUND(E11,2))-FIND(",",ROUND(E11,2))))*1)>=10^4,CHOOSE(LEFT(RIGHT(IF(LEN(TRIM(RIGHT(ROUND(E11,2),LEN(ROUND(E11,2))-FIND(",",ROUND(E11,2)))))<2,TRIM(RIGHT(ROUND(E11,2),LEN(ROUND(E11,2))-FIND(",",ROUND(E11,2))))*10,TRIM(RIGHT(ROUND(E11,2),LEN(ROUND(E11,2))-FIND(",",ROUND(E11,2))))*1),5),1)+1,"","on","yirmi","otuz","kırk","elli","altmış","yetmiş","seksen","doksan"),"")&IF(IF(LEN(TRIM(RIGHT(ROUND(E11,2),LEN(ROUND(E11,2))-FIND(",",ROUND(E11,2)))))<2,TRIM(RIGHT(ROUND(E11,2),LEN(ROUND(E11,2))-FIND(",",ROUND(E11,2))))*10,TRIM(RIGHT(ROUND(E11,2),LEN(ROUND(E11,2))-FIND(",",ROUND(E11,2))))*1)>=10^3,CHOOSE(LEFT(RIGHT(IF(LEN(TRIM(RIGHT(ROUND(E11,2),LEN(ROUND(E11,2))-FIND(",",ROUND(E11,2)))))<2,TRIM(RIGHT(ROUND(E11,2),LEN(ROUND(E11,2))-FIND(",",ROUND(E11,2))))*10,TRIM(RIGHT(ROUND(E11,2),LEN(ROUND(E11,2))-FIND(",",ROUND(E11,2))))*1),4),1)+1,"","","iki","üç","dört","beş","altı","yedi","sekiz","dokuz"),"")&IF(IF(LEN(TRIM(RIGHT(ROUND(E11,2),LEN(ROUND(E11,2))-FIND(",",ROUND(E11,2)))))<2,TRIM(RIGHT(ROUND(E11,2),LEN(ROUND(E11,2))-FIND(",",ROUND(E11,2))))*10,TRIM(RIGHT(ROUND(E11,2),LEN(ROUND(E11,2))-FIND(",",ROUND(E11,2))))*1)>=10,CHOOSE(LEFT(RIGHT(IF(LEN(TRIM(RIGHT(ROUND(E11,2),LEN(ROUND(E11,2))-FIND(",",ROUND(E11,2)))))<2,TRIM(RIGHT(ROUND(E11,2),LEN(ROUND(E11,2))-FIND(",",ROUND(E11,2))))*10,TRIM(RIGHT(ROUND(E11,2),LEN(ROUND(E11,2))-FIND(",",ROUND(E11,2))))*1),2),1)+1,"","on","yirmi","otuz","kırk","elli","altmış","yetmiş","seksen","doksan"),"")&CHOOSE(MOD(IF(LEN(TRIM(RIGHT(ROUND(E11,2),LEN(ROUND(E11,2))-FIND(",",ROUND(E11,2)))))<2,TRIM(RIGHT(ROUND(E11,2),LEN(ROUND(E11,2))-FIND(",",ROUND(E11,2))))*10,TRIM(RIGHT(ROUND(E11,2),LEN(ROUND(E11,2))-FIND(",",ROUND(E11,2))))*1),10)+1,"","bir","iki","üç","dört","beş","altı","yedi","sekiz","dokuz")) & " Kr") -> İkibin TL | G11: =G10 -> NAKDEN | H11: 9. Taksit
