Workbook

Sheet 02_26
F1: GİRİŞ | G1: ÇIKIŞ | H1: BAKİYE
A2: - OCAK 2026 | C2: TOPLAM | D2: =SUM(D4:D21) -> 17494.51 | E2: =SUM(E4:E21) -> -59229.72 | F2: =SUM(F4:F21) -> 0 | G2: =SUM(G4:G21) -> -41629.72 | H2: =F2+G2 -> -41629.72
H4: =H3+F4+G4 -> 0
H5: =H4+F5+G5 -> 0
B6: KK 4876 İşbank | E6: =E24 -> -41629.72 | G6: =E6 -> -41629.72 | H6: =H5+F6+G6 -> -41629.72
B7: KK 5165 Denizbank | E7: =E77 -> 0 | G7: =E7 -> 0 | H7: =H6+F7+G7 -> -41629.72
B8: Elektrik 9522138254 Sanayi | E8: 0 | H8: =H7+F8+G8 -> -41629.72
B9: Doğalgaz 800004222954 Kümbet D10 | E9: -1000 | H9: =H8+F9+G9 -> -41629.72
B10: Doğalgaz 800004222959 Kümbet D09 | E10: -200 | H10: =H9+F10+G10 -> -41629.72
B11: maaş | D11: 17494.51 | H11: =H10+F11+G11 -> -41629.72
B12: umut | E12: -7500 | H12: =H11+F12+G12 -> -41629.72
B13: Genel Masraf | E13: -7500 | H13: =H12+F13+G13 -> -41629.72
B14: Elektrik 5847500300 Kümbet D09 | E14: -600 | H14: =H13+F14+G14 -> -41629.72
B15: Elektrik 8222520300 Kümbet D10 | E15: -800 | H15: =H14+F15+G15 -> -41629.72
H16: =H15+F16+G16 -> -41629.72
H17: =H16+F17+G17 -> -41629.72
H18: =H17+F18+G18 -> -41629.72
H19: =H18+F19+G19 -> -41629.72
H20: =H19+F20+G20 -> -41629.72
B24: İşbank 4876 KK | E24: =SUM(E25:E44) -> -41629.72
E26: HESAP KESİM
B27: şubat
A28: 45880 | B28: ajet ist | C28: 5126 | D28: 6 -6 | E28: -854.33
A29: 45880 | B29: euroka tcross sigorta | C29: 16598.9 | D29: 6 -9 | E29: -1844.32
A30: 45901 | B30: AJET İSTANBUL | C30: 2307 | D30: 5 -6 | E30: -384.5
B31: ikea | C31: 2400 | D31: 2 -3 | E31: -800
B32: ikea | C32: 2118.97 | D32: 2 -3 | E32: -706.32
B33: ikea dolap | C33: 25999 | D33: 2 -9 | E33: -2888.78
B34: ikea | C34: 2160 | D34: 2 -3 | E34: -720
B35: ikea | C35: 425.46 | D35: 2 -3 | E35: -141.82
B36: motomax kask eldiven | C36: 7680 | D36: 2 -6 | E36: -1280
B37: decathlon ayakkabı atila-hc | C37: 4992.2 | D37: 2 -6 | E37: -832.03
D44: KALAN TAKSİTLİ BORÇ TOPLAMI | E44: =SUM(E46:E74) -> -31177.62
B45: mart
A46: 45880 | B46: euroka tcross sigorta | C46: 16598.9 | D46: 7 -9 | E46: -1844.32
A47: 45901 | B47: AJET İSTANBUL | C47: 2307 | D47: 6 -6 | E47: -384.5
B48: ikea | C48: 2400 | D48: 3 -3 | E48: -800
B49: ikea | C49: 2118.97 | D49: 3 -3 | E49: -706.32
B50: ikea dolap | C50: 25999 | D50: 3 -9 | E50: -2888.78
B51: ikea | C51: 2160 | D51: 3 -3 | E51: -720
...

Sheet 01_26
F1: GİRİŞ | G1: ÇIKIŞ | H1: BAKİYE
A2: - OCAK 2026 | C2: TOPLAM | D2: =SUM(D4:D21) -> 17494.51 | E2: =SUM(E4:E21) -> -62635.78 | F2: =SUM(F4:F21) -> 0 | G2: =SUM(G4:G21) -> -45035.78 | H2: =F2+G2 -> -45035.78
H4: =H3+F4+G4 -> 0
H5: =H4+F5+G5 -> 0
B6: KK 4876 İşbank | E6: =E24 -> -45035.78 | G6: =E6 -> -45035.78 | H6: =H5+F6+G6 -> -45035.78
B7: KK 5165 Denizbank | E7: =E120 -> 0 | G7: =E7 -> 0 | H7: =H6+F7+G7 -> -45035.78
B8: Elektrik 9522138254 Sanayi | E8: 0 | H8: =H7+F8+G8 -> -45035.78
B9: Doğalgaz 800004222954 Kümbet D10 | E9: -1000 | H9: =H8+F9+G9 -> -45035.78
B10: Doğalgaz 800004222959 Kümbet D09 | E10: -200 | H10: =H9+F10+G10 -> -45035.78
B11: maaş | D11: 17494.51 | H11: =H10+F11+G11 -> -45035.78
B12: umut | E12: -7500 | H12: =H11+F12+G12 -> -45035.78
B13: Genel Masraf | E13: -7500 | H13: =H12+F13+G13 -> -45035.78
B14: Elektrik 5847500300 Kümbet D09 | E14: -600 | H14: =H13+F14+G14 -> -45035.78
B15: Elektrik 8222520300 Kümbet D10 | E15: -800 | H15: =H14+F15+G15 -> -45035.78
H16: =H15+F16+G16 -> -45035.78
H17: =H16+F17+G17 -> -45035.78
H18: =H17+F18+G18 -> -45035.78
H19: =H18+F19+G19 -> -45035.78
H20: =H19+F20+G20 -> -45035.78
B24: İşbank 4876 KK | E24: =SUM(E25:E69) -> -45035.78
A27: 45880 | B27: ajet ist | C27: 5126 | D27: 5 -6 | E27: -854.33
A28: 45880 | B28: euroka tcross sigorta | C28: 16598.9 | D28: 5 -9 | E28: -1844.32
B29: ajet ist | C29: 2307 | D29: 4 -6 | E29: -384.5
B30: ikea | C30: 2400 | D30: 1 -3 | E30: -800
B31: ikea | C31: 2118.97 | D31: 1 -3 | E31: -706.32
B32: ikea dolap | C32: 25999 | D32: 1 -9 | E32: -2888.78
B33: ikea | C33: 2160 | D33: 1 -3 | E33: -720
B34: ikea | C34: 425.46 | D34: 1 -3 | E34: -141.82
B35: motomax kask eldiven | C35: 7680 | D35: 1 -6 | E35: -1280
B36: decathlon ayakkabı atila-hc | C36: 4992.2 | D36: 1 -6 | E36: -832.03
A38: 45988 | B38: ceyda habek malatyalı ali | E38: -530
B39: nish oyopark | E39: -120
B40: otopark | E40: -150
A41: 45990 | B41: mrkt | E41: -679.85
B42: depo avm | E42: -240
B43: balcan ayşe yemek | E43: -780
A44: 45991 | B44: habu döner | E44: -1190
B45: poaş mazot transporter | E45: -3830.09
B46: ceyda habek malatyalı ali | E46: -750
B47: mrkt | E47: -466.35
...

Sheet GNLK-_2025
C1: TAHMİNİ | F1: GERÇEKLEŞEN | K1: NZN | L1: HC | N1: NY
A2: -2024 | B2: GİRİŞ | C2: ÇIKIŞ | D2: BAKİYE | E2: GİRİŞ | F2: ÇIKIŞ | G2: BAKİYE | J2: kR | K2: 0.235384 | L2: =1-K2 -> 0.764616 | M2: Hc 1/1 | N2: =#REF!/1000 -> #REF!
A3: Ocak | B3: ='01_25'!D2 -> 398664 | C3: ='01_25'!E2 -> -55562.4 | D3: =B3+C3 -> 343101.6 | E3: ='01_25'!F2 -> 320054.88 | F3: ='01_25'!G2 -> -59018.87 | G3: =E3+F3 -> 261036.01 | I3: dgs | J3: 180 | M3: =J3 -> 180 | N3: ='01_25'!E133/1000 -> 0.96499
A4: Şubat | B4: ='02_25'!D2 -> 45000 | C4: ='02_25'!E2 -> -75400.4 | D4: =B4+C4+D3 -> 312701.2 | E4: ='02_25'!F2 -> 30054.88 | F4: ='02_25'!G2 -> -96628.72 | G4: =E4+F4+G3 -> 194462.17 | I4: sF | J4: 235 | K4: =J4*$K$2 -> 55.31524 | L4: =J4-K4 -> 179.68476 | N4: ='02_25'!E130/1000 -> 16.2
A5: Mart | B5: ='03_25'!D2 -> 30000 | C5: ='03_25'!E2 -> -79968.85 | D5: =B5+C5+D4 -> 262732.35 | E5: ='03_25'!F2 -> 32994.19 | F5: ='03_25'!G2 -> -186074.7 | G5: =E5+F5+G4 -> 41381.66 | I5: tzg | M5: =J5 -> 0 | N5: ='03_25'!E146/1000 -> 0
A6: Nisan | B6: ='04_25'!D2 -> 15000 | C6: ='04_25'!E2 -> -191614.26 | D6: =B6+C6+D5 -> 86118.09 | E6: ='04_25'!F2 -> 15054.88 | F6: ='04_25'!G2 -> -191809.25 | G6: =E6+F6+G5 -> -135372.71 | I6: maaş ocak-haziran | M6: =E18/1000 -> 15 | N6: ='04_25'!E117/1000 -> 32.55
A7: Mayıs | B7: ='05_25'!D2 -> 15000 | C7: ='05_25'!E2 -> -59780.37 | D7: =B7+C7+D6 -> 41337.72 | E7: ='05_25'!F2 -> 19054.88 | F7: ='05_25'!G2 -> -60755.16 | G7: =E7+F7+G6 -> -177072.99 | I7: maaş temmuz-aralık | M7: =E19/1000 -> #REF! | N7: ='05_25'!E115/1000 -> 1.159
A8: Hazrn | B8: ='06_25'!D2 -> 15000 | C8: ='06_25'!E2 -> -76228.43 | D8: =B8+C8+D7 -> -19890.71 | E8: ='06_25'!F2 -> 15054.88 | F8: ='06_25'!G2 -> -109005.52 | G8: =E8+F8+G7 -> -271023.63 | I8: lise | J8: 225 | M8: =J8/4 -> 56.25 | N8: ='06_25'!E141/1000 -> 0.87226
A9: Temmz | B9: ='07_25'!D2 -> 15000 | C9: ='07_25'!E2 -> -93124.89 | D9: =B9+C9+D8 -> -98015.6 | E9: ='07_25'!F2 -> 17494.51 | F9: ='07_25'!G2 -> -127505.39 | G9: =E9+F9+G8 -> -381034.51 | I9: sE | J9: 204 | K9: =J9*$K$2 -> 48.018336 | L9: =J9-K9 -> 155.98166 | N9: ='07_25'!E180/1000 -> 0.87226
A10: Ağusts | B10: ='08_25'!D2 -> 17494.51 | C10: ='08_25'!E2 -> -95750 | D10: =B10+C10+D9 -> -176271.09 | E10: ='08_25'!F2 -> 17564.53 | F10: ='08_25'!G2 -> -99089.92 | G10: =E10+F10+G9 -> -462559.9 | I10: ap | J10: 0 | M10: =J10*0.13 -> 0 | N10: ='08_25'!E187/1000 -> 0
A11: Eylül | B11: ='09_25'!D2 -> 17494.51 | C11: ='09_25'!E2 -> -79785.7 | D11: =B11+C11+D10 -> -238562.28 | E11: ='09_25'!F2 -> 57500 | F11: ='09_25'!G2 -> -93673.89 | G11: =E11+F11+G10 -> -498733.79 | I11: sG | J11: 0 | K11: =J11*$K$2 -> 0 | L11: =J11-K11 -> 0 | N11: ='09_25'!E165/1000 -> 0
A12: Ekim | B12: ='10_25'!D2 -> 17494.51 | C12: ='10_25'!E2 -> -54105.36 | D12: =B12+C12+D11 -> -275173.13 | E12: ='10_25'!F2 -> 17564.53 | F12: ='10_25'!G2 -> -54899.36 | G12: =E12+F12+G11 -> -536068.62 | I12: sA | J12: 0 | K12: =J12*$K$2 -> 0 | L12: =J12-K12 -> 0 | N12: ='10_25'!E137/1000 -> 0
A13: Kasım | B13: ='11_25'!D2 -> 17494.51 | C13: ='11_25'!E2 -> -73331.92 | D13: =B13+C13+D12 -> -331010.54 | E13: ='11_25'!F2 -> 17564.53 | F13: ='11_25'!G2 -> -20914.86 | G13: =E13+F13+G12 -> -555713.48 | I13: sCD | J13: 219 | K13: =J13*$K$2 -> 51.549096 | L13: =J13-K13 -> 167.4509 | N13: ='11_25'!E120/1000 -> 0
A14: Aralık | B14: ='12_25'!D2 -> 17494.51 | C14: ='12_25'!E2 -> -76440.48 | D14: =B14+C14+D13 -> -381122.17 | E14: ='12_25'!F2 -> 373564.53 | F14: ='12_25'!G2 -> -155436.73 | G14: =E14+F14+G13 -> -570902.56 | I14: sB | J14: 290 | K14: =J14*$K$2 -> 68.26136 | L14: =J14-K14 -> 221.73864 | N14: ='12_25'!E213/1000 -> 0
A15: TPLM | B15: =SUM(B3:B14) -> 621136.55 | C15: =SUM(C3:C14) -> -1002258.7 | D15: =B15+C15 -> -381122.17 | E15: =SUM(E3:E14) -> 933521.22 | F15: =SUM(F3:F14) -> -1113294.7 | G15: =E15+F15 -> -570902.56 | J15: =SUM(J3:J14) -> 1353 | K15: =SUM(K4:K14) -> 223.14403 | L15: =SUM(L4:L14) -> 724.85597 | M15: =M10+M8+M6+M5+M3+M7 -> #REF!
A16: 12 | B16: =B15/A16 -> 51761.379 | C16: =C15/A16 -> -83521.56 | E16: =E15/A16 -> 77793.435 | F16: =F15/A16 -> -92774.56 | G16: =G15/A16 -> -47575.213 | J16: =J15/12 -> 112.75 | K16: =K15/12 -> 18.595336 | L16: =L15/12 -> 60.404664 | M16: =M15/12 -> #REF! | N16: =AVERAGE(N2:N15) -> #REF!
K17: TPLM | L17: =L15+M15 -> #REF!
D18: ocak-haziran maaş toplamı | E18: ='01_25'!F32+'02_25'!F14+'02_25'!F26+'03_25'!F18+'04_25'!F41+'05_25'!F19+'06_25'!F22+'06_25'!F34+'04_25'!F14 -> 15000 | K18: AYLK | M18: =L17/12 -> #REF!
D19: temmuz-aralık maaş toplamı | E19: ='07_25'!F25+'08_25'!F20+'09_25'!F19+'10_25'!F25+'11_25'!#REF!+'12_25'!F22 -> #REF!
D20: Toplam ;Emekli maaşı | E20: =SUM(E18:E19) -> #REF!
B21: 44896
B22: 6986.25 | C22: 0.375785 | D22: 0.4925919
B23: =B22*C22 -> 2625.328 | C23: ocak artış % | D23: =B22*D22 -> 3441.3702
B24: =SUM(B22:B23) -> 9611.578 | C24: ocak 23 maaş | D24: =D23+B22 -> 10427.62
C25: =(D27/D25)-1 -> #DIV/0!
C26: temmuz artış
C27: temmuz 23 maaş | D27: 13006.38

Sheet PERI_25
B2: 2025 | C2: hesaba yazılmayan | D2: hacı ödeme | E2: peri ödeme | F2: BAKİYE
F3: peri_2024-f65
A4: 45657 | B4: 2024 den devir PERİ BORÇLU | F4: 257330
F5: =F4 -> 257330
A6: 45667 | B6: 4 ad çeyrek *5000 | D6: 20000 | F6: =F5+D6-E6 -> 277330
A7: 45672 | B7: bankadan havale | E7: 25000 | F7: =F6+D7-E7 -> 252330
A8: 45672 | B8: Taksit 6/12 - 36500 peri havale | E8: 31000 | F8: =F7+D8-E8 -> 221330
A9: 45709 | B9: peri havale | E9: 26000 | F9: =F8+D9-E9 -> 195330
A10: 45741 | B10: peri havale | E10: 36000 | F10: =F9+D10-E10 -> 159330
A11: 45762 | B11: Taksit 9/12 - 36500 | E11: 36500 | F11: =F10+D11-E11 -> 122830
A12: 45792 | B12: Taksit 10/12 - 36500 | E12: 35000 | F12: =F11+D12-E12 -> 87830
A13: 45823 | B13: Taksit 11/12 - 36500 | E13: 25000 | F13: =F12+D13-E13 -> 62830
A14: 45728 | B14: audi buji örkç | D14: 1400 | F14: =F13+D14-E14 -> 64230
A15: 45728 | B15: audi buji 1800 bobin 650 antfrz 600 işç "1000 | D15: 4150 | F15: =F14+D15-E15 -> 68380
A16: 45728 | B16: elektrikçi adnan işçilik iş havale | D16: 1500 | F16: =F15+D16-E16 -> 69880
A17: 45739 | B17: toyota benz sivas peri | D17: 1200 | F17: =F16+D17-E17 -> 71080
A18: 45733 | B18: audi yağ hava-yağ filt | D18: 1400 | F18: =F17+D18-E18 -> 72480
B19: akü 6*625 | D19: 3750 | F19: =F18+D19-E19 -> 76230
A20: 45772 | B20: klima | D20: 700 | F20: =F19+D20-E20 -> 76930
A21: 45772 | B21: silecek | D21: 700 | F21: =F20+D21-E21 -> 77630
A22: 45772 | B22: antifiriz vs | D22: 1200 | F22: =F21+D22-E22 -> 78830
A23: 45772 | B23: klima | D23: 700 | F23: =F22+D23-E23 -> 79530
A24: 45772 | B24: silecek | D24: 700 | F24: =F23+D24-E24 -> 80230
A25: 45772 | B25: antifiriz vs | D25: 1200 | F25: =F24+D25-E25 -> 81430
A26: 45829 | B26: fren disk ön 4000 trw | D26: 6500 | F26: =F25+D26-E26 -> 87930
A27: 45829 | B27: fren balata ön arka 800 trw | F27: =F26+D27-E27 -> 87930
A28: 45829 | B28: fren disk arka torna 1200 TL trw | F28: =F27+D28-E28 -> 87930
A29: 45829 | B29: sağ rotil febi | F29: =F28+D29-E29 -> 87930
A30: 45853 | B30: Taksit 12/12 - 36500 | E30: 36000 | F30: =F29+D30-E30 -> 51930
A31: 45884 | E31: 26000 | F31: =F30+D31-E31 -> 25930
A32: 45890 | E32: 11000 | F32: =F31+D32-E32 -> 14930
B33: KALAN BAKİYE | F33: =F32+D33-E33 -> 14930
F34: =F33+D34-E34 -> 14930
A35: 45733 | B35: audi turbo soğ radyt örkç | D35: 2500 | F35: =F34+D35-E35 -> 17430
A36: 45740 | B36: audi zincir iş havale | D36: 8500 | F36: =F35+D36-E36 -> 25930
A37: 45740 | B37: audi motor iş havale | D37: 90000 | F37: =F36+D37-E37 -> 115930
A38: 45743 | B38: motor nakliye volkan çetiner | D38: 1600 | F38: =F37+D38-E38 -> 117530
A39: 45829 | B39: motor-fren işçilik | D39: 30000 | F39: =F38+D39-E39 -> 147530
A40: 45761 | B40: motor kulakları yağ çubuğu kk | D40: 4500 | F40: =F39+D40-E40 -> 152030
A42: 45902 | B42: hesabı pervine attım | D42: altın gr | E42: 3500 | F42: =F40/E42 -> 43.437143
...

Sheet 12_25
F1: GİRİŞ | G1: ÇIKIŞ | H1: BAKİYE
A2: - ARALIK 2025 | C2: TOPLAM | D2: =SUM(D4:D31) -> 17494.51 | E2: =SUM(E4:E31) -> -76440.48 | F2: =SUM(F4:F31) -> 373564.53 | G2: =SUM(G4:G31) -> -155436.73 | H2: =F2+G2 -> 218127.8
H4: =H3+F4+G4 -> 0
A5: 45992 | B5: Elektrik 5847500300 Kümbet D09 | E5: -600 | G5: -550 | H5: =H4+F5+G5 -> -550
A6: 45992 | B6: Elektrik 8222520300 Kümbet D10 | E6: -800 | G6: -865 | H6: =H5+F6+G6 -> -1415
B7: KK 4876 İşbank | E7: =E37 -> -57440.48 | G7: =E7 -> -57440.48 | H7: =H6+F7+G7 -> -58855.48
B8: KK 4876 İşbank euro | G8: -34674.75 | H8: =H7+F8+G8 -> -93530.23
B9: KK 5165 Denizbank | E9: =E130 -> 0 | G9: =E9 -> 0 | H9: =H8+F9+G9 -> -93530.23
H10: =H9+F10+G10 -> -93530.23
A11: 45996 | B11: SanCD Ali Demirel Kira | F11: 301000 | H11: =H10+F11+G11 -> 207469.77
B12: Elektrik 9522138254 Sanayi | E12: 0 | H12: =H11+F12+G12 -> 207469.77
B13: Doğalgaz 800004222954 Kümbet D10 | E13: -1000 | G13: -2345 | H13: =H12+F13+G13 -> 205124.77
B14: Doğalgaz 800004222959 Kümbet D09 | E14: -200 | G14: -50 | H14: =H13+F14+G14 -> 205074.77
H15: =H14+F15+G15 -> 205074.77
B16: maaş | D16: 17494.51 | F16: 17564.53 | H16: =H15+F16+G16 -> 222639.3
B17: umut | G17: -21000 | H17: =H16+F17+G17 -> 201639.3
A18: 46019 | B18: umut | E18: -7500 | G18: -9000 | H18: =H17+F18+G18 -> 192639.3
B19: Genel Masraf | E19: -7500 | G19: -7500 | H19: =H18+F19+G19 -> 185139.3
A20: 45996 | B20: yaseminden | F20: 55000
A21: 45999 | B21: yasemine | G21: -20000
H22: =H19+F22+G22 -> 185139.3
A23: 46020 | B23: Elektrik 5847500300 Kümbet D09 | E23: -600 | G23: -735 | H23: =H22+F23+G23 -> 184404.3
A24: 46020 | B24: Elektrik 8222520300 Kümbet D10 | E24: -800 | G24: -415 | H24: =H23+F24+G24 -> 183989.3
A25: 46006 | B25: BAHÇE | G25: -80 | H25: =H24+F25+G25 -> 183909.3
A26: 46014 | B26: 2249 + yurtdışı 3 gb | G26: -781.5 | H26: =H25+F26+G26 -> 183127.8
H27: =H26+F27+G27 -> 183127.8
H28: =H27+F28+G28 -> 183127.8
H29: =H28+F29+G29 -> 183127.8
B37: İşbank 4876 KK | E37: =SUM(E38:E83) -> -57440.48 | F37: 57440.48
A39: 45817 | B39: atasun yasemin güneş gzlğü | D39: 6 -6 | E39: -406.65
A40: 45880 | B40: ajet ist | C40: 5126 | D40: 4 -6 | E40: -854.33
A41: 45880 | B41: euroka tcross sigorta | C41: 16598.9 | D41: 4 -9 | E41: -1844.32
B42: ajet ist | C42: 2307 | D42: 3 -6 | E42: -384.5
A46: 45956 | B46: CVZLİ | E46: -130
B47: mrkt | E47: -83.26
B48: pide | E48: -270
A49: 45959 | B49: et | E49: -800
B50: bnzn | E50: -1000
B51: mrkt | E51: -24.95
B52: mrkt | E52: -149.95
...

Sheet 11_25
F1: GİRİŞ | G1: ÇIKIŞ | I1: BAKİYE
A2: - KASIM 2025 | C2: TOPLAM | D2: =SUM(D4:D16) -> 17494.51 | E2: =SUM(E4:E16) -> -73331.92 | F2: =SUM(F4:F16) -> 17564.53 | G2: =SUM(G4:G16) -> -20914.86 | I2: =F2+G2 -> -20914.86
I4: =I3+F4+G4 -> 0
I5: =I4+F5+G5 -> 0
A6: 45964 | B6: emrullah özer salih ant-sameturgut masraf | G6: -10000 | I6: =I5+F6+G6 -> -10000
A7: 45965 | B7: KK 4876 İşbank | E7: =E19 -> -21799.29 | G7: =E7 -> -21799.29 | I7: =I6+F7+G7 -> -31799.29
B8: KK 5165 Denizbank | E8: =E69 -> 0 | G8: =E8 -> 0 | I8: =I7+F8+G8 -> -31799.29
B9: Elektrik 9522138254 Sanayi | E9: 0 | I9: =I8+F9+G9 -> -31799.29
B10: Doğalgaz 800004222954 Kümbet D10 | E10: -1000 | G10: -1195 | I10: =I9+F10+G10 -> -31799.29
B11: Doğalgaz 800004222959 Kümbet D09 | E11: -200 | G11: -45 | I11: =I10+F11+G11 -> -31799.29
B12: maaş | D12: 17494.51 | F12: 17564.53 | I12: =I11+F12+G12 -> -31799.29
B13: umut | E13: -7500 | G13: -9000 | I13: =I12+F13+G13 -> -31799.29
B14: Genel Masraf | E14: -7500 | I14: =I13+F14+G14 -> -31799.29
I15: =I14+F15+G15 -> -31799.29
B19: İşbank 4876 KK | E19: =SUM(E20:E66) -> -21799.29
A21: 45817 | B21: atasun yasemin güneş gzlğü | D21: 5 -6 | E21: -406.67
A22: 45790 | B22: koton | C22: 1407.46 | D22: 6 - 6 | E22: -234.56
A23: 45880 | B23: ajet ist | C23: 5126 | D23: 3 -6 | E23: -854.33
A24: 45880 | B24: euroka tcross sigorta | C24: 16598.9 | D24: 3 -9 | E24: -1844.32
A25: 45901 | B25: AJET İSTANBUL | C25: 2307 | D25: 2 -6 | E25: -384.5
A27: 45925 | B27: et dnr | E27: -250
B28: isot | E28: -250
B29: amazon modem | E29: -2521.03
A30: 45926 | B30: çklkl pide | E30: -165
B31: mrkt | E31: -80
B32: mrkt | E32: -52
B33: tvk dnr | E33: -135
B34: pide fab | E34: -520
B35: unal başpınar | E35: -100
B36: tvk dnr | E36: -130
A37: 45931 | B37: audi muayene | E37: -2869.34
B38: tvk dnr | E38: -90
B39: işkmb | E39: -120
B40: çklkl pide | E40: -165
B41: mrkt | E41: -162.5
B42: mrkt | E42: -80
B43: mrkt | E43: -590.26
B44: et dnr | E44: -250
B45: audi benzin | E45: -500
A46: 45936 | B46: ödeme | D46: 29005.36
...

Sheet 10_25
F1: GİRİŞ | G1: ÇIKIŞ | H1: BAKİYE
A2: - EKİM 2025 | C2: TOPLAM | D2: =SUM(D4:D27) -> 17494.51 | E2: =SUM(E4:E27) -> -54105.36 | F2: =SUM(F4:F27) -> 17564.53 | G2: =SUM(G4:G27) -> -54899.36 | H2: =F2+G2 -> -37334.83
H4: =H3+F4+G4 -> 0
H5: =H4+F5+G5 -> 0
H6: =H5+F6+G6 -> 0
A7: 45934 | B7: işbank ytrm hesabı saklama | G7: -157.5 | H7: =H6+F7+G7 -> -157.5
H8: =H7+F8+G8 -> -157.5
A9: 45936 | B9: KK 4876 İşbank | E9: =E30 -> -29005.36 | G9: =E9 -> -29005.36 | H9: =H8+F9+G9 -> -29162.86
B10: KK 5165 Denizbank | E10: =E71 -> 0 | G10: =E10 -> 0 | H10: =H9+F10+G10 -> -29162.86
A11: 45943 | G11: -130 | H11: =H10+F11+G11 -> -29292.86
A12: 45944 | B12: av emrullah - salih ant Adli Tıp K. İmza | G12: -5750 | H12: =H11+F12+G12 -> -35042.86
A13: 45947 | B13: Doğalgaz 800004222954 Kümbet D10 | E13: -1000 | G13: -245 | H13: =H12+F13+G13 -> -35287.86
A14: 45947 | B14: Doğalgaz 800004222959 Kümbet D09 | E14: -200 | G14: -60 | H14: =H13+F14+G14 -> -35347.86
H15: =H14+F15+G15 -> -35347.86
B16: maaş | D16: 17494.51 | F16: 17564.53 | H16: =H15+F16+G16 -> -17783.33
B17: yasemin | E17: -7500 | H17: =H16+F17+G17 -> -17783.33
B18: umut | E18: -7500 | G18: -9000 | H18: =H17+F18+G18 -> -26783.33
B19: Genel Masraf | E19: -7500 | G19: -9000 | H19: =H18+F19+G19 -> -35783.33
A20: 45952 | B20: tcell 2240 | G20: -281.5 | H20: =H19+F20+G20 -> -36064.83
A21: 45957 | B21: Elektrik 5847500300 Kümbet D09 | E21: -600 | G21: -515 | H21: =H20+F21+G21 -> -36579.83
A22: 45957 | B22: Elektrik 8222520300 Kümbet D10 | E22: -800 | G22: -755 | H22: =H21+F22+G22 -> -37334.83
H23: =H22+F23+G23 -> -37334.83
H24: =H23+F24+G24 -> -37334.83
B25: TUSDATA 2025 30/30 8845 - 8845 = 0 | H25: =H24+F25+G25 -> -37334.83
H26: =H25+F26+G26 -> -37334.83
H27: =H26+F27+G27 -> -37334.83
B30: İşbank 4876 KK | E30: =SUM(E32:E70) -> -29005.36
A32: 45817 | B32: atasun yasemin güneş gzlğü | D32: 4 -6 | E32: -406.67 | F32: 0
A33: 45790 | B33: koton | C33: 1407.46 | D33: 5 - 6 | E33: -234.58 | F33: 0
A34: 45880 | B34: ajet ist | C34: 5126 | D34: 2 -6 | E34: -854.33 | F34: 0
A35: 45880 | B35: euroka tcross sigorta | C35: 16598.9 | D35: 2 -9 | E35: -1844.32 | F35: 0
A36: 45901 | B36: AJET İSTANBUL | C36: 2307 | D36: 1 -6 | E36: -384.5 | F36: 0
A40: 45894 | B40: bahçe sulama | E40: -900
A41: 45895 | E41: -100
A42: 45895 | B42: PİDE | E42: -140
B43: MRKT | E43: -117.5
B44: DÖNER | E44: -250
A45: 45898 | B45: İDSOT BAHÇE ÇMNTO 110 DMR BĞLM 50 | E45: -160
A46: 45901 | B46: SİVAS KÖFTE YSMN TAYİN | E46: -775
A47: 45902 | B47: MRKT | E47: -481.18
...

Sheet 09_25
F1: GİRİŞ | G1: ÇIKIŞ | H1: BAKİYE
A2: - EYLÜL 2025 | C2: TOPLAM | D2: =SUM(D4:D34) -> 17494.51 | E2: =SUM(E4:E34) -> -79785.7 | F2: =SUM(F4:F34) -> 57500 | G2: =SUM(G4:G33) -> -93673.89 | H2: =F2+G2 -> -36173.89
H4: =H3+F4+G4 -> 0
H5: =H4+F5+G5 -> 0
A6: 45905 | B6: vdfn 2240 | G6: -212.75 | H6: =H5+F6+G6 -> -212.75
A7: 45904 | B7: KK 4876 İşbank | E7: =E39 -> -47204.14 | G7: =E7 -> -47204.14 | H7: =H6+F7+G7 -> -47416.89
A8: 45902 | B8: KK 5165 Denizbank | C8: SON ÖDEME | E8: =E122 -> -625 | G8: =E8 -> -625 | H8: =H7+F8+G8 -> -48041.89
H9: =H8+F9+G9 -> -48041.89
B10: Aidat Marmara Royal Site 9/12 | E10: -2117.06 | G10: -2117 | H10: =H9+F10+G10 -> -50158.89
A11: 45920 | B11: Kira Adem Özen 4/12 Mrmr Ryl A Blok 82 aidat İADESİ | F11: 40000 | H11: =H10+F11+G11 -> -10158.89
B12: 2 aylık depozito * 25 000 (son kira bedeli) eylülde 12 gün oturuldu 10 000 TL | H12: =H11+F12+G12 -> -10158.89
A13: 45910 | B13: umut | G13: -10000 | H13: =H12+F13+G13 -> -20158.89
A14: 45911 | B14: yasemin | G14: -5000 | H14: =H13+F14+G14 -> -25158.89
B15: Doğalgaz 800004222954 Kümbet D10 | E15: -1000 | G15: -120 | H15: =H14+F15+G15 -> -25278.89
B16: Doğalgaz 800004222959 Kümbet D09 | E16: -200 | G16: -35 | H16: =H15+F16+G16 -> -25313.89
A17: 45923 | B17: turkcell 2240 | E17: -239.5 | H17: =H16+F17+G17 -> -25313.89
B18: maaş | D18: 17494.51 | F18: 17500 | H18: =H17+F18+G18 -> -7813.89
B19: yasemin | E19: -9000 | G19: -9000 | H19: =H18+F19+G19 -> -16813.89
B20: umut | E20: -9000 | G20: -9000 | H20: =H19+F20+G20 -> -25813.89
B21: Genel Masraf | E21: -9000 | G21: -9000 | H21: =H20+F21+G21 -> -34813.89
H22: =H21+F22+G22 -> -34813.89
H23: =H22+F23+G23 -> -34813.89
H24: =H23+F24+G24 -> -34813.89
A25: 45929 | B25: Elektrik 5847500300 Kümbet D09 | E25: -600 | G25: -540 | H25: =H24+F25+G25 -> -35353.89
A26: 45929 | B26: Elektrik 8222520300 Kümbet D10 | E26: -800 | G26: -820 | H26: =H25+F26+G26 -> -36173.89
H27: =H26+F27+G27 -> -36173.89
H28: =H27+F28+G28 -> -36173.89
B29: TUSDATA 2025 29/30 17690 - 8845 = 8845 | H29: =H28+F29+G29 -> -36173.89
H30: =H29+F30+G30 -> -36173.89
H31: =H30+F31+G31 -> -36173.89
B39: İşbank 4876 KK | E39: =SUM(E41:E114) -> -47204.14
A41: 45811 | B41: kurban kızılay peri nakit ödedi | C41: 5250 | D41: 3 -3 | E41: -1750 | F41: 0
A42: 45811 | B42: kurban kızılay peri nakit ödedi | C42: 5250 | D42: 3 -3 | E42: -1750 | F42: 0
A43: 45811 | B43: kurban kızılay | C43: 5250 | D43: 3 -3 | E43: -1750 | F43: 0
A44: 45811 | B44: kurban mehmetçik vakfı | C44: 14500 | D44: 3 -3 | E44: -4833.33 | F44: 0
A45: 45817 | B45: atasun yasemin güneş gzlğü | D45: 3 -6 | E45: -406.67 | F45: 0
A46: 45790 | B46: koton | C46: 1407.46 | D46: 4 - 6 | E46: -234.58 | F46: 0
A47: 45828 | B47: basbug.com audi fren disk-balata | C47: 6500 | D47: 3 -3 | E47: -2166.66 | F47: 0
A48: 45805 | B48: belediye | C48: 1380 | D48: 3 -3 | E48: -460 | F48: 0
A49: 45805 | B49: belediye | C49: 4373.6 | D49: 3 -3 | E49: -1457.87 | F49: 0
...

Sheet 08_25
F1: GİRİŞ | G1: ÇIKIŞ | H1: BAKİYE
A2: - AĞUSTOS 2025 | C2: TOPLAM | D2: =SUM(D4:D27) -> 17494.51 | E2: =SUM(E4:E27) -> -95750 | F2: =SUM(F4:F27) -> 17564.53 | G2: =SUM(G4:G27) -> -99089.92 | H2: =F2+G2 -> -81525.39
H4: =H3+F4+G4 -> 0
H5: =H4+F5+G5 -> 0
A6: 45873 | B6: KK 4876 İşbank | E6: =E30 -> -42696.2 | G6: =E6 -> -42696.2 | H6: =H5+F6+G6 -> -42696.2
A7: 45873 | B7: KK 5165 Denizbank | E7: =E111 -> -636.74 | G7: =E7 -> -636.74 | H7: =H6+F7+G7 -> -43332.94
H8: =H7+F8+G8 -> -43332.94
A9: 45873 | B9: Aidat Marmara Royal Site 9/12 | E9: -2117.06 | G9: -2116.98 | H9: =H8+F9+G9 -> -45449.92
A10: 45880 | B10: Kira Adem Özen 3/12 Mrmr Ryl A Blok 82 | E10: -25000 | G10: -25000 | H10: =H9+F10+G10 -> -70449.92
B11: Elektrik 9522138254 Sanayi | E11: 0 | H11: =H10+F11+G11 -> -70449.92
H12: =H11+F12+G12 -> -70449.92
A13: 45887 | B13: Doğalgaz 800004222954 Kümbet D10 | E13: -1000 | G13: -140 | H13: =H12+F13+G13 -> -70589.92
A14: 45887 | B14: Doğalgaz 800004222959 Kümbet D09 | E14: -200 | G14: -35 | H14: =H13+F14+G14 -> -70624.92
B15: Doğalgaz Marmara Royal Ablok D:82 | E15: -200 | H15: =H14+F15+G15 -> -70624.92
B16: maaş | D16: 17494.51 | F16: 17564.53 | H16: =H15+F16+G16 -> -53060.39
B17: yasemin | E17: -7500 | G17: -9000 | H17: =H16+F17+G17 -> -62060.39
B18: umut | E18: -7500 | G18: -9000 | H18: =H17+F18+G18 -> -71060.39
B19: Genel Masraf | E19: -7500 | G19: -9000 | H19: =H18+F19+G19 -> -80060.39
A20: 45898 | B20: Elektrik 5847500300 Kümbet D09 | E20: -600 | G20: -540 | H20: =H19+F20+G20 -> -80600.39
A21: 45898 | B21: Elektrik 8222520300 Kümbet D10 | E21: -800 | G21: -925 | H21: =H20+F21+G21 -> -81525.39
B22: Elektrik 8758480300 bahçe | H22: =H21+F22+G22 -> -81525.39
H23: =H22+F23+G23 -> -81525.39
B24: TUSDATA 2025 28/30 26535 - 8845 = 17690 | H24: =H23+F24+G24 -> -81525.39
H25: =H24+F25+G25 -> -81525.39
H26: =H25+F26+G26 -> -81525.39
B30: İşbank 4876 KK | E30: =SUM(E31:E106) -> -42696.2 | F30: 42696.2
A32: 45715 | B32: turknet 12 aylık internet | C32: 5938.68 | D32: 6 - 6 | E32: -989.8
A33: 45811 | B33: kurban kızılay peri nakit ödedi | C33: 5250 | D33: 2 -3 | E33: -1750
A34: 45811 | B34: kurban kızılay peri nakit ödedi | C34: 5250 | D34: 2 -3 | E34: -1750
A35: 45811 | B35: kurban kızılay | C35: 5250 | D35: 2 -3 | E35: -1750
A36: 45811 | B36: kurban mehmetçik vakfı | C36: 14500 | D36: 2 -3 | E36: -4833.33
A37: 45817 | B37: atasun yasemin güneş gzlğü | D37: 2 -6 | E37: -406.67
A38: 45790 | B38: koton | C38: 1407.46 | D38: 3 - 6 | E38: -234.58
A39: 45828 | B39: basbug.com audi fren disk-balata | C39: 6500 | D39: 2 -3 | E39: -2166.67
A40: 45805 | B40: belediye | C40: 1380 | D40: 2 -3 | E40: -460 | F40: 0
A41: 45805 | B41: belediye | C41: 4373.6 | D41: 2 -3 | E41: -1457.87 | F41: 0
B42: belediye emlak hacı | C42: 0
A44: 45833 | B44: isot sny beyaz çadır 8*5 mt | E44: -1000
A45: 45833 | B45: aksoy metal sny aydınlık | E45: -5750
A46: 45835 | B46: koçtaş | E46: -819.8
...

Sheet 07_25
F1: GİRİŞ | G1: ÇIKIŞ | H1: BAKİYE
A2: - TEMMUZ 2025 | C2: TOPLAM | D2: =SUM(D4:D26) -> 15000 | E2: =SUM(E4:E26) -> -93124.89 | F2: =SUM(F4:F26) -> 17494.51 | G2: =SUM(G4:G26) -> -127505.39 | H2: =F2+G2 -> -110010.88
H4: =H3+F4+G4 -> 0
H5: =H4+F5+G5 -> 0
B6: nazan havale | G6: -20000 | H6: =H5+F6+G6 -> -20000
B7: alp bey karne | G7: -1500 | H7: =H6+F7+G7 -> -21500
A8: 45845 | B8: KK 4876 İşbank | E8: =E30 -> -39087.63 | G8: =E8 -> -39087.63 | H8: =H7+F8+G8 -> -60587.63
B9: KK 5165 Denizbank | E9: =E105 -> -1620.2 | G9: -1620.5 | H9: =H8+F9+G9 -> -62208.13
H10: =H9+F10+G10 -> -62208.13
A11: 45846 | B11: Aidat Marmara Royal Site 9/12 | E11: -2117.06 | G11: -2168.51 | H11: =H10+F11+G11 -> -64376.64
A12: 45846 | B12: Kira Adem Özen 2/12 Mrmr Ryl A Blok 82 | E12: -25000 | G12: -25000 | H12: =H11+F12+G12 -> -89376.64 | J12: 67000
B13: Elektrik 9522138254 Sanayi | E13: 0 | H13: =H12+F13+G13 -> -89376.64 | J13: 47
A14: 45855 | B14: Doğalgaz 800004222954 Kümbet D10 | E14: -1000 | G14: -75 | H14: =H13+F14+G14 -> -89451.64
A15: 45855 | B15: Doğalgaz 800004222959 Kümbet D09 | E15: -200 | G15: -50 | H15: =H14+F15+G15 -> -89501.64
B16: Doğalgaz Marmara Royal Ablok D:82 | E16: -200 | H16: =H15+F16+G16 -> -89501.64
B17: maaş | D17: 15000 | F17: 17494.51 | H17: =H16+F17+G17 -> -72007.13
B18: yasemin | E18: -7500 | G18: -9000 | H18: =H17+F18+G18 -> -81007.13
B19: umut | E19: -7500 | G19: -20000 | H19: =H18+F19+G19 -> -101007.13
B20: Genel Masraf | E20: -7500 | G20: -7500 | H20: =H19+F20+G20 -> -108507.13
A21: 45868 | B21: vdfn 2240 | G21: -213.75 | H21: =H20+F21+G21 -> -108720.88
A22: 45869 | B22: Elektrik 5847500300 Kümbet D09 | E22: -600 | G22: -495 | H22: =H21+F22+G22 -> -109215.88
A23: 45869 | B23: Elektrik 8222520300 Kümbet D10 | E23: -800 | G23: -795 | H23: =H22+F23+G23 -> -110010.88
B24: TUSDATA 2025 27/30 35380 - 8845 = 26535 | H24: =H23+F24+G24 -> -110010.88
H25: =H24+F25+G25 -> -110010.88
H26: =H25+F26+G26 -> -110010.88
H27: =H26+F27+G27 -> -110010.88
H28: =H27+F28+G28 -> -110010.88
B30: İşbank 4876 KK | E30: =SUM(E32:E103) -> -39087.63
A32: 45715 | B32: turknet 12 aylık internet | C32: 5938.68 | D32: 5 - 6 | E32: -989.78 | F32: 0
A33: 45811 | B33: kurban kızılay peri nakit ödedi | C33: 5250 | D33: 0 -3 | E33: -1750 | F33: 0
A34: 45811 | B34: kurban kızılay peri nakit ödedi | C34: 5250 | D34: 0 -3 | E34: -1750 | F34: 0
A35: 45811 | B35: kurban kızılay | C35: 5250 | D35: 1 -3 | E35: -1750 | F35: 0
A36: 45811 | B36: kurban mehmetçik vakfı | C36: 14500 | D36: 1 -3 | E36: -4833.33 | F36: 0
A37: 45817 | B37: atasun yasemin güneş gzlğü | D37: 1 -6 | E37: -406.67 | F37: 0
A38: 45790 | B38: koton | C38: 1407.46 | D38: 2 - 6 | E38: -234.58 | F38: 0
A39: 45828 | B39: basbug.com audi fren disk-balata | C39: 6500 | D39: 1 -3 | E39: -2166.67
A40: 45805 | B40: belediye | C40: 1380 | D40: 1 -3 | E40: -460 | F40: 0
A41: 45805 | B41: belediye | C41: 4373.6 | D41: 1 -3 | E41: -1457.87 | F41: 0
B42: belediye emlak hacı | C42: 0
A44: 45802 | B44: tvk dnr | E44: -80
...

Sheet 06_25
F1: GİRİŞ | G1: ÇIKIŞ | H1: BAKİYE
A2: - HAZİRAN 2025 | C2: TOPLAM | D2: =SUM(D4:D34) -> 15000 | E2: =SUM(E4:E34) -> -76228.43 | F2: =SUM(F4:F34) -> 15054.88 | G2: =SUM(G4:G34) -> -109005.52 | H2: =F2+G2 -> -93950.64
H4: =H3+F4+G4 -> 0
A5: 45810 | B5: Elektrik 5847500300 Kümbet D09 | E5: -600 | G5: -510 | H5: =H4+F5+G5 -> -510
A6: 45810 | B6: Elektrik 8222520300 Kümbet D10 | E6: -800 | G6: -820 | H6: =H5+F6+G6 -> -1330
A7: 45810 | B7: voda 2240 | E7: -212.75 | G7: -212.75 | H7: =H6+F7+G7 -> -1542.75
A8: 45810 | B8: KK 5165 Denizbank | E8: =E76 -> -625 | G8: =E8 -> -625 | H8: =H7+F8+G8 -> -2167.75
A9: 45812 | B9: KK 4876 İşbank | E9: =E38 -> -21573.62 | G9: =E9 -> -21573.62 | H9: =H8+F9+G9 -> -23741.37
A10: 45818 | B10: Kira Adem Özen 1/12 Mrmr Ryl A Blok 82 | E10: -25000 | G10: -25000 | H10: =H9+F10+G10 -> -48741.37
B11: Elektrik 9522138254 Sanayi | E11: 0 | H11: =H10+F11+G11 -> -48741.37
A12: 45819 | B12: Aidat Marmara Royal Site 9/12 | E12: -2117.06 | G12: -2138.15 | H12: =H11+F12+G12 -> -50879.52
A13: 45819 | B13: Doğalgaz Marmara Royal Ablok D:82 | E13: -200 | G13: -229 | H13: =H12+F13+G13 -> -51108.52
A14: 45828 | B14: fide-çorap arif ustadan emanet ödendi | G14: -950 | H14: =H13+F14+G14 -> -52058.52
A15: 45828 | B15: Doğalgaz 800004222954 Kümbet D10 | C15: 316.06 | D15: devletten | E15: -1000 | G15: -250 | H15: =H14+F15+G15 -> -52308.52
A16: 45828 | B16: Doğalgaz 800004222959 Kümbet D09 | E16: -200 | G16: 0 | H16: =H15+F16+G16 -> -52308.52
A17: 45832 | B17: audi motor-fren işçilik havale | G17: -10000 | H17: =H16+F17+G17 -> -62308.52
A18: 45834 | B18: audi motor-fren işçilik | G18: -20000 | H18: =H17+F18+G18 -> -82308.52
A19: 45834 | B19: doğuş üsk kat cam camcı isa | G19: -3000 | H19: =H18+F19+G19 -> -85308.52
H20: =H19+F20+G20 -> -85308.52
B21: maaş | D21: 15000 | F21: 15054.88 | H21: =H20+F21+G21 -> -70253.64
B22: yasemin | E22: -7500 | G22: -7506 | H22: =H21+F22+G22 -> -77759.64
B23: umut | E23: -7500 | G23: -7506 | H23: =H22+F23+G23 -> -85265.64
B24: Genel Masraf | E24: -7500 | G24: -7500 | H24: =H23+F24+G24 -> -92765.64
H25: =H24+F25+G25 -> -92765.64
H26: =H25+F26+G26 -> -92765.64
H27: =H26+F27+G27 -> -92765.64
A28: 45838 | B28: Elektrik 5847500300 Kümbet D09 | E28: -600 | G28: -485 | H28: =H27+F28+G28 -> -93250.64
A29: 45838 | B29: Elektrik 8222520300 Kümbet D10 | E29: -800 | G29: -700 | H29: =H28+F29+G29 -> -93950.64
H30: =H29+F30+G30 -> -93950.64
H31: =H30+F31+G31 -> -93950.64
B32: TUSDATA 2025 26/30 44225 - 8845 = 35380 | H32: =H31+F32+G32 -> -93950.64
H33: =H32+F33+G33 -> -93950.64
H34: =H33+F34+G34 -> -93950.64
B38: İşbank 4876 KK | E38: =SUM(E39:E70) -> -21573.62
A40: 45715 | B40: turknet 12 aylık internet | C40: 5938.68 | D40: 4 - 6 | E40: -989.78
A41: 45790 | B41: koton | C41: 1407.46 | D41: 1 - 6 | E41: -234.58
A43: 45772 | B43: audi silecek | E43: -700
A44: 45772 | B44: audi antifiriz vs | E44: -1200
B45: belediye sayaç sanayi | E45: -2820
A46: 45777 | B46: tvk dnr | E46: -80
...

Sheet 05_25
F1: GİRİŞ | G1: ÇIKIŞ | H1: BAKİYE
A2: - MAYIS 2025 | C2: TOPLAM | D2: =SUM(D4:D25) -> 15000 | E2: =SUM(E4:E25) -> -59780.37 | F2: =SUM(F4:F25) -> 19054.88 | G2: =SUM(G4:G25) -> -60755.16 | H2: =F2+G2 -> -41700.28
H4: =H3+F4+G4 -> 0
H5: =H4+F5+G5 -> 0
A6: 45749 | B6: Aidat Marmara Royal Site 9/12 | E6: -2117.06 | G6: -2116.98 | H6: =H5+F6+G6 -> -2116.98
A7: 45782 | B7: KK 4876 İşbank | E7: =E31 -> -7461.47 | G7: =E7 -> -7461.47 | H7: =H6+F7+G7 -> -9578.45
A8: 45782 | B8: KK 4876 İşbank 24,09 euro x44,2038 | C8: 24.09 | E8: =E32 -> 0 | G8: -1064.87 | H8: =H7+F8+G8 -> -10643.32
A9: 45782 | B9: KK 5165 Denizbank | E9: =E56 -> -8801.84 | G9: =E9 -> -8801.84 | H9: =H8+F9+G9 -> -19445.16
A10: 45786 | B10: Kira Adem Özen 12/12 Mrmr Ryl A Blok 82 | E10: -17500 | G10: -17500 | H10: =H9+F10+G10 -> -36945.16
B11: Elektrik 9522138254 Sanayi | E11: 0 | H11: =H10+F11+G11 -> -36945.16
A12: 45797 | B12: Doğalgaz 800004222954 Kümbet D10 | C12: 1604.97 | D12: devlet | E12: -1000 | G12: -1265 | H12: =H11+F12+G12 -> -38210.16
A13: 45797 | B13: Doğalgaz 800004222959 Kümbet D09 | C13: 47.55 | D13: devlet | E13: -200 | G13: -35 | H13: =H12+F13+G13 -> -38245.16
B14: Doğalgaz Marmara Royal Ablok D:82 | E14: -200 | H14: =H13+F14+G14 -> -38245.16
B15: maaş | D15: 15000 | F15: 15054.88 | H15: =H14+F15+G15 -> -23190.28
A16: 45804 | B16: yasemin | E16: -7500 | G16: -7505 | H16: =H15+F16+G16 -> -30695.28
A17: 45804 | B17: umut | E17: -7500 | G17: -7505 | H17: =H16+F17+G17 -> -38200.28
B18: Genel Masraf | E18: -7500 | G18: -7500 | H18: =H17+F18+G18 -> -45700.28
A19: 45804 | B19: SANAYI BELEDIYE SAYC UCRETI | C19: 2024 / 10 | D19: iş kk | H19: =H18+F19+G19 -> -45700.28
H20: =H19+F20+G20 -> -45700.28
A21: 45808 | B21: maaş kurban bayramlık | F21: 4000 | H21: =H20+F21+G21 -> -41700.28
H22: =H21+F22+G22 -> -41700.28
B23: TUSDATA 2025 25/30 53070 - 8845 = 44225 | H23: =H22+F23+G23 -> -41700.28
H24: =H23+F24+G24 -> -41700.28
H25: =H24+F25+G25 -> -41700.28
I30: lise arksı ifraz
B31: İşbank 4876 KK | E31: =SUM(E32:E47) -> -7461.47 | I31: 8850 | J31: applksyn
I32: 48000 | J32: ifraz
I33: 6000 | J33: bld hrc
A34: 45715 | B34: turknet 12 aylık internet | C34: 5938.68 | D34: 3 - 6 | E34: -989.78 | I34: 3000 | J34: kdstr hrc
I35: 5000 | J35: tapu
A36: 45751 | B36: ödeme | D36: 123984.02 | I36: =SUM(I31:I35) -> 70850
A37: 45751 | B37: gib | E37: -672.4 | I37: 2 | J37: 0.5
A38: 45754 | B38: eziç yemek | E38: -3740 | I38: =I36/I37 -> 35425
A39: 45756 | B39: çilem ltd. hellim | E39: -390 | I39: =I38/J39 -> 5060.7143 | J39: 7
A40: 45764 | B40: mrk | E40: -138.81 | I40: =I38/J40 -> 8856.25 | J40: 4
A41: 45766 | B41: tvk dnr | E41: -80 | J41: kişi
A42: 45767 | B42: pide kmç | E42: -140
A43: 45770 | B43: kftc ysf | E43: -300
A44: 45770 | B44: mrk | E44: -372.15
A45: 45771 | B45: benzin bahçe | E45: -250
...

Sheet 04_25
F1: GİRİŞ | G1: ÇIKIŞ | H1: BAKİYE
A2: - NİSAN 2025 | C2: TOPLAM | D2: =SUM(D4:D30) -> 15000 | E2: =SUM(E4:E30) -> -191614.26 | F2: =SUM(F4:F30) -> 15054.88 | G2: =SUM(G4:G30) -> -191809.25 | H2: =F2+G2 -> -176754.37
H4: =H3+F4+G4 -> 0
H5: =H4+F5+G5 -> 0
A6: 45749 | B6: Aidat Marmara Royal Site 9/12 | E6: -2117.06 | G6: -2116.98 | H6: =H5+F6+G6 -> -2116.98
A7: 45750 | B7: KK 5165 Denizbank 27-3-25 | E7: =E50 -> -19953.18 | G7: =E7 -> -19953.18 | H7: =H6+F7+G7 -> -22070.16
A8: 45720 | B8: KK 4876 İşbank | E8: =E33 -> -123984.02 | G8: =E8 -> -123984.02 | H8: =H7+F8+G8 -> -146054.18
A9: 45754 | B9: alumba kira damga vergisi | G9: -672.4 | H9: =H8+F9+G9 -> -146726.58
A10: 45755 | B10: Kira Adem Özen 11/12 Mrmr Ryl A Blok 82 | E10: -17500 | G10: -17500 | H10: =H9+F10+G10 -> -164226.58
H11: =H10+F11+G11 -> -164226.58
H12: =H11+F12+G12 -> -164226.58
B13: Elektrik 9522138254 Sanayi | E13: 0 | H13: =H12+F13+G13 -> -164226.58
A14: 45763 | B14: Doğalgaz 800004222954 Kümbet D10 | E14: -1000 | G14: -1175 | H14: =H13+F14+G14 -> -165401.58
A15: 45763 | B15: Doğalgaz 800004222959 Kümbet D09 | E15: -200 | G15: -30 | H15: =H14+F15+G15 -> -165431.58
A16: 45777 | B16: Doğalgaz Marmara Royal Ablok D:82 | E16: -200 | G16: -185.67 | H16: =H15+F16+G16 -> -165617.25
B17: maaş | D17: 15000 | F17: 15054.88 | H17: =H16+F17+G17 -> -150562.37
B18: yasemin | E18: -7500 | G18: -7504 | H18: =H17+F18+G18 -> -158066.37
B19: umut | E19: -7500 | G19: -7504 | H19: =H18+F19+G19 -> -165570.37
B20: Genel Masraf | E20: -7500 | G20: -7500 | H20: =H19+F20+G20 -> -173070.37
A21: 45744 | B21: SANAYI BELEDIYE SAYC UCRETI | C21: 2024 / 8 | D21: kk | E21: -1380 | H21: =H20+F21+G21 -> -173070.37
A22: 45776 | B22: SANAYI BELEDIYE SAYC UCRETI | C22: 2024 / 9 | D22: kk | E22: -1380 | H22: =H21+F22+G22 -> -173070.37
A23: 45775 | B23: Elektrik 5847500300 Kümbet D09 | E23: -600 | G23: -335 | H23: =H22+F23+G23 -> -173405.37
A24: 45775 | B24: Elektrik 8222520300 Kümbet D10 | E24: -800 | G24: -560 | H24: =H23+F24+G24 -> -173965.37
A25: 45764 | B25: Elektrik 8758480300 Bahçe | G25: -70 | H25: =H24+F25+G25 -> -174035.37
H26: =H25+F26+G26 -> -174035.37
B27: TUSDATA 2025 24/30 61915 - 8845 = 53070 | H27: =H26+F27+G27 -> -174035.37
A28: 45764 | B28: av.emrulah-merdalkipel-tahliye | G28: -2500 | H28: =H27+F28+G28 -> -176535.37
A29: 45777 | B29: VODA 2240 | G29: -219 | H29: =H28+F29+G29 -> -176754.37
B33: İşbank 4876 KK | E33: =SUM(E35:E45) -> -123984.02
A35: 45713 | B35: euro borç tl karşılığı rum kesimi mrkt khv | C35: ??????? | E35: -291.36 | F35: 1
A37: 45715 | B37: turknet 12 aylık internet | C37: 5938.68 | D37: 2 - 6 | E37: -989.78 | F37: 1
A38: 45716 | B38: DAU yasemin okul | E38: -1023.05 | F38: 1
A39: 45716 | B39: DAU yasemin okul | E39: -118966.5 | F39: 1
A40: 45716 | B40: BELEDİYE sanayi sayaç 7 taksitler | E40: -1380 | F40: 1
A41: 45723 | B41: ödeme | D41: 19043.61
A42: 45741 | B42: yıllık ücret | E42: -1262 | F42: 1
B43: faiz | E43: -4.77
B44: faiz | E44: -3.46
B45: bsmv | E45: -63.1
E46: HESAP KESİM
...

Sheet 03_25
F1: GİRİŞ | G1: ÇIKIŞ | H1: BAKİYE
A2: - MART 2025 | C2: TOPLAM | D2: =SUM(D4:D36) -> 30000 | E2: =SUM(E4:E36) -> -79968.85 | F2: =SUM(F4:F36) -> 32994.19 | G2: =SUM(G4:G40) -> -186074.7 | H2: =F2+G2 -> -153080.51
H4: =H3+F4+G4 -> 0
H5: =H4+F5+G5 -> 0
A6: 45718 | B6: vodafone 2240 | G6: -213.25 | H6: =H5+F6+G6 -> -213.25
B7: Elektrik 9522138254 Sanayi | E7: 0 | H7: =H6+F7+G7 -> -213.25
A8: 45721 | B8: Aidat Marmara Royal Site 9/12 | E8: -2117.06 | G8: -2116.98 | H8: =H7+F8+G8 -> -2330.23
A9: 45722 | B9: KK 5165 Denizbank | E9: =E67 -> -14628.18 | G9: =E9 -> -14628.18 | H9: =H8+F9+G9 -> -16958.41
A10: 45723 | B10: KK 4876 İşbank | E10: =E43 -> -19043.61 | G10: =E10 -> -19043.61 | H10: =H9+F10+G10 -> -36002.02
A11: 45721 | B11: Doğuş Kira 7/12-2025-26 | D11: 15000 | F11: 15000 | H11: =H10+F11+G11 -> -21002.02
A12: 45723 | B12: Kira Adem Özen 10/12 Mrmr Ryl A Blok 82 | E12: -17500 | G12: -17500 | H12: =H11+F12+G12 -> -38502.02
A13: 45734 | B13: Doğalgaz 800004222954 Kümbet D10 | E13: -1000 | G13: -2645 | H13: =H12+F13+G13 -> -41147.02
A14: 45733 | B14: Doğalgaz 800004222959 Kümbet D09 | E14: -200 | G14: -25 | H14: =H13+F14+G14 -> -41172.02
H15: =H14+F15+G15 -> -41172.02
B16: maaş | D16: 15000 | F16: 14994.19 | H16: =H15+F16+G16 -> -26177.83
B17: bayram harçlığı | F17: 3000 | H17: =H16+F17+G17 -> -23177.83
B18: yasemin | E18: -7500 | G18: -9003 | H18: =H17+F18+G18 -> -32180.83
B19: umut | E19: -7500 | G19: -7503 | H19: =H18+F19+G19 -> -39683.83
B20: umut bayram elden | G20: -1400 | H20: =H19+F20+G20 -> -41083.83
B21: Genel Masraf | E21: -7500 | G21: -7500 | H21: =H20+F21+G21 -> -48583.83
H22: =H21+F22+G22 -> -48583.83
H23: =H22+F23+G23 -> -48583.83
A24: 45716 | B24: SANAYI BELEDIYE SAYC UCRETI | C24: 2024 / 8/9 | E24: -1380 | H24: =H23+F24+G24 -> -48583.83
A25: 45744 | B25: Elektrik 5847500300 Kümbet D09 | E25: -600 | G25: -340 | H25: =H24+F25+G25 -> -48923.83
A26: 45744 | B26: Elektrik 8222520300 Kümbet D10 | E26: -800 | G26: -565 | H26: =H25+F26+G26 -> -49488.83
B27: TUSDATA 2025 23/30 70760 - 8845 = 61915 | H27: =H26+F27+G27 -> -49488.83
H28: =H27+F28+G28 -> -49488.83
H29: =H28+F29+G29 -> -49488.83
A30: 45741 | B30: Doğalgaz Marmara Royal Ablok D:82 | E30: -200 | G30: -565.88 | H30: =H29+F30+G30 -> -50054.71
B31: emrullah - ali demirel istinaf | G31: -2800 | H31: =H30+F31+G31 -> -52854.71
A32: 45743 | B32: vodafone 2240 | G32: -213 | H32: =H31+F32+G32 -> -53067.71
A33: 45740 | B33: audi zincir | G33: -8500 | H33: =H32+F33+G33 -> -61567.71
A34: 45740 | B34: audi motor | G34: -90000 | H34: =H33+F34+G34 -> -151567.71
B35: hvl masraf | C35: audi toplam masraf nisan ayı kk hesabı altında | G35: -12.8 | H35: =H34+F35+G35 -> -151580.51
A36: 45728 | B36: elektrikçi adnan işçilik | G36: -1500 | H36: =H35+F36+G36 -> -153080.51
H37: =H36+F37+G37 -> -153080.51
B43: İşbank 4876 KK | E43: =SUM(E44:E61) -> -19043.61
A45: 45715 | B45: turknet 12 aylık internet | C45: 5938.7 | D45: 1 - 6 | E45: -989.78 | F45: 0
A46: 45715 | B46: BELEDİYE sanayi sayaç 5-6 taksitler | E46: -2820 | F46: 0
A47: 45715 | B47: belediye hmb 2024 emlak-su | E47: -3196.34 | F47: 0
...

Sheet 02_25
F1: GİRİŞ | G1: ÇIKIŞ | H1: BAKİYE
A2: - ŞUBAT 2025 | C2: TOPLAM | D2: =SUM(D4:D31) -> 45000 | E2: =SUM(E4:E32) -> -75400.4 | F2: =SUM(F4:F32) -> 30054.88 | G2: =SUM(G4:G32) -> -96628.72 | H2: =F2+G2 -> -66573.84
H4: =H3+F4+G4 -> 0
H5: =H4+F5+G5 -> 0
H6: =H5+F6+G6 -> 0
A7: 45692 | B7: KK 4876 İşbank | E7: =E37 -> 0 | G7: =E7 -> 0 | H7: =H6+F7+G7 -> 0
A8: 45691 | B8: KK 5165 Denizbank | E8: =E52 -> -29103.34 | G8: =E8 -> -29103.34 | H8: =H7+F8+G8 -> -29103.34
A9: 45873 | B9: emrullah özere - ali demirel avukatlık ücreti | G9: -18000 | H9: =H8+F9+G9 -> -47103.34
A10: 45692 | B10: Aidat Marmara Royal Site 9/12 | E10: -2117.06 | G10: -2116.98 | H10: =H9+F10+G10 -> -49220.32
A11: 45699 | B11: Kira Adem Özen 9/12 Mrmr Ryl A Blok 82 | E11: -17500 | G11: -17500 | H11: =H10+F11+G11 -> -66720.32
A12: 45699 | B12: Doğalgaz Marmara Royal Ablok D:82 | E12: -200 | G12: -391.01 | H12: =H11+F12+G12 -> -67111.33
B13: Elektrik 9522138254 Sanayi | E13: 0 | H13: =H12+F13+G13 -> -67111.33
A14: 45705 | B14: Doğuş Kira 6/12-2025-26 | D14: 15000 | F14: 15000 | H14: =H13+F14+G14 -> -52111.33
A15: 45705 | B15: Doğalgaz 800004222954 Kümbet D10 | E15: -1000 | G15: -2305 | H15: =H14+F15+G15 -> -54416.33
A16: 45705 | B16: Doğalgaz 800004222959 Kümbet D09 | E16: -200 | G16: -40 | H16: =H15+F16+G16 -> -54456.33
A17: 45709 | B17: ali demirel ihtar noter msrf için av. Emrullaha havale | G17: -2391.39 | H17: =H16+F17+G17 -> -56847.72
H18: =H17+F18+G18 -> -56847.72
B19: maaş | D19: 15000 | F19: 15054.88 | H19: =H18+F19+G19 -> -41792.84
B20: yasemin | E20: -7500 | G20: -7502 | H20: =H19+F20+G20 -> -49294.84
B21: umut | E21: -7500 | G21: -7502 | H21: =H20+F21+G21 -> -56796.84
B22: Genel Masraf | E22: -7500 | G22: -7502 | H22: =H21+F22+G22 -> -64298.84
H23: =H22+F23+G23 -> -64298.84
H24: =H23+F24+G24 -> -64298.84
A25: 45716 | B25: SANAYI BELEDIYE SAYC UCRETI | C25: 2024 / 7/9 iş kk | E25: -1380 | G25: -1380 | H25: =H24+F25+G25 -> -65678.84
A26: 45716 | B26: Elektrik 5847500300 Kümbet D09 | E26: -600 | G26: -325 | H26: =H25+F26+G26 -> -66003.84
A27: 45716 | B27: Elektrik 8222520300 Kümbet D10 | E27: -800 | G27: -570 | H27: =H26+F27+G27 -> -66573.84
B28: Doğuş Kira 7/12-2025-26 | D28: 15000 | H28: =H27+F28+G28 -> -66573.84
H29: =H28+F29+G29 -> -66573.84
B30: TUSDATA 2025 22/30 79605 - 8845 = 70760 | H30: =H29+F30+G30 -> -66573.84
H31: =H30+F31+G31 -> -66573.84
H32: =H31+F32+G32 -> -66573.84
H35: 15000
G36: 2025 01 tüfe | H36: 0.5635
B37: İşbank 4876 KK | E37: =SUM(E38:E49) -> 0 | H37: =H36*H35 -> 8452.5
E38: HESAP KESİM | G38: doğuş | H38: =SUM(H37+H35) -> 23452.5
B52: Denizbank 5165 kk | E52: =SUM(E53:E98) -> -29103.34
A56: 46018 | B56: cevizli | E56: -135
A57: 46016 | B57: kkasap | E57: -240
A58: 46015 | B58: pideci mustafa | E58: -550
A59: 46020 | B59: pegasus kıbrıs umut mezuniyet peri-atila-hc kysr | E59: -12762 | F59: 0
...

Sheet 01_25
F1: GİRİŞ | G1: ÇIKIŞ | H1: BAKİYE
A2: - OCAK 2025 | C2: TOPLAM | D2: =SUM(D4:D44) -> 398664 | E2: =SUM(E4:E44) -> -55562.4 | F2: =SUM(F4:F44) -> 320054.88 | G2: =SUM(G4:G44) -> -59018.87 | H2: =F2+G2 -> 261036.01
H4: =H3+F4+G4 -> 0
H5: =H4+F5+G5 -> 0
A6: 45660 | B6: SnyB salih ant 16 asgari ücret * 22104 = 353664 | H6: =H5+F6+G6 -> 0
A7: 45660 | B7: SnyB salih ant bankadan | D7: 353664 | F7: 290000 | H7: =H6+F7+G7 -> 290000
B8: umut banka hesabı – hmb hesaba havale – 801 – 209 nazan | H8: =H7+F8+G8 -> 290000
A9: 45660 | B9: KK 4876 İşbank | E9: =E67 -> 0 | G9: =E9 -> 0 | H9: =H8+F9+G9 -> 290000
A10: 45660 | B10: KK 5165 Denizbank | E10: =E82 -> -7885.34 | G10: =E10 -> -7885.34 | H10: =H9+F10+G10 -> 282114.66
H11: =H10+F11+G11 -> 282114.66
B12: Aidat Marmara Royal Site 9/12 | E12: -2117.06 | G12: =E12 -> -2117.06 | H12: =H11+F12+G12 -> 279997.6
B13: Kira Adem Özen 8/12 Mrmr Ryl A Blok 82 | E13: -17500 | G13: =E13 -> -17500 | H13: =H12+F13+G13 -> 262497.6
B14: Elektrik 9522138254 Sanayi | E14: 0 | G14: 0 | H14: =H13+F14+G14 -> 262497.6
A15: 45671 | B15: Doğuş Kira 5/12-2025-26 bankadan | D15: 15000 | F15: 15000 | H15: =H14+F15+G15 -> 277497.6
H16: =H15+F16+G16 -> 277497.6
A17: 45677 | B17: Doğalgaz 800004222954 Kümbet D10 | E17: -1000 | G17: -2390 | H17: =H16+F17+G17 -> 275107.6
A18: 45677 | B18: Doğalgaz 800004222959 Kümbet D09 | E18: -200 | G18: -25 | H18: =H17+F18+G18 -> 275082.6
A19: 45677 | B19: Doğalgaz Marmara Royal Ablok D:82 | E19: -200 | G19: -288.97 | H19: =H18+F19+G19 -> 274793.63
H20: =H19+F20+G20 -> 274793.63
A21: 45684 | B21: yasemin 24 ocak için | G21: -4000 | H21: =H20+F21+G21 -> 270793.63
A22: 45684 | B22: yasemin | E22: -7500 | G22: -7501 | H22: =H21+F22+G22 -> 263292.63
A23: 45684 | B23: umut | E23: -7500 | G23: -7501 | H23: =H22+F23+G23 -> 255791.63
A24: 45684 | B24: Genel Masraf | E24: -7500 | G24: -7500 | H24: =H23+F24+G24 -> 248291.63
A25: 45684 | B25: ahmet alp karne | G25: -1000 | H25: =H24+F25+G25 -> 247291.63
A26: 45655 | B26: SANAYI BELEDIYE SAYC UCRETI | C26: 2024 / 5/9 | E26: -1380 | H26: =H25+F26+G26 -> 247291.63
A27: 45686 | B27: SANAYI BELEDIYE SAYC UCRETI | C27: 2024 / 6/9 | E27: -1380 | H27: =H26+F27+G27 -> 247291.63
A28: 45684 | B28: emlak vergileri İŞ KK İLE ÖDENDİ AYŞE-HMB - PERİ BORC YOK | H28: =H27+F28+G28 -> 247291.63
B29: turknet yıllık internet | C29: dnz kk | H29: =H28+F29+G29 -> 247291.63
H30: =H29+F30+G30 -> 247291.63
A31: 45688 | B31: Elektrik 5847500300 Kümbet D09 | E31: -600 | G31: -425 | H31: =H30+F31+G31 -> 246866.63
A32: 45688 | B32: Elektrik 8222520300 Kümbet D10 | E32: -800 | G32: -680 | H32: =H31+F32+G32 -> 246186.63
A33: 45688 | B33: voda 2240 | G33: -205.5 | H33: =H32+F33+G33 -> 245981.13
B34: Doğuş Kira 6/12-2025-26 | D34: 15000 | H34: =H33+F34+G34 -> 245981.13
B35: maaş | D35: 15000 | F35: 15054.88 | H35: =H34+F35+G35 -> 261036.01
B36: TUSDATA 2025 21/30 1*8595 = 8595-250 = 8345 | H36: =H35+F36+G36 -> 261036.01
H37: =H36+F37+G37 -> 261036.01
B47: TUSDATA 2023 8/30 8*250 = 2000 ÖDENDİ
B48: TUSDATA 2024 9/30 – 20/30 12*250 = 3000 ÖDENDİ + 250 TL fazla ödeme yapıldı
B49: TUSDATA 2025 21/30 1*8595 = 8595
B50: TUSDATA 2025 22/30-30/30 9*8845 = 79605
...

Sheet PERI_24
B2: 2024 | C2: hesaba yazılmayan | D2: hacı ödeme | E2: peri ödeme | F2: BAKİYE
A5: 45291 | B5: 2023 den devir PERİ BORÇLU | F5: 1072
A6: 45306 | B6: aliden kredi için alınan 15/01/2024 taksidi | E6: 3450 | F6: =F5+D6-E6 -> -2378
A7: 45309 | B7: audi mtv 2024-1 | D7: 899 | F7: =F6+D7-E7 -> -1479
A8: 45309 | B8: trafik cezası maliyeden | D8: 1093.65 | F8: =F7+D8-E8 -> -385.35
A9: 45310 | B9: ankaraya giderken nakit (umut) | D9: 1000 | F9: =F8+D9-E9 -> 614.65
A10: 45319 | B10: trafik cezası muhtardan | C10: 713.25 | F10: =F9+D10-E10 -> 614.65
B11: kayseri otobüs bileti | D11: 1200 | F11: =F10+D11-E11 -> 1814.65
A12: 45366 | B12: 1 adet çeyrek | D12: 4100 | F12: =F11+D12-E12 -> 5914.65
A13: 45366 | B13: işbanktan hacıya havale | E13: 6300 | F13: =F12+D13-E13 -> -385.35
A14: 45366 | B14: işbanktan periye havale kred iiçin | D14: 3450 | F14: =F13+D14-E14 -> 3064.65
A15: 45366 | B15: ziraat kredi ödemesi | E15: 3461 | F15: =F14+D15-E15 -> -396.35
A16: 45371 | B16: audi teker porya-yazlık lastik değişimi | C16: 3350 | F16: =F15+D16-E16 -> -396.35
A17: 45412 | B17: panter testere 1/9 | E17: 500 | F17: =F16+D17-E17 -> -896.35
A18: 45398 | B18: işbanktan periye havale kred iiçin | D18: 3467 | E18: 3461 | F18: =F17+D18-E18 -> -890.35
B19: azaerbaycan otel için 240 usd *32 | E19: 7680 | F19: =F18+D19-E19 -> -8570.35
A20: 45427 | B20: ali kredi için -ali bankaya yatırmış | F20: =F19+D20-E20 -> -8570.35
A21: 45442 | B21: panter testere 2/9 | E21: 500 | F21: =F20+D21-E21 -> -9070.35
A22: 45442 | B22: audi kaza için alınan | E22: 120000 | F22: =F21+D22-E22 -> -129070.35
A23: 45442 | B23: audi kaza için harcanan | D23: 21000 | F23: =F22+D23-E23 -> -108070.35
A24: 45458 | B24: aliden kredi için alınan 15/06/2024 taksidi | D24: 3450 | F24: =F23+D24-E24 -> -104620.35
A25: 45458 | B25: ziraate havale kredi için bayram öncesi | E25: 3467 | F25: =F24+D25-E25 -> -108087.35
A26: 45453 | B26: benzin | C26: 1500 | F26: =F25+D26-E26 -> -108087.35
B27: trafik cezaı yıldızeli | C27: 1300 | F27: =F26+D27-E27 -> -108087.35
A28: 45470 | B28: çeyrek 5 ad. 4030 * 5 | D28: 20150 | F28: =F27+D28-E28 -> -87937.35
A29: 45473 | B29: panter testere 3/9 | E29: 500 | F29: =F28+D29-E29 -> -88437.35
A30: 45487 | B30: elden nakit aliden alınan kredi için | D30: 3500 | F30: =F29+D30-E30 -> -84937.35
A31: 45487 | B31: peri ziraat kredi ödemesi taksit 76 | E31: 3465.81 | F31: =F30+D31-E31 -> -88403.16
A32: 45503 | B32: panter testere 4/9 -9/9 6 taksit | E32: 3000 | F32: =F31+D32-E32 -> -91403.16
B33: ARACI ALMADAN ÖNCE HACI BORÇ TOPLAMI | F33: =F32+D33-E33 -> -91403.16
B35: tcross 12-8-2024 | D35: 1466500 | F35: =D35-E35 -> 1466500
B36: sigorta | D36: 11631 | F36: =F35+D36-E36 -> 1478131
B37: kasko | D37: 15500 | F37: =F36+D37-E37 -> 1493631
B38: ARAÇ TOPLAM MALİYET | F38: =F37+D38-E38 -> 1493631
F39: =F38+D39-E39 -> 1493631
B40: ARAÇ ÖNCESİ HESAP | E40: =F33*-1 -> 91403.16 | F40: =F39+D40-E40 -> 1402227.8
B41: TRAFİK SİGORTASI | E41: 11631 | F41: =F40+D41-E41 -> 1390596.8
B42: KASKO 9 taksitte ödenecek peri kk | E42: 15500 | F42: =F41+D42-E42 -> 1375096.8
B43: atiladan yasemine araba için | E43: 100000 | F43: =F42+D43-E43 -> 1275096.8
B44: Yasemin + dersanedwn | E44: 75000 | F44: =F43+D44-E44 -> 1200096.8
...

Sheet cross
E2: gr | F2: 2513
E3: çeyrek | F3: 4100
E4: s1 | F4: 26.15
E5: iş 801
D7: adet | E7: fiyat | F7: tutar | H7: bakiye
A8: gelen | B8: 44562 | C8: 94,25 gr bilezik * 2400 TL/gr (22 ayar) | D8: 94.25 | E8: 2400 | F8: 225000
A9: altın | B9: 44562 | C9: 78 çeyrek * 4200 | D9: 78 | E9: 4200 | F9: 325000
B11: 45509 | C11: iş 801 | D11: 779 | E11: 710.60565 | F11: =E11*D11 -> 553561.8 | G11: =F11 -> 553561.8 | H11: =G11 -> 553561.8
A14: pervin | B14: 45509 | C14: pervin 13 ad çeyrek *4200 benim kasada | D14: 13 | E14: =$F$3 -> 4100 | F14: =E14*D14 -> 53300 | H14: =H11+F14 -> 606861.8
B15: 45357 | C15: pervin 6 ad çeyrek *4200 benim kasada | D15: 6 | E15: =$F$3 -> 4100 | F15: =E15*D15 -> 24600 | H15: =H14+F15 -> 631461.8
C16: pervin 1 ad tam *16200 benim kasada | D16: 1 | E16: 16000 | F16: =E16*D16 -> 16000 | H16: =H15+F16 -> 647461.8
C17: pervin 1 ad gram *2500 benim kasada | D17: 1 | E17: =$F$2 -> 2513 | F17: =E17*D17 -> 2513 | H17: =H16+F17 -> 649974.8
C18: pervin banka 10 kasada | D18: 10 | E18: =$F$3 -> 4100 | F18: =E18*D18 -> 41000 | G18: =SUM(F14:F18) -> 137413 | H18: =H17+F18 -> 690974.8
A20: hacı | B20: 45509 | C20: okul parasından gelecek (nakit) | D20: 1 | E20: 60000 | F20: =E20*D20 -> 60000 | H20: =H18+F20 -> 750974.8
C21: gr altın 5 * 2500 OKUL PARASI KALSIN | D21: 5 | E21: =$F$2 -> 2513 | F21: =E21*D21 -> 12565
C22: gr altın 36 * 2500 (audi) | D22: 32 | E22: =$F$2 -> 2513 | F22: =E22*D22 -> 80416 | H22: =H20+F22 -> 831390.8 | I22: BOZ
C23: gr altın 94 * 2520 | D23: 93 | E23: =$F$2 -> 2513 | F23: =E23*D23 -> 233709 | H23: =H22+F23 -> 1065099.8 | I23: BOZ
C24: dolsr 850 *32 OKUL PARASI KALSIN | D24: 850 | E24: 31 | F24: =E24*D24 -> 26350 | I24: BOZ
C25: s1 25,93*7500 | D25: 7500 | E25: =$F$4 -> 26.15 | F25: =E25*D25 -> 196125 | G25: =SUM(F20:F25) -> 609165 | H25: =H23+F25 -> 1261224.8 | I25: BOZ
A27: yasemin | B27: satıldı | C27: s1 | D27: 471 | E27: =$F$4 -> 26.15 | F27: =E27*D27 -> 12316.65 | H27: =H25+F27 -> 1273541.4 | I27: boz
C28: ytr 801 | D28: 31 | E28: 709 | F28: =E28*D28 -> 21979 | H28: =H27+F28 -> 1295520.4 | I28: ASIL HESAP
B29: satıldı | C29: ytr 808 722 adet deil TL imiş | D29: 30 | E29: 722 | F29: =E29*D29 -> 21660 | H29: =H28+F29 -> 1317180.4 | I29: boz
C30: ytr 812 | D30: 3680 | E30: 0.85 | F30: =E30*D30 -> 3128 | H30: =H29+F30 -> 1320308.4 | I30: KALSIN
B31: satıldı | C31: gr OKUL PARASI KALSIN | D31: 77.3 | E31: =$F$2 -> 2513 | F31: =E31*D31 -> 194254.9 | G31: =SUM(F27:F31) -> 253338.55
H32: =H30+F32 -> 1320308.4
A33: Atila | C33: nakit | F33: 100000 | G33: =F33 -> 100000 | H33: =H32+F33 -> 1420308.4 | I33: GELECEK
A34: Ali | C34: nakit | F34: 68000 | G34: 68000 | H34: =H33+F34 -> 1488308.4 | I34: GELECEK
G42: ÖDEME | J42: KALAN
J43: 1500000
C44: uyasemin iş 801 | F44: 22058 | H44: =H43+F44-G44 -> 22058
A45: yasemin | C45: umut okul parasından umut -> peri > yasemin havale edildi | F45: 155000 | H45: =H44+F45-G45 -> 177058
C46: kaparo için doğuş otoya yaseminden havale | G46: 50000 | H46: =H45+F46-G46 -> 127058 | I46: ÖDENDİ | J46: =J43-G46 -> 1450000
C47: yasemin 808 den gelen | F47: 722 | H47: =H46+F47-G47 -> 127780 | I47: HESAPTA
H48: =H47+F48-G48 -> 127780
H49: =H48+F49-G49 -> 127780
C50: yasemin s1 den gelecek ÇARŞAMBA SATILDI | F50: 12290 | H50: =H49+F50-G50 -> 140070 | I50: GELECEK | J50: =J46-G50 -> 1450000
J51: =J50-H50 -> 1309930
B55: 45509 | C55: hacı iş 801 | D55: 779 | E55: 711.5756 | F55: =E55*D55 -> 554317.39 | H55: =H54+F55-G55 -> 554317.39 | I55: HESAPTA
H56: =H55+F56-G56 -> 554317.39
C57: gr | D57: 125 | E57: 2510 | F57: =E57*D57 -> 313750 | H57: =H56+F57-G57 -> 868067.39 | I57: GELECEK
...

Sheet GNLK-_2024
C1: TAHMİNİ | F1: GERÇEKLEŞEN | K1: NZN | L1: HC | N1: NY
A2: -2024 | B2: GİRİŞ | C2: ÇIKIŞ | D2: BAKİYE | E2: GİRİŞ | F2: ÇIKIŞ | G2: BAKİYE | J2: kR | K2: 0.235384 | L2: =1-K2 -> 0.764616 | M2: Hc 1/1 | N2: =F115/1000 -> 698.2203
A3: Ocak | B3: ='01_24'!D2 -> 340464.6 | C3: ='01_24'!E2 -> -52469.76 | D3: =B3+C3 -> 287994.84 | E3: ='01_24'!F2 -> 194911.58 | F3: ='01_24'!G2 -> -66377.21 | G3: =E3+F3 -> 128534.37 | I3: dgs | J3: 180 | M3: =J3 -> 180 | N3: ='01_24'!E118/1000 -> 813.15151
A4: Şubat | B4: ='02_24'!D2 -> 19300 | C4: ='02_24'!E2 -> -65325.85 | D4: =B4+C4+D3 -> 241968.99 | E4: ='02_24'!F2 -> 20543.64 | F4: ='02_24'!G2 -> -69834.74 | G4: =E4+F4+G3 -> 79243.27 | I4: sF | J4: 235 | K4: =J4*$K$2 -> 55.31524 | L4: =J4-K4 -> 179.68476 | N4: ='02_24'!E111/1000 -> 809.24983
A5: Mart | B5: ='03_24'!D2 -> 12800 | C5: ='03_24'!E2 -> -114592.82 | D5: =B5+C5+D4 -> 140176.17 | E5: ='03_24'!F2 -> 19667.49 | F5: ='03_24'!G2 -> -116144.16 | G5: =E5+F5+G4 -> -17233.4 | I5: tzg | M5: =J5 -> 0 | N5: ='03_24'!E108/1000 -> 745.85205
A6: Nisan | B6: ='04_24'!D2 -> 40000 | C6: ='04_24'!E2 -> -51710.3 | D6: =B6+C6+D5 -> 128465.87 | E6: ='04_24'!F2 -> 332427.62 | F6: ='04_24'!G2 -> -86892.22 | G6: =E6+F6+G5 -> 228302 | I6: maaş ocak-haziran | M6: =E18/1000 -> 68.50557 | N6: ='04_24'!E111/1000 -> 774.28774
A7: Mayıs | B7: ='05_24'!D2 -> 25000 | C7: ='05_24'!E2 -> -64525.01 | D7: =B7+C7+D6 -> 88940.86 | E7: ='05_24'!F2 -> 25427.62 | F7: ='05_24'!G2 -> -64483.92 | G7: =E7+F7+G6 -> 189245.7 | I7: maaş temmuz-aralık | M7: =E19/1000 -> 77.93537 | N7: ='05_24'!E101/1000 -> 1018.9679
A8: Hazrn | B8: ='06_24'!D2 -> 33500 | C8: ='06_24'!E2 -> -77377.564 | D8: =B8+C8+D7 -> 45063.296 | E8: ='06_24'!F2 -> 13427.62 | F8: ='06_24'!G2 -> -97778.154 | G8: =E8+F8+G7 -> 104895.17 | I8: lise | J8: 225 | M8: =J8/4 -> 56.25 | N8: ='06_24'!E118/1000 -> 794.30216
A9: Temmz | B9: ='07_24'!D2 -> 51000 | C9: ='07_24'!E2 -> -85166.06 | D9: =B9+C9+D8 -> 10897.236 | E9: ='07_24'!F2 -> 27984.15 | F9: ='07_24'!G2 -> -87971.62 | G9: =E9+F9+G8 -> 44907.696 | I9: sE | J9: 204 | K9: =J9*$K$2 -> 48.018336 | L9: =J9-K9 -> 155.98166 | N9: ='07_24'!E133/1000 -> 981.30373
A10: Ağusts | B10: ='08_24'!D2 -> 195484.15 | C10: ='08_24'!E2 -> -88440.67 | D10: =B10+C10+D9 -> 117940.72 | E10: ='08_24'!F2 -> 28006.38 | F10: ='08_24'!G2 -> -88381.87 | G10: =E10+F10+G9 -> -15467.794 | I10: ap | J10: 500 | M10: =J10*0.13 -> 65 | N10: ='08_24'!E125/1000 -> 981.30373
A11: Eylül | B11: ='09_24'!D2 -> 36484.15 | C11: ='09_24'!E2 -> -81364.9 | D11: =B11+C11+D10 -> 73059.966 | E11: ='09_24'!F2 -> 98006.38 | F11: ='09_24'!G2 -> -69863.54 | G11: =E11+F11+G10 -> 12675.046 | I11: sG | J11: 0 | K11: =J11*$K$2 -> 0 | L11: =J11-K11 -> 0 | N11: ='09_24'!E101/1000 -> 749.1966
A12: Ekim | B12: ='10_24'!D2 -> 27984.15 | C12: ='10_24'!E2 -> -126233.27 | D12: =B12+C12+D11 -> -25189.154 | E12: ='10_24'!F2 -> 64006.38 | F12: ='10_24'!G2 -> -123041.59 | G12: =E12+F12+G11 -> -46360.164 | I12: sA | J12: 0 | K12: =J12*$K$2 -> 0 | L12: =J12-K12 -> 0 | N12: ='10_24'!E136/1000 -> 726.0586
A13: Kasım | B13: ='11_24'!D2 -> 277984.15 | C13: ='11_24'!E2 -> -182434.39 | D13: =B13+C13+D12 -> 70360.606 | E13: ='11_24'!F2 -> 212306.38 | F13: ='11_24'!G2 -> -220559.32 | G13: =E13+F13+G12 -> -54613.104 | I13: sCD | J13: 219 | K13: =J13*$K$2 -> 51.549096 | L13: =J13-K13 -> 167.4509 | N13: ='11_24'!E111/1000 -> 695.35238
A14: Aralık | B14: ='12_24'!D2 -> 27984.15 | C14: ='12_24'!E2 -> -62202.76 | D14: =B14+C14+D13 -> 36141.996 | E14: ='12_24'!F2 -> 246925.7 | F14: ='12_24'!G2 -> -130909.76 | G14: =E14+F14+G13 -> 61402.836 | I14: sB | J14: 170 | K14: =J14*$K$2 -> 40.01528 | L14: =J14-K14 -> 129.98472 | N14: ='12_24'!E125/1000 -> 676.38338
A15: TPLM | B15: =SUM(B3:B14) -> 1087985.4 | C15: =SUM(C3:C14) -> -1051843.4 | D15: =B15+C15 -> 36141.996 | E15: =SUM(E3:E14) -> 1283640.9 | F15: =SUM(F3:F14) -> -1222238.1 | G15: =E15+F15 -> 61402.836 | J15: =SUM(J3:J14) -> 1733 | K15: =SUM(K4:K14) -> 194.89795 | L15: =SUM(L4:L14) -> 633.10205 | M15: =M10+M8+M6+M5+M3+M7 -> 447.69094
A16: 12 | B16: =B15/A16 -> 90665.446 | C16: =C15/A16 -> -87653.613 | E16: =E15/A16 -> 106970.08 | F16: =F15/A16 -> -101853.18 | G16: =G15/A16 -> 5116.903 | J16: =J15/12 -> 144.41667 | K16: =K15/12 -> 16.241496 | L16: =L15/12 -> 52.758504 | M16: =M15/12 -> 37.307578 | N16: =AVERAGE(N2:N15) -> 804.89461
K17: TPLM | L17: =L15+M15 -> 1080.793
D18: ocak-haziran maaş toplamı | E18: ='01_24'!F27+'02_24'!F14+'02_24'!F25+'03_24'!F19+'04_24'!F41+'05_24'!F22+'06_24'!F19+'06_24'!F31+'04_24'!F15 -> 68505.57 | K18: AYLK | M18: =L17/12 -> 90.066082
D19: temmuz-aralık maaş toplamı | E19: ='07_24'!F30+'08_24'!F25+'09_24'!F19+'10_24'!F29+'11_24'!F34+'12_24'!F22 -> 77935.37
D20: Toplam ;Emekli maaşı | E20: =SUM(E18:E19) -> 146440.94
B21: 44896
B22: 6986.25 | C22: 0.375785 | D22: 0.4925919
B23: =B22*C22 -> 2625.328 | C23: ocak artış % | D23: =B22*D22 -> 3441.3702
B24: =SUM(B22:B23) -> 9611.578 | C24: ocak 23 maaş | D24: =D23+B22 -> 10427.62
C25: =(D27/D24)-1 -> 0.2473009
C26: temmuz artış
C27: temmuz 23 maaş | D27: 13006.38
B30: MAHKEME
C31: DEMİREL ARABULUCULUK
C32: MERDAL TAKİP
B34: FATURA
C35: ELEKTRİK
C36: KREDİ
B37: TZG
C38: ÖLÇÜM
C39: SINIR TESPİTİ
C40: DUVAR VE KAPI YAPIMI
C41: ELEKTRİK-SU ABONE İŞLEMLERİ
C42: ELEKTRİK TESİSAT
B43: BAHÇE
...

Sheet 12_24
F1: GİRİŞ | G1: ÇIKIŞ | H1: BAKİYE
A2: - ARALIK 2024 | C2: TOPLAM | D2: =SUM(D4:D40) -> 27984.15 | E2: =SUM(E4:E41) -> -62202.76 | F2: =SUM(F4:F40) -> 246925.7 | G2: =SUM(G4:G36) -> -130909.76 | H2: =F2+G2 -> 116015.94
H4: =H3+F4+G4 -> 0
A5: 45631 | B5: KK 4876 İşbank | E5: =E76 -> -1797.23 | G5: =E5 -> -1797.23 | H5: =H4+F5+G5 -> -1797.23
A6: 45630 | B6: KK 5165 Denizbank | E6: =E91 -> -9239.03 | G6: =E6 -> -9239.03 | H6: =H5+F6+G6 -> -11036.26
A7: 45630 | B7: Aidat Marmara Royal Site 9/12 | E7: -1500 | G7: -1512.13 | H7: =H6+F7+G7 -> -12548.39
B8: Kira Adem Özen 7/12 Mrmr Ryl A Blok 82 | E8: -17500 | G8: -17500 | H8: =H7+F8+G8 -> -30048.39
B9: Elektrik 9522138254 Sanayi | E9: =E71*-1 -> 0 | H9: =H8+F9+G9 -> -30048.39
H10: =H9+F10+G10 -> -30048.39
A11: 45630 | B11: SANAYI BELEDIYE SAYC UCRETI | C11: 2024 / 3 | D11: dnxkk | E11: -1380 | H11: =H10+F11+G11 -> -30048.39
A12: 45630 | B12: SANAYI BELEDIYE SAYC UCRETI | C12: 2024 / 4 | D12: dnxkk | E12: -1380 | H12: =H11+F12+G12 -> -30048.39
A13: 45630 | B13: BİNA VERGİSİ | D13: dnxkk | E13: -1415 | H13: =H12+F13+G13 -> -30048.39
A14: 45630 | B14: KÜLTÜR VERGİSİ | D14: dnxkk | E14: -141.5 | H14: =H13+F14+G14 -> -30048.39
B15: Nazan Kira ödemesi 12+ | G15: -60000 | H15: =H14+F15+G15 -> -90048.39
B16: umut kiradan | G16: -19000 | H16: =H15+F16+G16 -> -109048.39
B17: snyB Ali Demirel bankadan | F17: 219000 | H17: =H16+F17+G17 -> 109951.61
B18: Doğuş Kira 4/12-2025-26 | F18: 15000 | H18: =H17+F18+G18 -> 124951.61
A19: 45642 | B19: Doğalgaz 800004222954 Kümbet D10 | C19: devlet | E19: -300 | G19: -2035 | H19: =H18+F19+G19 -> 122916.61
