Workbook

Sheet Sheet4
C1: Sanayi_F_95m2_este
C2: Merdal Kipel
C4: 31 Mart 2022 – 30 Mart 2023
C5: Yıllık Ücret | E5: 48000
C6: Ödeme şekli
C7: Nakit 7 ay | E7: 28000
C8: Aylık 5 ay | E8: 4000
C10: KİRA HESAP ÖZETİ
E11: tutar | F11: bakiye
A12: 44650 | C12: 2021-22 kira bedeli | E12: 28000 | F12: =E12 -> 28000
F13: =F12+E13 -> 28000
A14: 44650 | C14: elden nakit 2022-1-7. ay ödemesi | E14: -28000 | F14: =F13+E14 -> 0
A15: 44681 | C15: 5. ay kira 2022-8 | E15: 4000 | F15: =F14+E15 -> 4000
A16: 44681 | C16: 5. ay kira 2022-8 ödemesi 4000 TL | E16: -4000 | F16: =F15+E16 -> 0
C17: Denizlik mermer | E17: 375 | F17: =F16+E17 -> 375
A18: 44711 | C18: 6. ay kira 2022-9 | E18: 4000 | F18: =F17+E18 -> 4375
A19: 44711 | C19: 6. ay kira 2022-9 ödemesi 4000 TL | E19: -4000 | F19: =F18+E19 -> 375
A20: 44742 | C20: 7. ay kira 2022-10 | E20: 4000 | F20: =F19+E20 -> 4375
A21: 44742 | C21: 7. ay kira 2022-10 ödemesi 4000 TL | F21: =F20+E21 -> 4375
C22: ödenmeyen kira farkı temmuz tüfe | D22: 2.37 | E22: =F21*D22/100 -> 103.6875 | F22: =F21+E22 -> 4478.6875
A23: 44772 | C23: 8. ay kira 2022-11 | E23: 4000 | F23: =F22+E23 -> 8478.6875
A24: 44772 | C24: 8. ay kira 2022-11 ödemesi 4000 TL | F24: =F23+E24 -> 8478.6875
C25: ödenmeyen kira farkı 08 tüfe | D25: 1.46 | E25: =F24*D25/100 -> 123.78884 | F25: =F24+E25 -> 8602.4763
A26: 44803 | C26: 9. ay kira 2022-12 | E26: 4000 | F26: =F25+E26 -> 12602.476
A27: 44803 | C27: 9. ay kira 2022-12 ödemesi 4000 TL | F27: =F26+E27 -> 12602.476
C28: ödenmeyen kira farkı 09 tüfe | D28: 3.08 | E28: =F27*D28/100 -> 388.15627 | F28: =F27+E28 -> 12990.633
C30: 2023-2024 kira ödemeleri | F30: =F28+E30 -> 12990.633
A31: 44834 | C31: 10. ay kira 2023-1 | E31: 4000 | F31: =F30+E31 -> 16990.633
A32: 44834 | C32: 10. ay kira 2023-1 ödemesi 4000 TL | F32: =F31+E32 -> 16990.633
C33: ödenmeyen kira farkı 10 tüfe | D33: 3.08 | E33: =F32*D33/100 -> 523.31148 | F33: =F32+E33 -> 17513.944
A34: 44864 | C34: 11. ay kira 2023-2 | E34: 4000 | F34: =F33+E34 -> 21513.944
A35: 44864 | C35: 11. ay kira 2023-2 ödemesi 4000 TL | F35: =F34+E35 -> 21513.944
C36: ödenmeyen kira farkı 11 tüfe | D36: 3.08 | E36: =F35*D36/100 -> 662.62948 | F36: =F35+E36 -> 22176.574
C37: 5 boy 40*40 2 mm profil | E37: 2000 | F37: =F36+E37 -> 24176.574
A38: 44864 | C38: 12. ay kira 2023-3 | F38: =F37+E38 -> 24176.574
A39: 44864 | C39: 12. ay kira 2023-3 ödemesi 4000 TL | E39: 4000 | F39: =F38+E39 -> 28176.574
C40: ödenmeyen kira farkı 12 tüfe | D40: 3.08 | E40: =F39*D40/100 -> 867.83847 | F40: =F39+E40 -> 29044.412
A42: 2022-23 yılı yapılan ödemelere göre oturma süresi
A43: 44650 | B43: 1 | C43: Ödendi 28000/4 = 7 ay kirası
A44: 44681 | B44: 2 | C44: ödendi
...

Sheet Senet Borçlu Alacaklı Giriş
B1: Alacaklı Adı Soyadı / Unvanı
B2: İl | C2: TOKAT
A4: BORÇLU | B4: Kişilik | C4: Gerçek Kişi
B5: Adı Soyadı / Unvanı | C5: Emre AKTAŞ
B6: Adresi
B7: Vergi Dairesi | C7: Tokat
B8: Vergi No/TC Kimlik No | C8: 251 4497 7278
A9: KEFİL | B9: Adı Soyadı / Unvanı
B10: Adresi
B11: Vergi Dairesi
B12: Vergi No/TC Kimlik No

Sheet Senet Taksit Giriş
B2: Senet No | C2: Düzenleme Tarihi | D2: Vade Tarihi | E2: Tutarı Rakamla | F2: Tutarı Yazıyla | G2: Borcun Nedeni | H2: Senet Mühteviyatı
A3: 3 | B3: 1 | C3: 44419 | E3: 28000 | F3: =PROPER(IF(IF(LEN(SUBSTITUTE(ROUND(E3,2), ",", ""))=LEN(ROUND(E3,2)),ROUND(E3,2),TRIM(LEFT(ROUND(E3,2),FIND(",",ROUND(E3,2))-1)))*1>=10^6,CHOOSE(LEFT(RIGHT(IF(LEN(SUBSTITUTE(ROUND(E3,2), ",", ""))=LEN(ROUND(E3,2)),ROUND(E3,2),TRIM(LEFT(ROUND(E3,2),FIND(",",ROUND(E3,2))-1)))*1,7),1)+1,"","birmilyon","ikimilyon","üçmilyon","dörtmilyon","beşmilyon","altımilyon","yedimilyon","sekizmilyon","dokuzmilyon"),"")&IF(IF(LEN(SUBSTITUTE(ROUND(E3,2), ",", ""))=LEN(ROUND(E3,2)),ROUND(E3,2),TRIM(LEFT(ROUND(E3,2),FIND(",",ROUND(E3,2))-1)))*1>=10^5,CHOOSE(LEFT(RIGHT(IF(LEN(SUBSTITUTE(ROUND(E3,2), ",", ""))=LEN(ROUND(E3,2)),ROUND(E3,2),TRIM(LEFT(ROUND(E3,2),FIND(",",ROUND(E3,2))-1)))*1,6),1)+1,"","yüz","ikiyüz","üçyüz","dörtyüz","beşyüz","altıyüz","yediyüz","sekizyüz","dokuzyüz"),"")&IF(IF(LEN(SUBSTITUTE(ROUND(E3,2), ",", ""))=LEN(ROUND(E3,2)),ROUND(E3,2),TRIM(LEFT(ROUND(E3,2),FIND(",",ROUND(E3,2))-1)))*1>=10^4,CHOOSE(LEFT(RIGHT(IF(LEN(SUBSTITUTE(ROUND(E3,2), ",", ""))=LEN(ROUND(E3,2)),ROUND(E3,2),TRIM(LEFT(ROUND(E3,2),FIND(",",ROUND(E3,2))-1)))*1,5),1)+1,"","on","yirmi","otuz","kırk","elli","altmış","yetmiş","seksen","doksan"),"")&IF(IF(LEN(SUBSTITUTE(ROUND(E3,2), ",", ""))=LEN(ROUND(E3,2)),ROUND(E3,2),TRIM(LEFT(ROUND(E3,2),FIND(",",ROUND(E3,2))-1)))*1>=10^3,CHOOSE(LEFT(RIGHT(IF(LEN(SUBSTITUTE(ROUND(E3,2), ",", ""))=LEN(ROUND(E3,2)),ROUND(E3,2),TRIM(LEFT(ROUND(E3,2),FIND(",",ROUND(E3,2))-1)))*1,4),1)+1,"","","iki","üç","dört","beş","altı","yedi","sekiz","dokuz"),"")&IF(AND(IF(LEN(SUBSTITUTE(ROUND(E3,2), ",", ""))=LEN(ROUND(E3,2)),ROUND(E3,2),TRIM(LEFT(ROUND(E3,2),FIND(",",ROUND(E3,2))-1)))*1>=10^3,VALUE(LEFT(RIGHT(IF(LEN(SUBSTITUTE(ROUND(E3,2), ",", ""))=LEN(ROUND(E3,2)),ROUND(E3,2),TRIM(LEFT(ROUND(E3,2),FIND(",",ROUND(E3,2))-1)))*1,6),3))>0),IF(AND(IF(LEN(SUBSTITUTE(ROUND(E3,2), ",", ""))=LEN(ROUND(E3,2)),ROUND(E3,2),TRIM(LEFT(ROUND(E3,2),FIND(",",ROUND(E3,2))-1)))*1>1999,LEFT(RIGHT(IF(LEN(SUBSTITUTE(ROUND(E3,2), ",", ""))=LEN(ROUND(E3,2)),ROUND(E3,2),TRIM(LEFT(ROUND(E3,2),FIND(",",ROUND(E3,2))-1)))*1,4),1)="1",LEFT(RIGHT(IF(LEN(SUBSTITUTE(ROUND(E3,2), ",", ""))=LEN(ROUND(E3,2)),ROUND(E3,2),TRIM(LEFT(ROUND(E3,2),FIND(",",ROUND(E3,2))-1)))*1,6),2)<>"00"),"birbin","bin"),"")&IF(IF(LEN(SUBSTITUTE(ROUND(E3,2), ",", ""))=LEN(ROUND(E3,2)),ROUND(E3,2),TRIM(LEFT(ROUND(E3,2),FIND(",",ROUND(E3,2))-1)))*1>=100,CHOOSE(LEFT(RIGHT(IF(LEN(SUBSTITUTE(ROUND(E3,2), ",", ""))=LEN(ROUND(E3,2)),ROUND(E3,2),TRIM(LEFT(ROUND(E3,2),FIND(",",ROUND(E3,2))-1)))*1,3),1)+1,"","yüz","ikiyüz","üçyüz","dörtyüz","beşyüz","altıyüz","yediyüz","sekizyüz","dokuzyüz"),"")&IF(IF(LEN(SUBSTITUTE(ROUND(E3,2), ",", ""))=LEN(ROUND(E3,2)),ROUND(E3,2),TRIM(LEFT(ROUND(E3,2),FIND(",",ROUND(E3,2))-1)))*1>=10,CHOOSE(LEFT(RIGHT(IF(LEN(SUBSTITUTE(ROUND(E3,2), ",", ""))=LEN(ROUND(E3,2)),ROUND(E3,2),TRIM(LEFT(ROUND(E3,2),FIND(",",ROUND(E3,2))-1)))*1,2),1)+1,"","on","yirmi","otuz","kırk","elli","altmış","yetmiş","seksen","doksan"),"")&CHOOSE(MOD(IF(LEN(SUBSTITUTE(ROUND(E3,2), ",", ""))=LEN(ROUND(E3,2)),ROUND(E3,2),TRIM(LEFT(ROUND(E3,2),FIND(",",ROUND(E3,2))-1)))*1,10)+1,"","bir","iki","üç","dört","beş","altı","yedi","sekiz","dokuz")) & " TL " & IF(OR(LEN(SUBSTITUTE(E3, ",", ""))=LEN(E3),LEN(SUBSTITUTE(ROUND(E3,2), ",", ""))=LEN(ROUND(E3,2))),"", PROPER(IF(IF(LEN(TRIM(RIGHT(ROUND(E3,2),LEN(ROUND(E3,2))-FIND(",",ROUND(E3,2)))))<2,TRIM(RIGHT(ROUND(E3,2),LEN(ROUND(E3,2))-FIND(",",ROUND(E3,2))))*10,TRIM(RIGHT(ROUND(E3,2),LEN(ROUND(E3,2))-FIND(",",ROUND(E3,2))))*1)>=10^5,CHOOSE(LEFT(RIGHT(IF(LEN(TRIM(RIGHT(ROUND(E3,2),LEN(ROUND(E3,2))-FIND(",",ROUND(E3,2)))))<2,TRIM(RIGHT(ROUND(E3,2),LEN(ROUND(E3,2))-FIND(",",ROUND(E3,2))))*10,TRIM(RIGHT(ROUND(E3,2),LEN(ROUND(E3,2))-FIND(",",ROUND(E3,2))))*1),6),1)+1,"","yüz","ikiyüz","üçyüz","dörtyüz","beşyüz","altıyüz","yediyüz","sekizyüz","dokuzyüz"),"")&IF(IF(LEN(TRIM(RIGHT(ROUND(E3,2),LEN(ROUND(E3,2))-FIND(",",ROUND(E3,2)))))<2,TRIM(RIGHT(ROUND(E3,2),LEN(ROUND(E3,2))-FIND(",",ROUND(E3,2))))*10,TRIM(RIGHT(ROUND(E3,2),LEN(ROUND(E3,2))-FIND(",",ROUND(E3,2))))*1)>=10^4,CHOOSE(LEFT(RIGHT(IF(LEN(TRIM(RIGHT(ROUND(E3,2),LEN(ROUND(E3,2))-FIND(",",ROUND(E3,2)))))<2,TRIM(RIGHT(ROUND(E3,2),LEN(ROUND(E3,2))-FIND(",",ROUND(E3,2))))*10,TRIM(RIGHT(ROUND(E3,2),LEN(ROUND(E3,2))-FIND(",",ROUND(E3,2))))*1),5),1)+1,"","on","yirmi","otuz","kırk","elli","altmış","yetmiş","seksen","doksan"),"")&IF(IF(LEN(TRIM(RIGHT(ROUND(E3,2),LEN(ROUND(E3,2))-FIND(",",ROUND(E3,2)))))<2,TRIM(RIGHT(ROUND(E3,2),LEN(ROUND(E3,2))-FIND(",",ROUND(E3,2))))*10,TRIM(RIGHT(ROUND(E3,2),LEN(ROUND(E3,2))-FIND(",",ROUND(E3,2))))*1)>=10^3,CHOOSE(LEFT(RIGHT(IF(LEN(TRIM(RIGHT(ROUND(E3,2),LEN(ROUND(E3,2))-FIND(",",ROUND(E3,2)))))<2,TRIM(RIGHT(ROUND(E3,2),LEN(ROUND(E3,2))-FIND(",",ROUND(E3,2))))*10,TRIM(RIGHT(ROUND(E3,2),LEN(ROUND(E3,2))-FIND(",",ROUND(E3,2))))*1),4),1)+1,"","","iki","üç","dört","beş","altı","yedi","sekiz","dokuz"),"")&IF(IF(LEN(TRIM(RIGHT(ROUND(E3,2),LEN(ROUND(E3,2))-FIND(",",ROUND(E3,2)))))<2,TRIM(RIGHT(ROUND(E3,2),LEN(ROUND(E3,2))-FIND(",",ROUND(E3,2))))*10,TRIM(RIGHT(ROUND(E3,2),LEN(ROUND(E3,2))-FIND(",",ROUND(E3,2))))*1)>=10,CHOOSE(LEFT(RIGHT(IF(LEN(TRIM(RIGHT(ROUND(E3,2),LEN(ROUND(E3,2))-FIND(",",ROUND(E3,2)))))<2,TRIM(RIGHT(ROUND(E3,2),LEN(ROUND(E3,2))-FIND(",",ROUND(E3,2))))*10,TRIM(RIGHT(ROUND(E3,2),LEN(ROUND(E3,2))-FIND(",",ROUND(E3,2))))*1),2),1)+1,"","on","yirmi","otuz","kırk","elli","altmış","yetmiş","seksen","doksan"),"")&CHOOSE(MOD(IF(LEN(TRIM(RIGHT(ROUND(E3,2),LEN(ROUND(E3,2))-FIND(",",ROUND(E3,2)))))<2,TRIM(RIGHT(ROUND(E3,2),LEN(ROUND(E3,2))-FIND(",",ROUND(E3,2))))*10,TRIM(RIGHT(ROUND(E3,2),LEN(ROUND(E3,2))-FIND(",",ROUND(E3,2))))*1),10)+1,"","bir","iki","üç","dört","beş","altı","yedi","sekiz","dokuz")) & " Krş") -> Yirmisekizbin TL | G3: nakden | H3: 1. Taksit
B4: 2 | C4: 44252 | D4: 44316 | F4: =PROPER(IF(IF(LEN(SUBSTITUTE(ROUND(E4,2), ",", ""))=LEN(ROUND(E4,2)),ROUND(E4,2),TRIM(LEFT(ROUND(E4,2),FIND(",",ROUND(E4,2))-1)))*1>=10^6,CHOOSE(LEFT(RIGHT(IF(LEN(SUBSTITUTE(ROUND(E4,2), ",", ""))=LEN(ROUND(E4,2)),ROUND(E4,2),TRIM(LEFT(ROUND(E4,2),FIND(",",ROUND(E4,2))-1)))*1,7),1)+1,"","birmilyon","ikimilyon","üçmilyon","dörtmilyon","beşmilyon","altımilyon","yedimilyon","sekizmilyon","dokuzmilyon"),"")&IF(IF(LEN(SUBSTITUTE(ROUND(E4,2), ",", ""))=LEN(ROUND(E4,2)),ROUND(E4,2),TRIM(LEFT(ROUND(E4,2),FIND(",",ROUND(E4,2))-1)))*1>=10^5,CHOOSE(LEFT(RIGHT(IF(LEN(SUBSTITUTE(ROUND(E4,2), ",", ""))=LEN(ROUND(E4,2)),ROUND(E4,2),TRIM(LEFT(ROUND(E4,2),FIND(",",ROUND(E4,2))-1)))*1,6),1)+1,"","yüz","ikiyüz","üçyüz","dörtyüz","beşyüz","altıyüz","yediyüz","sekizyüz","dokuzyüz"),"")&IF(IF(LEN(SUBSTITUTE(ROUND(E4,2), ",", ""))=LEN(ROUND(E4,2)),ROUND(E4,2),TRIM(LEFT(ROUND(E4,2),FIND(",",ROUND(E4,2))-1)))*1>=10^4,CHOOSE(LEFT(RIGHT(IF(LEN(SUBSTITUTE(ROUND(E4,2), ",", ""))=LEN(ROUND(E4,2)),ROUND(E4,2),TRIM(LEFT(ROUND(E4,2),FIND(",",ROUND(E4,2))-1)))*1,5),1)+1,"","on","yirmi","otuz","kırk","elli","altmış","yetmiş","seksen","doksan"),"")&IF(IF(LEN(SUBSTITUTE(ROUND(E4,2), ",", ""))=LEN(ROUND(E4,2)),ROUND(E4,2),TRIM(LEFT(ROUND(E4,2),FIND(",",ROUND(E4,2))-1)))*1>=10^3,CHOOSE(LEFT(RIGHT(IF(LEN(SUBSTITUTE(ROUND(E4,2), ",", ""))=LEN(ROUND(E4,2)),ROUND(E4,2),TRIM(LEFT(ROUND(E4,2),FIND(",",ROUND(E4,2))-1)))*1,4),1)+1,"","","iki","üç","dört","beş","altı","yedi","sekiz","dokuz"),"")&IF(AND(IF(LEN(SUBSTITUTE(ROUND(E4,2), ",", ""))=LEN(ROUND(E4,2)),ROUND(E4,2),TRIM(LEFT(ROUND(E4,2),FIND(",",ROUND(E4,2))-1)))*1>=10^3,VALUE(LEFT(RIGHT(IF(LEN(SUBSTITUTE(ROUND(E4,2), ",", ""))=LEN(ROUND(E4,2)),ROUND(E4,2),TRIM(LEFT(ROUND(E4,2),FIND(",",ROUND(E4,2))-1)))*1,6),3))>0),IF(AND(IF(LEN(SUBSTITUTE(ROUND(E4,2), ",", ""))=LEN(ROUND(E4,2)),ROUND(E4,2),TRIM(LEFT(ROUND(E4,2),FIND(",",ROUND(E4,2))-1)))*1>1999,LEFT(RIGHT(IF(LEN(SUBSTITUTE(ROUND(E4,2), ",", ""))=LEN(ROUND(E4,2)),ROUND(E4,2),TRIM(LEFT(ROUND(E4,2),FIND(",",ROUND(E4,2))-1)))*1,4),1)="1",LEFT(RIGHT(IF(LEN(SUBSTITUTE(ROUND(E4,2), ",", ""))=LEN(ROUND(E4,2)),ROUND(E4,2),TRIM(LEFT(ROUND(E4,2),FIND(",",ROUND(E4,2))-1)))*1,6),2)<>"00"),"birbin","bin"),"")&IF(IF(LEN(SUBSTITUTE(ROUND(E4,2), ",", ""))=LEN(ROUND(E4,2)),ROUND(E4,2),TRIM(LEFT(ROUND(E4,2),FIND(",",ROUND(E4,2))-1)))*1>=100,CHOOSE(LEFT(RIGHT(IF(LEN(SUBSTITUTE(ROUND(E4,2), ",", ""))=LEN(ROUND(E4,2)),ROUND(E4,2),TRIM(LEFT(ROUND(E4,2),FIND(",",ROUND(E4,2))-1)))*1,3),1)+1,"","yüz","ikiyüz","üçyüz","dörtyüz","beşyüz","altıyüz","yediyüz","sekizyüz","dokuzyüz"),"")&IF(IF(LEN(SUBSTITUTE(ROUND(E4,2), ",", ""))=LEN(ROUND(E4,2)),ROUND(E4,2),TRIM(LEFT(ROUND(E4,2),FIND(",",ROUND(E4,2))-1)))*1>=10,CHOOSE(LEFT(RIGHT(IF(LEN(SUBSTITUTE(ROUND(E4,2), ",", ""))=LEN(ROUND(E4,2)),ROUND(E4,2),TRIM(LEFT(ROUND(E4,2),FIND(",",ROUND(E4,2))-1)))*1,2),1)+1,"","on","yirmi","otuz","kırk","elli","altmış","yetmiş","seksen","doksan"),"")&CHOOSE(MOD(IF(LEN(SUBSTITUTE(ROUND(E4,2), ",", ""))=LEN(ROUND(E4,2)),ROUND(E4,2),TRIM(LEFT(ROUND(E4,2),FIND(",",ROUND(E4,2))-1)))*1,10)+1,"","bir","iki","üç","dört","beş","altı","yedi","sekiz","dokuz")) & " TL " & IF(OR(LEN(SUBSTITUTE(E4, ",", ""))=LEN(E4),LEN(SUBSTITUTE(ROUND(E4,2), ",", ""))=LEN(ROUND(E4,2))),"", PROPER(IF(IF(LEN(TRIM(RIGHT(ROUND(E4,2),LEN(ROUND(E4,2))-FIND(",",ROUND(E4,2)))))<2,TRIM(RIGHT(ROUND(E4,2),LEN(ROUND(E4,2))-FIND(",",ROUND(E4,2))))*10,TRIM(RIGHT(ROUND(E4,2),LEN(ROUND(E4,2))-FIND(",",ROUND(E4,2))))*1)>=10^5,CHOOSE(LEFT(RIGHT(IF(LEN(TRIM(RIGHT(ROUND(E4,2),LEN(ROUND(E4,2))-FIND(",",ROUND(E4,2)))))<2,TRIM(RIGHT(ROUND(E4,2),LEN(ROUND(E4,2))-FIND(",",ROUND(E4,2))))*10,TRIM(RIGHT(ROUND(E4,2),LEN(ROUND(E4,2))-FIND(",",ROUND(E4,2))))*1),6),1)+1,"","yüz","ikiyüz","üçyüz","dörtyüz","beşyüz","altıyüz","yediyüz","sekizyüz","dokuzyüz"),"")&IF(IF(LEN(TRIM(RIGHT(ROUND(E4,2),LEN(ROUND(E4,2))-FIND(",",ROUND(E4,2)))))<2,TRIM(RIGHT(ROUND(E4,2),LEN(ROUND(E4,2))-FIND(",",ROUND(E4,2))))*10,TRIM(RIGHT(ROUND(E4,2),LEN(ROUND(E4,2))-FIND(",",ROUND(E4,2))))*1)>=10^4,CHOOSE(LEFT(RIGHT(IF(LEN(TRIM(RIGHT(ROUND(E4,2),LEN(ROUND(E4,2))-FIND(",",ROUND(E4,2)))))<2,TRIM(RIGHT(ROUND(E4,2),LEN(ROUND(E4,2))-FIND(",",ROUND(E4,2))))*10,TRIM(RIGHT(ROUND(E4,2),LEN(ROUND(E4,2))-FIND(",",ROUND(E4,2))))*1),5),1)+1,"","on","yirmi","otuz","kırk","elli","altmış","yetmiş","seksen","doksan"),"")&IF(IF(LEN(TRIM(RIGHT(ROUND(E4,2),LEN(ROUND(E4,2))-FIND(",",ROUND(E4,2)))))<2,TRIM(RIGHT(ROUND(E4,2),LEN(ROUND(E4,2))-FIND(",",ROUND(E4,2))))*10,TRIM(RIGHT(ROUND(E4,2),LEN(ROUND(E4,2))-FIND(",",ROUND(E4,2))))*1)>=10^3,CHOOSE(LEFT(RIGHT(IF(LEN(TRIM(RIGHT(ROUND(E4,2),LEN(ROUND(E4,2))-FIND(",",ROUND(E4,2)))))<2,TRIM(RIGHT(ROUND(E4,2),LEN(ROUND(E4,2))-FIND(",",ROUND(E4,2))))*10,TRIM(RIGHT(ROUND(E4,2),LEN(ROUND(E4,2))-FIND(",",ROUND(E4,2))))*1),4),1)+1,"","","iki","üç","dört","beş","altı","yedi","sekiz","dokuz"),"")&IF(IF(LEN(TRIM(RIGHT(ROUND(E4,2),LEN(ROUND(E4,2))-FIND(",",ROUND(E4,2)))))<2,TRIM(RIGHT(ROUND(E4,2),LEN(ROUND(E4,2))-FIND(",",ROUND(E4,2))))*10,TRIM(RIGHT(ROUND(E4,2),LEN(ROUND(E4,2))-FIND(",",ROUND(E4,2))))*1)>=10,CHOOSE(LEFT(RIGHT(IF(LEN(TRIM(RIGHT(ROUND(E4,2),LEN(ROUND(E4,2))-FIND(",",ROUND(E4,2)))))<2,TRIM(RIGHT(ROUND(E4,2),LEN(ROUND(E4,2))-FIND(",",ROUND(E4,2))))*10,TRIM(RIGHT(ROUND(E4,2),LEN(ROUND(E4,2))-FIND(",",ROUND(E4,2))))*1),2),1)+1,"","on","yirmi","otuz","kırk","elli","altmış","yetmiş","seksen","doksan"),"")&CHOOSE(MOD(IF(LEN(TRIM(RIGHT(ROUND(E4,2),LEN(ROUND(E4,2))-FIND(",",ROUND(E4,2)))))<2,TRIM(RIGHT(ROUND(E4,2),LEN(ROUND(E4,2))-FIND(",",ROUND(E4,2))))*10,TRIM(RIGHT(ROUND(E4,2),LEN(ROUND(E4,2))-FIND(",",ROUND(E4,2))))*1),10)+1,"","bir","iki","üç","dört","beş","altı","yedi","sekiz","dokuz")) & " Kr") -> TL | G4: =G3 -> nakden | H4: 2. Taksit

Sheet Senet Önizleme
C3: =$H17 &" - Taksit No: " & $J5&" " -> Emre AKTAŞ - Taksit No: - 1 -
F4: VADE | H4: TÜRK LIRASI | J4: No | L4: DÜZENLEME TARIHI
F5: ='Senet Taksit Giriş'!D3 | H5: ="# "&TEXT(('Senet Taksit Giriş'!E3),"#.##0,00")&" TL #" -> # 28.000,00 TL # | J5: ="- "&TEXT(INT('Senet Taksit Giriş'!B3),"##.##0")&" -" -> - 1 - | L5: ='Senet Taksit Giriş'!C3 -> 44419
F8: =" İş bu emre muharrer senedim"&IF('Senet Borçlu Alacaklı Giriş'!$C$4="Gerçek Kişi","in","izin")&" mükabilinde "&IF(TEXT(F5,"dd mmmm yyyy")=" "," ",TEXT(F5,"dd mmmm yyyy"))&" tarihinde; Sayın : "&IF('Senet Borçlu Alacaklı Giriş'!$C$1=""," ",'Senet Borçlu Alacaklı Giriş'!$C$1)&" veyahut emruhavalesine yukarıda yazılı Yalnız # "&'Senet Taksit Giriş'!F3&" # kayıtsız ve şartsız ödemeyi vaadederi"&IF('Senet Borçlu Alacaklı Giriş'!$C$4="Gerçek Kişi","m.","z.")&" Bedeli "&'Senet Taksit Giriş'!G3&" ahzolunmuştur. İş bu bono vadesinde ödenmediği taktirde; iş bu bononun düzenleme tarihinin temerrüt başlangıç tarihi olarak kabul edileceğini, müteakip bonolarında muacceliyet kesbedeceğini,"&" ihtilaf vukuunda "&'Senet Borçlu Alacaklı Giriş'!$C$2&" mahkemelerinin selahiyetini şimdiden kabul eyleri"&IF('Senet Borçlu Alacaklı Giriş'!$C$4="Gerçek Kişi","m.","z.") -> İş bu emre muharrer senedimin mükabilinde tarihinde; Sayın : veyahut emruhavalesine yukarıda yazılı Yalnız # Yirmisekizbin TL # kayıtsız ve şartsız ödemeyi vaadederim. Bedeli nakden ahzolunmuştur. İş bu bono vadesinde ödenmediği taktirde; iş bu bononun düzenleme tarihinin temerrüt başlangıç tarihi olarak kabul edileceğini, müteakip bonolarında muacceliyet kesbedeceğini, ihtilaf vukuunda TOKAT mahkemelerinin selahiyetini şimdiden kabul eylerim.
F17: Borçlu İsim-Unvan | G17: : | H17: ='Senet Borçlu Alacaklı Giriş'!C5 -> Emre AKTAŞ
F18: Tc Kimlik No | G18: : | H18: ='Senet Borçlu Alacaklı Giriş'!$C$8 -> 251 4497 7278
F19: Adres | J19: İmza
F20: ='Senet Borçlu Alacaklı Giriş'!$C$6 -> 0
F24: ="Vergi Dairesi " -> Vergi Dairesi | G24: : | H24: ='Senet Borçlu Alacaklı Giriş'!$C$7 -> Tokat
F26: KEFİL İsim Unvan | G26: : | H26: ='Senet Borçlu Alacaklı Giriş'!$C$9
F27: TC Kimlik No | G27: : | H27: ='Senet Borçlu Alacaklı Giriş'!$C$12
F28: Adres | J28: İmza
F29: ='Senet Borçlu Alacaklı Giriş'!$C$10
F33: ="Vergi Dairesi " -> Vergi Dairesi | H33: ='Senet Borçlu Alacaklı Giriş'!$C$11
C39: =$H53 &" - Taksit No: " & $J41&" " -> 0 - Taksit No: 2
F40: VADE | H40: TÜRK LIRASI | J40: No | L40: DÜZENLEME TARIHI
F41: ='Senet Taksit Giriş'!D4 -> 44316 | H41: ='Senet Taksit Giriş'!E4 -> 0 | J41: ='Senet Taksit Giriş'!B4 -> 2 | L41: ='Senet Taksit Giriş'!C4 -> 44252
F44: =" İş bu emre muharrer senedim"&IF('Senet Borçlu Alacaklı Giriş'!$C$4="Gerçek Kişi","in","izin")&" mükabilinde "&IF(TEXT(F41,"dd mmmm yyyy")=" "," ",TEXT(F41,"dd mmmm yyyy"))&" tarihinde; Sayın : "&IF('Senet Borçlu Alacaklı Giriş'!$C$1=""," ",'Senet Borçlu Alacaklı Giriş'!$C$1)&" veyahut emruhavalesine yukarıda yazılı Yalnız # "&'Senet Taksit Giriş'!F40&" # kayıtsız ve şartsız ödemeyi vaadederi"&IF('Senet Borçlu Alacaklı Giriş'!$C$4="Gerçek Kişi","m.","z.")&" Bedeli "&'Senet Taksit Giriş'!G40&" ahzolunmuştur. İş bu bono vadesinde ödenmediği taktirde; iş bu bononun düzenleme tarihinin temerrüt başlangıç tarihi olarak kabul edileceğini, müteakip bonolarında muacceliyet kesbedeceğini,"&" ihtilaf vukuunda "&'Senet Borçlu Alacaklı Giriş'!$C$2&" mahkemelerinin selahiyetini şimdiden kabul eyleri"&IF('Senet Borçlu Alacaklı Giriş'!$C$4="Gerçek Kişi","m.","z.") -> İş bu emre muharrer senedimin mükabilinde 00 mmmm 2021 tarihinde; Sayın : veyahut emruhavalesine yukarıda yazılı Yalnız # # kayıtsız ve şartsız ödemeyi vaadederim. Bedeli ahzolunmuştur. İş bu bono vadesinde ödenmediği taktirde; iş bu bononun düzenleme tarihinin temerrüt başlangıç tarihi olarak kabul edileceğini, müteakip bonolarında muacceliyet kesbedeceğini, ihtilaf vukuunda TOKAT mahkemelerinin selahiyetini şimdiden kabul eylerim.
F53: Borçlu İsim-Unvan | G53: : | H53: ='Senet Borçlu Alacaklı Giriş'!C42 -> 0
F54: Tc Kimlik No | G54: : | H54: ='Senet Borçlu Alacaklı Giriş'!$C$8 -> 251 4497 7278
F55: Adres | J55: İmza
F56: ='Senet Borçlu Alacaklı Giriş'!$C$6 -> 0
F60: ="Vergi Dairesi " -> Vergi Dairesi | G60: : | H60: ='Senet Borçlu Alacaklı Giriş'!$C$7 -> Tokat
F62: KEFİL İsim Unvan | G62: : | H62: ='Senet Borçlu Alacaklı Giriş'!$C$9
F63: TC Kimlik No | G63: : | H63: ='Senet Borçlu Alacaklı Giriş'!$C$12
F64: Adres | J64: İmza
F65: ='Senet Borçlu Alacaklı Giriş'!$C$10
F69: ="Vergi Dairesi " -> Vergi Dairesi | H69: ='Senet Borçlu Alacaklı Giriş'!$C$11

Sheet Sheet5
B3: ödenecek teminat | C3: 1500 | D3: =C3 -> 1500
A4: 44692 | B4: 4. ay elektrik | C4: 209.53 | D4: =D3+C4 -> 1709.53
B5: 4. ay elektrik ödeme | C5: -230.48 | D5: =D4+C5 -> 1479.05
A6: 44723 | B6: 5. ay elektrik | C6: 236.48 | D6: =D5+C6 -> 1715.53
B7: 5. ay elektrik ödeme | C7: -445.63 | D7: =D6+C7 -> 1269.9
A8: 44753 | B8: 6. ay elektrik | C8: 443.01 | D8: =D7+C8 -> 1712.91
B9: 6. ay elektrik ödeme | C9: -465.16 | D9: =D8+C9 -> 1247.75
A10: 44784 | B10: 7. ay elektrik | C10: 465.05 | D10: =D9+C10 -> 1712.8
B11: 7. ay elektrik ödeme | C11: -488.3 | D11: =D10+C11 -> 1224.5
A12: 44815 | B12: 8. ay elektrik | C12: 842.85 | D12: =D11+C12 -> 2067.35
B13: 8. ay elektrik ödeme | C13: -904.99 | D13: =D12+C13 -> 1162.36
A14: 44845 | B14: 9. ay elektrik | C14: 787.33 | D14: =D13+C14 -> 1949.69
B15: 9. ay elektrik ödeme | C15: -846.7 | D15: =D14+C15 -> 1102.99
A16: 44876 | B16: 10. ay elektrik | D16: =D15+C16 -> 1102.99
B17: 10. ay elektrik ödeme | D17: =D16+C17 -> 1102.99
