Workbook

Sheet Sheet4
B2: Sinan ÇELİK
C4: HESAP ÖZETİ
F5: tutar | G5: bakiye
C6: 01-01-2026 / 31-12-2026
C7: 2026 kira bedeli | F7: 420000 | G7: =F7 -> 420000
C8: ilk 2 ay | F8: -60000 | G8: =G7+F8 -> 360000
C9: indirim | F9: -60000 | G9: =G8+F9 -> 300000
B10: 46045 | C10: ilk ödeme | D10: 2026 3-4-5 | F10: -90000 | G10: =G9+F10 -> 210000
A11: 1 | B11: 46111 | C11: Senet 30000 TL | D11: 2026-6
A12: 2 | B12: 46142 | C12: Senet 30000 TL | D12: 2026-7
A13: 3 | B13: 46172 | C13: Senet 30000 TL | D13: 2026-8
A14: 4 | B14: 46203 | C14: Senet 30000 TL | D14: 2026-9
A15: 5 | B15: 46233 | C15: Senet 30000 TL | D15: 2026-10
A16: 6 | B16: 46264 | C16: Senet 30000 TL | D16: 2026-11
A17: 7 | B17: 46295 | C17: Senet 30000 TL | D17: 2026-12
C18: 2027 kira bedeli | F18: 420000+tüfe artışı
A19: 8 | B19: 46325 | D19: 2027-1
A20: 9 | B20: 46356 | D20: 2027-2
A21: 10 | B21: 46386 | D21: 2027-3
A22: 11 | B22: 46417 | D22: 2027-4
A23: 12 | B23: 46446 | D23: 2027-5
A24: 13 | B24: 46476 | D24: 2027-6
A25: 14 | B25: 46507 | D25: 2027-7
A26: 15 | B26: 46537 | D26: 2027-8
A27: 16 | B27: 46568 | D27: 2027-9
A28: 17 | B28: 46598 | D28: 2027-10
A29: 18 | B29: 46629 | D29: 2027-11
A30: 19 | B30: 46660 | D30: 2027-12

Sheet Senet Borçlu Alacaklı Giriş
B1: Alacaklı Adı Soyadı / Unvanı | C1: HACI MURAT BALCI
B2: İl | C2: TOKAT
A4: BORÇLU | B4: Kişilik | C4: Tüzel Kişi
B5: Adı Soyadı / Unvanı | C5: Bursa Fabrika Satış Mağazası – Adem Duman
B6: Adresi | C6: Hızarhane Cad. No:5 TOKAT
B7: Vergi Dairesi | C7: Tokat
B8: Vergi No/TC Kimlik No | C8: 341 3267 6260
A9: KEFİL | B9: Adı Soyadı / Unvanı | C9: Adem Duman
B10: Adresi | C10: Esentepe Mah. Şehit Ulaşar Cad. Belde Sitesi B Blk. K1: D:3 TOKAT
B11: Vergi Dairesi | C11: Tokat
B12: Vergi No/TC Kimlik No | C12: 341 3267 6260

Sheet Senet Taksit Giriş
B2: Senet No | C2: Düzenleme Tarihi | D2: Vade Tarihi | E2: Tutarı Rakamla | F2: Tutarı Yazıyla | G2: Borcun Nedeni | H2: Senet Mühteviyatı
A3: 3 | B3: 1 | C3: 44252 | D3: 44285 | E3: 2000 | F3: =PROPER(IF(IF(LEN(SUBSTITUTE(ROUND(E3,2), ",", ""))=LEN(ROUND(E3,2)),ROUND(E3,2),TRIM(LEFT(ROUND(E3,2),FIND(",",ROUND(E3,2))-1)))*1>=10^6,CHOOSE(LEFT(RIGHT(IF(LEN(SUBSTITUTE(ROUND(E3,2), ",", ""))=LEN(ROUND(E3,2)),ROUND(E3,2),TRIM(LEFT(ROUND(E3,2),FIND(",",ROUND(E3,2))-1)))*1,7),1)+1,"","birmilyon","ikimilyon","üçmilyon","dörtmilyon","beşmilyon","altımilyon","yedimilyon","sekizmilyon","dokuzmilyon"),"")&IF(IF(LEN(SUBSTITUTE(ROUND(E3,2), ",", ""))=LEN(ROUND(E3,2)),ROUND(E3,2),TRIM(LEFT(ROUND(E3,2),FIND(",",ROUND(E3,2))-1)))*1>=10^5,CHOOSE(LEFT(RIGHT(IF(LEN(SUBSTITUTE(ROUND(E3,2), ",", ""))=LEN(ROUND(E3,2)),ROUND(E3,2),TRIM(LEFT(ROUND(E3,2),FIND(",",ROUND(E3,2))-1)))*1,6),1)+1,"","yüz","ikiyüz","üçyüz","dörtyüz","beşyüz","altıyüz","yediyüz","sekizyüz","dokuzyüz"),"")&IF(IF(LEN(SUBSTITUTE(ROUND(E3,2), ",", ""))=LEN(ROUND(E3,2)),ROUND(E3,2),TRIM(LEFT(ROUND(E3,2),FIND(",",ROUND(E3,2))-1)))*1>=10^4,CHOOSE(LEFT(RIGHT(IF(LEN(SUBSTITUTE(ROUND(E3,2), ",", ""))=LEN(ROUND(E3,2)),ROUND(E3,2),TRIM(LEFT(ROUND(E3,2),FIND(",",ROUND(E3,2))-1)))*1,5),1)+1,"","on","yirmi","otuz","kırk","elli","altmış","yetmiş","seksen","doksan"),"")&IF(IF(LEN(SUBSTITUTE(ROUND(E3,2), ",", ""))=LEN(ROUND(E3,2)),ROUND(E3,2),TRIM(LEFT(ROUND(E3,2),FIND(",",ROUND(E3,2))-1)))*1>=10^3,CHOOSE(LEFT(RIGHT(IF(LEN(SUBSTITUTE(ROUND(E3,2), ",", ""))=LEN(ROUND(E3,2)),ROUND(E3,2),TRIM(LEFT(ROUND(E3,2),FIND(",",ROUND(E3,2))-1)))*1,4),1)+1,"","","iki","üç","dört","beş","altı","yedi","sekiz","dokuz"),"")&IF(AND(IF(LEN(SUBSTITUTE(ROUND(E3,2), ",", ""))=LEN(ROUND(E3,2)),ROUND(E3,2),TRIM(LEFT(ROUND(E3,2),FIND(",",ROUND(E3,2))-1)))*1>=10^3,VALUE(LEFT(RIGHT(IF(LEN(SUBSTITUTE(ROUND(E3,2), ",", ""))=LEN(ROUND(E3,2)),ROUND(E3,2),TRIM(LEFT(ROUND(E3,2),FIND(",",ROUND(E3,2))-1)))*1,6),3))>0),IF(AND(IF(LEN(SUBSTITUTE(ROUND(E3,2), ",", ""))=LEN(ROUND(E3,2)),ROUND(E3,2),TRIM(LEFT(ROUND(E3,2),FIND(",",ROUND(E3,2))-1)))*1>1999,LEFT(RIGHT(IF(LEN(SUBSTITUTE(ROUND(E3,2), ",", ""))=LEN(ROUND(E3,2)),ROUND(E3,2),TRIM(LEFT(ROUND(E3,2),FIND(",",ROUND(E3,2))-1)))*1,4),1)="1",LEFT(RIGHT(IF(LEN(SUBSTITUTE(ROUND(E3,2), ",", ""))=LEN(ROUND(E3,2)),ROUND(E3,2),TRIM(LEFT(ROUND(E3,2),FIND(",",ROUND(E3,2))-1)))*1,6),2)<>"00"),"birbin","bin"),"")&IF(IF(LEN(SUBSTITUTE(ROUND(E3,2), ",", ""))=LEN(ROUND(E3,2)),ROUND(E3,2),TRIM(LEFT(ROUND(E3,2),FIND(",",ROUND(E3,2))-1)))*1>=100,CHOOSE(LEFT(RIGHT(IF(LEN(SUBSTITUTE(ROUND(E3,2), ",", ""))=LEN(ROUND(E3,2)),ROUND(E3,2),TRIM(LEFT(ROUND(E3,2),FIND(",",ROUND(E3,2))-1)))*1,3),1)+1,"","yüz","ikiyüz","üçyüz","dörtyüz","beşyüz","altıyüz","yediyüz","sekizyüz","dokuzyüz"),"")&IF(IF(LEN(SUBSTITUTE(ROUND(E3,2), ",", ""))=LEN(ROUND(E3,2)),ROUND(E3,2),TRIM(LEFT(ROUND(E3,2),FIND(",",ROUND(E3,2))-1)))*1>=10,CHOOSE(LEFT(RIGHT(IF(LEN(SUBSTITUTE(ROUND(E3,2), ",", ""))=LEN(ROUND(E3,2)),ROUND(E3,2),TRIM(LEFT(ROUND(E3,2),FIND(",",ROUND(E3,2))-1)))*1,2),1)+1,"","on","yirmi","otuz","kırk","elli","altmış","yetmiş","seksen","doksan"),"")&CHOOSE(MOD(IF(LEN(SUBSTITUTE(ROUND(E3,2), ",", ""))=LEN(ROUND(E3,2)),ROUND(E3,2),TRIM(LEFT(ROUND(E3,2),FIND(",",ROUND(E3,2))-1)))*1,10)+1,"","bir","iki","üç","dört","beş","altı","yedi","sekiz","dokuz")) & " TL " & IF(OR(LEN(SUBSTITUTE(E3, ",", ""))=LEN(E3),LEN(SUBSTITUTE(ROUND(E3,2), ",", ""))=LEN(ROUND(E3,2))),"", PROPER(IF(IF(LEN(TRIM(RIGHT(ROUND(E3,2),LEN(ROUND(E3,2))-FIND(",",ROUND(E3,2)))))<2,TRIM(RIGHT(ROUND(E3,2),LEN(ROUND(E3,2))-FIND(",",ROUND(E3,2))))*10,TRIM(RIGHT(ROUND(E3,2),LEN(ROUND(E3,2))-FIND(",",ROUND(E3,2))))*1)>=10^5,CHOOSE(LEFT(RIGHT(IF(LEN(TRIM(RIGHT(ROUND(E3,2),LEN(ROUND(E3,2))-FIND(",",ROUND(E3,2)))))<2,TRIM(RIGHT(ROUND(E3,2),LEN(ROUND(E3,2))-FIND(",",ROUND(E3,2))))*10,TRIM(RIGHT(ROUND(E3,2),LEN(ROUND(E3,2))-FIND(",",ROUND(E3,2))))*1),6),1)+1,"","yüz","ikiyüz","üçyüz","dörtyüz","beşyüz","altıyüz","yediyüz","sekizyüz","dokuzyüz"),"")&IF(IF(LEN(TRIM(RIGHT(ROUND(E3,2),LEN(ROUND(E3,2))-FIND(",",ROUND(E3,2)))))<2,TRIM(RIGHT(ROUND(E3,2),LEN(ROUND(E3,2))-FIND(",",ROUND(E3,2))))*10,TRIM(RIGHT(ROUND(E3,2),LEN(ROUND(E3,2))-FIND(",",ROUND(E3,2))))*1)>=10^4,CHOOSE(LEFT(RIGHT(IF(LEN(TRIM(RIGHT(ROUND(E3,2),LEN(ROUND(E3,2))-FIND(",",ROUND(E3,2)))))<2,TRIM(RIGHT(ROUND(E3,2),LEN(ROUND(E3,2))-FIND(",",ROUND(E3,2))))*10,TRIM(RIGHT(ROUND(E3,2),LEN(ROUND(E3,2))-FIND(",",ROUND(E3,2))))*1),5),1)+1,"","on","yirmi","otuz","kırk","elli","altmış","yetmiş","seksen","doksan"),"")&IF(IF(LEN(TRIM(RIGHT(ROUND(E3,2),LEN(ROUND(E3,2))-FIND(",",ROUND(E3,2)))))<2,TRIM(RIGHT(ROUND(E3,2),LEN(ROUND(E3,2))-FIND(",",ROUND(E3,2))))*10,TRIM(RIGHT(ROUND(E3,2),LEN(ROUND(E3,2))-FIND(",",ROUND(E3,2))))*1)>=10^3,CHOOSE(LEFT(RIGHT(IF(LEN(TRIM(RIGHT(ROUND(E3,2),LEN(ROUND(E3,2))-FIND(",",ROUND(E3,2)))))<2,TRIM(RIGHT(ROUND(E3,2),LEN(ROUND(E3,2))-FIND(",",ROUND(E3,2))))*10,TRIM(RIGHT(ROUND(E3,2),LEN(ROUND(E3,2))-FIND(",",ROUND(E3,2))))*1),4),1)+1,"","","iki","üç","dört","beş","altı","yedi","sekiz","dokuz"),"")&IF(IF(LEN(TRIM(RIGHT(ROUND(E3,2),LEN(ROUND(E3,2))-FIND(",",ROUND(E3,2)))))<2,TRIM(RIGHT(ROUND(E3,2),LEN(ROUND(E3,2))-FIND(",",ROUND(E3,2))))*10,TRIM(RIGHT(ROUND(E3,2),LEN(ROUND(E3,2))-FIND(",",ROUND(E3,2))))*1)>=10,CHOOSE(LEFT(RIGHT(IF(LEN(TRIM(RIGHT(ROUND(E3,2),LEN(ROUND(E3,2))-FIND(",",ROUND(E3,2)))))<2,TRIM(RIGHT(ROUND(E3,2),LEN(ROUND(E3,2))-FIND(",",ROUND(E3,2))))*10,TRIM(RIGHT(ROUND(E3,2),LEN(ROUND(E3,2))-FIND(",",ROUND(E3,2))))*1),2),1)+1,"","on","yirmi","otuz","kırk","elli","altmış","yetmiş","seksen","doksan"),"")&CHOOSE(MOD(IF(LEN(TRIM(RIGHT(ROUND(E3,2),LEN(ROUND(E3,2))-FIND(",",ROUND(E3,2)))))<2,TRIM(RIGHT(ROUND(E3,2),LEN(ROUND(E3,2))-FIND(",",ROUND(E3,2))))*10,TRIM(RIGHT(ROUND(E3,2),LEN(ROUND(E3,2))-FIND(",",ROUND(E3,2))))*1),10)+1,"","bir","iki","üç","dört","beş","altı","yedi","sekiz","dokuz")) & " Kr") -> İkibin TL | G3: NAKDEN | H3: 1. Taksit
B4: 2 | C4: 44252 | D4: 44316 | E4: 2000 | F4: =PROPER(IF(IF(LEN(SUBSTITUTE(ROUND(E4,2), ",", ""))=LEN(ROUND(E4,2)),ROUND(E4,2),TRIM(LEFT(ROUND(E4,2),FIND(",",ROUND(E4,2))-1)))*1>=10^6,CHOOSE(LEFT(RIGHT(IF(LEN(SUBSTITUTE(ROUND(E4,2), ",", ""))=LEN(ROUND(E4,2)),ROUND(E4,2),TRIM(LEFT(ROUND(E4,2),FIND(",",ROUND(E4,2))-1)))*1,7),1)+1,"","birmilyon","ikimilyon","üçmilyon","dörtmilyon","beşmilyon","altımilyon","yedimilyon","sekizmilyon","dokuzmilyon"),"")&IF(IF(LEN(SUBSTITUTE(ROUND(E4,2), ",", ""))=LEN(ROUND(E4,2)),ROUND(E4,2),TRIM(LEFT(ROUND(E4,2),FIND(",",ROUND(E4,2))-1)))*1>=10^5,CHOOSE(LEFT(RIGHT(IF(LEN(SUBSTITUTE(ROUND(E4,2), ",", ""))=LEN(ROUND(E4,2)),ROUND(E4,2),TRIM(LEFT(ROUND(E4,2),FIND(",",ROUND(E4,2))-1)))*1,6),1)+1,"","yüz","ikiyüz","üçyüz","dörtyüz","beşyüz","altıyüz","yediyüz","sekizyüz","dokuzyüz"),"")&IF(IF(LEN(SUBSTITUTE(ROUND(E4,2), ",", ""))=LEN(ROUND(E4,2)),ROUND(E4,2),TRIM(LEFT(ROUND(E4,2),FIND(",",ROUND(E4,2))-1)))*1>=10^4,CHOOSE(LEFT(RIGHT(IF(LEN(SUBSTITUTE(ROUND(E4,2), ",", ""))=LEN(ROUND(E4,2)),ROUND(E4,2),TRIM(LEFT(ROUND(E4,2),FIND(",",ROUND(E4,2))-1)))*1,5),1)+1,"","on","yirmi","otuz","kırk","elli","altmış","yetmiş","seksen","doksan"),"")&IF(IF(LEN(SUBSTITUTE(ROUND(E4,2), ",", ""))=LEN(ROUND(E4,2)),ROUND(E4,2),TRIM(LEFT(ROUND(E4,2),FIND(",",ROUND(E4,2))-1)))*1>=10^3,CHOOSE(LEFT(RIGHT(IF(LEN(SUBSTITUTE(ROUND(E4,2), ",", ""))=LEN(ROUND(E4,2)),ROUND(E4,2),TRIM(LEFT(ROUND(E4,2),FIND(",",ROUND(E4,2))-1)))*1,4),1)+1,"","","iki","üç","dört","beş","altı","yedi","sekiz","dokuz"),"")&IF(AND(IF(LEN(SUBSTITUTE(ROUND(E4,2), ",", ""))=LEN(ROUND(E4,2)),ROUND(E4,2),TRIM(LEFT(ROUND(E4,2),FIND(",",ROUND(E4,2))-1)))*1>=10^3,VALUE(LEFT(RIGHT(IF(LEN(SUBSTITUTE(ROUND(E4,2), ",", ""))=LEN(ROUND(E4,2)),ROUND(E4,2),TRIM(LEFT(ROUND(E4,2),FIND(",",ROUND(E4,2))-1)))*1,6),3))>0),IF(AND(IF(LEN(SUBSTITUTE(ROUND(E4,2), ",", ""))=LEN(ROUND(E4,2)),ROUND(E4,2),TRIM(LEFT(ROUND(E4,2),FIND(",",ROUND(E4,2))-1)))*1>1999,LEFT(RIGHT(IF(LEN(SUBSTITUTE(ROUND(E4,2), ",", ""))=LEN(ROUND(E4,2)),ROUND(E4,2),TRIM(LEFT(ROUND(E4,2),FIND(",",ROUND(E4,2))-1)))*1,4),1)="1",LEFT(RIGHT(IF(LEN(SUBSTITUTE(ROUND(E4,2), ",", ""))=LEN(ROUND(E4,2)),ROUND(E4,2),TRIM(LEFT(ROUND(E4,2),FIND(",",ROUND(E4,2))-1)))*1,6),2)<>"00"),"birbin","bin"),"")&IF(IF(LEN(SUBSTITUTE(ROUND(E4,2), ",", ""))=LEN(ROUND(E4,2)),ROUND(E4,2),TRIM(LEFT(ROUND(E4,2),FIND(",",ROUND(E4,2))-1)))*1>=100,CHOOSE(LEFT(RIGHT(IF(LEN(SUBSTITUTE(ROUND(E4,2), ",", ""))=LEN(ROUND(E4,2)),ROUND(E4,2),TRIM(LEFT(ROUND(E4,2),FIND(",",ROUND(E4,2))-1)))*1,3),1)+1,"","yüz","ikiyüz","üçyüz","dörtyüz","beşyüz","altıyüz","yediyüz","sekizyüz","dokuzyüz"),"")&IF(IF(LEN(SUBSTITUTE(ROUND(E4,2), ",", ""))=LEN(ROUND(E4,2)),ROUND(E4,2),TRIM(LEFT(ROUND(E4,2),FIND(",",ROUND(E4,2))-1)))*1>=10,CHOOSE(LEFT(RIGHT(IF(LEN(SUBSTITUTE(ROUND(E4,2), ",", ""))=LEN(ROUND(E4,2)),ROUND(E4,2),TRIM(LEFT(ROUND(E4,2),FIND(",",ROUND(E4,2))-1)))*1,2),1)+1,"","on","yirmi","otuz","kırk","elli","altmış","yetmiş","seksen","doksan"),"")&CHOOSE(MOD(IF(LEN(SUBSTITUTE(ROUND(E4,2), ",", ""))=LEN(ROUND(E4,2)),ROUND(E4,2),TRIM(LEFT(ROUND(E4,2),FIND(",",ROUND(E4,2))-1)))*1,10)+1,"","bir","iki","üç","dört","beş","altı","yedi","sekiz","dokuz")) & " TL " & IF(OR(LEN(SUBSTITUTE(E4, ",", ""))=LEN(E4),LEN(SUBSTITUTE(ROUND(E4,2), ",", ""))=LEN(ROUND(E4,2))),"", PROPER(IF(IF(LEN(TRIM(RIGHT(ROUND(E4,2),LEN(ROUND(E4,2))-FIND(",",ROUND(E4,2)))))<2,TRIM(RIGHT(ROUND(E4,2),LEN(ROUND(E4,2))-FIND(",",ROUND(E4,2))))*10,TRIM(RIGHT(ROUND(E4,2),LEN(ROUND(E4,2))-FIND(",",ROUND(E4,2))))*1)>=10^5,CHOOSE(LEFT(RIGHT(IF(LEN(TRIM(RIGHT(ROUND(E4,2),LEN(ROUND(E4,2))-FIND(",",ROUND(E4,2)))))<2,TRIM(RIGHT(ROUND(E4,2),LEN(ROUND(E4,2))-FIND(",",ROUND(E4,2))))*10,TRIM(RIGHT(ROUND(E4,2),LEN(ROUND(E4,2))-FIND(",",ROUND(E4,2))))*1),6),1)+1,"","yüz","ikiyüz","üçyüz","dörtyüz","beşyüz","altıyüz","yediyüz","sekizyüz","dokuzyüz"),"")&IF(IF(LEN(TRIM(RIGHT(ROUND(E4,2),LEN(ROUND(E4,2))-FIND(",",ROUND(E4,2)))))<2,TRIM(RIGHT(ROUND(E4,2),LEN(ROUND(E4,2))-FIND(",",ROUND(E4,2))))*10,TRIM(RIGHT(ROUND(E4,2),LEN(ROUND(E4,2))-FIND(",",ROUND(E4,2))))*1)>=10^4,CHOOSE(LEFT(RIGHT(IF(LEN(TRIM(RIGHT(ROUND(E4,2),LEN(ROUND(E4,2))-FIND(",",ROUND(E4,2)))))<2,TRIM(RIGHT(ROUND(E4,2),LEN(ROUND(E4,2))-FIND(",",ROUND(E4,2))))*10,TRIM(RIGHT(ROUND(E4,2),LEN(ROUND(E4,2))-FIND(",",ROUND(E4,2))))*1),5),1)+1,"","on","yirmi","otuz","kırk","elli","altmış","yetmiş","seksen","doksan"),"")&IF(IF(LEN(TRIM(RIGHT(ROUND(E4,2),LEN(ROUND(E4,2))-FIND(",",ROUND(E4,2)))))<2,TRIM(RIGHT(ROUND(E4,2),LEN(ROUND(E4,2))-FIND(",",ROUND(E4,2))))*10,TRIM(RIGHT(ROUND(E4,2),LEN(ROUND(E4,2))-FIND(",",ROUND(E4,2))))*1)>=10^3,CHOOSE(LEFT(RIGHT(IF(LEN(TRIM(RIGHT(ROUND(E4,2),LEN(ROUND(E4,2))-FIND(",",ROUND(E4,2)))))<2,TRIM(RIGHT(ROUND(E4,2),LEN(ROUND(E4,2))-FIND(",",ROUND(E4,2))))*10,TRIM(RIGHT(ROUND(E4,2),LEN(ROUND(E4,2))-FIND(",",ROUND(E4,2))))*1),4),1)+1,"","","iki","üç","dört","beş","altı","yedi","sekiz","dokuz"),"")&IF(IF(LEN(TRIM(RIGHT(ROUND(E4,2),LEN(ROUND(E4,2))-FIND(",",ROUND(E4,2)))))<2,TRIM(RIGHT(ROUND(E4,2),LEN(ROUND(E4,2))-FIND(",",ROUND(E4,2))))*10,TRIM(RIGHT(ROUND(E4,2),LEN(ROUND(E4,2))-FIND(",",ROUND(E4,2))))*1)>=10,CHOOSE(LEFT(RIGHT(IF(LEN(TRIM(RIGHT(ROUND(E4,2),LEN(ROUND(E4,2))-FIND(",",ROUND(E4,2)))))<2,TRIM(RIGHT(ROUND(E4,2),LEN(ROUND(E4,2))-FIND(",",ROUND(E4,2))))*10,TRIM(RIGHT(ROUND(E4,2),LEN(ROUND(E4,2))-FIND(",",ROUND(E4,2))))*1),2),1)+1,"","on","yirmi","otuz","kırk","elli","altmış","yetmiş","seksen","doksan"),"")&CHOOSE(MOD(IF(LEN(TRIM(RIGHT(ROUND(E4,2),LEN(ROUND(E4,2))-FIND(",",ROUND(E4,2)))))<2,TRIM(RIGHT(ROUND(E4,2),LEN(ROUND(E4,2))-FIND(",",ROUND(E4,2))))*10,TRIM(RIGHT(ROUND(E4,2),LEN(ROUND(E4,2))-FIND(",",ROUND(E4,2))))*1),10)+1,"","bir","iki","üç","dört","beş","altı","yedi","sekiz","dokuz")) & " Kr") -> İkibin TL | G4: =G3 -> NAKDEN | H4: 2. Taksit
B5: 3 | C5: 44252 | D5: 44346 | E5: 2000 | F5: =PROPER(IF(IF(LEN(SUBSTITUTE(ROUND(E5,2), ",", ""))=LEN(ROUND(E5,2)),ROUND(E5,2),TRIM(LEFT(ROUND(E5,2),FIND(",",ROUND(E5,2))-1)))*1>=10^6,CHOOSE(LEFT(RIGHT(IF(LEN(SUBSTITUTE(ROUND(E5,2), ",", ""))=LEN(ROUND(E5,2)),ROUND(E5,2),TRIM(LEFT(ROUND(E5,2),FIND(",",ROUND(E5,2))-1)))*1,7),1)+1,"","birmilyon","ikimilyon","üçmilyon","dörtmilyon","beşmilyon","altımilyon","yedimilyon","sekizmilyon","dokuzmilyon"),"")&IF(IF(LEN(SUBSTITUTE(ROUND(E5,2), ",", ""))=LEN(ROUND(E5,2)),ROUND(E5,2),TRIM(LEFT(ROUND(E5,2),FIND(",",ROUND(E5,2))-1)))*1>=10^5,CHOOSE(LEFT(RIGHT(IF(LEN(SUBSTITUTE(ROUND(E5,2), ",", ""))=LEN(ROUND(E5,2)),ROUND(E5,2),TRIM(LEFT(ROUND(E5,2),FIND(",",ROUND(E5,2))-1)))*1,6),1)+1,"","yüz","ikiyüz","üçyüz","dörtyüz","beşyüz","altıyüz","yediyüz","sekizyüz","dokuzyüz"),"")&IF(IF(LEN(SUBSTITUTE(ROUND(E5,2), ",", ""))=LEN(ROUND(E5,2)),ROUND(E5,2),TRIM(LEFT(ROUND(E5,2),FIND(",",ROUND(E5,2))-1)))*1>=10^4,CHOOSE(LEFT(RIGHT(IF(LEN(SUBSTITUTE(ROUND(E5,2), ",", ""))=LEN(ROUND(E5,2)),ROUND(E5,2),TRIM(LEFT(ROUND(E5,2),FIND(",",ROUND(E5,2))-1)))*1,5),1)+1,"","on","yirmi","otuz","kırk","elli","altmış","yetmiş","seksen","doksan"),"")&IF(IF(LEN(SUBSTITUTE(ROUND(E5,2), ",", ""))=LEN(ROUND(E5,2)),ROUND(E5,2),TRIM(LEFT(ROUND(E5,2),FIND(",",ROUND(E5,2))-1)))*1>=10^3,CHOOSE(LEFT(RIGHT(IF(LEN(SUBSTITUTE(ROUND(E5,2), ",", ""))=LEN(ROUND(E5,2)),ROUND(E5,2),TRIM(LEFT(ROUND(E5,2),FIND(",",ROUND(E5,2))-1)))*1,4),1)+1,"","","iki","üç","dört","beş","altı","yedi","sekiz","dokuz"),"")&IF(AND(IF(LEN(SUBSTITUTE(ROUND(E5,2), ",", ""))=LEN(ROUND(E5,2)),ROUND(E5,2),TRIM(LEFT(ROUND(E5,2),FIND(",",ROUND(E5,2))-1)))*1>=10^3,VALUE(LEFT(RIGHT(IF(LEN(SUBSTITUTE(ROUND(E5,2), ",", ""))=LEN(ROUND(E5,2)),ROUND(E5,2),TRIM(LEFT(ROUND(E5,2),FIND(",",ROUND(E5,2))-1)))*1,6),3))>0),IF(AND(IF(LEN(SUBSTITUTE(ROUND(E5,2), ",", ""))=LEN(ROUND(E5,2)),ROUND(E5,2),TRIM(LEFT(ROUND(E5,2),FIND(",",ROUND(E5,2))-1)))*1>1999,LEFT(RIGHT(IF(LEN(SUBSTITUTE(ROUND(E5,2), ",", ""))=LEN(ROUND(E5,2)),ROUND(E5,2),TRIM(LEFT(ROUND(E5,2),FIND(",",ROUND(E5,2))-1)))*1,4),1)="1",LEFT(RIGHT(IF(LEN(SUBSTITUTE(ROUND(E5,2), ",", ""))=LEN(ROUND(E5,2)),ROUND(E5,2),TRIM(LEFT(ROUND(E5,2),FIND(",",ROUND(E5,2))-1)))*1,6),2)<>"00"),"birbin","bin"),"")&IF(IF(LEN(SUBSTITUTE(ROUND(E5,2), ",", ""))=LEN(ROUND(E5,2)),ROUND(E5,2),TRIM(LEFT(ROUND(E5,2),FIND(",",ROUND(E5,2))-1)))*1>=100,CHOOSE(LEFT(RIGHT(IF(LEN(SUBSTITUTE(ROUND(E5,2), ",", ""))=LEN(ROUND(E5,2)),ROUND(E5,2),TRIM(LEFT(ROUND(E5,2),FIND(",",ROUND(E5,2))-1)))*1,3),1)+1,"","yüz","ikiyüz","üçyüz","dörtyüz","beşyüz","altıyüz","yediyüz","sekizyüz","dokuzyüz"),"")&IF(IF(LEN(SUBSTITUTE(ROUND(E5,2), ",", ""))=LEN(ROUND(E5,2)),ROUND(E5,2),TRIM(LEFT(ROUND(E5,2),FIND(",",ROUND(E5,2))-1)))*1>=10,CHOOSE(LEFT(RIGHT(IF(LEN(SUBSTITUTE(ROUND(E5,2), ",", ""))=LEN(ROUND(E5,2)),ROUND(E5,2),TRIM(LEFT(ROUND(E5,2),FIND(",",ROUND(E5,2))-1)))*1,2),1)+1,"","on","yirmi","otuz","kırk","elli","altmış","yetmiş","seksen","doksan"),"")&CHOOSE(MOD(IF(LEN(SUBSTITUTE(ROUND(E5,2), ",", ""))=LEN(ROUND(E5,2)),ROUND(E5,2),TRIM(LEFT(ROUND(E5,2),FIND(",",ROUND(E5,2))-1)))*1,10)+1,"","bir","iki","üç","dört","beş","altı","yedi","sekiz","dokuz")) & " TL " & IF(OR(LEN(SUBSTITUTE(E5, ",", ""))=LEN(E5),LEN(SUBSTITUTE(ROUND(E5,2), ",", ""))=LEN(ROUND(E5,2))),"", PROPER(IF(IF(LEN(TRIM(RIGHT(ROUND(E5,2),LEN(ROUND(E5,2))-FIND(",",ROUND(E5,2)))))<2,TRIM(RIGHT(ROUND(E5,2),LEN(ROUND(E5,2))-FIND(",",ROUND(E5,2))))*10,TRIM(RIGHT(ROUND(E5,2),LEN(ROUND(E5,2))-FIND(",",ROUND(E5,2))))*1)>=10^5,CHOOSE(LEFT(RIGHT(IF(LEN(TRIM(RIGHT(ROUND(E5,2),LEN(ROUND(E5,2))-FIND(",",ROUND(E5,2)))))<2,TRIM(RIGHT(ROUND(E5,2),LEN(ROUND(E5,2))-FIND(",",ROUND(E5,2))))*10,TRIM(RIGHT(ROUND(E5,2),LEN(ROUND(E5,2))-FIND(",",ROUND(E5,2))))*1),6),1)+1,"","yüz","ikiyüz","üçyüz","dörtyüz","beşyüz","altıyüz","yediyüz","sekizyüz","dokuzyüz"),"")&IF(IF(LEN(TRIM(RIGHT(ROUND(E5,2),LEN(ROUND(E5,2))-FIND(",",ROUND(E5,2)))))<2,TRIM(RIGHT(ROUND(E5,2),LEN(ROUND(E5,2))-FIND(",",ROUND(E5,2))))*10,TRIM(RIGHT(ROUND(E5,2),LEN(ROUND(E5,2))-FIND(",",ROUND(E5,2))))*1)>=10^4,CHOOSE(LEFT(RIGHT(IF(LEN(TRIM(RIGHT(ROUND(E5,2),LEN(ROUND(E5,2))-FIND(",",ROUND(E5,2)))))<2,TRIM(RIGHT(ROUND(E5,2),LEN(ROUND(E5,2))-FIND(",",ROUND(E5,2))))*10,TRIM(RIGHT(ROUND(E5,2),LEN(ROUND(E5,2))-FIND(",",ROUND(E5,2))))*1),5),1)+1,"","on","yirmi","otuz","kırk","elli","altmış","yetmiş","seksen","doksan"),"")&IF(IF(LEN(TRIM(RIGHT(ROUND(E5,2),LEN(ROUND(E5,2))-FIND(",",ROUND(E5,2)))))<2,TRIM(RIGHT(ROUND(E5,2),LEN(ROUND(E5,2))-FIND(",",ROUND(E5,2))))*10,TRIM(RIGHT(ROUND(E5,2),LEN(ROUND(E5,2))-FIND(",",ROUND(E5,2))))*1)>=10^3,CHOOSE(LEFT(RIGHT(IF(LEN(TRIM(RIGHT(ROUND(E5,2),LEN(ROUND(E5,2))-FIND(",",ROUND(E5,2)))))<2,TRIM(RIGHT(ROUND(E5,2),LEN(ROUND(E5,2))-FIND(",",ROUND(E5,2))))*10,TRIM(RIGHT(ROUND(E5,2),LEN(ROUND(E5,2))-FIND(",",ROUND(E5,2))))*1),4),1)+1,"","","iki","üç","dört","beş","altı","yedi","sekiz","dokuz"),"")&IF(IF(LEN(TRIM(RIGHT(ROUND(E5,2),LEN(ROUND(E5,2))-FIND(",",ROUND(E5,2)))))<2,TRIM(RIGHT(ROUND(E5,2),LEN(ROUND(E5,2))-FIND(",",ROUND(E5,2))))*10,TRIM(RIGHT(ROUND(E5,2),LEN(ROUND(E5,2))-FIND(",",ROUND(E5,2))))*1)>=10,CHOOSE(LEFT(RIGHT(IF(LEN(TRIM(RIGHT(ROUND(E5,2),LEN(ROUND(E5,2))-FIND(",",ROUND(E5,2)))))<2,TRIM(RIGHT(ROUND(E5,2),LEN(ROUND(E5,2))-FIND(",",ROUND(E5,2))))*10,TRIM(RIGHT(ROUND(E5,2),LEN(ROUND(E5,2))-FIND(",",ROUND(E5,2))))*1),2),1)+1,"","on","yirmi","otuz","kırk","elli","altmış","yetmiş","seksen","doksan"),"")&CHOOSE(MOD(IF(LEN(TRIM(RIGHT(ROUND(E5,2),LEN(ROUND(E5,2))-FIND(",",ROUND(E5,2)))))<2,TRIM(RIGHT(ROUND(E5,2),LEN(ROUND(E5,2))-FIND(",",ROUND(E5,2))))*10,TRIM(RIGHT(ROUND(E5,2),LEN(ROUND(E5,2))-FIND(",",ROUND(E5,2))))*1),10)+1,"","bir","iki","üç","dört","beş","altı","yedi","sekiz","dokuz")) & " Kr") -> İkibin TL | G5: =G4 -> NAKDEN | H5: 3. Taksit
B6: 4 | C6: 44252 | D6: 44377 | E6: 2000 | F6: =PROPER(IF(IF(LEN(SUBSTITUTE(ROUND(E6,2), ",", ""))=LEN(ROUND(E6,2)),ROUND(E6,2),TRIM(LEFT(ROUND(E6,2),FIND(",",ROUND(E6,2))-1)))*1>=10^6,CHOOSE(LEFT(RIGHT(IF(LEN(SUBSTITUTE(ROUND(E6,2), ",", ""))=LEN(ROUND(E6,2)),ROUND(E6,2),TRIM(LEFT(ROUND(E6,2),FIND(",",ROUND(E6,2))-1)))*1,7),1)+1,"","birmilyon","ikimilyon","üçmilyon","dörtmilyon","beşmilyon","altımilyon","yedimilyon","sekizmilyon","dokuzmilyon"),"")&IF(IF(LEN(SUBSTITUTE(ROUND(E6,2), ",", ""))=LEN(ROUND(E6,2)),ROUND(E6,2),TRIM(LEFT(ROUND(E6,2),FIND(",",ROUND(E6,2))-1)))*1>=10^5,CHOOSE(LEFT(RIGHT(IF(LEN(SUBSTITUTE(ROUND(E6,2), ",", ""))=LEN(ROUND(E6,2)),ROUND(E6,2),TRIM(LEFT(ROUND(E6,2),FIND(",",ROUND(E6,2))-1)))*1,6),1)+1,"","yüz","ikiyüz","üçyüz","dörtyüz","beşyüz","altıyüz","yediyüz","sekizyüz","dokuzyüz"),"")&IF(IF(LEN(SUBSTITUTE(ROUND(E6,2), ",", ""))=LEN(ROUND(E6,2)),ROUND(E6,2),TRIM(LEFT(ROUND(E6,2),FIND(",",ROUND(E6,2))-1)))*1>=10^4,CHOOSE(LEFT(RIGHT(IF(LEN(SUBSTITUTE(ROUND(E6,2), ",", ""))=LEN(ROUND(E6,2)),ROUND(E6,2),TRIM(LEFT(ROUND(E6,2),FIND(",",ROUND(E6,2))-1)))*1,5),1)+1,"","on","yirmi","otuz","kırk","elli","altmış","yetmiş","seksen","doksan"),"")&IF(IF(LEN(SUBSTITUTE(ROUND(E6,2), ",", ""))=LEN(ROUND(E6,2)),ROUND(E6,2),TRIM(LEFT(ROUND(E6,2),FIND(",",ROUND(E6,2))-1)))*1>=10^3,CHOOSE(LEFT(RIGHT(IF(LEN(SUBSTITUTE(ROUND(E6,2), ",", ""))=LEN(ROUND(E6,2)),ROUND(E6,2),TRIM(LEFT(ROUND(E6,2),FIND(",",ROUND(E6,2))-1)))*1,4),1)+1,"","","iki","üç","dört","beş","altı","yedi","sekiz","dokuz"),"")&IF(AND(IF(LEN(SUBSTITUTE(ROUND(E6,2), ",", ""))=LEN(ROUND(E6,2)),ROUND(E6,2),TRIM(LEFT(ROUND(E6,2),FIND(",",ROUND(E6,2))-1)))*1>=10^3,VALUE(LEFT(RIGHT(IF(LEN(SUBSTITUTE(ROUND(E6,2), ",", ""))=LEN(ROUND(E6,2)),ROUND(E6,2),TRIM(LEFT(ROUND(E6,2),FIND(",",ROUND(E6,2))-1)))*1,6),3))>0),IF(AND(IF(LEN(SUBSTITUTE(ROUND(E6,2), ",", ""))=LEN(ROUND(E6,2)),ROUND(E6,2),TRIM(LEFT(ROUND(E6,2),FIND(",",ROUND(E6,2))-1)))*1>1999,LEFT(RIGHT(IF(LEN(SUBSTITUTE(ROUND(E6,2), ",", ""))=LEN(ROUND(E6,2)),ROUND(E6,2),TRIM(LEFT(ROUND(E6,2),FIND(",",ROUND(E6,2))-1)))*1,4),1)="1",LEFT(RIGHT(IF(LEN(SUBSTITUTE(ROUND(E6,2), ",", ""))=LEN(ROUND(E6,2)),ROUND(E6,2),TRIM(LEFT(ROUND(E6,2),FIND(",",ROUND(E6,2))-1)))*1,6),2)<>"00"),"birbin","bin"),"")&IF(IF(LEN(SUBSTITUTE(ROUND(E6,2), ",", ""))=LEN(ROUND(E6,2)),ROUND(E6,2),TRIM(LEFT(ROUND(E6,2),FIND(",",ROUND(E6,2))-1)))*1>=100,CHOOSE(LEFT(RIGHT(IF(LEN(SUBSTITUTE(ROUND(E6,2), ",", ""))=LEN(ROUND(E6,2)),ROUND(E6,2),TRIM(LEFT(ROUND(E6,2),FIND(",",ROUND(E6,2))-1)))*1,3),1)+1,"","yüz","ikiyüz","üçyüz","dörtyüz","beşyüz","altıyüz","yediyüz","sekizyüz","dokuzyüz"),"")&IF(IF(LEN(SUBSTITUTE(ROUND(E6,2), ",", ""))=LEN(ROUND(E6,2)),ROUND(E6,2),TRIM(LEFT(ROUND(E6,2),FIND(",",ROUND(E6,2))-1)))*1>=10,CHOOSE(LEFT(RIGHT(IF(LEN(SUBSTITUTE(ROUND(E6,2), ",", ""))=LEN(ROUND(E6,2)),ROUND(E6,2),TRIM(LEFT(ROUND(E6,2),FIND(",",ROUND(E6,2))-1)))*1,2),1)+1,"","on","yirmi","otuz","kırk","elli","altmış","yetmiş","seksen","doksan"),"")&CHOOSE(MOD(IF(LEN(SUBSTITUTE(ROUND(E6,2), ",", ""))=LEN(ROUND(E6,2)),ROUND(E6,2),TRIM(LEFT(ROUND(E6,2),FIND(",",ROUND(E6,2))-1)))*1,10)+1,"","bir","iki","üç","dört","beş","altı","yedi","sekiz","dokuz")) & " TL " & IF(OR(LEN(SUBSTITUTE(E6, ",", ""))=LEN(E6),LEN(SUBSTITUTE(ROUND(E6,2), ",", ""))=LEN(ROUND(E6,2))),"", PROPER(IF(IF(LEN(TRIM(RIGHT(ROUND(E6,2),LEN(ROUND(E6,2))-FIND(",",ROUND(E6,2)))))<2,TRIM(RIGHT(ROUND(E6,2),LEN(ROUND(E6,2))-FIND(",",ROUND(E6,2))))*10,TRIM(RIGHT(ROUND(E6,2),LEN(ROUND(E6,2))-FIND(",",ROUND(E6,2))))*1)>=10^5,CHOOSE(LEFT(RIGHT(IF(LEN(TRIM(RIGHT(ROUND(E6,2),LEN(ROUND(E6,2))-FIND(",",ROUND(E6,2)))))<2,TRIM(RIGHT(ROUND(E6,2),LEN(ROUND(E6,2))-FIND(",",ROUND(E6,2))))*10,TRIM(RIGHT(ROUND(E6,2),LEN(ROUND(E6,2))-FIND(",",ROUND(E6,2))))*1),6),1)+1,"","yüz","ikiyüz","üçyüz","dörtyüz","beşyüz","altıyüz","yediyüz","sekizyüz","dokuzyüz"),"")&IF(IF(LEN(TRIM(RIGHT(ROUND(E6,2),LEN(ROUND(E6,2))-FIND(",",ROUND(E6,2)))))<2,TRIM(RIGHT(ROUND(E6,2),LEN(ROUND(E6,2))-FIND(",",ROUND(E6,2))))*10,TRIM(RIGHT(ROUND(E6,2),LEN(ROUND(E6,2))-FIND(",",ROUND(E6,2))))*1)>=10^4,CHOOSE(LEFT(RIGHT(IF(LEN(TRIM(RIGHT(ROUND(E6,2),LEN(ROUND(E6,2))-FIND(",",ROUND(E6,2)))))<2,TRIM(RIGHT(ROUND(E6,2),LEN(ROUND(E6,2))-FIND(",",ROUND(E6,2))))*10,TRIM(RIGHT(ROUND(E6,2),LEN(ROUND(E6,2))-FIND(",",ROUND(E6,2))))*1),5),1)+1,"","on","yirmi","otuz","kırk","elli","altmış","yetmiş","seksen","doksan"),"")&IF(IF(LEN(TRIM(RIGHT(ROUND(E6,2),LEN(ROUND(E6,2))-FIND(",",ROUND(E6,2)))))<2,TRIM(RIGHT(ROUND(E6,2),LEN(ROUND(E6,2))-FIND(",",ROUND(E6,2))))*10,TRIM(RIGHT(ROUND(E6,2),LEN(ROUND(E6,2))-FIND(",",ROUND(E6,2))))*1)>=10^3,CHOOSE(LEFT(RIGHT(IF(LEN(TRIM(RIGHT(ROUND(E6,2),LEN(ROUND(E6,2))-FIND(",",ROUND(E6,2)))))<2,TRIM(RIGHT(ROUND(E6,2),LEN(ROUND(E6,2))-FIND(",",ROUND(E6,2))))*10,TRIM(RIGHT(ROUND(E6,2),LEN(ROUND(E6,2))-FIND(",",ROUND(E6,2))))*1),4),1)+1,"","","iki","üç","dört","beş","altı","yedi","sekiz","dokuz"),"")&IF(IF(LEN(TRIM(RIGHT(ROUND(E6,2),LEN(ROUND(E6,2))-FIND(",",ROUND(E6,2)))))<2,TRIM(RIGHT(ROUND(E6,2),LEN(ROUND(E6,2))-FIND(",",ROUND(E6,2))))*10,TRIM(RIGHT(ROUND(E6,2),LEN(ROUND(E6,2))-FIND(",",ROUND(E6,2))))*1)>=10,CHOOSE(LEFT(RIGHT(IF(LEN(TRIM(RIGHT(ROUND(E6,2),LEN(ROUND(E6,2))-FIND(",",ROUND(E6,2)))))<2,TRIM(RIGHT(ROUND(E6,2),LEN(ROUND(E6,2))-FIND(",",ROUND(E6,2))))*10,TRIM(RIGHT(ROUND(E6,2),LEN(ROUND(E6,2))-FIND(",",ROUND(E6,2))))*1),2),1)+1,"","on","yirmi","otuz","kırk","elli","altmış","yetmiş","seksen","doksan"),"")&CHOOSE(MOD(IF(LEN(TRIM(RIGHT(ROUND(E6,2),LEN(ROUND(E6,2))-FIND(",",ROUND(E6,2)))))<2,TRIM(RIGHT(ROUND(E6,2),LEN(ROUND(E6,2))-FIND(",",ROUND(E6,2))))*10,TRIM(RIGHT(ROUND(E6,2),LEN(ROUND(E6,2))-FIND(",",ROUND(E6,2))))*1),10)+1,"","bir","iki","üç","dört","beş","altı","yedi","sekiz","dokuz")) & " Kr") -> İkibin TL | G6: =G5 -> NAKDEN | H6: 4. Taksit
B7: 5 | C7: 44252 | D7: 44407 | E7: 14000 | F7: =PROPER(IF(IF(LEN(SUBSTITUTE(ROUND(E7,2), ",", ""))=LEN(ROUND(E7,2)),ROUND(E7,2),TRIM(LEFT(ROUND(E7,2),FIND(",",ROUND(E7,2))-1)))*1>=10^6,CHOOSE(LEFT(RIGHT(IF(LEN(SUBSTITUTE(ROUND(E7,2), ",", ""))=LEN(ROUND(E7,2)),ROUND(E7,2),TRIM(LEFT(ROUND(E7,2),FIND(",",ROUND(E7,2))-1)))*1,7),1)+1,"","birmilyon","ikimilyon","üçmilyon","dörtmilyon","beşmilyon","altımilyon","yedimilyon","sekizmilyon","dokuzmilyon"),"")&IF(IF(LEN(SUBSTITUTE(ROUND(E7,2), ",", ""))=LEN(ROUND(E7,2)),ROUND(E7,2),TRIM(LEFT(ROUND(E7,2),FIND(",",ROUND(E7,2))-1)))*1>=10^5,CHOOSE(LEFT(RIGHT(IF(LEN(SUBSTITUTE(ROUND(E7,2), ",", ""))=LEN(ROUND(E7,2)),ROUND(E7,2),TRIM(LEFT(ROUND(E7,2),FIND(",",ROUND(E7,2))-1)))*1,6),1)+1,"","yüz","ikiyüz","üçyüz","dörtyüz","beşyüz","altıyüz","yediyüz","sekizyüz","dokuzyüz"),"")&IF(IF(LEN(SUBSTITUTE(ROUND(E7,2), ",", ""))=LEN(ROUND(E7,2)),ROUND(E7,2),TRIM(LEFT(ROUND(E7,2),FIND(",",ROUND(E7,2))-1)))*1>=10^4,CHOOSE(LEFT(RIGHT(IF(LEN(SUBSTITUTE(ROUND(E7,2), ",", ""))=LEN(ROUND(E7,2)),ROUND(E7,2),TRIM(LEFT(ROUND(E7,2),FIND(",",ROUND(E7,2))-1)))*1,5),1)+1,"","on","yirmi","otuz","kırk","elli","altmış","yetmiş","seksen","doksan"),"")&IF(IF(LEN(SUBSTITUTE(ROUND(E7,2), ",", ""))=LEN(ROUND(E7,2)),ROUND(E7,2),TRIM(LEFT(ROUND(E7,2),FIND(",",ROUND(E7,2))-1)))*1>=10^3,CHOOSE(LEFT(RIGHT(IF(LEN(SUBSTITUTE(ROUND(E7,2), ",", ""))=LEN(ROUND(E7,2)),ROUND(E7,2),TRIM(LEFT(ROUND(E7,2),FIND(",",ROUND(E7,2))-1)))*1,4),1)+1,"","","iki","üç","dört","beş","altı","yedi","sekiz","dokuz"),"")&IF(AND(IF(LEN(SUBSTITUTE(ROUND(E7,2), ",", ""))=LEN(ROUND(E7,2)),ROUND(E7,2),TRIM(LEFT(ROUND(E7,2),FIND(",",ROUND(E7,2))-1)))*1>=10^3,VALUE(LEFT(RIGHT(IF(LEN(SUBSTITUTE(ROUND(E7,2), ",", ""))=LEN(ROUND(E7,2)),ROUND(E7,2),TRIM(LEFT(ROUND(E7,2),FIND(",",ROUND(E7,2))-1)))*1,6),3))>0),IF(AND(IF(LEN(SUBSTITUTE(ROUND(E7,2), ",", ""))=LEN(ROUND(E7,2)),ROUND(E7,2),TRIM(LEFT(ROUND(E7,2),FIND(",",ROUND(E7,2))-1)))*1>1999,LEFT(RIGHT(IF(LEN(SUBSTITUTE(ROUND(E7,2), ",", ""))=LEN(ROUND(E7,2)),ROUND(E7,2),TRIM(LEFT(ROUND(E7,2),FIND(",",ROUND(E7,2))-1)))*1,4),1)="1",LEFT(RIGHT(IF(LEN(SUBSTITUTE(ROUND(E7,2), ",", ""))=LEN(ROUND(E7,2)),ROUND(E7,2),TRIM(LEFT(ROUND(E7,2),FIND(",",ROUND(E7,2))-1)))*1,6),2)<>"00"),"birbin","bin"),"")&IF(IF(LEN(SUBSTITUTE(ROUND(E7,2), ",", ""))=LEN(ROUND(E7,2)),ROUND(E7,2),TRIM(LEFT(ROUND(E7,2),FIND(",",ROUND(E7,2))-1)))*1>=100,CHOOSE(LEFT(RIGHT(IF(LEN(SUBSTITUTE(ROUND(E7,2), ",", ""))=LEN(ROUND(E7,2)),ROUND(E7,2),TRIM(LEFT(ROUND(E7,2),FIND(",",ROUND(E7,2))-1)))*1,3),1)+1,"","yüz","ikiyüz","üçyüz","dörtyüz","beşyüz","altıyüz","yediyüz","sekizyüz","dokuzyüz"),"")&IF(IF(LEN(SUBSTITUTE(ROUND(E7,2), ",", ""))=LEN(ROUND(E7,2)),ROUND(E7,2),TRIM(LEFT(ROUND(E7,2),FIND(",",ROUND(E7,2))-1)))*1>=10,CHOOSE(LEFT(RIGHT(IF(LEN(SUBSTITUTE(ROUND(E7,2), ",", ""))=LEN(ROUND(E7,2)),ROUND(E7,2),TRIM(LEFT(ROUND(E7,2),FIND(",",ROUND(E7,2))-1)))*1,2),1)+1,"","on","yirmi","otuz","kırk","elli","altmış","yetmiş","seksen","doksan"),"")&CHOOSE(MOD(IF(LEN(SUBSTITUTE(ROUND(E7,2), ",", ""))=LEN(ROUND(E7,2)),ROUND(E7,2),TRIM(LEFT(ROUND(E7,2),FIND(",",ROUND(E7,2))-1)))*1,10)+1,"","bir","iki","üç","dört","beş","altı","yedi","sekiz","dokuz")) & " TL " & IF(OR(LEN(SUBSTITUTE(E7, ",", ""))=LEN(E7),LEN(SUBSTITUTE(ROUND(E7,2), ",", ""))=LEN(ROUND(E7,2))),"", PROPER(IF(IF(LEN(TRIM(RIGHT(ROUND(E7,2),LEN(ROUND(E7,2))-FIND(",",ROUND(E7,2)))))<2,TRIM(RIGHT(ROUND(E7,2),LEN(ROUND(E7,2))-FIND(",",ROUND(E7,2))))*10,TRIM(RIGHT(ROUND(E7,2),LEN(ROUND(E7,2))-FIND(",",ROUND(E7,2))))*1)>=10^5,CHOOSE(LEFT(RIGHT(IF(LEN(TRIM(RIGHT(ROUND(E7,2),LEN(ROUND(E7,2))-FIND(",",ROUND(E7,2)))))<2,TRIM(RIGHT(ROUND(E7,2),LEN(ROUND(E7,2))-FIND(",",ROUND(E7,2))))*10,TRIM(RIGHT(ROUND(E7,2),LEN(ROUND(E7,2))-FIND(",",ROUND(E7,2))))*1),6),1)+1,"","yüz","ikiyüz","üçyüz","dörtyüz","beşyüz","altıyüz","yediyüz","sekizyüz","dokuzyüz"),"")&IF(IF(LEN(TRIM(RIGHT(ROUND(E7,2),LEN(ROUND(E7,2))-FIND(",",ROUND(E7,2)))))<2,TRIM(RIGHT(ROUND(E7,2),LEN(ROUND(E7,2))-FIND(",",ROUND(E7,2))))*10,TRIM(RIGHT(ROUND(E7,2),LEN(ROUND(E7,2))-FIND(",",ROUND(E7,2))))*1)>=10^4,CHOOSE(LEFT(RIGHT(IF(LEN(TRIM(RIGHT(ROUND(E7,2),LEN(ROUND(E7,2))-FIND(",",ROUND(E7,2)))))<2,TRIM(RIGHT(ROUND(E7,2),LEN(ROUND(E7,2))-FIND(",",ROUND(E7,2))))*10,TRIM(RIGHT(ROUND(E7,2),LEN(ROUND(E7,2))-FIND(",",ROUND(E7,2))))*1),5),1)+1,"","on","yirmi","otuz","kırk","elli","altmış","yetmiş","seksen","doksan"),"")&IF(IF(LEN(TRIM(RIGHT(ROUND(E7,2),LEN(ROUND(E7,2))-FIND(",",ROUND(E7,2)))))<2,TRIM(RIGHT(ROUND(E7,2),LEN(ROUND(E7,2))-FIND(",",ROUND(E7,2))))*10,TRIM(RIGHT(ROUND(E7,2),LEN(ROUND(E7,2))-FIND(",",ROUND(E7,2))))*1)>=10^3,CHOOSE(LEFT(RIGHT(IF(LEN(TRIM(RIGHT(ROUND(E7,2),LEN(ROUND(E7,2))-FIND(",",ROUND(E7,2)))))<2,TRIM(RIGHT(ROUND(E7,2),LEN(ROUND(E7,2))-FIND(",",ROUND(E7,2))))*10,TRIM(RIGHT(ROUND(E7,2),LEN(ROUND(E7,2))-FIND(",",ROUND(E7,2))))*1),4),1)+1,"","","iki","üç","dört","beş","altı","yedi","sekiz","dokuz"),"")&IF(IF(LEN(TRIM(RIGHT(ROUND(E7,2),LEN(ROUND(E7,2))-FIND(",",ROUND(E7,2)))))<2,TRIM(RIGHT(ROUND(E7,2),LEN(ROUND(E7,2))-FIND(",",ROUND(E7,2))))*10,TRIM(RIGHT(ROUND(E7,2),LEN(ROUND(E7,2))-FIND(",",ROUND(E7,2))))*1)>=10,CHOOSE(LEFT(RIGHT(IF(LEN(TRIM(RIGHT(ROUND(E7,2),LEN(ROUND(E7,2))-FIND(",",ROUND(E7,2)))))<2,TRIM(RIGHT(ROUND(E7,2),LEN(ROUND(E7,2))-FIND(",",ROUND(E7,2))))*10,TRIM(RIGHT(ROUND(E7,2),LEN(ROUND(E7,2))-FIND(",",ROUND(E7,2))))*1),2),1)+1,"","on","yirmi","otuz","kırk","elli","altmış","yetmiş","seksen","doksan"),"")&CHOOSE(MOD(IF(LEN(TRIM(RIGHT(ROUND(E7,2),LEN(ROUND(E7,2))-FIND(",",ROUND(E7,2)))))<2,TRIM(RIGHT(ROUND(E7,2),LEN(ROUND(E7,2))-FIND(",",ROUND(E7,2))))*10,TRIM(RIGHT(ROUND(E7,2),LEN(ROUND(E7,2))-FIND(",",ROUND(E7,2))))*1),10)+1,"","bir","iki","üç","dört","beş","altı","yedi","sekiz","dokuz")) & " Kr") -> Ondörtbin TL | G7: =G6 -> NAKDEN | H7: 5. Taksit
B8: 6 | C8: 44252 | D8: 44438 | E8: 2000 | F8: =PROPER(IF(IF(LEN(SUBSTITUTE(ROUND(E8,2), ",", ""))=LEN(ROUND(E8,2)),ROUND(E8,2),TRIM(LEFT(ROUND(E8,2),FIND(",",ROUND(E8,2))-1)))*1>=10^6,CHOOSE(LEFT(RIGHT(IF(LEN(SUBSTITUTE(ROUND(E8,2), ",", ""))=LEN(ROUND(E8,2)),ROUND(E8,2),TRIM(LEFT(ROUND(E8,2),FIND(",",ROUND(E8,2))-1)))*1,7),1)+1,"","birmilyon","ikimilyon","üçmilyon","dörtmilyon","beşmilyon","altımilyon","yedimilyon","sekizmilyon","dokuzmilyon"),"")&IF(IF(LEN(SUBSTITUTE(ROUND(E8,2), ",", ""))=LEN(ROUND(E8,2)),ROUND(E8,2),TRIM(LEFT(ROUND(E8,2),FIND(",",ROUND(E8,2))-1)))*1>=10^5,CHOOSE(LEFT(RIGHT(IF(LEN(SUBSTITUTE(ROUND(E8,2), ",", ""))=LEN(ROUND(E8,2)),ROUND(E8,2),TRIM(LEFT(ROUND(E8,2),FIND(",",ROUND(E8,2))-1)))*1,6),1)+1,"","yüz","ikiyüz","üçyüz","dörtyüz","beşyüz","altıyüz","yediyüz","sekizyüz","dokuzyüz"),"")&IF(IF(LEN(SUBSTITUTE(ROUND(E8,2), ",", ""))=LEN(ROUND(E8,2)),ROUND(E8,2),TRIM(LEFT(ROUND(E8,2),FIND(",",ROUND(E8,2))-1)))*1>=10^4,CHOOSE(LEFT(RIGHT(IF(LEN(SUBSTITUTE(ROUND(E8,2), ",", ""))=LEN(ROUND(E8,2)),ROUND(E8,2),TRIM(LEFT(ROUND(E8,2),FIND(",",ROUND(E8,2))-1)))*1,5),1)+1,"","on","yirmi","otuz","kırk","elli","altmış","yetmiş","seksen","doksan"),"")&IF(IF(LEN(SUBSTITUTE(ROUND(E8,2), ",", ""))=LEN(ROUND(E8,2)),ROUND(E8,2),TRIM(LEFT(ROUND(E8,2),FIND(",",ROUND(E8,2))-1)))*1>=10^3,CHOOSE(LEFT(RIGHT(IF(LEN(SUBSTITUTE(ROUND(E8,2), ",", ""))=LEN(ROUND(E8,2)),ROUND(E8,2),TRIM(LEFT(ROUND(E8,2),FIND(",",ROUND(E8,2))-1)))*1,4),1)+1,"","","iki","üç","dört","beş","altı","yedi","sekiz","dokuz"),"")&IF(AND(IF(LEN(SUBSTITUTE(ROUND(E8,2), ",", ""))=LEN(ROUND(E8,2)),ROUND(E8,2),TRIM(LEFT(ROUND(E8,2),FIND(",",ROUND(E8,2))-1)))*1>=10^3,VALUE(LEFT(RIGHT(IF(LEN(SUBSTITUTE(ROUND(E8,2), ",", ""))=LEN(ROUND(E8,2)),ROUND(E8,2),TRIM(LEFT(ROUND(E8,2),FIND(",",ROUND(E8,2))-1)))*1,6),3))>0),IF(AND(IF(LEN(SUBSTITUTE(ROUND(E8,2), ",", ""))=LEN(ROUND(E8,2)),ROUND(E8,2),TRIM(LEFT(ROUND(E8,2),FIND(",",ROUND(E8,2))-1)))*1>1999,LEFT(RIGHT(IF(LEN(SUBSTITUTE(ROUND(E8,2), ",", ""))=LEN(ROUND(E8,2)),ROUND(E8,2),TRIM(LEFT(ROUND(E8,2),FIND(",",ROUND(E8,2))-1)))*1,4),1)="1",LEFT(RIGHT(IF(LEN(SUBSTITUTE(ROUND(E8,2), ",", ""))=LEN(ROUND(E8,2)),ROUND(E8,2),TRIM(LEFT(ROUND(E8,2),FIND(",",ROUND(E8,2))-1)))*1,6),2)<>"00"),"birbin","bin"),"")&IF(IF(LEN(SUBSTITUTE(ROUND(E8,2), ",", ""))=LEN(ROUND(E8,2)),ROUND(E8,2),TRIM(LEFT(ROUND(E8,2),FIND(",",ROUND(E8,2))-1)))*1>=100,CHOOSE(LEFT(RIGHT(IF(LEN(SUBSTITUTE(ROUND(E8,2), ",", ""))=LEN(ROUND(E8,2)),ROUND(E8,2),TRIM(LEFT(ROUND(E8,2),FIND(",",ROUND(E8,2))-1)))*1,3),1)+1,"","yüz","ikiyüz","üçyüz","dörtyüz","beşyüz","altıyüz","yediyüz","sekizyüz","dokuzyüz"),"")&IF(IF(LEN(SUBSTITUTE(ROUND(E8,2), ",", ""))=LEN(ROUND(E8,2)),ROUND(E8,2),TRIM(LEFT(ROUND(E8,2),FIND(",",ROUND(E8,2))-1)))*1>=10,CHOOSE(LEFT(RIGHT(IF(LEN(SUBSTITUTE(ROUND(E8,2), ",", ""))=LEN(ROUND(E8,2)),ROUND(E8,2),TRIM(LEFT(ROUND(E8,2),FIND(",",ROUND(E8,2))-1)))*1,2),1)+1,"","on","yirmi","otuz","kırk","elli","altmış","yetmiş","seksen","doksan"),"")&CHOOSE(MOD(IF(LEN(SUBSTITUTE(ROUND(E8,2), ",", ""))=LEN(ROUND(E8,2)),ROUND(E8,2),TRIM(LEFT(ROUND(E8,2),FIND(",",ROUND(E8,2))-1)))*1,10)+1,"","bir","iki","üç","dört","beş","altı","yedi","sekiz","dokuz")) & " TL " & IF(OR(LEN(SUBSTITUTE(E8, ",", ""))=LEN(E8),LEN(SUBSTITUTE(ROUND(E8,2), ",", ""))=LEN(ROUND(E8,2))),"", PROPER(IF(IF(LEN(TRIM(RIGHT(ROUND(E8,2),LEN(ROUND(E8,2))-FIND(",",ROUND(E8,2)))))<2,TRIM(RIGHT(ROUND(E8,2),LEN(ROUND(E8,2))-FIND(",",ROUND(E8,2))))*10,TRIM(RIGHT(ROUND(E8,2),LEN(ROUND(E8,2))-FIND(",",ROUND(E8,2))))*1)>=10^5,CHOOSE(LEFT(RIGHT(IF(LEN(TRIM(RIGHT(ROUND(E8,2),LEN(ROUND(E8,2))-FIND(",",ROUND(E8,2)))))<2,TRIM(RIGHT(ROUND(E8,2),LEN(ROUND(E8,2))-FIND(",",ROUND(E8,2))))*10,TRIM(RIGHT(ROUND(E8,2),LEN(ROUND(E8,2))-FIND(",",ROUND(E8,2))))*1),6),1)+1,"","yüz","ikiyüz","üçyüz","dörtyüz","beşyüz","altıyüz","yediyüz","sekizyüz","dokuzyüz"),"")&IF(IF(LEN(TRIM(RIGHT(ROUND(E8,2),LEN(ROUND(E8,2))-FIND(",",ROUND(E8,2)))))<2,TRIM(RIGHT(ROUND(E8,2),LEN(ROUND(E8,2))-FIND(",",ROUND(E8,2))))*10,TRIM(RIGHT(ROUND(E8,2),LEN(ROUND(E8,2))-FIND(",",ROUND(E8,2))))*1)>=10^4,CHOOSE(LEFT(RIGHT(IF(LEN(TRIM(RIGHT(ROUND(E8,2),LEN(ROUND(E8,2))-FIND(",",ROUND(E8,2)))))<2,TRIM(RIGHT(ROUND(E8,2),LEN(ROUND(E8,2))-FIND(",",ROUND(E8,2))))*10,TRIM(RIGHT(ROUND(E8,2),LEN(ROUND(E8,2))-FIND(",",ROUND(E8,2))))*1),5),1)+1,"","on","yirmi","otuz","kırk","elli","altmış","yetmiş","seksen","doksan"),"")&IF(IF(LEN(TRIM(RIGHT(ROUND(E8,2),LEN(ROUND(E8,2))-FIND(",",ROUND(E8,2)))))<2,TRIM(RIGHT(ROUND(E8,2),LEN(ROUND(E8,2))-FIND(",",ROUND(E8,2))))*10,TRIM(RIGHT(ROUND(E8,2),LEN(ROUND(E8,2))-FIND(",",ROUND(E8,2))))*1)>=10^3,CHOOSE(LEFT(RIGHT(IF(LEN(TRIM(RIGHT(ROUND(E8,2),LEN(ROUND(E8,2))-FIND(",",ROUND(E8,2)))))<2,TRIM(RIGHT(ROUND(E8,2),LEN(ROUND(E8,2))-FIND(",",ROUND(E8,2))))*10,TRIM(RIGHT(ROUND(E8,2),LEN(ROUND(E8,2))-FIND(",",ROUND(E8,2))))*1),4),1)+1,"","","iki","üç","dört","beş","altı","yedi","sekiz","dokuz"),"")&IF(IF(LEN(TRIM(RIGHT(ROUND(E8,2),LEN(ROUND(E8,2))-FIND(",",ROUND(E8,2)))))<2,TRIM(RIGHT(ROUND(E8,2),LEN(ROUND(E8,2))-FIND(",",ROUND(E8,2))))*10,TRIM(RIGHT(ROUND(E8,2),LEN(ROUND(E8,2))-FIND(",",ROUND(E8,2))))*1)>=10,CHOOSE(LEFT(RIGHT(IF(LEN(TRIM(RIGHT(ROUND(E8,2),LEN(ROUND(E8,2))-FIND(",",ROUND(E8,2)))))<2,TRIM(RIGHT(ROUND(E8,2),LEN(ROUND(E8,2))-FIND(",",ROUND(E8,2))))*10,TRIM(RIGHT(ROUND(E8,2),LEN(ROUND(E8,2))-FIND(",",ROUND(E8,2))))*1),2),1)+1,"","on","yirmi","otuz","kırk","elli","altmış","yetmiş","seksen","doksan"),"")&CHOOSE(MOD(IF(LEN(TRIM(RIGHT(ROUND(E8,2),LEN(ROUND(E8,2))-FIND(",",ROUND(E8,2)))))<2,TRIM(RIGHT(ROUND(E8,2),LEN(ROUND(E8,2))-FIND(",",ROUND(E8,2))))*10,TRIM(RIGHT(ROUND(E8,2),LEN(ROUND(E8,2))-FIND(",",ROUND(E8,2))))*1),10)+1,"","bir","iki","üç","dört","beş","altı","yedi","sekiz","dokuz")) & " Kr") -> İkibin TL | G8: =G7 -> NAKDEN | H8: 6. Taksit
B9: 7 | C9: 44252 | D9: 44469 | E9: 2000 | F9: =PROPER(IF(IF(LEN(SUBSTITUTE(ROUND(E9,2), ",", ""))=LEN(ROUND(E9,2)),ROUND(E9,2),TRIM(LEFT(ROUND(E9,2),FIND(",",ROUND(E9,2))-1)))*1>=10^6,CHOOSE(LEFT(RIGHT(IF(LEN(SUBSTITUTE(ROUND(E9,2), ",", ""))=LEN(ROUND(E9,2)),ROUND(E9,2),TRIM(LEFT(ROUND(E9,2),FIND(",",ROUND(E9,2))-1)))*1,7),1)+1,"","birmilyon","ikimilyon","üçmilyon","dörtmilyon","beşmilyon","altımilyon","yedimilyon","sekizmilyon","dokuzmilyon"),"")&IF(IF(LEN(SUBSTITUTE(ROUND(E9,2), ",", ""))=LEN(ROUND(E9,2)),ROUND(E9,2),TRIM(LEFT(ROUND(E9,2),FIND(",",ROUND(E9,2))-1)))*1>=10^5,CHOOSE(LEFT(RIGHT(IF(LEN(SUBSTITUTE(ROUND(E9,2), ",", ""))=LEN(ROUND(E9,2)),ROUND(E9,2),TRIM(LEFT(ROUND(E9,2),FIND(",",ROUND(E9,2))-1)))*1,6),1)+1,"","yüz","ikiyüz","üçyüz","dörtyüz","beşyüz","altıyüz","yediyüz","sekizyüz","dokuzyüz"),"")&IF(IF(LEN(SUBSTITUTE(ROUND(E9,2), ",", ""))=LEN(ROUND(E9,2)),ROUND(E9,2),TRIM(LEFT(ROUND(E9,2),FIND(",",ROUND(E9,2))-1)))*1>=10^4,CHOOSE(LEFT(RIGHT(IF(LEN(SUBSTITUTE(ROUND(E9,2), ",", ""))=LEN(ROUND(E9,2)),ROUND(E9,2),TRIM(LEFT(ROUND(E9,2),FIND(",",ROUND(E9,2))-1)))*1,5),1)+1,"","on","yirmi","otuz","kırk","elli","altmış","yetmiş","seksen","doksan"),"")&IF(IF(LEN(SUBSTITUTE(ROUND(E9,2), ",", ""))=LEN(ROUND(E9,2)),ROUND(E9,2),TRIM(LEFT(ROUND(E9,2),FIND(",",ROUND(E9,2))-1)))*1>=10^3,CHOOSE(LEFT(RIGHT(IF(LEN(SUBSTITUTE(ROUND(E9,2), ",", ""))=LEN(ROUND(E9,2)),ROUND(E9,2),TRIM(LEFT(ROUND(E9,2),FIND(",",ROUND(E9,2))-1)))*1,4),1)+1,"","","iki","üç","dört","beş","altı","yedi","sekiz","dokuz"),"")&IF(AND(IF(LEN(SUBSTITUTE(ROUND(E9,2), ",", ""))=LEN(ROUND(E9,2)),ROUND(E9,2),TRIM(LEFT(ROUND(E9,2),FIND(",",ROUND(E9,2))-1)))*1>=10^3,VALUE(LEFT(RIGHT(IF(LEN(SUBSTITUTE(ROUND(E9,2), ",", ""))=LEN(ROUND(E9,2)),ROUND(E9,2),TRIM(LEFT(ROUND(E9,2),FIND(",",ROUND(E9,2))-1)))*1,6),3))>0),IF(AND(IF(LEN(SUBSTITUTE(ROUND(E9,2), ",", ""))=LEN(ROUND(E9,2)),ROUND(E9,2),TRIM(LEFT(ROUND(E9,2),FIND(",",ROUND(E9,2))-1)))*1>1999,LEFT(RIGHT(IF(LEN(SUBSTITUTE(ROUND(E9,2), ",", ""))=LEN(ROUND(E9,2)),ROUND(E9,2),TRIM(LEFT(ROUND(E9,2),FIND(",",ROUND(E9,2))-1)))*1,4),1)="1",LEFT(RIGHT(IF(LEN(SUBSTITUTE(ROUND(E9,2), ",", ""))=LEN(ROUND(E9,2)),ROUND(E9,2),TRIM(LEFT(ROUND(E9,2),FIND(",",ROUND(E9,2))-1)))*1,6),2)<>"00"),"birbin","bin"),"")&IF(IF(LEN(SUBSTITUTE(ROUND(E9,2), ",", ""))=LEN(ROUND(E9,2)),ROUND(E9,2),TRIM(LEFT(ROUND(E9,2),FIND(",",ROUND(E9,2))-1)))*1>=100,CHOOSE(LEFT(RIGHT(IF(LEN(SUBSTITUTE(ROUND(E9,2), ",", ""))=LEN(ROUND(E9,2)),ROUND(E9,2),TRIM(LEFT(ROUND(E9,2),FIND(",",ROUND(E9,2))-1)))*1,3),1)+1,"","yüz","ikiyüz","üçyüz","dörtyüz","beşyüz","altıyüz","yediyüz","sekizyüz","dokuzyüz"),"")&IF(IF(LEN(SUBSTITUTE(ROUND(E9,2), ",", ""))=LEN(ROUND(E9,2)),ROUND(E9,2),TRIM(LEFT(ROUND(E9,2),FIND(",",ROUND(E9,2))-1)))*1>=10,CHOOSE(LEFT(RIGHT(IF(LEN(SUBSTITUTE(ROUND(E9,2), ",", ""))=LEN(ROUND(E9,2)),ROUND(E9,2),TRIM(LEFT(ROUND(E9,2),FIND(",",ROUND(E9,2))-1)))*1,2),1)+1,"","on","yirmi","otuz","kırk","elli","altmış","yetmiş","seksen","doksan"),"")&CHOOSE(MOD(IF(LEN(SUBSTITUTE(ROUND(E9,2), ",", ""))=LEN(ROUND(E9,2)),ROUND(E9,2),TRIM(LEFT(ROUND(E9,2),FIND(",",ROUND(E9,2))-1)))*1,10)+1,"","bir","iki","üç","dört","beş","altı","yedi","sekiz","dokuz")) & " TL " & IF(OR(LEN(SUBSTITUTE(E9, ",", ""))=LEN(E9),LEN(SUBSTITUTE(ROUND(E9,2), ",", ""))=LEN(ROUND(E9,2))),"", PROPER(IF(IF(LEN(TRIM(RIGHT(ROUND(E9,2),LEN(ROUND(E9,2))-FIND(",",ROUND(E9,2)))))<2,TRIM(RIGHT(ROUND(E9,2),LEN(ROUND(E9,2))-FIND(",",ROUND(E9,2))))*10,TRIM(RIGHT(ROUND(E9,2),LEN(ROUND(E9,2))-FIND(",",ROUND(E9,2))))*1)>=10^5,CHOOSE(LEFT(RIGHT(IF(LEN(TRIM(RIGHT(ROUND(E9,2),LEN(ROUND(E9,2))-FIND(",",ROUND(E9,2)))))<2,TRIM(RIGHT(ROUND(E9,2),LEN(ROUND(E9,2))-FIND(",",ROUND(E9,2))))*10,TRIM(RIGHT(ROUND(E9,2),LEN(ROUND(E9,2))-FIND(",",ROUND(E9,2))))*1),6),1)+1,"","yüz","ikiyüz","üçyüz","dörtyüz","beşyüz","altıyüz","yediyüz","sekizyüz","dokuzyüz"),"")&IF(IF(LEN(TRIM(RIGHT(ROUND(E9,2),LEN(ROUND(E9,2))-FIND(",",ROUND(E9,2)))))<2,TRIM(RIGHT(ROUND(E9,2),LEN(ROUND(E9,2))-FIND(",",ROUND(E9,2))))*10,TRIM(RIGHT(ROUND(E9,2),LEN(ROUND(E9,2))-FIND(",",ROUND(E9,2))))*1)>=10^4,CHOOSE(LEFT(RIGHT(IF(LEN(TRIM(RIGHT(ROUND(E9,2),LEN(ROUND(E9,2))-FIND(",",ROUND(E9,2)))))<2,TRIM(RIGHT(ROUND(E9,2),LEN(ROUND(E9,2))-FIND(",",ROUND(E9,2))))*10,TRIM(RIGHT(ROUND(E9,2),LEN(ROUND(E9,2))-FIND(",",ROUND(E9,2))))*1),5),1)+1,"","on","yirmi","otuz","kırk","elli","altmış","yetmiş","seksen","doksan"),"")&IF(IF(LEN(TRIM(RIGHT(ROUND(E9,2),LEN(ROUND(E9,2))-FIND(",",ROUND(E9,2)))))<2,TRIM(RIGHT(ROUND(E9,2),LEN(ROUND(E9,2))-FIND(",",ROUND(E9,2))))*10,TRIM(RIGHT(ROUND(E9,2),LEN(ROUND(E9,2))-FIND(",",ROUND(E9,2))))*1)>=10^3,CHOOSE(LEFT(RIGHT(IF(LEN(TRIM(RIGHT(ROUND(E9,2),LEN(ROUND(E9,2))-FIND(",",ROUND(E9,2)))))<2,TRIM(RIGHT(ROUND(E9,2),LEN(ROUND(E9,2))-FIND(",",ROUND(E9,2))))*10,TRIM(RIGHT(ROUND(E9,2),LEN(ROUND(E9,2))-FIND(",",ROUND(E9,2))))*1),4),1)+1,"","","iki","üç","dört","beş","altı","yedi","sekiz","dokuz"),"")&IF(IF(LEN(TRIM(RIGHT(ROUND(E9,2),LEN(ROUND(E9,2))-FIND(",",ROUND(E9,2)))))<2,TRIM(RIGHT(ROUND(E9,2),LEN(ROUND(E9,2))-FIND(",",ROUND(E9,2))))*10,TRIM(RIGHT(ROUND(E9,2),LEN(ROUND(E9,2))-FIND(",",ROUND(E9,2))))*1)>=10,CHOOSE(LEFT(RIGHT(IF(LEN(TRIM(RIGHT(ROUND(E9,2),LEN(ROUND(E9,2))-FIND(",",ROUND(E9,2)))))<2,TRIM(RIGHT(ROUND(E9,2),LEN(ROUND(E9,2))-FIND(",",ROUND(E9,2))))*10,TRIM(RIGHT(ROUND(E9,2),LEN(ROUND(E9,2))-FIND(",",ROUND(E9,2))))*1),2),1)+1,"","on","yirmi","otuz","kırk","elli","altmış","yetmiş","seksen","doksan"),"")&CHOOSE(MOD(IF(LEN(TRIM(RIGHT(ROUND(E9,2),LEN(ROUND(E9,2))-FIND(",",ROUND(E9,2)))))<2,TRIM(RIGHT(ROUND(E9,2),LEN(ROUND(E9,2))-FIND(",",ROUND(E9,2))))*10,TRIM(RIGHT(ROUND(E9,2),LEN(ROUND(E9,2))-FIND(",",ROUND(E9,2))))*1),10)+1,"","bir","iki","üç","dört","beş","altı","yedi","sekiz","dokuz")) & " Kr") -> İkibin TL | G9: =G8 -> NAKDEN | H9: 7. Taksit
B10: 8 | C10: 44252 | D10: 44499 | E10: 2000 | F10: =PROPER(IF(IF(LEN(SUBSTITUTE(ROUND(E10,2), ",", ""))=LEN(ROUND(E10,2)),ROUND(E10,2),TRIM(LEFT(ROUND(E10,2),FIND(",",ROUND(E10,2))-1)))*1>=10^6,CHOOSE(LEFT(RIGHT(IF(LEN(SUBSTITUTE(ROUND(E10,2), ",", ""))=LEN(ROUND(E10,2)),ROUND(E10,2),TRIM(LEFT(ROUND(E10,2),FIND(",",ROUND(E10,2))-1)))*1,7),1)+1,"","birmilyon","ikimilyon","üçmilyon","dörtmilyon","beşmilyon","altımilyon","yedimilyon","sekizmilyon","dokuzmilyon"),"")&IF(IF(LEN(SUBSTITUTE(ROUND(E10,2), ",", ""))=LEN(ROUND(E10,2)),ROUND(E10,2),TRIM(LEFT(ROUND(E10,2),FIND(",",ROUND(E10,2))-1)))*1>=10^5,CHOOSE(LEFT(RIGHT(IF(LEN(SUBSTITUTE(ROUND(E10,2), ",", ""))=LEN(ROUND(E10,2)),ROUND(E10,2),TRIM(LEFT(ROUND(E10,2),FIND(",",ROUND(E10,2))-1)))*1,6),1)+1,"","yüz","ikiyüz","üçyüz","dörtyüz","beşyüz","altıyüz","yediyüz","sekizyüz","dokuzyüz"),"")&IF(IF(LEN(SUBSTITUTE(ROUND(E10,2), ",", ""))=LEN(ROUND(E10,2)),ROUND(E10,2),TRIM(LEFT(ROUND(E10,2),FIND(",",ROUND(E10,2))-1)))*1>=10^4,CHOOSE(LEFT(RIGHT(IF(LEN(SUBSTITUTE(ROUND(E10,2), ",", ""))=LEN(ROUND(E10,2)),ROUND(E10,2),TRIM(LEFT(ROUND(E10,2),FIND(",",ROUND(E10,2))-1)))*1,5),1)+1,"","on","yirmi","otuz","kırk","elli","altmış","yetmiş","seksen","doksan"),"")&IF(IF(LEN(SUBSTITUTE(ROUND(E10,2), ",", ""))=LEN(ROUND(E10,2)),ROUND(E10,2),TRIM(LEFT(ROUND(E10,2),FIND(",",ROUND(E10,2))-1)))*1>=10^3,CHOOSE(LEFT(RIGHT(IF(LEN(SUBSTITUTE(ROUND(E10,2), ",", ""))=LEN(ROUND(E10,2)),ROUND(E10,2),TRIM(LEFT(ROUND(E10,2),FIND(",",ROUND(E10,2))-1)))*1,4),1)+1,"","","iki","üç","dört","beş","altı","yedi","sekiz","dokuz"),"")&IF(AND(IF(LEN(SUBSTITUTE(ROUND(E10,2), ",", ""))=LEN(ROUND(E10,2)),ROUND(E10,2),TRIM(LEFT(ROUND(E10,2),FIND(",",ROUND(E10,2))-1)))*1>=10^3,VALUE(LEFT(RIGHT(IF(LEN(SUBSTITUTE(ROUND(E10,2), ",", ""))=LEN(ROUND(E10,2)),ROUND(E10,2),TRIM(LEFT(ROUND(E10,2),FIND(",",ROUND(E10,2))-1)))*1,6),3))>0),IF(AND(IF(LEN(SUBSTITUTE(ROUND(E10,2), ",", ""))=LEN(ROUND(E10,2)),ROUND(E10,2),TRIM(LEFT(ROUND(E10,2),FIND(",",ROUND(E10,2))-1)))*1>1999,LEFT(RIGHT(IF(LEN(SUBSTITUTE(ROUND(E10,2), ",", ""))=LEN(ROUND(E10,2)),ROUND(E10,2),TRIM(LEFT(ROUND(E10,2),FIND(",",ROUND(E10,2))-1)))*1,4),1)="1",LEFT(RIGHT(IF(LEN(SUBSTITUTE(ROUND(E10,2), ",", ""))=LEN(ROUND(E10,2)),ROUND(E10,2),TRIM(LEFT(ROUND(E10,2),FIND(",",ROUND(E10,2))-1)))*1,6),2)<>"00"),"birbin","bin"),"")&IF(IF(LEN(SUBSTITUTE(ROUND(E10,2), ",", ""))=LEN(ROUND(E10,2)),ROUND(E10,2),TRIM(LEFT(ROUND(E10,2),FIND(",",ROUND(E10,2))-1)))*1>=100,CHOOSE(LEFT(RIGHT(IF(LEN(SUBSTITUTE(ROUND(E10,2), ",", ""))=LEN(ROUND(E10,2)),ROUND(E10,2),TRIM(LEFT(ROUND(E10,2),FIND(",",ROUND(E10,2))-1)))*1,3),1)+1,"","yüz","ikiyüz","üçyüz","dörtyüz","beşyüz","altıyüz","yediyüz","sekizyüz","dokuzyüz"),"")&IF(IF(LEN(SUBSTITUTE(ROUND(E10,2), ",", ""))=LEN(ROUND(E10,2)),ROUND(E10,2),TRIM(LEFT(ROUND(E10,2),FIND(",",ROUND(E10,2))-1)))*1>=10,CHOOSE(LEFT(RIGHT(IF(LEN(SUBSTITUTE(ROUND(E10,2), ",", ""))=LEN(ROUND(E10,2)),ROUND(E10,2),TRIM(LEFT(ROUND(E10,2),FIND(",",ROUND(E10,2))-1)))*1,2),1)+1,"","on","yirmi","otuz","kırk","elli","altmış","yetmiş","seksen","doksan"),"")&CHOOSE(MOD(IF(LEN(SUBSTITUTE(ROUND(E10,2), ",", ""))=LEN(ROUND(E10,2)),ROUND(E10,2),TRIM(LEFT(ROUND(E10,2),FIND(",",ROUND(E10,2))-1)))*1,10)+1,"","bir","iki","üç","dört","beş","altı","yedi","sekiz","dokuz")) & " TL " & IF(OR(LEN(SUBSTITUTE(E10, ",", ""))=LEN(E10),LEN(SUBSTITUTE(ROUND(E10,2), ",", ""))=LEN(ROUND(E10,2))),"", PROPER(IF(IF(LEN(TRIM(RIGHT(ROUND(E10,2),LEN(ROUND(E10,2))-FIND(",",ROUND(E10,2)))))<2,TRIM(RIGHT(ROUND(E10,2),LEN(ROUND(E10,2))-FIND(",",ROUND(E10,2))))*10,TRIM(RIGHT(ROUND(E10,2),LEN(ROUND(E10,2))-FIND(",",ROUND(E10,2))))*1)>=10^5,CHOOSE(LEFT(RIGHT(IF(LEN(TRIM(RIGHT(ROUND(E10,2),LEN(ROUND(E10,2))-FIND(",",ROUND(E10,2)))))<2,TRIM(RIGHT(ROUND(E10,2),LEN(ROUND(E10,2))-FIND(",",ROUND(E10,2))))*10,TRIM(RIGHT(ROUND(E10,2),LEN(ROUND(E10,2))-FIND(",",ROUND(E10,2))))*1),6),1)+1,"","yüz","ikiyüz","üçyüz","dörtyüz","beşyüz","altıyüz","yediyüz","sekizyüz","dokuzyüz"),"")&IF(IF(LEN(TRIM(RIGHT(ROUND(E10,2),LEN(ROUND(E10,2))-FIND(",",ROUND(E10,2)))))<2,TRIM(RIGHT(ROUND(E10,2),LEN(ROUND(E10,2))-FIND(",",ROUND(E10,2))))*10,TRIM(RIGHT(ROUND(E10,2),LEN(ROUND(E10,2))-FIND(",",ROUND(E10,2))))*1)>=10^4,CHOOSE(LEFT(RIGHT(IF(LEN(TRIM(RIGHT(ROUND(E10,2),LEN(ROUND(E10,2))-FIND(",",ROUND(E10,2)))))<2,TRIM(RIGHT(ROUND(E10,2),LEN(ROUND(E10,2))-FIND(",",ROUND(E10,2))))*10,TRIM(RIGHT(ROUND(E10,2),LEN(ROUND(E10,2))-FIND(",",ROUND(E10,2))))*1),5),1)+1,"","on","yirmi","otuz","kırk","elli","altmış","yetmiş","seksen","doksan"),"")&IF(IF(LEN(TRIM(RIGHT(ROUND(E10,2),LEN(ROUND(E10,2))-FIND(",",ROUND(E10,2)))))<2,TRIM(RIGHT(ROUND(E10,2),LEN(ROUND(E10,2))-FIND(",",ROUND(E10,2))))*10,TRIM(RIGHT(ROUND(E10,2),LEN(ROUND(E10,2))-FIND(",",ROUND(E10,2))))*1)>=10^3,CHOOSE(LEFT(RIGHT(IF(LEN(TRIM(RIGHT(ROUND(E10,2),LEN(ROUND(E10,2))-FIND(",",ROUND(E10,2)))))<2,TRIM(RIGHT(ROUND(E10,2),LEN(ROUND(E10,2))-FIND(",",ROUND(E10,2))))*10,TRIM(RIGHT(ROUND(E10,2),LEN(ROUND(E10,2))-FIND(",",ROUND(E10,2))))*1),4),1)+1,"","","iki","üç","dört","beş","altı","yedi","sekiz","dokuz"),"")&IF(IF(LEN(TRIM(RIGHT(ROUND(E10,2),LEN(ROUND(E10,2))-FIND(",",ROUND(E10,2)))))<2,TRIM(RIGHT(ROUND(E10,2),LEN(ROUND(E10,2))-FIND(",",ROUND(E10,2))))*10,TRIM(RIGHT(ROUND(E10,2),LEN(ROUND(E10,2))-FIND(",",ROUND(E10,2))))*1)>=10,CHOOSE(LEFT(RIGHT(IF(LEN(TRIM(RIGHT(ROUND(E10,2),LEN(ROUND(E10,2))-FIND(",",ROUND(E10,2)))))<2,TRIM(RIGHT(ROUND(E10,2),LEN(ROUND(E10,2))-FIND(",",ROUND(E10,2))))*10,TRIM(RIGHT(ROUND(E10,2),LEN(ROUND(E10,2))-FIND(",",ROUND(E10,2))))*1),2),1)+1,"","on","yirmi","otuz","kırk","elli","altmış","yetmiş","seksen","doksan"),"")&CHOOSE(MOD(IF(LEN(TRIM(RIGHT(ROUND(E10,2),LEN(ROUND(E10,2))-FIND(",",ROUND(E10,2)))))<2,TRIM(RIGHT(ROUND(E10,2),LEN(ROUND(E10,2))-FIND(",",ROUND(E10,2))))*10,TRIM(RIGHT(ROUND(E10,2),LEN(ROUND(E10,2))-FIND(",",ROUND(E10,2))))*1),10)+1,"","bir","iki","üç","dört","beş","altı","yedi","sekiz","dokuz")) & " Kr") -> İkibin TL | G10: =G9 -> NAKDEN | H10: 8. Taksit
B11: 9 | C11: 44252 | D11: 44530 | E11: 2000 | F11: =PROPER(IF(IF(LEN(SUBSTITUTE(ROUND(E11,2), ",", ""))=LEN(ROUND(E11,2)),ROUND(E11,2),TRIM(LEFT(ROUND(E11,2),FIND(",",ROUND(E11,2))-1)))*1>=10^6,CHOOSE(LEFT(RIGHT(IF(LEN(SUBSTITUTE(ROUND(E11,2), ",", ""))=LEN(ROUND(E11,2)),ROUND(E11,2),TRIM(LEFT(ROUND(E11,2),FIND(",",ROUND(E11,2))-1)))*1,7),1)+1,"","birmilyon","ikimilyon","üçmilyon","dörtmilyon","beşmilyon","altımilyon","yedimilyon","sekizmilyon","dokuzmilyon"),"")&IF(IF(LEN(SUBSTITUTE(ROUND(E11,2), ",", ""))=LEN(ROUND(E11,2)),ROUND(E11,2),TRIM(LEFT(ROUND(E11,2),FIND(",",ROUND(E11,2))-1)))*1>=10^5,CHOOSE(LEFT(RIGHT(IF(LEN(SUBSTITUTE(ROUND(E11,2), ",", ""))=LEN(ROUND(E11,2)),ROUND(E11,2),TRIM(LEFT(ROUND(E11,2),FIND(",",ROUND(E11,2))-1)))*1,6),1)+1,"","yüz","ikiyüz","üçyüz","dörtyüz","beşyüz","altıyüz","yediyüz","sekizyüz","dokuzyüz"),"")&IF(IF(LEN(SUBSTITUTE(ROUND(E11,2), ",", ""))=LEN(ROUND(E11,2)),ROUND(E11,2),TRIM(LEFT(ROUND(E11,2),FIND(",",ROUND(E11,2))-1)))*1>=10^4,CHOOSE(LEFT(RIGHT(IF(LEN(SUBSTITUTE(ROUND(E11,2), ",", ""))=LEN(ROUND(E11,2)),ROUND(E11,2),TRIM(LEFT(ROUND(E11,2),FIND(",",ROUND(E11,2))-1)))*1,5),1)+1,"","on","yirmi","otuz","kırk","elli","altmış","yetmiş","seksen","doksan"),"")&IF(IF(LEN(SUBSTITUTE(ROUND(E11,2), ",", ""))=LEN(ROUND(E11,2)),ROUND(E11,2),TRIM(LEFT(ROUND(E11,2),FIND(",",ROUND(E11,2))-1)))*1>=10^3,CHOOSE(LEFT(RIGHT(IF(LEN(SUBSTITUTE(ROUND(E11,2), ",", ""))=LEN(ROUND(E11,2)),ROUND(E11,2),TRIM(LEFT(ROUND(E11,2),FIND(",",ROUND(E11,2))-1)))*1,4),1)+1,"","","iki","üç","dört","beş","altı","yedi","sekiz","dokuz"),"")&IF(AND(IF(LEN(SUBSTITUTE(ROUND(E11,2), ",", ""))=LEN(ROUND(E11,2)),ROUND(E11,2),TRIM(LEFT(ROUND(E11,2),FIND(",",ROUND(E11,2))-1)))*1>=10^3,VALUE(LEFT(RIGHT(IF(LEN(SUBSTITUTE(ROUND(E11,2), ",", ""))=LEN(ROUND(E11,2)),ROUND(E11,2),TRIM(LEFT(ROUND(E11,2),FIND(",",ROUND(E11,2))-1)))*1,6),3))>0),IF(AND(IF(LEN(SUBSTITUTE(ROUND(E11,2), ",", ""))=LEN(ROUND(E11,2)),ROUND(E11,2),TRIM(LEFT(ROUND(E11,2),FIND(",",ROUND(E11,2))-1)))*1>1999,LEFT(RIGHT(IF(LEN(SUBSTITUTE(ROUND(E11,2), ",", ""))=LEN(ROUND(E11,2)),ROUND(E11,2),TRIM(LEFT(ROUND(E11,2),FIND(",",ROUND(E11,2))-1)))*1,4),1)="1",LEFT(RIGHT(IF(LEN(SUBSTITUTE(ROUND(E11,2), ",", ""))=LEN(ROUND(E11,2)),ROUND(E11,2),TRIM(LEFT(ROUND(E11,2),FIND(",",ROUND(E11,2))-1)))*1,6),2)<>"00"),"birbin","bin"),"")&IF(IF(LEN(SUBSTITUTE(ROUND(E11,2), ",", ""))=LEN(ROUND(E11,2)),ROUND(E11,2),TRIM(LEFT(ROUND(E11,2),FIND(",",ROUND(E11,2))-1)))*1>=100,CHOOSE(LEFT(RIGHT(IF(LEN(SUBSTITUTE(ROUND(E11,2), ",", ""))=LEN(ROUND(E11,2)),ROUND(E11,2),TRIM(LEFT(ROUND(E11,2),FIND(",",ROUND(E11,2))-1)))*1,3),1)+1,"","yüz","ikiyüz","üçyüz","dörtyüz","beşyüz","altıyüz","yediyüz","sekizyüz","dokuzyüz"),"")&IF(IF(LEN(SUBSTITUTE(ROUND(E11,2), ",", ""))=LEN(ROUND(E11,2)),ROUND(E11,2),TRIM(LEFT(ROUND(E11,2),FIND(",",ROUND(E11,2))-1)))*1>=10,CHOOSE(LEFT(RIGHT(IF(LEN(SUBSTITUTE(ROUND(E11,2), ",", ""))=LEN(ROUND(E11,2)),ROUND(E11,2),TRIM(LEFT(ROUND(E11,2),FIND(",",ROUND(E11,2))-1)))*1,2),1)+1,"","on","yirmi","otuz","kırk","elli","altmış","yetmiş","seksen","doksan"),"")&CHOOSE(MOD(IF(LEN(SUBSTITUTE(ROUND(E11,2), ",", ""))=LEN(ROUND(E11,2)),ROUND(E11,2),TRIM(LEFT(ROUND(E11,2),FIND(",",ROUND(E11,2))-1)))*1,10)+1,"","bir","iki","üç","dört","beş","altı","yedi","sekiz","dokuz")) & " TL " & IF(OR(LEN(SUBSTITUTE(E11, ",", ""))=LEN(E11),LEN(SUBSTITUTE(ROUND(E11,2), ",", ""))=LEN(ROUND(E11,2))),"", PROPER(IF(IF(LEN(TRIM(RIGHT(ROUND(E11,2),LEN(ROUND(E11,2))-FIND(",",ROUND(E11,2)))))<2,TRIM(RIGHT(ROUND(E11,2),LEN(ROUND(E11,2))-FIND(",",ROUND(E11,2))))*10,TRIM(RIGHT(ROUND(E11,2),LEN(ROUND(E11,2))-FIND(",",ROUND(E11,2))))*1)>=10^5,CHOOSE(LEFT(RIGHT(IF(LEN(TRIM(RIGHT(ROUND(E11,2),LEN(ROUND(E11,2))-FIND(",",ROUND(E11,2)))))<2,TRIM(RIGHT(ROUND(E11,2),LEN(ROUND(E11,2))-FIND(",",ROUND(E11,2))))*10,TRIM(RIGHT(ROUND(E11,2),LEN(ROUND(E11,2))-FIND(",",ROUND(E11,2))))*1),6),1)+1,"","yüz","ikiyüz","üçyüz","dörtyüz","beşyüz","altıyüz","yediyüz","sekizyüz","dokuzyüz"),"")&IF(IF(LEN(TRIM(RIGHT(ROUND(E11,2),LEN(ROUND(E11,2))-FIND(",",ROUND(E11,2)))))<2,TRIM(RIGHT(ROUND(E11,2),LEN(ROUND(E11,2))-FIND(",",ROUND(E11,2))))*10,TRIM(RIGHT(ROUND(E11,2),LEN(ROUND(E11,2))-FIND(",",ROUND(E11,2))))*1)>=10^4,CHOOSE(LEFT(RIGHT(IF(LEN(TRIM(RIGHT(ROUND(E11,2),LEN(ROUND(E11,2))-FIND(",",ROUND(E11,2)))))<2,TRIM(RIGHT(ROUND(E11,2),LEN(ROUND(E11,2))-FIND(",",ROUND(E11,2))))*10,TRIM(RIGHT(ROUND(E11,2),LEN(ROUND(E11,2))-FIND(",",ROUND(E11,2))))*1),5),1)+1,"","on","yirmi","otuz","kırk","elli","altmış","yetmiş","seksen","doksan"),"")&IF(IF(LEN(TRIM(RIGHT(ROUND(E11,2),LEN(ROUND(E11,2))-FIND(",",ROUND(E11,2)))))<2,TRIM(RIGHT(ROUND(E11,2),LEN(ROUND(E11,2))-FIND(",",ROUND(E11,2))))*10,TRIM(RIGHT(ROUND(E11,2),LEN(ROUND(E11,2))-FIND(",",ROUND(E11,2))))*1)>=10^3,CHOOSE(LEFT(RIGHT(IF(LEN(TRIM(RIGHT(ROUND(E11,2),LEN(ROUND(E11,2))-FIND(",",ROUND(E11,2)))))<2,TRIM(RIGHT(ROUND(E11,2),LEN(ROUND(E11,2))-FIND(",",ROUND(E11,2))))*10,TRIM(RIGHT(ROUND(E11,2),LEN(ROUND(E11,2))-FIND(",",ROUND(E11,2))))*1),4),1)+1,"","","iki","üç","dört","beş","altı","yedi","sekiz","dokuz"),"")&IF(IF(LEN(TRIM(RIGHT(ROUND(E11,2),LEN(ROUND(E11,2))-FIND(",",ROUND(E11,2)))))<2,TRIM(RIGHT(ROUND(E11,2),LEN(ROUND(E11,2))-FIND(",",ROUND(E11,2))))*10,TRIM(RIGHT(ROUND(E11,2),LEN(ROUND(E11,2))-FIND(",",ROUND(E11,2))))*1)>=10,CHOOSE(LEFT(RIGHT(IF(LEN(TRIM(RIGHT(ROUND(E11,2),LEN(ROUND(E11,2))-FIND(",",ROUND(E11,2)))))<2,TRIM(RIGHT(ROUND(E11,2),LEN(ROUND(E11,2))-FIND(",",ROUND(E11,2))))*10,TRIM(RIGHT(ROUND(E11,2),LEN(ROUND(E11,2))-FIND(",",ROUND(E11,2))))*1),2),1)+1,"","on","yirmi","otuz","kırk","elli","altmış","yetmiş","seksen","doksan"),"")&CHOOSE(MOD(IF(LEN(TRIM(RIGHT(ROUND(E11,2),LEN(ROUND(E11,2))-FIND(",",ROUND(E11,2)))))<2,TRIM(RIGHT(ROUND(E11,2),LEN(ROUND(E11,2))-FIND(",",ROUND(E11,2))))*10,TRIM(RIGHT(ROUND(E11,2),LEN(ROUND(E11,2))-FIND(",",ROUND(E11,2))))*1),10)+1,"","bir","iki","üç","dört","beş","altı","yedi","sekiz","dokuz")) & " Kr") -> İkibin TL | G11: =G10 -> NAKDEN | H11: 9. Taksit
B12: 10 | C12: 44252 | D12: 44560 | E12: 2000 | F12: =PROPER(IF(IF(LEN(SUBSTITUTE(ROUND(E12,2), ",", ""))=LEN(ROUND(E12,2)),ROUND(E12,2),TRIM(LEFT(ROUND(E12,2),FIND(",",ROUND(E12,2))-1)))*1>=10^6,CHOOSE(LEFT(RIGHT(IF(LEN(SUBSTITUTE(ROUND(E12,2), ",", ""))=LEN(ROUND(E12,2)),ROUND(E12,2),TRIM(LEFT(ROUND(E12,2),FIND(",",ROUND(E12,2))-1)))*1,7),1)+1,"","birmilyon","ikimilyon","üçmilyon","dörtmilyon","beşmilyon","altımilyon","yedimilyon","sekizmilyon","dokuzmilyon"),"")&IF(IF(LEN(SUBSTITUTE(ROUND(E12,2), ",", ""))=LEN(ROUND(E12,2)),ROUND(E12,2),TRIM(LEFT(ROUND(E12,2),FIND(",",ROUND(E12,2))-1)))*1>=10^5,CHOOSE(LEFT(RIGHT(IF(LEN(SUBSTITUTE(ROUND(E12,2), ",", ""))=LEN(ROUND(E12,2)),ROUND(E12,2),TRIM(LEFT(ROUND(E12,2),FIND(",",ROUND(E12,2))-1)))*1,6),1)+1,"","yüz","ikiyüz","üçyüz","dörtyüz","beşyüz","altıyüz","yediyüz","sekizyüz","dokuzyüz"),"")&IF(IF(LEN(SUBSTITUTE(ROUND(E12,2), ",", ""))=LEN(ROUND(E12,2)),ROUND(E12,2),TRIM(LEFT(ROUND(E12,2),FIND(",",ROUND(E12,2))-1)))*1>=10^4,CHOOSE(LEFT(RIGHT(IF(LEN(SUBSTITUTE(ROUND(E12,2), ",", ""))=LEN(ROUND(E12,2)),ROUND(E12,2),TRIM(LEFT(ROUND(E12,2),FIND(",",ROUND(E12,2))-1)))*1,5),1)+1,"","on","yirmi","otuz","kırk","elli","altmış","yetmiş","seksen","doksan"),"")&IF(IF(LEN(SUBSTITUTE(ROUND(E12,2), ",", ""))=LEN(ROUND(E12,2)),ROUND(E12,2),TRIM(LEFT(ROUND(E12,2),FIND(",",ROUND(E12,2))-1)))*1>=10^3,CHOOSE(LEFT(RIGHT(IF(LEN(SUBSTITUTE(ROUND(E12,2), ",", ""))=LEN(ROUND(E12,2)),ROUND(E12,2),TRIM(LEFT(ROUND(E12,2),FIND(",",ROUND(E12,2))-1)))*1,4),1)+1,"","","iki","üç","dört","beş","altı","yedi","sekiz","dokuz"),"")&IF(AND(IF(LEN(SUBSTITUTE(ROUND(E12,2), ",", ""))=LEN(ROUND(E12,2)),ROUND(E12,2),TRIM(LEFT(ROUND(E12,2),FIND(",",ROUND(E12,2))-1)))*1>=10^3,VALUE(LEFT(RIGHT(IF(LEN(SUBSTITUTE(ROUND(E12,2), ",", ""))=LEN(ROUND(E12,2)),ROUND(E12,2),TRIM(LEFT(ROUND(E12,2),FIND(",",ROUND(E12,2))-1)))*1,6),3))>0),IF(AND(IF(LEN(SUBSTITUTE(ROUND(E12,2), ",", ""))=LEN(ROUND(E12,2)),ROUND(E12,2),TRIM(LEFT(ROUND(E12,2),FIND(",",ROUND(E12,2))-1)))*1>1999,LEFT(RIGHT(IF(LEN(SUBSTITUTE(ROUND(E12,2), ",", ""))=LEN(ROUND(E12,2)),ROUND(E12,2),TRIM(LEFT(ROUND(E12,2),FIND(",",ROUND(E12,2))-1)))*1,4),1)="1",LEFT(RIGHT(IF(LEN(SUBSTITUTE(ROUND(E12,2), ",", ""))=LEN(ROUND(E12,2)),ROUND(E12,2),TRIM(LEFT(ROUND(E12,2),FIND(",",ROUND(E12,2))-1)))*1,6),2)<>"00"),"birbin","bin"),"")&IF(IF(LEN(SUBSTITUTE(ROUND(E12,2), ",", ""))=LEN(ROUND(E12,2)),ROUND(E12,2),TRIM(LEFT(ROUND(E12,2),FIND(",",ROUND(E12,2))-1)))*1>=100,CHOOSE(LEFT(RIGHT(IF(LEN(SUBSTITUTE(ROUND(E12,2), ",", ""))=LEN(ROUND(E12,2)),ROUND(E12,2),TRIM(LEFT(ROUND(E12,2),FIND(",",ROUND(E12,2))-1)))*1,3),1)+1,"","yüz","ikiyüz","üçyüz","dörtyüz","beşyüz","altıyüz","yediyüz","sekizyüz","dokuzyüz"),"")&IF(IF(LEN(SUBSTITUTE(ROUND(E12,2), ",", ""))=LEN(ROUND(E12,2)),ROUND(E12,2),TRIM(LEFT(ROUND(E12,2),FIND(",",ROUND(E12,2))-1)))*1>=10,CHOOSE(LEFT(RIGHT(IF(LEN(SUBSTITUTE(ROUND(E12,2), ",", ""))=LEN(ROUND(E12,2)),ROUND(E12,2),TRIM(LEFT(ROUND(E12,2),FIND(",",ROUND(E12,2))-1)))*1,2),1)+1,"","on","yirmi","otuz","kırk","elli","altmış","yetmiş","seksen","doksan"),"")&CHOOSE(MOD(IF(LEN(SUBSTITUTE(ROUND(E12,2), ",", ""))=LEN(ROUND(E12,2)),ROUND(E12,2),TRIM(LEFT(ROUND(E12,2),FIND(",",ROUND(E12,2))-1)))*1,10)+1,"","bir","iki","üç","dört","beş","altı","yedi","sekiz","dokuz")) & " TL " & IF(OR(LEN(SUBSTITUTE(E12, ",", ""))=LEN(E12),LEN(SUBSTITUTE(ROUND(E12,2), ",", ""))=LEN(ROUND(E12,2))),"", PROPER(IF(IF(LEN(TRIM(RIGHT(ROUND(E12,2),LEN(ROUND(E12,2))-FIND(",",ROUND(E12,2)))))<2,TRIM(RIGHT(ROUND(E12,2),LEN(ROUND(E12,2))-FIND(",",ROUND(E12,2))))*10,TRIM(RIGHT(ROUND(E12,2),LEN(ROUND(E12,2))-FIND(",",ROUND(E12,2))))*1)>=10^5,CHOOSE(LEFT(RIGHT(IF(LEN(TRIM(RIGHT(ROUND(E12,2),LEN(ROUND(E12,2))-FIND(",",ROUND(E12,2)))))<2,TRIM(RIGHT(ROUND(E12,2),LEN(ROUND(E12,2))-FIND(",",ROUND(E12,2))))*10,TRIM(RIGHT(ROUND(E12,2),LEN(ROUND(E12,2))-FIND(",",ROUND(E12,2))))*1),6),1)+1,"","yüz","ikiyüz","üçyüz","dörtyüz","beşyüz","altıyüz","yediyüz","sekizyüz","dokuzyüz"),"")&IF(IF(LEN(TRIM(RIGHT(ROUND(E12,2),LEN(ROUND(E12,2))-FIND(",",ROUND(E12,2)))))<2,TRIM(RIGHT(ROUND(E12,2),LEN(ROUND(E12,2))-FIND(",",ROUND(E12,2))))*10,TRIM(RIGHT(ROUND(E12,2),LEN(ROUND(E12,2))-FIND(",",ROUND(E12,2))))*1)>=10^4,CHOOSE(LEFT(RIGHT(IF(LEN(TRIM(RIGHT(ROUND(E12,2),LEN(ROUND(E12,2))-FIND(",",ROUND(E12,2)))))<2,TRIM(RIGHT(ROUND(E12,2),LEN(ROUND(E12,2))-FIND(",",ROUND(E12,2))))*10,TRIM(RIGHT(ROUND(E12,2),LEN(ROUND(E12,2))-FIND(",",ROUND(E12,2))))*1),5),1)+1,"","on","yirmi","otuz","kırk","elli","altmış","yetmiş","seksen","doksan"),"")&IF(IF(LEN(TRIM(RIGHT(ROUND(E12,2),LEN(ROUND(E12,2))-FIND(",",ROUND(E12,2)))))<2,TRIM(RIGHT(ROUND(E12,2),LEN(ROUND(E12,2))-FIND(",",ROUND(E12,2))))*10,TRIM(RIGHT(ROUND(E12,2),LEN(ROUND(E12,2))-FIND(",",ROUND(E12,2))))*1)>=10^3,CHOOSE(LEFT(RIGHT(IF(LEN(TRIM(RIGHT(ROUND(E12,2),LEN(ROUND(E12,2))-FIND(",",ROUND(E12,2)))))<2,TRIM(RIGHT(ROUND(E12,2),LEN(ROUND(E12,2))-FIND(",",ROUND(E12,2))))*10,TRIM(RIGHT(ROUND(E12,2),LEN(ROUND(E12,2))-FIND(",",ROUND(E12,2))))*1),4),1)+1,"","","iki","üç","dört","beş","altı","yedi","sekiz","dokuz"),"")&IF(IF(LEN(TRIM(RIGHT(ROUND(E12,2),LEN(ROUND(E12,2))-FIND(",",ROUND(E12,2)))))<2,TRIM(RIGHT(ROUND(E12,2),LEN(ROUND(E12,2))-FIND(",",ROUND(E12,2))))*10,TRIM(RIGHT(ROUND(E12,2),LEN(ROUND(E12,2))-FIND(",",ROUND(E12,2))))*1)>=10,CHOOSE(LEFT(RIGHT(IF(LEN(TRIM(RIGHT(ROUND(E12,2),LEN(ROUND(E12,2))-FIND(",",ROUND(E12,2)))))<2,TRIM(RIGHT(ROUND(E12,2),LEN(ROUND(E12,2))-FIND(",",ROUND(E12,2))))*10,TRIM(RIGHT(ROUND(E12,2),LEN(ROUND(E12,2))-FIND(",",ROUND(E12,2))))*1),2),1)+1,"","on","yirmi","otuz","kırk","elli","altmış","yetmiş","seksen","doksan"),"")&CHOOSE(MOD(IF(LEN(TRIM(RIGHT(ROUND(E12,2),LEN(ROUND(E12,2))-FIND(",",ROUND(E12,2)))))<2,TRIM(RIGHT(ROUND(E12,2),LEN(ROUND(E12,2))-FIND(",",ROUND(E12,2))))*10,TRIM(RIGHT(ROUND(E12,2),LEN(ROUND(E12,2))-FIND(",",ROUND(E12,2))))*1),10)+1,"","bir","iki","üç","dört","beş","altı","yedi","sekiz","dokuz")) & " Kr") -> İkibin TL | G12: =G11 -> NAKDEN | H12: 10. Taksit
